{
  "Mayavi": {
    "urls": [
      "https://bugzilla.redhat.com/show_bug.cgi?id=2351390"
    ],
    "summaries": [
      "Mayavi fails to build with Python 3.14: TestMayaviGarbageCollection.test_mlab_scene_model_with_gui: IndexError: list index out of range"
    ]
  },
  "asv": {
    "urls": [
      "https://bugzilla.redhat.com/show_bug.cgi?id=2367256",
      "https://bugzilla.redhat.com/show_bug.cgi?id=2339908"
    ],
    "summaries": [
      "asv fails to build with Python 3.14: AttributeError: 'Constant' object has no attribute 's'",
      "asv: FTBFS in Fedora rawhide/f42"
    ]
  },
  "bandit": {
    "urls": [
      "https://bugzilla.redhat.com/show_bug.cgi?id=2351393"
    ],
    "summaries": [
      "bandit fails to build with Python 3.14: TypeError: Error: Str is not a valid node type in AST"
    ]
  },
  "binwalk": {
    "urls": [
      "https://bugzilla.redhat.com/show_bug.cgi?id=2336914"
    ],
    "summaries": [
      "binwalk fails to build with Python 3.14: TypeError: unsupported operand type(s) for +=: 'NoneType' and 'int'"
    ]
  },
  "borgbackup": {
    "urls": [
      "https://bugzilla.redhat.com/show_bug.cgi?id=2326916"
    ],
    "summaries": [
      "borgbackup fails to build with Python 3.14: OSError: AF_UNIX path too long when compiling"
    ]
  },
  "calibre": {
    "urls": [
      "https://bugzilla.redhat.com/show_bug.cgi?id=2371688"
    ],
    "summaries": [
      "F43FailsToInstall: calibre, FTBFS: Bus error (core dumped)"
    ]
  },
  "cantera": {
    "urls": [
      "https://bugzilla.redhat.com/show_bug.cgi?id=2371689"
    ],
    "summaries": [
      "F43FailsToInstall: python3-cantera"
    ]
  },
  "capstone": {
    "urls": [
      "https://bugzilla.redhat.com/show_bug.cgi?id=2345714"
    ],
    "summaries": [
      "capstone fails to build with Python 3.14: from capstone import *: ImportError: ERROR: fail to load the dynamic library"
    ]
  },
  "chirp": {
    "urls": [
      "https://bugzilla.redhat.com/show_bug.cgi?id=2361634"
    ],
    "summaries": [
      "chirp FTBFS in rawhide"
    ]
  },
  "cjdns": {
    "urls": [
      "https://bugzilla.redhat.com/show_bug.cgi?id=2339969"
    ],
    "summaries": [
      "cjdns: FTBFS in Fedora rawhide/f42"
    ]
  },
  "copr-backend": {
    "urls": [
      "https://bugzilla.redhat.com/show_bug.cgi?id=2351386"
    ],
    "summaries": [
      "copr-backend fails to build with Python 3.14: TestActionWorkerManager.test_add_task_for_running_worker: TypeError: cannot pickle 'itertools.count' object"
    ]
  },
  "diceware": {
    "urls": [
      "https://bugzilla.redhat.com/show_bug.cgi?id=2340075",
      "https://bugzilla.redhat.com/show_bug.cgi?id=2329832"
    ],
    "summaries": [
      "diceware: FTBFS in Fedora rawhide/f42",
      "diceware fails to build with sphinx 8.x: ERROR: Invalid value `None` in intersphinx_mapping['http://docs.python.org/']."
    ]
  },
  "dlib": {
    "urls": [
      "https://bugzilla.redhat.com/show_bug.cgi?id=2366197"
    ],
    "summaries": [
      "dlib fails to build with Python 3.14: AssertionError in tests checking refcounting"
    ]
  },
  "git-filter-repo": {
    "urls": [
      "https://bugzilla.redhat.com/show_bug.cgi?id=2365637"
    ],
    "summaries": [
      "git-filter-repo fails to build with Python 3.14: == t9394-filter-repo-sanity-checks-and-bigger-repo-setup.sh == --replace-text all options not ok"
    ]
  },
  "httpie": {
    "urls": [
      "https://bugzilla.redhat.com/show_bug.cgi?id=2350335"
    ],
    "summaries": [
      "httpie fails to build with Python 3.14: test_lazy_choices_help: AssertionError: Expected 'getter' to not have been called. Called 1 times."
    ]
  },
  "ikiwiki": {
    "urls": [
      "https://bugzilla.redhat.com/show_bug.cgi?id=2340642"
    ],
    "summaries": [
      "ikiwiki-3.20200202.4-4.fc43 FTBFS: Installed (but unpackaged) file(s) found: /usr/sbin/ikiwiki-mass-rebuild"
    ]
  },
  "kurchu": {
    "urls": [
      "https://bugzilla.redhat.com/show_bug.cgi?id=2371734"
    ],
    "summaries": [
      "F43FailsToInstall: kurchu"
    ]
  },
  "libpeas": {
    "urls": [
      "https://bugzilla.redhat.com/show_bug.cgi?id=2366247"
    ],
    "summaries": [
      "libpeas fails to build with Python 3.14: test-extension-py  TIMEOUT"
    ]
  },
  "libunity": {
    "urls": [
      "https://bugzilla.redhat.com/show_bug.cgi?id=2368739"
    ],
    "summaries": [
      "libunity: FTBFS in Fedora Rawhide (probably since gettext 0.25)"
    ]
  },
  "linode-cli": {
    "urls": [
      "https://bugzilla.redhat.com/show_bug.cgi?id=2368974",
      "https://bugzilla.redhat.com/show_bug.cgi?id=2340775"
    ],
    "summaries": [
      "linode-cli fails to build with Python 3.14: The current dist-git state is unbuildable",
      "linode-cli: FTBFS in Fedora rawhide/f42"
    ]
  },
  "monkeytype": {
    "urls": [
      "https://bugzilla.redhat.com/show_bug.cgi?id=2356179"
    ],
    "summaries": [
      "monkeytype fails to build with Python 3.14: typing.Union changed with Python 3.14.0a6"
    ]
  },
  "mopidy": {
    "urls": [
      "https://bugzilla.redhat.com/show_bug.cgi?id=2367738"
    ],
    "summaries": [
      "mopidy fails to build with Python 3.14:  RuntimeError: unable to get value"
    ]
  },
  "ocrmypdf": {
    "urls": [
      "https://bugzilla.redhat.com/show_bug.cgi?id=2357508"
    ],
    "summaries": [
      "ocrmypdf fails to build with Python 3.14: multiprocessing.Process now starts with forkserver method instead of fork, causing pickling error"
    ]
  },
  "opencv": {
    "urls": [
      "https://bugzilla.redhat.com/show_bug.cgi?id=2368529"
    ],
    "summaries": [
      "opencv fails to build with Python 3.14: a failure in the %build phase"
    ]
  },
  "patool": {
    "urls": [
      "https://bugzilla.redhat.com/show_bug.cgi?id=2366470"
    ],
    "summaries": [
      "patool fails to build with Python 3.14: Codec Load Error: /usr/bin/7z.so : errno=25 : Inappropriate ioctl for device"
    ]
  },
  "pcs": {
    "urls": [
      "https://bugzilla.redhat.com/show_bug.cgi?id=2371770"
    ],
    "summaries": [
      "F43FailsToInstall: pcs, pcs-web-ui"
    ]
  },
  "petsc": {
    "urls": [
      "https://bugzilla.redhat.com/show_bug.cgi?id=2359524"
    ],
    "summaries": [
      "petsc fails to build with Python 3.14: AssertionError: 2 != 3 self.assertEqual(getrefcount(ctx), 3)"
    ]
  },
  "protobuf": {
    "urls": [
      "https://bugzilla.redhat.com/show_bug.cgi?id=2343969"
    ],
    "summaries": [
      "protobuf doesn't build on s390x and i686, blocking the Python 3.14 rebuild"
    ]
  },
  "pychess": {
    "urls": [
      "https://bugzilla.redhat.com/show_bug.cgi?id=2328708"
    ],
    "summaries": [
      "pychess fails to build with Python 3.14: RuntimeError: There is no current event loop in thread 'MainThread'."
    ]
  },
  "pylibacl": {
    "urls": [
      "https://bugzilla.redhat.com/show_bug.cgi?id=2359502"
    ],
    "summaries": [
      "pylibacl fails to build with Python 3.14: tests/test_acls.py::TestModification: Failed: Wrong reference count, expected 2-1024 and got 1"
    ]
  },
  "pylint": {
    "urls": [
      "https://bugzilla.redhat.com/show_bug.cgi?id=2368703"
    ],
    "summaries": [
      "pylint fails to build with Python 3.14: AssertionError tests/test_functional.py::test_functional"
    ]
  },
  "pyproj": {
    "urls": [
      "https://bugzilla.redhat.com/show_bug.cgi?id=2371782"
    ],
    "summaries": [
      "F43FailsToInstall: python3-pyproj"
    ]
  },
  "pyserial-asyncio": {
    "urls": [
      "https://bugzilla.redhat.com/show_bug.cgi?id=2327980"
    ],
    "summaries": [
      "pyserial-asyncio fails to build with Python 3.14: RuntimeError: There is no current event loop in thread 'MainThread'."
    ]
  },
  "pysubnettree": {
    "urls": [
      "https://bugzilla.redhat.com/show_bug.cgi?id=2366464",
      "https://bugzilla.redhat.com/show_bug.cgi?id=2341123"
    ],
    "summaries": [
      "pysubnettree fails to build with Python 3.14/Fedora Rawhide: error: too many arguments to function \u2018func\u2019; expected 0, have 1",
      "pysubnettree: FTBFS in Fedora rawhide/f42"
    ]
  },
  "python-Mastodon": {
    "urls": [
      "https://bugzilla.redhat.com/show_bug.cgi?id=2369422"
    ],
    "summaries": [
      "python-Mastodon fails to build with Python 3.14: ValueError: Unknown type <something> | None"
    ]
  },
  "python-TestSlide": {
    "urls": [
      "https://bugzilla.redhat.com/show_bug.cgi?id=2371789",
      "https://bugzilla.redhat.com/show_bug.cgi?id=2350306",
      "https://bugzilla.redhat.com/show_bug.cgi?id=2343971"
    ],
    "summaries": [
      "F43FailsToInstall: python3-testslide",
      "Heads-up: python-TestSlide fails to build with python-pygments 2.19.1 on Fedora 43",
      "python-TestSlide fails to build with Python 3.14: ERROR collecting tests/mock_callable_testslide.py: RuntimeError: dictionary changed size during iteration"
    ]
  },
  "python-aiokafka": {
    "urls": [
      "https://bugzilla.redhat.com/show_bug.cgi?id=2346517"
    ],
    "summaries": [
      "python-aiokafka fails to build with Python 3.14: DeprecationWarning: 'asyncio.get_event_loop_policy' is deprecated and slated for removal in Python 3.16"
    ]
  },
  "python-ansible-runner": {
    "urls": [
      "https://bugzilla.redhat.com/show_bug.cgi?id=2371793"
    ],
    "summaries": [
      "F43FailsToInstall: python3-ansible-runner"
    ]
  },
  "python-astdoc": {
    "urls": [
      "https://bugzilla.redhat.com/show_bug.cgi?id=2349452"
    ],
    "summaries": [
      "python-astdoc fails to build with Python 3.14: 3 doctests fail, e.g.: Expected: <ast.Name object at 0x...> Got: Name(id='int', ctx=Load())"
    ]
  },
  "python-avocado": {
    "urls": [
      "https://bugzilla.redhat.com/show_bug.cgi?id=2341130",
      "https://bugzilla.redhat.com/show_bug.cgi?id=2325218"
    ],
    "summaries": [
      "python-avocado: FTBFS in Fedora rawhide/f42",
      "python-avocado fails to build with Python 3.14: Error running method \"pre_tests\" of plugin \"fetchasset\": module 'ast' has no attribute 'Str' + Avocado crashed: TypeError: cannot pickle '_thread.RLock' object"
    ]
  },
  "python-awesomeversion": {
    "urls": [
      "https://bugzilla.redhat.com/show_bug.cgi?id=2366476"
    ],
    "summaries": [
      "python-awesomeversion fails to build in Fedora Rawhide: rm: cannot remove '/builddir/build/BUILD/python-awesomeversion-22.9.0-build/BUILDROOT//usr/lib/python3.14/site-packages/LICENCE.md': No such file or directory"
    ]
  },
  "python-beancount": {
    "urls": [
      "https://bugzilla.redhat.com/show_bug.cgi?id=2359530"
    ],
    "summaries": [
      "python-beancount fails to build with Python 3.14: TestReferenceCounting and TestLexer fail with AssertionError"
    ]
  },
  "python-beartype": {
    "urls": [
      "https://bugzilla.redhat.com/show_bug.cgi?id=2341131",
      "https://bugzilla.redhat.com/show_bug.cgi?id=2322721"
    ],
    "summaries": [
      "python-beartype: FTBFS in Fedora rawhide/f42",
      "python-beartype fails to build with Python 3.14: ImportError: cannot import name 'ByteString' from 'typing'"
    ]
  },
  "python-billiard": {
    "urls": [
      "https://bugzilla.redhat.com/show_bug.cgi?id=2323167"
    ],
    "summaries": [
      "python-billiard fails to build with Python 3.14: AttributeError: module 'subprocess' has no attribute '_USE_VFORK'"
    ]
  },
  "python-boutdata": {
    "urls": [
      "https://bugzilla.redhat.com/show_bug.cgi?id=2371821"
    ],
    "summaries": [
      "F43FailsToInstall: python3-boutdata"
    ]
  },
  "python-capturer": {
    "urls": [
      "https://bugzilla.redhat.com/show_bug.cgi?id=2328004"
    ],
    "summaries": [
      "python-capturer fails to build with Python 3.14: OSError: [Errno 29] Illegal seek"
    ]
  },
  "python-catkin_tools": {
    "urls": [
      "https://bugzilla.redhat.com/show_bug.cgi?id=2341134",
      "https://bugzilla.redhat.com/show_bug.cgi?id=2329848"
    ],
    "summaries": [
      "python-catkin_tools: FTBFS in Fedora rawhide/f42",
      "python-catkin_tools fails to build with sphinx 8.x:  ERROR: Invalid value `None` in intersphinx_mapping['http://docs.python.org/']."
    ]
  },
  "python-cerberus": {
    "urls": [
      "https://bugzilla.redhat.com/show_bug.cgi?id=2366466"
    ],
    "summaries": [
      "python-cerberus fails to build in Fedora Rawhide:  File not found: /builddir/build/BUILD/python-cerberus-1.3.4-build/BUILDROOT/usr/lib/python3.14/site-packages/Cerberus-1.3.4.dist-info"
    ]
  },
  "python-chalice": {
    "urls": [
      "https://bugzilla.redhat.com/show_bug.cgi?id=2342568"
    ],
    "summaries": [
      "python-chalice fails to build with Python 3.14: AttributeError: module 'ast' has no attribute 'Str'"
    ]
  },
  "python-colcon-meson": {
    "urls": [
      "https://bugzilla.redhat.com/show_bug.cgi?id=2368744"
    ],
    "summaries": [
      "python-colcon-meson fails to build with Python 3.14: test_capital_case: TypeError: InterpreterBase.__init__() missing 2 required positional arguments: 'subproject_dir' and 'env'"
    ]
  },
  "python-colcon-parallel-executor": {
    "urls": [
      "https://bugzilla.redhat.com/show_bug.cgi?id=2325186"
    ],
    "summaries": [
      "python-colcon-parallel-executor fails to build with Python 3.14: test_parallel: AssertionError: DeprecationWarning: 'asyncio.iscoroutinefunction' is deprecated and slated for removal in Python 3.16; use inspect.iscoroutinefunction() instead"
    ]
  },
  "python-colorful": {
    "urls": [
      "https://bugzilla.redhat.com/show_bug.cgi?id=2325168"
    ],
    "summaries": [
      "python-colorful fails to build with Python 3.14: ast.Constant.s has been removed from Python 3.14"
    ]
  },
  "python-confuse": {
    "urls": [
      "https://bugzilla.redhat.com/show_bug.cgi?id=2327966"
    ],
    "summaries": [
      "python-confuse fails to build with Python 3.14: AttributeError: module 'pkgutil' has no attribute 'get_loader'"
    ]
  },
  "python-crcmod": {
    "urls": [
      "https://bugzilla.redhat.com/show_bug.cgi?id=2329852"
    ],
    "summaries": [
      "python-crcmod fails to build with sphinx 8.x: ERROR: Invalid value `None` in intersphinx_mapping['/usr/share/doc/python3-docs/html/']."
    ]
  },
  "python-crick": {
    "urls": [
      "https://bugzilla.redhat.com/show_bug.cgi?id=2367454"
    ],
    "summaries": [
      "python-crick fails to build with Python 3.14: crick/tests/test_space_saving.py::test_merge_algorithm[s111-s211] Fatal Python error: Segmentation fault"
    ]
  },
  "python-dataclassy": {
    "urls": [
      "https://bugzilla.redhat.com/show_bug.cgi?id=2325200"
    ],
    "summaries": [
      "python-dataclassy fails to build with Python 3.14: TypeError: Beta() takes no arguments"
    ]
  },
  "python-diff-cover": {
    "urls": [
      "https://bugzilla.redhat.com/show_bug.cgi?id=2350299"
    ],
    "summaries": [
      "Heads-up: python-diff-cover fails to build with python-pygments 2.19.1 on Fedora 43"
    ]
  },
  "python-django-configurations": {
    "urls": [
      "https://bugzilla.redhat.com/show_bug.cgi?id=2366494"
    ],
    "summaries": [
      "python-django-configurations fails to build with Python 3.14: ValueTests.test_cache_url_value: AssertionError:"
    ]
  },
  "python-django-contrib-comments": {
    "urls": [
      "https://bugzilla.redhat.com/show_bug.cgi?id=2366520"
    ],
    "summaries": [
      "python-django-contrib-comments fails to build with Python 3.14: ImportError: Module \"django.contrib.auth.hashers\" does not define a \"UnsaltedMD5PasswordHasher\" attribute/class"
    ]
  },
  "python-django-filter": {
    "urls": [
      "https://bugzilla.redhat.com/show_bug.cgi?id=2336944"
    ],
    "summaries": [
      "python-django-filter fails to build with Python 3.14: AttributeError: module 'pkgutil' has no attribute 'find_loader'"
    ]
  },
  "python-dunamai": {
    "urls": [
      "https://bugzilla.redhat.com/show_bug.cgi?id=2371874"
    ],
    "summaries": [
      "F43FailsToInstall: python3-dunamai"
    ]
  },
  "python-envisage": {
    "urls": [
      "https://bugzilla.redhat.com/show_bug.cgi?id=2369420"
    ],
    "summaries": [
      "python-envisage: FTBFS in Fedora Rawhide: ModuleNotFoundError: No module named 'configobj'"
    ]
  },
  "python-exdir": {
    "urls": [
      "https://bugzilla.redhat.com/show_bug.cgi?id=2367253"
    ],
    "summaries": [
      "python-exdir fails to build with Python 3.14: TypeError: 'module' object is not iterable | TypeError: 'Plugin' object is not iterable"
    ]
  },
  "python-fiat": {
    "urls": [
      "https://bugzilla.redhat.com/show_bug.cgi?id=2371903"
    ],
    "summaries": [
      "F43FailsToInstall: python3-fiat"
    ]
  },
  "python-flake8-comprehensions": {
    "urls": [
      "https://bugzilla.redhat.com/show_bug.cgi?id=2351385"
    ],
    "summaries": [
      "python-flake8-comprehensions fails to build with Python 3.14: Unnecessary reversed call around sorted() in 10 tests"
    ]
  },
  "python-flask-session": {
    "urls": [
      "https://bugzilla.redhat.com/show_bug.cgi?id=2354108"
    ],
    "summaries": [
      "python-flask-session FTBFS due to missing tox configuration"
    ]
  },
  "python-fsleyes-widgets": {
    "urls": [
      "https://bugzilla.redhat.com/show_bug.cgi?id=2336911"
    ],
    "summaries": [
      "python-fsleyes-widgets fails to build with Python 3.14: AssertionError: assert 'file:/home/b...htmlfile.html' == 'file:///home...htmlfile.html'"
    ]
  },
  "python-gphoto2": {
    "urls": [
      "https://bugzilla.redhat.com/show_bug.cgi?id=2366465",
      "https://bugzilla.redhat.com/show_bug.cgi?id=2341158"
    ],
    "summaries": [
      "python-gphoto2 fails to build with Python 3.14: ModuleNotFoundError: No module named 'distutils.command.upload'",
      "python-gphoto2: FTBFS in Fedora rawhide/f42"
    ]
  },
  "python-h5netcdf": {
    "urls": [
      "https://bugzilla.redhat.com/show_bug.cgi?id=2325222"
    ],
    "summaries": [
      "python-h5netcdf fails to build with Python 3.14: test_no_circular_references: AssertionError"
    ]
  },
  "python-howdoi": {
    "urls": [
      "https://bugzilla.redhat.com/show_bug.cgi?id=2342558"
    ],
    "summaries": [
      "python-howdoi fails to build with Python 3.14: AssertionError: 'ERROR: Unable to reach google. Do you need to use a proxy? + json.decoder.JSONDecodeError"
    ]
  },
  "python-inject": {
    "urls": [
      "https://bugzilla.redhat.com/show_bug.cgi?id=2327978"
    ],
    "summaries": [
      "python-inject fails to build with Python 3.14: RuntimeError: There is no current event loop in thread 'MainThread'."
    ]
  },
  "python-invoke": {
    "urls": [
      "https://bugzilla.redhat.com/show_bug.cgi?id=2365652"
    ],
    "summaries": [
      "python-invoke fails to build with Python 3.14: SystemError: buffer overflow in 16 tests"
    ]
  },
  "python-ipfshttpclient": {
    "urls": [
      "https://bugzilla.redhat.com/show_bug.cgi?id=2368589"
    ],
    "summaries": [
      "python-ipfshttpclient fails to build with Python 3.14: AssertionError: assert ['(?![.])(?s:literal)\\\\z'] == ['(?![.])(?s:literal)\\\\Z']"
    ]
  },
  "python-janus": {
    "urls": [
      "https://bugzilla.redhat.com/show_bug.cgi?id=2371953"
    ],
    "summaries": [
      "F43FailsToInstall: python3-janus"
    ]
  },
  "python-josepy": {
    "urls": [
      "https://bugzilla.redhat.com/show_bug.cgi?id=2359514"
    ],
    "summaries": [
      "python-josepy fails to build with Python 3.14: ValueError: Field `alg` in JSONObject `Header` has no type annotation."
    ]
  },
  "python-markups": {
    "urls": [
      "https://bugzilla.redhat.com/show_bug.cgi?id=2366489"
    ],
    "summaries": [
      "python-markups fails to build with Python 3.14: AssertionError in test_get_pygments_stylesheet"
    ]
  },
  "python-msal": {
    "urls": [
      "https://bugzilla.redhat.com/show_bug.cgi?id=2323170"
    ],
    "summaries": [
      "python-msal fails to build with Python 3.14: test_no_two_concurrent_receivers_can_listen_on_same_port: AssertionError: OSError not raised"
    ]
  },
  "python-neatdend": {
    "urls": [
      "https://bugzilla.redhat.com/show_bug.cgi?id=2341170"
    ],
    "summaries": [
      "python-neatdend: FTBFS in Fedora rawhide/f42"
    ]
  },
  "python-niaarmts": {
    "urls": [
      "https://bugzilla.redhat.com/show_bug.cgi?id=2369421"
    ],
    "summaries": [
      "python-niaarmts fails to build with Python 3.14: ERROR: Package 'niaarmts' requires a different Python: 3.14.0 not in '<3.14,>=3.11'"
    ]
  },
  "python-octave-kernel": {
    "urls": [
      "https://bugzilla.redhat.com/show_bug.cgi?id=2341176"
    ],
    "summaries": [
      "python-octave-kernel: FTBFS in Fedora rawhide/f42"
    ]
  },
  "python-pamela": {
    "urls": [
      "https://bugzilla.redhat.com/show_bug.cgi?id=2366474"
    ],
    "summaries": [
      "python-pamela fails to build with Python 3.14: pamela.PAMError: [PAM Error 26] Critical error - immediate abort"
    ]
  },
  "python-pkginfo2": {
    "urls": [
      "https://bugzilla.redhat.com/show_bug.cgi?id=2366490"
    ],
    "summaries": [
      "python-pkginfo2: FTBFS in Fedora Rawhide: AssertionError: None != '30.0.0'"
    ]
  },
  "python-praw": {
    "urls": [
      "https://bugzilla.redhat.com/show_bug.cgi?id=2342562"
    ],
    "summaries": [
      "python-praw fails to build with Python 3.14: RuntimeError: There is no current event loop in thread 'MainThread'."
    ]
  },
  "python-pudb": {
    "urls": [
      "https://bugzilla.redhat.com/show_bug.cgi?id=2365643"
    ],
    "summaries": [
      "python-pudb fails to build with Python 3.14: ImportError: cannot import name 'format_exception' from 'pudb.lowlevel'"
    ]
  },
  "python-pure-protobuf": {
    "urls": [
      "https://bugzilla.redhat.com/show_bug.cgi?id=2322710"
    ],
    "summaries": [
      "python-pure-protobuf fails to build with Python 3.14: ImportError: cannot import name 'ByteString' from 'typing'"
    ]
  },
  "python-pycec": {
    "urls": [
      "https://bugzilla.redhat.com/show_bug.cgi?id=2327973"
    ],
    "summaries": [
      "python-pycec fails to build with Python 3.14: RuntimeError: There is no current event loop in thread 'MainThread'."
    ]
  },
  "python-pydantic-core": {
    "urls": [
      "https://bugzilla.redhat.com/show_bug.cgi?id=2325425"
    ],
    "summaries": [
      "python-pydantic-core fails to build with Python 3.14: AssertionError: Regex pattern did not match. + AttributeError: module 'typing' has no attribute 'ByteString'"
    ]
  },
  "python-pyemd": {
    "urls": [
      "https://bugzilla.redhat.com/show_bug.cgi?id=2319698"
    ],
    "summaries": [
      "python-pyemd fails to build with setuptools 74+"
    ]
  },
  "python-pymdown-extensions": {
    "urls": [
      "https://bugzilla.redhat.com/show_bug.cgi?id=2372063",
      "https://bugzilla.redhat.com/show_bug.cgi?id=2350300",
      "https://bugzilla.redhat.com/show_bug.cgi?id=2336948"
    ],
    "summaries": [
      "F43FailsToInstall: python3-pymdown-extensions+extra, python3-pymdown-extensions",
      "Heads-up: python-pymdown-extensions fails to build with python-pygments 2.19.1 on Fedora 43",
      "python-pymdown-extensions fails to build with Python 3.14: TestAbsolute.test_relative_path and TestAbsoluteFileScheme.test_relative_path AssertionErrors"
    ]
  },
  "python-pymeeus": {
    "urls": [
      "https://bugzilla.redhat.com/show_bug.cgi?id=2341186",
      "https://bugzilla.redhat.com/show_bug.cgi?id=2329890"
    ],
    "summaries": [
      "python-pymeeus: FTBFS in Fedora rawhide/f42",
      "python-pymeeus fails to build with sphinx 8.x: ERROR: Invalid value `None` in intersphinx_mapping['https://docs.python.org/']."
    ]
  },
  "python-pymongo": {
    "urls": [
      "https://bugzilla.redhat.com/show_bug.cgi?id=2356166",
      "https://bugzilla.redhat.com/show_bug.cgi?id=2341188"
    ],
    "summaries": [
      "python-pymongo fails to build with Python 3.14: DeprecationWarning: 'asyncio.iscoroutinefunction' and 'asyncio.get_event_loop_policy' is deprecated and slated for removal in Python 3.16",
      "python-pymongo: FTBFS in Fedora rawhide/f42"
    ]
  },
  "python-pyopencl": {
    "urls": [
      "https://bugzilla.redhat.com/show_bug.cgi?id=2341190"
    ],
    "summaries": [
      "python-pyopencl: FTBFS in Fedora rawhide/f42"
    ]
  },
  "python-pyopengl": {
    "urls": [
      "https://bugzilla.redhat.com/show_bug.cgi?id=2341191"
    ],
    "summaries": [
      "python-pyopengl: FTBFS in Fedora rawhide/f42"
    ]
  },
  "python-pytest-lsp": {
    "urls": [
      "https://bugzilla.redhat.com/show_bug.cgi?id=2349451"
    ],
    "summaries": [
      "python-pytest-lsp fails to build with Python 3.14: warnings counts differ, resulting in AssertionError in 3 tests"
    ]
  },
  "python-pytest-twisted": {
    "urls": [
      "https://bugzilla.redhat.com/show_bug.cgi?id=2368594"
    ],
    "summaries": [
      "python-pytest-twisted fails to build with Python 3.14: RuntimeError: There is no current event loop in thread 'MainThread'."
    ]
  },
  "python-pyupgrade": {
    "urls": [
      "https://bugzilla.redhat.com/show_bug.cgi?id=2322713"
    ],
    "summaries": [
      "python-pyupgrade fails to build with Python 3.14: AttributeError: module 'ast' has no attribute 'Str'"
    ]
  },
  "python-pyvlx": {
    "urls": [
      "https://bugzilla.redhat.com/show_bug.cgi?id=2327983"
    ],
    "summaries": [
      "python-pyvlx fails to build with Python 3.14: RuntimeError: There is no current event loop in thread 'MainThread'."
    ]
  },
  "python-readability-lxml": {
    "urls": [
      "https://bugzilla.redhat.com/show_bug.cgi?id=2323185"
    ],
    "summaries": [
      "python-readability-lxml fails to build with Python 3.14: _pickle.PicklingError: Can't pickle <function TestArticleOnly.test_many_repeated_spaces at 0x7ff0ea064460>: it's not the same object as tests.test_article_only.TestArticleOnly.test_many_repeated_spa"
    ]
  },
  "python-recordclass": {
    "urls": [
      "https://bugzilla.redhat.com/show_bug.cgi?id=2327968"
    ],
    "summaries": [
      "python-recordclass fails to build with Python 3.14: 25 failures, 65 errors in the test suite"
    ]
  },
  "python-remoto": {
    "urls": [
      "https://bugzilla.redhat.com/show_bug.cgi?id=2366491",
      "https://bugzilla.redhat.com/show_bug.cgi?id=2341205"
    ],
    "summaries": [
      "python-remoto fails to build with Python 3.14: AttributeError: 'TestRemoteError' object has no attribute 'traceback'",
      "python-remoto: FTBFS in Fedora rawhide/f42"
    ]
  },
  "python-rosdep": {
    "urls": [
      "https://bugzilla.redhat.com/show_bug.cgi?id=2341207",
      "https://bugzilla.redhat.com/show_bug.cgi?id=2329891"
    ],
    "summaries": [
      "python-rosdep: FTBFS in Fedora rawhide/f42",
      "python-rosdep fails to build with sphinx 8.x: ERROR: Invalid value `None` in intersphinx_mapping['http://docs.python.org/']."
    ]
  },
  "python-rstcheck": {
    "urls": [
      "https://bugzilla.redhat.com/show_bug.cgi?id=2322705"
    ],
    "summaries": [
      "python-rstcheck fails to build with Python 3.14: AttributeError: 'Constant' object has no attribute 's'"
    ]
  },
  "python-rx": {
    "urls": [
      "https://bugzilla.redhat.com/show_bug.cgi?id=2327979"
    ],
    "summaries": [
      "python-rx fails to build with Python 3.14: RuntimeError: There is no current event loop in thread 'MainThread'."
    ]
  },
  "python-simframe": {
    "urls": [
      "https://bugzilla.redhat.com/show_bug.cgi?id=2352552"
    ],
    "summaries": [
      "python-simframe fails to build with Python 3.14: TypeError: cannot pickle 'itertools.cycle' object"
    ]
  },
  "python-streamlink": {
    "urls": [
      "https://bugzilla.redhat.com/show_bug.cgi?id=2353127"
    ],
    "summaries": [
      "python-streamlink fails to build with Python 3.14: test_deprecated: AssetionError: Left contains one more item: <warnings.WarningMessage object at 0x7fd80afa3410>"
    ]
  },
  "python-telnetlib3": {
    "urls": [
      "https://bugzilla.redhat.com/show_bug.cgi?id=2354126"
    ],
    "summaries": [
      "python-telnetlib3 FTBFS due to missing tox configuration"
    ]
  },
  "python-tenacity": {
    "urls": [
      "https://bugzilla.redhat.com/show_bug.cgi?id=2327977"
    ],
    "summaries": [
      "python-tenacity fails to build with Python 3.14: RuntimeError: There is no current event loop in thread 'MainThread'."
    ]
  },
  "python-textual": {
    "urls": [
      "https://bugzilla.redhat.com/show_bug.cgi?id=2367457",
      "https://bugzilla.redhat.com/show_bug.cgi?id=2341224"
    ],
    "summaries": [
      "python-textual fails to build with Python 3.14: RuntimeError: There is no current event loop in thread 'MainThread'.",
      "python-textual: FTBFS in Fedora rawhide/f42"
    ]
  },
  "python-toolz": {
    "urls": [
      "https://bugzilla.redhat.com/show_bug.cgi?id=2323168"
    ],
    "summaries": [
      "python-toolz fails to build with Python 3.14: AssertionError: is_none: assert should_curry(getattr(operator, k)) == isinstance(v, toolz.curry), k"
    ]
  },
  "python-torch": {
    "urls": [
      "https://bugzilla.redhat.com/show_bug.cgi?id=2372164"
    ],
    "summaries": [
      "F43FailsToInstall: python3-torch"
    ]
  },
  "python-towncrier": {
    "urls": [
      "https://bugzilla.redhat.com/show_bug.cgi?id=2354131"
    ],
    "summaries": [
      "python-towncrier FTBFS due to missing tox configuration"
    ]
  },
  "python-tpm2-pytss": {
    "urls": [
      "https://bugzilla.redhat.com/show_bug.cgi?id=2372172"
    ],
    "summaries": [
      "F43FailsToInstall: python3-tpm2-pytss"
    ]
  },
  "python-txaio": {
    "urls": [
      "https://bugzilla.redhat.com/show_bug.cgi?id=2327981"
    ],
    "summaries": [
      "python-txaio fails to build with Python 3.14: RuntimeError: There is no current event loop in thread 'MainThread'."
    ]
  },
  "python-typing-inspect": {
    "urls": [
      "https://bugzilla.redhat.com/show_bug.cgi?id=2325455"
    ],
    "summaries": [
      "python-typing-inspect fails to build with Python 3.14: AssertionError: {} != {'x': <class 'int'>, 'y': <class 'int'>}"
    ]
  },
  "python-uvloop": {
    "urls": [
      "https://bugzilla.redhat.com/show_bug.cgi?id=2341233",
      "https://bugzilla.redhat.com/show_bug.cgi?id=2326210"
    ],
    "summaries": [
      "python-uvloop: FTBFS in Fedora rawhide/f42",
      "python-uvloop fails to build with Python 3.14: AttributeError: module 'asyncio' has no attribute 'AbstractChildWatcher'"
    ]
  },
  "python-valkey": {
    "urls": [
      "https://bugzilla.redhat.com/show_bug.cgi?id=2349444"
    ],
    "summaries": [
      "python-valkey fails to build with Python 3.14: _pickle.PicklingError: Can't pickle local object <function TestMultiprocessing.test_close_connection_in_child.<locals>.target at 0x7f5aa68cddd0>"
    ]
  },
  "python-wordcloud": {
    "urls": [
      "https://bugzilla.redhat.com/show_bug.cgi?id=2335908"
    ],
    "summaries": [
      "python-wordcloud fails to build with Python 3.14: test_cli_as_executable: AssertionError: assert expected_output in out if ret_code == 0 else err"
    ]
  },
  "python-yappi": {
    "urls": [
      "https://bugzilla.redhat.com/show_bug.cgi?id=2323160"
    ],
    "summaries": [
      "python-yappi fails to build with Python 3.14: error: invalid use of incomplete typedef \u2018PyGenObject\u2019 {aka \u2018struct _PyGenObject\u2019}"
    ]
  },
  "python3-exiv2": {
    "urls": [
      "https://bugzilla.redhat.com/show_bug.cgi?id=2354137"
    ],
    "summaries": [
      "python3-exiv2 FTBFS due to missing tox configuration"
    ]
  },
  "qtile": {
    "urls": [
      "https://bugzilla.redhat.com/show_bug.cgi?id=2328711"
    ],
    "summaries": [
      "qtile fails to build with Python 3.14: _pickle.PicklingError: Can't pickle local object <function TestManager.start.<locals>.run_qtile at 0x7f9c5918fed0>"
    ]
  },
  "rebase-helper": {
    "urls": [
      "https://bugzilla.redhat.com/show_bug.cgi?id=2352551"
    ],
    "summaries": [
      "rebase-helper fails to build with Python 3.14: AssertionError in TestCLI.test_cli_unit and TestConfig.test_merge"
    ]
  },
  "rpm-head-signing": {
    "urls": [
      "https://bugzilla.redhat.com/show_bug.cgi?id=2366308"
    ],
    "summaries": [
      "rpm-head-signing: FTBFS in Fedora Rawhide with RPM 6"
    ]
  },
  "rss2email": {
    "urls": [
      "https://bugzilla.redhat.com/show_bug.cgi?id=2368743"
    ],
    "summaries": [
      "rss2email fails to build with Python 3.14: ERROR: test_email_data/tails/1.config..."
    ]
  },
  "signon-glib": {
    "urls": [
      "https://bugzilla.redhat.com/show_bug.cgi?id=2341348"
    ],
    "summaries": [
      "signon-glib: FTBFS in Fedora rawhide/f42"
    ]
  },
  "strongswan": {
    "urls": [
      "https://bugzilla.redhat.com/show_bug.cgi?id=2368971",
      "https://bugzilla.redhat.com/show_bug.cgi?id=2332864"
    ],
    "summaries": [
      "strongswan: FTBFS in Fedora Rawhide: error: possibly undefined macro: AC_LIB_PREFIX",
      "strongswan-5.9.14-5.fc42 FTBFS: strongswan-5.9.14/missing: line 81: aclocal-1.16: command not found"
    ]
  },
  "subversion": {
    "urls": [
      "https://bugzilla.redhat.com/show_bug.cgi?id=2359500"
    ],
    "summaries": [
      "subversion fails to build with Python 3.14: AssertionError: 3 != 4 : Memory leak!  Expected a ref count of 4 for svn_merge_range_t object, but got 3 instead (path: b'/trunk', index: 0)"
    ]
  },
  "sugar": {
    "urls": [
      "https://bugzilla.redhat.com/show_bug.cgi?id=2368968"
    ],
    "summaries": [
      "sugar: FTBFS in Fedora Rawhide"
    ]
  },
  "sugar-toolkit-gtk3": {
    "urls": [
      "https://bugzilla.redhat.com/show_bug.cgi?id=2372229"
    ],
    "summaries": [
      "F43FailsToInstall: sugar-toolkit-gtk3"
    ]
  },
  "ufw": {
    "urls": [
      "https://bugzilla.redhat.com/show_bug.cgi?id=2366458",
      "https://bugzilla.redhat.com/show_bug.cgi?id=2341477"
    ],
    "summaries": [
      "ufw fails to build in Fedora Rawhide: File not found: /builddir/build/BUILD/ufw-0.35-build/BUILDROOT/usr/bin/ufw",
      "ufw: FTBFS in Fedora rawhide/f42"
    ]
  },
  "visidata": {
    "urls": [
      "https://bugzilla.redhat.com/show_bug.cgi?id=2325446"
    ],
    "summaries": [
      "visidata fails to build with Python 3.14: TestVisidataPath.test_withName: AssertionError: assert 'foo' == 'foo.'"
    ]
  },
  "weasyprint": {
    "urls": [
      "https://bugzilla.redhat.com/show_bug.cgi?id=2372240"
    ],
    "summaries": [
      "F43FailsToInstall: python3-weasyprint. Segmentation fault when building with Python 3.14"
    ]
  },
  "yt-dlp": {
    "urls": [
      "https://bugzilla.redhat.com/show_bug.cgi?id=2345522"
    ],
    "summaries": [
      "yt-dlp fails to build with Python 3.14: TestTraversal.test_traversal_morsel: AssertionError: `...` should yield all values: Left contains one more item: 'item_value'"
    ]
  },
  "zeek": {
    "urls": [
      "https://bugzilla.redhat.com/show_bug.cgi?id=2366467",
      "https://bugzilla.redhat.com/show_bug.cgi?id=2341601"
    ],
    "summaries": [
      "zeek fails to build in Fedora Rawhide: Could not find prerequisite package 'BIND'",
      "zeek: FTBFS in Fedora rawhide/f42"
    ]
  }
}