{
  "Mayavi": {
    "urls": [
      "https://bugzilla.redhat.com/show_bug.cgi?id=2351390"
    ],
    "summaries": [
      "Mayavi fails to build with Python 3.14: TestMayaviGarbageCollection.test_mlab_scene_model_with_gui: IndexError: list index out of range"
    ]
  },
  "asv": {
    "urls": [
      "https://bugzilla.redhat.com/show_bug.cgi?id=2367256",
      "https://bugzilla.redhat.com/show_bug.cgi?id=2339908"
    ],
    "summaries": [
      "asv fails to build with Python 3.14: AttributeError: 'Constant' object has no attribute 's'",
      "asv: FTBFS in Fedora rawhide/f42"
    ]
  },
  "bandit": {
    "urls": [
      "https://bugzilla.redhat.com/show_bug.cgi?id=2351393"
    ],
    "summaries": [
      "bandit fails to build with Python 3.14: TypeError: Error: Str is not a valid node type in AST"
    ]
  },
  "binwalk": {
    "urls": [
      "https://bugzilla.redhat.com/show_bug.cgi?id=2336914"
    ],
    "summaries": [
      "binwalk fails to build with Python 3.14: TypeError: unsupported operand type(s) for +=: 'NoneType' and 'int'"
    ]
  },
  "borgbackup": {
    "urls": [
      "https://bugzilla.redhat.com/show_bug.cgi?id=2326916"
    ],
    "summaries": [
      "borgbackup fails to build with Python 3.14: OSError: AF_UNIX path too long when compiling"
    ]
  },
  "buildstream": {
    "urls": [
      "https://bugzilla.redhat.com/show_bug.cgi?id=2371687"
    ],
    "summaries": [
      "F43FailsToInstall: buildstream"
    ]
  },
  "cantera": {
    "urls": [
      "https://bugzilla.redhat.com/show_bug.cgi?id=2371689"
    ],
    "summaries": [
      "F43FailsToInstall: python3-cantera"
    ]
  },
  "cjdns": {
    "urls": [
      "https://bugzilla.redhat.com/show_bug.cgi?id=2339969"
    ],
    "summaries": [
      "cjdns: FTBFS in Fedora rawhide/f42"
    ]
  },
  "conda-build": {
    "urls": [
      "https://bugzilla.redhat.com/show_bug.cgi?id=2356162"
    ],
    "summaries": [
      "conda-build fails to build with Python 3.14: TypeError: _WorkItem.__init__() takes 3 positional arguments but 5 were given"
    ]
  },
  "copr-backend": {
    "urls": [
      "https://bugzilla.redhat.com/show_bug.cgi?id=2351386"
    ],
    "summaries": [
      "copr-backend fails to build with Python 3.14: TestActionWorkerManager.test_add_task_for_running_worker: TypeError: cannot pickle 'itertools.count' object"
    ]
  },
  "criu": {
    "urls": [
      "https://bugzilla.redhat.com/show_bug.cgi?id=2365821"
    ],
    "summaries": [
      "criu fails to build with Python 3.14: protobuf - TypeError: Metaclasses with custom tp_new are not supported."
    ]
  },
  "diceware": {
    "urls": [
      "https://bugzilla.redhat.com/show_bug.cgi?id=2340075",
      "https://bugzilla.redhat.com/show_bug.cgi?id=2329832"
    ],
    "summaries": [
      "diceware: FTBFS in Fedora rawhide/f42",
      "diceware fails to build with sphinx 8.x: ERROR: Invalid value `None` in intersphinx_mapping['http://docs.python.org/']."
    ]
  },
  "dlib": {
    "urls": [
      "https://bugzilla.redhat.com/show_bug.cgi?id=2366197"
    ],
    "summaries": [
      "dlib fails to build with Python 3.14: AssertionError in tests checking refcounting"
    ]
  },
  "httpie": {
    "urls": [
      "https://bugzilla.redhat.com/show_bug.cgi?id=2350335"
    ],
    "summaries": [
      "httpie fails to build with Python 3.14: test_lazy_choices_help: AssertionError: Expected 'getter' to not have been called. Called 1 times."
    ]
  },
  "kurchu": {
    "urls": [
      "https://bugzilla.redhat.com/show_bug.cgi?id=2371734"
    ],
    "summaries": [
      "F43FailsToInstall: kurchu"
    ]
  },
  "libpeas": {
    "urls": [
      "https://bugzilla.redhat.com/show_bug.cgi?id=2366247"
    ],
    "summaries": [
      "libpeas fails to build with Python 3.14: test-extension-py  TIMEOUT"
    ]
  },
  "libunity": {
    "urls": [
      "https://bugzilla.redhat.com/show_bug.cgi?id=2368739"
    ],
    "summaries": [
      "libunity: FTBFS in Fedora Rawhide (probably since gettext 0.25)"
    ]
  },
  "linode-cli": {
    "urls": [
      "https://bugzilla.redhat.com/show_bug.cgi?id=2368974",
      "https://bugzilla.redhat.com/show_bug.cgi?id=2340775"
    ],
    "summaries": [
      "linode-cli fails to build with Python 3.14: The current dist-git state is unbuildable",
      "linode-cli: FTBFS in Fedora rawhide/f42"
    ]
  },
  "monkeytype": {
    "urls": [
      "https://bugzilla.redhat.com/show_bug.cgi?id=2356179"
    ],
    "summaries": [
      "monkeytype fails to build with Python 3.14: typing.Union changed with Python 3.14.0a6"
    ]
  },
  "ocrmypdf": {
    "urls": [
      "https://bugzilla.redhat.com/show_bug.cgi?id=2357508"
    ],
    "summaries": [
      "ocrmypdf fails to build with Python 3.14: multiprocessing.Process now starts with forkserver method instead of fork, causing pickling error"
    ]
  },
  "opencv": {
    "urls": [],
    "summaries": []
  },
  "patool": {
    "urls": [
      "https://bugzilla.redhat.com/show_bug.cgi?id=2366470"
    ],
    "summaries": [
      "patool fails to build with Python 3.14: Codec Load Error: /usr/bin/7z.so : errno=25 : Inappropriate ioctl for device"
    ]
  },
  "pcs": {
    "urls": [
      "https://bugzilla.redhat.com/show_bug.cgi?id=2371770"
    ],
    "summaries": [
      "F43FailsToInstall: pcs, pcs-web-ui"
    ]
  },
  "pychess": {
    "urls": [
      "https://bugzilla.redhat.com/show_bug.cgi?id=2328708"
    ],
    "summaries": [
      "pychess fails to build with Python 3.14: RuntimeError: There is no current event loop in thread 'MainThread'."
    ]
  },
  "pylibacl": {
    "urls": [
      "https://bugzilla.redhat.com/show_bug.cgi?id=2359502"
    ],
    "summaries": [
      "pylibacl fails to build with Python 3.14: tests/test_acls.py::TestModification: Failed: Wrong reference count, expected 2-1024 and got 1"
    ]
  },
  "pylint": {
    "urls": [
      "https://bugzilla.redhat.com/show_bug.cgi?id=2368703"
    ],
    "summaries": [
      "pylint fails to build with Python 3.14: AssertionError tests/test_functional.py::test_functional"
    ]
  },
  "pyserial-asyncio": {
    "urls": [
      "https://bugzilla.redhat.com/show_bug.cgi?id=2327980"
    ],
    "summaries": [
      "pyserial-asyncio fails to build with Python 3.14: RuntimeError: There is no current event loop in thread 'MainThread'."
    ]
  },
  "pysubnettree": {
    "urls": [
      "https://bugzilla.redhat.com/show_bug.cgi?id=2366464",
      "https://bugzilla.redhat.com/show_bug.cgi?id=2341123"
    ],
    "summaries": [
      "pysubnettree fails to build with Python 3.14/Fedora Rawhide: error: too many arguments to function \u2018func\u2019; expected 0, have 1",
      "pysubnettree: FTBFS in Fedora rawhide/f42"
    ]
  },
  "python-Mastodon": {
    "urls": [
      "https://bugzilla.redhat.com/show_bug.cgi?id=2369422"
    ],
    "summaries": [
      "python-Mastodon fails to build with Python 3.14: ValueError: Unknown type <something> | None"
    ]
  },
  "python-TestSlide": {
    "urls": [
      "https://bugzilla.redhat.com/show_bug.cgi?id=2371789",
      "https://bugzilla.redhat.com/show_bug.cgi?id=2350306",
      "https://bugzilla.redhat.com/show_bug.cgi?id=2343971"
    ],
    "summaries": [
      "F43FailsToInstall: python3-testslide",
      "Heads-up: python-TestSlide fails to build with python-pygments 2.19.1 on Fedora 43",
      "python-TestSlide fails to build with Python 3.14: ERROR collecting tests/mock_callable_testslide.py: RuntimeError: dictionary changed size during iteration"
    ]
  },
  "python-aiokafka": {
    "urls": [
      "https://bugzilla.redhat.com/show_bug.cgi?id=2346517"
    ],
    "summaries": [
      "python-aiokafka fails to build with Python 3.14: DeprecationWarning: 'asyncio.get_event_loop_policy' is deprecated and slated for removal in Python 3.16"
    ]
  },
  "python-ansible-runner": {
    "urls": [
      "https://bugzilla.redhat.com/show_bug.cgi?id=2371793"
    ],
    "summaries": [
      "F43FailsToInstall: python3-ansible-runner"
    ]
  },
  "python-astdoc": {
    "urls": [
      "https://bugzilla.redhat.com/show_bug.cgi?id=2349452"
    ],
    "summaries": [
      "python-astdoc fails to build with Python 3.14: 3 doctests fail, e.g.: Expected: <ast.Name object at 0x...> Got: Name(id='int', ctx=Load())"
    ]
  },
  "python-avocado": {
    "urls": [
      "https://bugzilla.redhat.com/show_bug.cgi?id=2341130",
      "https://bugzilla.redhat.com/show_bug.cgi?id=2325218"
    ],
    "summaries": [
      "python-avocado: FTBFS in Fedora rawhide/f42",
      "python-avocado fails to build with Python 3.14: Error running method \"pre_tests\" of plugin \"fetchasset\": module 'ast' has no attribute 'Str' + Avocado crashed: TypeError: cannot pickle '_thread.RLock' object"
    ]
  },
  "python-awesomeversion": {
    "urls": [
      "https://bugzilla.redhat.com/show_bug.cgi?id=2366476"
    ],
    "summaries": [
      "python-awesomeversion fails to build in Fedora Rawhide: rm: cannot remove '/builddir/build/BUILD/python-awesomeversion-22.9.0-build/BUILDROOT//usr/lib/python3.14/site-packages/LICENCE.md': No such file or directory"
    ]
  },
  "python-aws-sam-translator": {
    "urls": [
      "https://bugzilla.redhat.com/show_bug.cgi?id=2353126"
    ],
    "summaries": [
      "python-aws-sam-translator fails to build with Python 3.14: 77 test failures, 4 error"
    ]
  },
  "python-beancount": {
    "urls": [
      "https://bugzilla.redhat.com/show_bug.cgi?id=2359530"
    ],
    "summaries": [
      "python-beancount fails to build with Python 3.14: TestReferenceCounting and TestLexer fail with AssertionError"
    ]
  },
  "python-beartype": {
    "urls": [
      "https://bugzilla.redhat.com/show_bug.cgi?id=2341131",
      "https://bugzilla.redhat.com/show_bug.cgi?id=2322721"
    ],
    "summaries": [
      "python-beartype: FTBFS in Fedora rawhide/f42",
      "python-beartype fails to build with Python 3.14: ImportError: cannot import name 'ByteString' from 'typing'"
    ]
  },
  "python-billiard": {
    "urls": [
      "https://bugzilla.redhat.com/show_bug.cgi?id=2323167"
    ],
    "summaries": [
      "python-billiard fails to build with Python 3.14: AttributeError: module 'subprocess' has no attribute '_USE_VFORK'"
    ]
  },
  "python-bluepyopt": {
    "urls": [
      "https://bugzilla.redhat.com/show_bug.cgi?id=2371820",
      "https://bugzilla.redhat.com/show_bug.cgi?id=2341132"
    ],
    "summaries": [
      "F43FailsToInstall: python3-bluepyopt",
      "python-bluepyopt: FTBFS in Fedora rawhide/f42"
    ]
  },
  "python-capturer": {
    "urls": [
      "https://bugzilla.redhat.com/show_bug.cgi?id=2328004"
    ],
    "summaries": [
      "python-capturer fails to build with Python 3.14: OSError: [Errno 29] Illegal seek"
    ]
  },
  "python-catkin_tools": {
    "urls": [
      "https://bugzilla.redhat.com/show_bug.cgi?id=2341134",
      "https://bugzilla.redhat.com/show_bug.cgi?id=2329848"
    ],
    "summaries": [
      "python-catkin_tools: FTBFS in Fedora rawhide/f42",
      "python-catkin_tools fails to build with sphinx 8.x:  ERROR: Invalid value `None` in intersphinx_mapping['http://docs.python.org/']."
    ]
  },
  "python-cerberus": {
    "urls": [
      "https://bugzilla.redhat.com/show_bug.cgi?id=2366466"
    ],
    "summaries": [
      "python-cerberus fails to build in Fedora Rawhide:  File not found: /builddir/build/BUILD/python-cerberus-1.3.4-build/BUILDROOT/usr/lib/python3.14/site-packages/Cerberus-1.3.4.dist-info"
    ]
  },
  "python-chalice": {
    "urls": [
      "https://bugzilla.redhat.com/show_bug.cgi?id=2342568"
    ],
    "summaries": [
      "python-chalice fails to build with Python 3.14: AttributeError: module 'ast' has no attribute 'Str'"
    ]
  },
  "python-colcon-meson": {
    "urls": [
      "https://bugzilla.redhat.com/show_bug.cgi?id=2368744"
    ],
    "summaries": [
      "python-colcon-meson fails to build with Python 3.14: test_capital_case: TypeError: InterpreterBase.__init__() missing 2 required positional arguments: 'subproject_dir' and 'env'"
    ]
  },
  "python-colcon-parallel-executor": {
    "urls": [
      "https://bugzilla.redhat.com/show_bug.cgi?id=2325186"
    ],
    "summaries": [
      "python-colcon-parallel-executor fails to build with Python 3.14: test_parallel: AssertionError: DeprecationWarning: 'asyncio.iscoroutinefunction' is deprecated and slated for removal in Python 3.16; use inspect.iscoroutinefunction() instead"
    ]
  },
  "python-confuse": {
    "urls": [
      "https://bugzilla.redhat.com/show_bug.cgi?id=2327966"
    ],
    "summaries": [
      "python-confuse fails to build with Python 3.14: AttributeError: module 'pkgutil' has no attribute 'get_loader'"
    ]
  },
  "python-crick": {
    "urls": [
      "https://bugzilla.redhat.com/show_bug.cgi?id=2367454"
    ],
    "summaries": [
      "python-crick fails to build with Python 3.14: crick/tests/test_space_saving.py::test_merge_algorithm[s111-s211] Fatal Python error: Segmentation fault"
    ]
  },
  "python-cytoolz": {
    "urls": [
      "https://bugzilla.redhat.com/show_bug.cgi?id=2371849"
    ],
    "summaries": [
      "F43FailsToInstall: python3-cytoolz"
    ]
  },
  "python-dataclassy": {
    "urls": [
      "https://bugzilla.redhat.com/show_bug.cgi?id=2325200"
    ],
    "summaries": [
      "python-dataclassy fails to build with Python 3.14: TypeError: Beta() takes no arguments"
    ]
  },
  "python-django-cacheops": {
    "urls": [
      "https://bugzilla.redhat.com/show_bug.cgi?id=2371864"
    ],
    "summaries": [
      "F43FailsToInstall: python3-django-cacheops"
    ]
  },
  "python-django-contrib-comments": {
    "urls": [
      "https://bugzilla.redhat.com/show_bug.cgi?id=2366520"
    ],
    "summaries": [
      "python-django-contrib-comments fails to build with Python 3.14: ImportError: Module \"django.contrib.auth.hashers\" does not define a \"UnsaltedMD5PasswordHasher\" attribute/class"
    ]
  },
  "python-django-filter": {
    "urls": [
      "https://bugzilla.redhat.com/show_bug.cgi?id=2336944"
    ],
    "summaries": [
      "python-django-filter fails to build with Python 3.14: AttributeError: module 'pkgutil' has no attribute 'find_loader'"
    ]
  },
  "python-earthpy": {
    "urls": [
      "https://bugzilla.redhat.com/show_bug.cgi?id=2371875",
      "https://bugzilla.redhat.com/show_bug.cgi?id=2341146"
    ],
    "summaries": [
      "F43FailsToInstall: python3-earthpy",
      "python-earthpy: FTBFS in Fedora rawhide/f42"
    ]
  },
  "python-fiat": {
    "urls": [
      "https://bugzilla.redhat.com/show_bug.cgi?id=2371903"
    ],
    "summaries": [
      "F43FailsToInstall: python3-fiat"
    ]
  },
  "python-flake8-comprehensions": {
    "urls": [
      "https://bugzilla.redhat.com/show_bug.cgi?id=2351385"
    ],
    "summaries": [
      "python-flake8-comprehensions fails to build with Python 3.14: Unnecessary reversed call around sorted() in 10 tests"
    ]
  },
  "python-fsleyes-widgets": {
    "urls": [
      "https://bugzilla.redhat.com/show_bug.cgi?id=2336911"
    ],
    "summaries": [
      "python-fsleyes-widgets fails to build with Python 3.14: AssertionError: assert 'file:/home/b...htmlfile.html' == 'file:///home...htmlfile.html'"
    ]
  },
  "python-gphoto2": {
    "urls": [
      "https://bugzilla.redhat.com/show_bug.cgi?id=2366465",
      "https://bugzilla.redhat.com/show_bug.cgi?id=2341158"
    ],
    "summaries": [
      "python-gphoto2 fails to build with Python 3.14: ModuleNotFoundError: No module named 'distutils.command.upload'",
      "python-gphoto2: FTBFS in Fedora rawhide/f42"
    ]
  },
  "python-howdoi": {
    "urls": [
      "https://bugzilla.redhat.com/show_bug.cgi?id=2342558"
    ],
    "summaries": [
      "python-howdoi fails to build with Python 3.14: AssertionError: 'ERROR: Unable to reach google. Do you need to use a proxy? + json.decoder.JSONDecodeError"
    ]
  },
  "python-ipfshttpclient": {
    "urls": [
      "https://bugzilla.redhat.com/show_bug.cgi?id=2368589"
    ],
    "summaries": [
      "python-ipfshttpclient fails to build with Python 3.14: AssertionError: assert ['(?![.])(?s:literal)\\\\z'] == ['(?![.])(?s:literal)\\\\Z']"
    ]
  },
  "python-janus": {
    "urls": [
      "https://bugzilla.redhat.com/show_bug.cgi?id=2371953"
    ],
    "summaries": [
      "F43FailsToInstall: python3-janus"
    ]
  },
  "python-markups": {
    "urls": [
      "https://bugzilla.redhat.com/show_bug.cgi?id=2366489"
    ],
    "summaries": [
      "python-markups fails to build with Python 3.14: AssertionError in test_get_pygments_stylesheet"
    ]
  },
  "python-neatdend": {
    "urls": [
      "https://bugzilla.redhat.com/show_bug.cgi?id=2341170"
    ],
    "summaries": [
      "python-neatdend: FTBFS in Fedora rawhide/f42"
    ]
  },
  "python-niaarmts": {
    "urls": [
      "https://bugzilla.redhat.com/show_bug.cgi?id=2369421"
    ],
    "summaries": [
      "python-niaarmts fails to build with Python 3.14: ERROR: Package 'niaarmts' requires a different Python: 3.14.0 not in '<3.14,>=3.11'"
    ]
  },
  "python-octave-kernel": {
    "urls": [
      "https://bugzilla.redhat.com/show_bug.cgi?id=2341176"
    ],
    "summaries": [
      "python-octave-kernel: FTBFS in Fedora rawhide/f42"
    ]
  },
  "python-pamela": {
    "urls": [
      "https://bugzilla.redhat.com/show_bug.cgi?id=2366474"
    ],
    "summaries": [
      "python-pamela fails to build with Python 3.14: pamela.PAMError: [PAM Error 26] Critical error - immediate abort"
    ]
  },
  "python-partd": {
    "urls": [
      "https://bugzilla.redhat.com/show_bug.cgi?id=2372026"
    ],
    "summaries": [
      "F43FailsToInstall: python3-partd+complete, python3-partd"
    ]
  },
  "python-pkginfo2": {
    "urls": [
      "https://bugzilla.redhat.com/show_bug.cgi?id=2366490"
    ],
    "summaries": [
      "python-pkginfo2: FTBFS in Fedora Rawhide: AssertionError: None != '30.0.0'"
    ]
  },
  "python-plotnine": {
    "urls": [
      "https://bugzilla.redhat.com/show_bug.cgi?id=2372035"
    ],
    "summaries": [
      "F43FailsToInstall: python3-plotnine+extra, python3-plotnine"
    ]
  },
  "python-praw": {
    "urls": [
      "https://bugzilla.redhat.com/show_bug.cgi?id=2342562"
    ],
    "summaries": [
      "python-praw fails to build with Python 3.14: RuntimeError: There is no current event loop in thread 'MainThread'."
    ]
  },
  "python-pure-protobuf": {
    "urls": [
      "https://bugzilla.redhat.com/show_bug.cgi?id=2322710"
    ],
    "summaries": [
      "python-pure-protobuf fails to build with Python 3.14: ImportError: cannot import name 'ByteString' from 'typing'"
    ]
  },
  "python-pybids": {
    "urls": [
      "https://bugzilla.redhat.com/show_bug.cgi?id=2372050"
    ],
    "summaries": [
      "F43FailsToInstall: python3-pybids+plotting, python3-pybids+test, python3-pybids+tests, python3-pybids"
    ]
  },
  "python-pycec": {
    "urls": [
      "https://bugzilla.redhat.com/show_bug.cgi?id=2327973"
    ],
    "summaries": [
      "python-pycec fails to build with Python 3.14: RuntimeError: There is no current event loop in thread 'MainThread'."
    ]
  },
  "python-pyemd": {
    "urls": [
      "https://bugzilla.redhat.com/show_bug.cgi?id=2319698"
    ],
    "summaries": [
      "python-pyemd fails to build with setuptools 74+"
    ]
  },
  "python-pymdown-extensions": {
    "urls": [
      "https://bugzilla.redhat.com/show_bug.cgi?id=2372063",
      "https://bugzilla.redhat.com/show_bug.cgi?id=2350300",
      "https://bugzilla.redhat.com/show_bug.cgi?id=2336948"
    ],
    "summaries": [
      "F43FailsToInstall: python3-pymdown-extensions+extra, python3-pymdown-extensions",
      "Heads-up: python-pymdown-extensions fails to build with python-pygments 2.19.1 on Fedora 43",
      "python-pymdown-extensions fails to build with Python 3.14: TestAbsolute.test_relative_path and TestAbsoluteFileScheme.test_relative_path AssertionErrors"
    ]
  },
  "python-pymeeus": {
    "urls": [
      "https://bugzilla.redhat.com/show_bug.cgi?id=2341186",
      "https://bugzilla.redhat.com/show_bug.cgi?id=2329890"
    ],
    "summaries": [
      "python-pymeeus: FTBFS in Fedora rawhide/f42",
      "python-pymeeus fails to build with sphinx 8.x: ERROR: Invalid value `None` in intersphinx_mapping['https://docs.python.org/']."
    ]
  },
  "python-pyopencl": {
    "urls": [
      "https://bugzilla.redhat.com/show_bug.cgi?id=2341190"
    ],
    "summaries": [
      "python-pyopencl: FTBFS in Fedora rawhide/f42"
    ]
  },
  "python-pysaml2": {
    "urls": [
      "https://bugzilla.redhat.com/show_bug.cgi?id=2372073",
      "https://bugzilla.redhat.com/show_bug.cgi?id=2341199"
    ],
    "summaries": [
      "F43FailsToInstall: python3-pysaml2",
      "python-pysaml2: FTBFS in Fedora rawhide/f42"
    ]
  },
  "python-pytest-lsp": {
    "urls": [
      "https://bugzilla.redhat.com/show_bug.cgi?id=2349451"
    ],
    "summaries": [
      "python-pytest-lsp fails to build with Python 3.14: warnings counts differ, resulting in AssertionError in 3 tests"
    ]
  },
  "python-pytest-twisted": {
    "urls": [
      "https://bugzilla.redhat.com/show_bug.cgi?id=2368594"
    ],
    "summaries": [
      "python-pytest-twisted fails to build with Python 3.14: RuntimeError: There is no current event loop in thread 'MainThread'."
    ]
  },
  "python-pyupgrade": {
    "urls": [
      "https://bugzilla.redhat.com/show_bug.cgi?id=2322713"
    ],
    "summaries": [
      "python-pyupgrade fails to build with Python 3.14: AttributeError: module 'ast' has no attribute 'Str'"
    ]
  },
  "python-pyvlx": {
    "urls": [
      "https://bugzilla.redhat.com/show_bug.cgi?id=2327983"
    ],
    "summaries": [
      "python-pyvlx fails to build with Python 3.14: RuntimeError: There is no current event loop in thread 'MainThread'."
    ]
  },
  "python-qcelemental": {
    "urls": [
      "https://bugzilla.redhat.com/show_bug.cgi?id=2372089"
    ],
    "summaries": [
      "F43FailsToInstall: python3-qcelemental"
    ]
  },
  "python-readability-lxml": {
    "urls": [
      "https://bugzilla.redhat.com/show_bug.cgi?id=2323185"
    ],
    "summaries": [
      "python-readability-lxml fails to build with Python 3.14: _pickle.PicklingError: Can't pickle <function TestArticleOnly.test_many_repeated_spaces at 0x7ff0ea064460>: it's not the same object as tests.test_article_only.TestArticleOnly.test_many_repeated_spa"
    ]
  },
  "python-recordclass": {
    "urls": [
      "https://bugzilla.redhat.com/show_bug.cgi?id=2327968"
    ],
    "summaries": [
      "python-recordclass fails to build with Python 3.14: 25 failures, 65 errors in the test suite"
    ]
  },
  "python-remoto": {
    "urls": [
      "https://bugzilla.redhat.com/show_bug.cgi?id=2366491",
      "https://bugzilla.redhat.com/show_bug.cgi?id=2341205"
    ],
    "summaries": [
      "python-remoto fails to build with Python 3.14: AttributeError: 'TestRemoteError' object has no attribute 'traceback'",
      "python-remoto: FTBFS in Fedora rawhide/f42"
    ]
  },
  "python-rosdep": {
    "urls": [
      "https://bugzilla.redhat.com/show_bug.cgi?id=2341207",
      "https://bugzilla.redhat.com/show_bug.cgi?id=2329891"
    ],
    "summaries": [
      "python-rosdep: FTBFS in Fedora rawhide/f42",
      "python-rosdep fails to build with sphinx 8.x: ERROR: Invalid value `None` in intersphinx_mapping['http://docs.python.org/']."
    ]
  },
  "python-rstcheck": {
    "urls": [
      "https://bugzilla.redhat.com/show_bug.cgi?id=2322705"
    ],
    "summaries": [
      "python-rstcheck fails to build with Python 3.14: AttributeError: 'Constant' object has no attribute 's'"
    ]
  },
  "python-rx": {
    "urls": [
      "https://bugzilla.redhat.com/show_bug.cgi?id=2327979"
    ],
    "summaries": [
      "python-rx fails to build with Python 3.14: RuntimeError: There is no current event loop in thread 'MainThread'."
    ]
  },
  "python-simframe": {
    "urls": [
      "https://bugzilla.redhat.com/show_bug.cgi?id=2352552"
    ],
    "summaries": [
      "python-simframe fails to build with Python 3.14: TypeError: cannot pickle 'itertools.cycle' object"
    ]
  },
  "python-sphinx-autobuild": {
    "urls": [
      "https://bugzilla.redhat.com/show_bug.cgi?id=2372144"
    ],
    "summaries": [
      "F43FailsToInstall: python3-sphinx-autobuild"
    ]
  },
  "python-sqlmodel": {
    "urls": [
      "https://bugzilla.redhat.com/show_bug.cgi?id=2372150"
    ],
    "summaries": [
      "F43FailsToInstall: python3-sqlmodel, python3-sqlmodel-slim"
    ]
  },
  "python-streamlink": {
    "urls": [
      "https://bugzilla.redhat.com/show_bug.cgi?id=2353127"
    ],
    "summaries": [
      "python-streamlink fails to build with Python 3.14: test_deprecated: AssetionError: Left contains one more item: <warnings.WarningMessage object at 0x7fd80afa3410>"
    ]
  },
  "python-textual": {
    "urls": [
      "https://bugzilla.redhat.com/show_bug.cgi?id=2367457",
      "https://bugzilla.redhat.com/show_bug.cgi?id=2341224"
    ],
    "summaries": [
      "python-textual fails to build with Python 3.14: RuntimeError: There is no current event loop in thread 'MainThread'.",
      "python-textual: FTBFS in Fedora rawhide/f42"
    ]
  },
  "python-torch": {
    "urls": [
      "https://bugzilla.redhat.com/show_bug.cgi?id=2372164"
    ],
    "summaries": [
      "F43FailsToInstall: python3-torch"
    ]
  },
  "python-towncrier": {
    "urls": [
      "https://bugzilla.redhat.com/show_bug.cgi?id=2354131"
    ],
    "summaries": [
      "python-towncrier FTBFS due to missing tox configuration"
    ]
  },
  "python-txaio": {
    "urls": [
      "https://bugzilla.redhat.com/show_bug.cgi?id=2327981"
    ],
    "summaries": [
      "python-txaio fails to build with Python 3.14: RuntimeError: There is no current event loop in thread 'MainThread'."
    ]
  },
  "python-typing-inspect": {
    "urls": [
      "https://bugzilla.redhat.com/show_bug.cgi?id=2325455"
    ],
    "summaries": [
      "python-typing-inspect fails to build with Python 3.14: AssertionError: {} != {'x': <class 'int'>, 'y': <class 'int'>}"
    ]
  },
  "python-uvloop": {
    "urls": [
      "https://bugzilla.redhat.com/show_bug.cgi?id=2341233",
      "https://bugzilla.redhat.com/show_bug.cgi?id=2326210"
    ],
    "summaries": [
      "python-uvloop: FTBFS in Fedora rawhide/f42",
      "python-uvloop fails to build with Python 3.14: AttributeError: module 'asyncio' has no attribute 'AbstractChildWatcher'"
    ]
  },
  "python-valkey": {
    "urls": [
      "https://bugzilla.redhat.com/show_bug.cgi?id=2349444"
    ],
    "summaries": [
      "python-valkey fails to build with Python 3.14: _pickle.PicklingError: Can't pickle local object <function TestMultiprocessing.test_close_connection_in_child.<locals>.target at 0x7f5aa68cddd0>"
    ]
  },
  "python-wordcloud": {
    "urls": [
      "https://bugzilla.redhat.com/show_bug.cgi?id=2335908"
    ],
    "summaries": [
      "python-wordcloud fails to build with Python 3.14: test_cli_as_executable: AssertionError: assert expected_output in out if ret_code == 0 else err"
    ]
  },
  "python-yappi": {
    "urls": [
      "https://bugzilla.redhat.com/show_bug.cgi?id=2323160"
    ],
    "summaries": [
      "python-yappi fails to build with Python 3.14: error: invalid use of incomplete typedef \u2018PyGenObject\u2019 {aka \u2018struct _PyGenObject\u2019}"
    ]
  },
  "python3-exiv2": {
    "urls": [
      "https://bugzilla.redhat.com/show_bug.cgi?id=2354137"
    ],
    "summaries": [
      "python3-exiv2 FTBFS due to missing tox configuration"
    ]
  },
  "qtile": {
    "urls": [
      "https://bugzilla.redhat.com/show_bug.cgi?id=2328711"
    ],
    "summaries": [
      "qtile fails to build with Python 3.14: _pickle.PicklingError: Can't pickle local object <function TestManager.start.<locals>.run_qtile at 0x7f9c5918fed0>"
    ]
  },
  "rpm-head-signing": {
    "urls": [
      "https://bugzilla.redhat.com/show_bug.cgi?id=2366308"
    ],
    "summaries": [
      "rpm-head-signing: FTBFS in Fedora Rawhide with RPM 6"
    ]
  },
  "rss2email": {
    "urls": [
      "https://bugzilla.redhat.com/show_bug.cgi?id=2368743"
    ],
    "summaries": [
      "rss2email fails to build with Python 3.14: ERROR: test_email_data/tails/1.config..."
    ]
  },
  "signon-glib": {
    "urls": [
      "https://bugzilla.redhat.com/show_bug.cgi?id=2341348"
    ],
    "summaries": [
      "signon-glib: FTBFS in Fedora rawhide/f42"
    ]
  },
  "strongswan": {
    "urls": [
      "https://bugzilla.redhat.com/show_bug.cgi?id=2368971",
      "https://bugzilla.redhat.com/show_bug.cgi?id=2332864"
    ],
    "summaries": [
      "strongswan: FTBFS in Fedora Rawhide: error: possibly undefined macro: AC_LIB_PREFIX",
      "strongswan-5.9.14-5.fc42 FTBFS: strongswan-5.9.14/missing: line 81: aclocal-1.16: command not found"
    ]
  },
  "sugar": {
    "urls": [
      "https://bugzilla.redhat.com/show_bug.cgi?id=2368968"
    ],
    "summaries": [
      "sugar: FTBFS in Fedora Rawhide"
    ]
  },
  "sugar-toolkit-gtk3": {
    "urls": [
      "https://bugzilla.redhat.com/show_bug.cgi?id=2372229"
    ],
    "summaries": [
      "F43FailsToInstall: sugar-toolkit-gtk3"
    ]
  },
  "tmt": {
    "urls": [
      "https://bugzilla.redhat.com/show_bug.cgi?id=2372233"
    ],
    "summaries": [
      "F43FailsToInstall: tmt+all, tmt+export-polarion, tmt+link-jira, tmt+provision-beaker, tmt+provision-bootc, tmt+provision-container, tmt+provision-virtual, tmt+report-junit, tmt+report-polarion, tmt+test-convert, tmt"
    ]
  },
  "visidata": {
    "urls": [
      "https://bugzilla.redhat.com/show_bug.cgi?id=2325446"
    ],
    "summaries": [
      "visidata fails to build with Python 3.14: TestVisidataPath.test_withName: AssertionError: assert 'foo' == 'foo.'"
    ]
  },
  "zeek": {
    "urls": [
      "https://bugzilla.redhat.com/show_bug.cgi?id=2366467",
      "https://bugzilla.redhat.com/show_bug.cgi?id=2341601"
    ],
    "summaries": [
      "zeek fails to build in Fedora Rawhide: Could not find prerequisite package 'BIND'",
      "zeek: FTBFS in Fedora rawhide/f42"
    ]
  }
}