{
  "Mayavi": {
    "urls": [
      "https://bugzilla.redhat.com/show_bug.cgi?id=2351390"
    ],
    "summaries": [
      "Mayavi fails to build with Python 3.14: TestMayaviGarbageCollection.test_mlab_scene_model_with_gui: IndexError: list index out of range"
    ]
  },
  "NiaAML-GUI": {
    "urls": [],
    "summaries": []
  },
  "PackageKit": {
    "urls": [],
    "summaries": []
  },
  "alot": {
    "urls": [
      "https://bugzilla.redhat.com/show_bug.cgi?id=2368593"
    ],
    "summaries": [
      "alot fails to build with Python 3.14: RuntimeError: There is no current event loop in thread 'MainThread'."
    ]
  },
  "ansible": {
    "urls": [],
    "summaries": []
  },
  "ansible-core": {
    "urls": [
      "https://bugzilla.redhat.com/show_bug.cgi?id=2366307"
    ],
    "summaries": [
      "ansible-core fails to build with Python 3.14: This version of ansible-test cannot be executed with Python version 3.14.0"
    ]
  },
  "arbor": {
    "urls": [],
    "summaries": []
  },
  "asv": {
    "urls": [
      "https://bugzilla.redhat.com/show_bug.cgi?id=2367256",
      "https://bugzilla.redhat.com/show_bug.cgi?id=2339908"
    ],
    "summaries": [
      "asv fails to build with Python 3.14: AttributeError: 'Constant' object has no attribute 's'",
      "asv: FTBFS in Fedora rawhide/f42"
    ]
  },
  "avogadro2-libs": {
    "urls": [],
    "summaries": []
  },
  "awscli2": {
    "urls": [
      "https://bugzilla.redhat.com/show_bug.cgi?id=2367786"
    ],
    "summaries": [
      "awscli2 fails to build with Python 3.14: various test failures"
    ]
  },
  "bandit": {
    "urls": [
      "https://bugzilla.redhat.com/show_bug.cgi?id=2351393"
    ],
    "summaries": [
      "bandit fails to build with Python 3.14: TypeError: Error: Str is not a valid node type in AST"
    ]
  },
  "bids-schema": {
    "urls": [],
    "summaries": []
  },
  "binwalk": {
    "urls": [
      "https://bugzilla.redhat.com/show_bug.cgi?id=2336914"
    ],
    "summaries": [
      "binwalk fails to build with Python 3.14: TypeError: unsupported operand type(s) for +=: 'NoneType' and 'int'"
    ]
  },
  "bluechi": {
    "urls": [
      "https://bugzilla.redhat.com/show_bug.cgi?id=2366508"
    ],
    "summaries": [
      "bluechi: FTBFS in Fedora Rawhide: error: call to \u2018*__inet_pton_chk\u2019 declared with attribute warning: inet_pton called with a destination buffer size too small"
    ]
  },
  "borgbackup": {
    "urls": [
      "https://bugzilla.redhat.com/show_bug.cgi?id=2326916"
    ],
    "summaries": [
      "borgbackup fails to build with Python 3.14: OSError: AF_UNIX path too long when compiling"
    ]
  },
  "calibre": {
    "urls": [],
    "summaries": []
  },
  "capstone": {
    "urls": [
      "https://bugzilla.redhat.com/show_bug.cgi?id=2345714"
    ],
    "summaries": [
      "capstone fails to build with Python 3.14: from capstone import *: ImportError: ERROR: fail to load the dynamic library"
    ]
  },
  "centpkg": {
    "urls": [],
    "summaries": []
  },
  "ceph": {
    "urls": [
      "https://bugzilla.redhat.com/show_bug.cgi?id=2336913"
    ],
    "summaries": [
      "ceph fails to build with Python 3.14: AttributeError: module 'pkgutil' has no attribute 'find_loader'"
    ]
  },
  "chirp": {
    "urls": [
      "https://bugzilla.redhat.com/show_bug.cgi?id=2361634"
    ],
    "summaries": [
      "chirp FTBFS in rawhide"
    ]
  },
  "cjdns": {
    "urls": [
      "https://bugzilla.redhat.com/show_bug.cgi?id=2339969"
    ],
    "summaries": [
      "cjdns: FTBFS in Fedora rawhide/f42"
    ]
  },
  "conda": {
    "urls": [
      "https://bugzilla.redhat.com/show_bug.cgi?id=2356170"
    ],
    "summaries": [
      "conda fails to build with Python 3.14: tests/test_shell.py: TypeError: 'str' object cannot be interpreted as an integer"
    ]
  },
  "conda-build": {
    "urls": [
      "https://bugzilla.redhat.com/show_bug.cgi?id=2356162"
    ],
    "summaries": [
      "conda-build fails to build with Python 3.14: TypeError: _WorkItem.__init__() takes 3 positional arguments but 5 were given"
    ]
  },
  "copr-backend": {
    "urls": [
      "https://bugzilla.redhat.com/show_bug.cgi?id=2351386"
    ],
    "summaries": [
      "copr-backend fails to build with Python 3.14: TestActionWorkerManager.test_add_task_for_running_worker: TypeError: cannot pickle 'itertools.count' object"
    ]
  },
  "copr-dist-git": {
    "urls": [],
    "summaries": []
  },
  "copr-keygen": {
    "urls": [],
    "summaries": []
  },
  "cozy": {
    "urls": [],
    "summaries": []
  },
  "cranc": {
    "urls": [],
    "summaries": []
  },
  "criu": {
    "urls": [
      "https://bugzilla.redhat.com/show_bug.cgi?id=2365821"
    ],
    "summaries": [
      "criu fails to build with Python 3.14: protobuf - TypeError: Metaclasses with custom tp_new are not supported."
    ]
  },
  "cryptlib": {
    "urls": [],
    "summaries": []
  },
  "csmock": {
    "urls": [],
    "summaries": []
  },
  "cura": {
    "urls": [],
    "summaries": []
  },
  "cxxtest": {
    "urls": [],
    "summaries": []
  },
  "d-feet": {
    "urls": [],
    "summaries": []
  },
  "dblatex": {
    "urls": [],
    "summaries": []
  },
  "ddiskit": {
    "urls": [],
    "summaries": []
  },
  "ddupdate": {
    "urls": [],
    "summaries": []
  },
  "dee": {
    "urls": [],
    "summaries": []
  },
  "deluge": {
    "urls": [],
    "summaries": []
  },
  "devscripts": {
    "urls": [],
    "summaries": []
  },
  "dib-utils": {
    "urls": [],
    "summaries": []
  },
  "diceware": {
    "urls": [
      "https://bugzilla.redhat.com/show_bug.cgi?id=2340075",
      "https://bugzilla.redhat.com/show_bug.cgi?id=2329832"
    ],
    "summaries": [
      "diceware: FTBFS in Fedora rawhide/f42",
      "diceware fails to build with sphinx 8.x: ERROR: Invalid value `None` in intersphinx_mapping['http://docs.python.org/']."
    ]
  },
  "did": {
    "urls": [
      "https://bugzilla.redhat.com/show_bug.cgi?id=2328006"
    ],
    "summaries": [
      "did fails to build with Python 3.14: AttributeError: module 'urllib.request' has no attribute 'FancyURLopener'"
    ]
  },
  "diskimage-builder": {
    "urls": [],
    "summaries": []
  },
  "dist-git-client": {
    "urls": [],
    "summaries": []
  },
  "distcc": {
    "urls": [],
    "summaries": []
  },
  "distgen": {
    "urls": [],
    "summaries": []
  },
  "dlib": {
    "urls": [
      "https://bugzilla.redhat.com/show_bug.cgi?id=2366197"
    ],
    "summaries": [
      "dlib fails to build with Python 3.14: AssertionError in tests checking refcounting"
    ]
  },
  "dnf-plugin-diff": {
    "urls": [],
    "summaries": []
  },
  "dnf-plugin-ovl": {
    "urls": [],
    "summaries": []
  },
  "dnfdaemon": {
    "urls": [],
    "summaries": []
  },
  "dnfdragora": {
    "urls": [],
    "summaries": []
  },
  "dnsconfd": {
    "urls": [],
    "summaries": []
  },
  "dnsviz": {
    "urls": [],
    "summaries": []
  },
  "doge": {
    "urls": [],
    "summaries": []
  },
  "dogtag-pki": {
    "urls": [],
    "summaries": []
  },
  "eggdrop": {
    "urls": [],
    "summaries": []
  },
  "electrum": {
    "urls": [],
    "summaries": []
  },
  "ephemeral-port-reserve": {
    "urls": [
      "https://bugzilla.redhat.com/show_bug.cgi?id=2366471"
    ],
    "summaries": [
      "ephemeral-port-reserve fails to build with Python 3.14: socket.gaierror: [Errno -3] Temporary failure in name resolution"
    ]
  },
  "espresso": {
    "urls": [
      "https://bugzilla.redhat.com/show_bug.cgi?id=2340139"
    ],
    "summaries": [
      "espresso: FTBFS in Fedora rawhide/f42"
    ]
  },
  "fedora-review": {
    "urls": [],
    "summaries": []
  },
  "fedpkg": {
    "urls": [],
    "summaries": []
  },
  "fedrq": {
    "urls": [],
    "summaries": []
  },
  "freeipa-desktop-profile": {
    "urls": [],
    "summaries": []
  },
  "git-filter-repo": {
    "urls": [
      "https://bugzilla.redhat.com/show_bug.cgi?id=2365637"
    ],
    "summaries": [
      "git-filter-repo fails to build with Python 3.14: == t9394-filter-repo-sanity-checks-and-bigger-repo-setup.sh == --replace-text all options not ok"
    ]
  },
  "glade": {
    "urls": [],
    "summaries": []
  },
  "gnofract4d": {
    "urls": [
      "https://bugzilla.redhat.com/show_bug.cgi?id=2339539"
    ],
    "summaries": [
      "gnofract4d fails to build with Python 3.14: AssertionError: 'ct_sin6 = (0.841471,-0)' != 'ct_sin6 = (0.841471,0)'"
    ]
  },
  "gom": {
    "urls": [],
    "summaries": []
  },
  "gplugin": {
    "urls": [],
    "summaries": []
  },
  "gst-devtools": {
    "urls": [],
    "summaries": []
  },
  "gst-editing-services": {
    "urls": [],
    "summaries": []
  },
  "home-assistant-cli": {
    "urls": [],
    "summaries": []
  },
  "httpie": {
    "urls": [
      "https://bugzilla.redhat.com/show_bug.cgi?id=2350335"
    ],
    "summaries": [
      "httpie fails to build with Python 3.14: test_lazy_choices_help: AssertionError: Expected 'getter' to not have been called. Called 1 times."
    ]
  },
  "ikiwiki": {
    "urls": [
      "https://bugzilla.redhat.com/show_bug.cgi?id=2366456",
      "https://bugzilla.redhat.com/show_bug.cgi?id=2340642"
    ],
    "summaries": [
      "ikiwiki fails to build in Rawhide: error: Installed (but unpackaged) file(s) found:  /usr/sbin/ikiwiki-mass-rebuild",
      "ikiwiki: FTBFS in Fedora rawhide/f42"
    ]
  },
  "ipython": {
    "urls": [
      "https://bugzilla.redhat.com/show_bug.cgi?id=2356174"
    ],
    "summaries": [
      "ipython fails to build with Python 3.14: AssertionErrors, pexpect.exceptions.TIMEOUTs and more in 12 tests"
    ]
  },
  "khal": {
    "urls": [],
    "summaries": []
  },
  "kitty": {
    "urls": [],
    "summaries": []
  },
  "kmymoney": {
    "urls": [],
    "summaries": []
  },
  "kvirc": {
    "urls": [],
    "summaries": []
  },
  "lensfun": {
    "urls": [],
    "summaries": []
  },
  "libaccounts-glib": {
    "urls": [],
    "summaries": []
  },
  "libarrow": {
    "urls": [],
    "summaries": []
  },
  "libgexiv2": {
    "urls": [],
    "summaries": []
  },
  "libgit2-glib": {
    "urls": [],
    "summaries": []
  },
  "libmodulemd": {
    "urls": [],
    "summaries": []
  },
  "libpeas": {
    "urls": [
      "https://bugzilla.redhat.com/show_bug.cgi?id=2366247"
    ],
    "summaries": [
      "libpeas fails to build with Python 3.14: test-extension-py  TIMEOUT"
    ]
  },
  "libpeas1": {
    "urls": [],
    "summaries": []
  },
  "libpoly": {
    "urls": [],
    "summaries": []
  },
  "libunity": {
    "urls": [],
    "summaries": []
  },
  "libvirt-test-API": {
    "urls": [],
    "summaries": []
  },
  "linode-cli": {
    "urls": [
      "https://bugzilla.redhat.com/show_bug.cgi?id=2340775"
    ],
    "summaries": [
      "linode-cli: FTBFS in Fedora rawhide/f42"
    ]
  },
  "mlpack": {
    "urls": [],
    "summaries": []
  },
  "monkeytype": {
    "urls": [
      "https://bugzilla.redhat.com/show_bug.cgi?id=2356179"
    ],
    "summaries": [
      "monkeytype fails to build with Python 3.14: typing.Union changed with Python 3.14.0a6"
    ]
  },
  "mopidy": {
    "urls": [
      "https://bugzilla.redhat.com/show_bug.cgi?id=2367738"
    ],
    "summaries": [
      "mopidy fails to build with Python 3.14:  RuntimeError: unable to get value"
    ]
  },
  "mopidy-mpd": {
    "urls": [],
    "summaries": []
  },
  "mrchem": {
    "urls": [
      "https://bugzilla.redhat.com/show_bug.cgi?id=2359498"
    ],
    "summaries": [
      "mrchem fails to build with Python 3.14: /builddir/build/BUILD/mrchem-1.1.4-build/mrchem-1.1.4/python/mrchem/input_parser/plumbing/pyparsing/core.py:5332: SyntaxWarning: 'return' in a 'finally' block"
    ]
  },
  "myst-nb": {
    "urls": [],
    "summaries": []
  },
  "nemo-extensions": {
    "urls": [],
    "summaries": []
  },
  "nextpnr": {
    "urls": [],
    "summaries": []
  },
  "obsctl": {
    "urls": [],
    "summaries": []
  },
  "ocrmypdf": {
    "urls": [
      "https://bugzilla.redhat.com/show_bug.cgi?id=2357508"
    ],
    "summaries": [
      "ocrmypdf fails to build with Python 3.14: multiprocessing.Process now starts with forkserver method instead of fork, causing pickling error"
    ]
  },
  "onnx": {
    "urls": [
      "https://bugzilla.redhat.com/show_bug.cgi?id=2366510"
    ],
    "summaries": [
      "onnx fails to build with Python 3.14: protobuf: TypeError: Metaclasses with custom tp_new are not supported."
    ]
  },
  "openapi-python-client": {
    "urls": [],
    "summaries": []
  },
  "opencv": {
    "urls": [
      "https://bugzilla.redhat.com/show_bug.cgi?id=2368529"
    ],
    "summaries": [
      "opencv fails to build with Python 3.14: a failure in the %build phase"
    ]
  },
  "openvino": {
    "urls": [],
    "summaries": []
  },
  "paperwork": {
    "urls": [],
    "summaries": []
  },
  "paraview": {
    "urls": [],
    "summaries": []
  },
  "patool": {
    "urls": [
      "https://bugzilla.redhat.com/show_bug.cgi?id=2366470"
    ],
    "summaries": [
      "patool fails to build with Python 3.14: Codec Load Error: /usr/bin/7z.so : errno=25 : Inappropriate ioctl for device"
    ]
  },
  "pcs": {
    "urls": [],
    "summaries": []
  },
  "poetry": {
    "urls": [
      "https://bugzilla.redhat.com/show_bug.cgi?id=2351383"
    ],
    "summaries": [
      "poetry fails to build with Python 3.14: AssertionError in test_isolated_env_install_discards_requirements_not_needed_by_env and test_python_get_preferred_default"
    ]
  },
  "poezio": {
    "urls": [
      "https://bugzilla.redhat.com/show_bug.cgi?id=2341088",
      "https://bugzilla.redhat.com/show_bug.cgi?id=2329835"
    ],
    "summaries": [
      "poezio: FTBFS in Fedora rawhide/f42",
      "poezio fails to build with sphinx 8.x:  ERROR: Invalid value `None` in intersphinx_mapping['http://docs.python.org/']."
    ]
  },
  "postfix-mta-sts-resolver": {
    "urls": [],
    "summaries": []
  },
  "prewikka-updatedb": {
    "urls": [],
    "summaries": []
  },
  "pybind11": {
    "urls": [
      "https://bugzilla.redhat.com/show_bug.cgi?id=2336889"
    ],
    "summaries": [
      "pybind11 fails to build with Python 3.14: AttributeError: 'pybind11_tests.pickling.PickleableWithDict' object has no attribute 'dynamic' + AssertionError"
    ]
  },
  "pychess": {
    "urls": [
      "https://bugzilla.redhat.com/show_bug.cgi?id=2328708"
    ],
    "summaries": [
      "pychess fails to build with Python 3.14: RuntimeError: There is no current event loop in thread 'MainThread'."
    ]
  },
  "pychromecast": {
    "urls": [
      "https://bugzilla.redhat.com/show_bug.cgi?id=2366486"
    ],
    "summaries": [
      "pychromecast fails to build with Python 3.14: protobuf: TypeError: Metaclasses with custom tp_new are not supported."
    ]
  },
  "pyflakes": {
    "urls": [
      "https://bugzilla.redhat.com/show_bug.cgi?id=2359503"
    ],
    "summaries": [
      "pyflakes fails to build with Python 3.14: SyntaxError: future feature print_statement is not defined"
    ]
  },
  "pygobject3": {
    "urls": [
      "https://bugzilla.redhat.com/show_bug.cgi?id=2359811"
    ],
    "summaries": [
      "pygobject3 fails to build with Python 3.14: Failed TestPythonReferenceCounting and TestRefCountsIntrospected and TestRefCountsNonIntrospected"
    ]
  },
  "pylibacl": {
    "urls": [
      "https://bugzilla.redhat.com/show_bug.cgi?id=2359502"
    ],
    "summaries": [
      "pylibacl fails to build with Python 3.14: tests/test_acls.py::TestModification: Failed: Wrong reference count, expected 2-1024 and got 1"
    ]
  },
  "pylint": {
    "urls": [],
    "summaries": []
  },
  "pyproj": {
    "urls": [],
    "summaries": []
  },
  "pysubnettree": {
    "urls": [
      "https://bugzilla.redhat.com/show_bug.cgi?id=2366464",
      "https://bugzilla.redhat.com/show_bug.cgi?id=2341123"
    ],
    "summaries": [
      "pysubnettree fails to build with Python 3.14/Fedora Rawhide: error: too many arguments to function \u2018func\u2019; expected 0, have 1",
      "pysubnettree: FTBFS in Fedora rawhide/f42"
    ]
  },
  "python-TestSlide": {
    "urls": [
      "https://bugzilla.redhat.com/show_bug.cgi?id=2350306",
      "https://bugzilla.redhat.com/show_bug.cgi?id=2343971"
    ],
    "summaries": [
      "Heads-up: python-TestSlide fails to build with python-pygments 2.19.1 on Fedora 43",
      "python-TestSlide fails to build with Python 3.14: ERROR collecting tests/mock_callable_testslide.py: RuntimeError: dictionary changed size during iteration"
    ]
  },
  "python-accuweather": {
    "urls": [],
    "summaries": []
  },
  "python-aioesphomeapi": {
    "urls": [
      "https://bugzilla.redhat.com/show_bug.cgi?id=2366202"
    ],
    "summaries": [
      "python-aioesphomeapi fails to build with Python 3.14: protobuf: TypeError: Metaclasses with custom tp_new are not supported"
    ]
  },
  "python-aiogqlc": {
    "urls": [],
    "summaries": []
  },
  "python-aiohttp-cors": {
    "urls": [],
    "summaries": []
  },
  "python-aiohttp-oauthlib": {
    "urls": [],
    "summaries": []
  },
  "python-aiohttp-socks": {
    "urls": [],
    "summaries": []
  },
  "python-aiohttp-sse-client": {
    "urls": [],
    "summaries": []
  },
  "python-aiokafka": {
    "urls": [
      "https://bugzilla.redhat.com/show_bug.cgi?id=2346517"
    ],
    "summaries": [
      "python-aiokafka fails to build with Python 3.14: DeprecationWarning: 'asyncio.get_event_loop_policy' is deprecated and slated for removal in Python 3.16"
    ]
  },
  "python-aioresponses": {
    "urls": [],
    "summaries": []
  },
  "python-aioruckus": {
    "urls": [],
    "summaries": []
  },
  "python-aiosmtpd": {
    "urls": [
      "https://bugzilla.redhat.com/show_bug.cgi?id=2322718"
    ],
    "summaries": [
      "python-aiosmtpd fails to build with Python 3.14: ImportError: cannot import name 'ByteString' from 'typing'"
    ]
  },
  "python-aiounittest": {
    "urls": [
      "https://bugzilla.redhat.com/show_bug.cgi?id=2356177"
    ],
    "summaries": [
      "python-aiounittest fails to build with Python 3.14: RuntimeError: There is no current event loop in thread 'MainThread'."
    ]
  },
  "python-ansible-runner": {
    "urls": [],
    "summaries": []
  },
  "python-anyio": {
    "urls": [
      "https://bugzilla.redhat.com/show_bug.cgi?id=2367992"
    ],
    "summaries": [
      "python-anyio fails to build with Python 3.14: test_copy and test_copy_into fail with pathlib's AttributeError: 'Path' object has no attribute '_copy_from'"
    ]
  },
  "python-apsw": {
    "urls": [
      "https://bugzilla.redhat.com/show_bug.cgi?id=2368619"
    ],
    "summaries": [
      "python-apsw fails to build with Python 3.14: AttributeError: 'DataClassRowFactory.4524B5' object has no attribute '__annotations__'. Did you mean: '__annotate_func__'?"
    ]
  },
  "python-aresponses": {
    "urls": [],
    "summaries": []
  },
  "python-array-api-strict": {
    "urls": [
      "https://bugzilla.redhat.com/show_bug.cgi?id=2365875"
    ],
    "summaries": [
      "python-array-api-strict fails to build with Python 3.14: test_iter: Failed: DID NOT RAISE <class 'TypeError'>"
    ]
  },
  "python-astdoc": {
    "urls": [
      "https://bugzilla.redhat.com/show_bug.cgi?id=2349452"
    ],
    "summaries": [
      "python-astdoc fails to build with Python 3.14: 3 doctests fail, e.g.: Expected: <ast.Name object at 0x...> Got: Name(id='int', ctx=Load())"
    ]
  },
  "python-astroML": {
    "urls": [],
    "summaries": []
  },
  "python-astroplan": {
    "urls": [],
    "summaries": []
  },
  "python-astropy": {
    "urls": [
      "https://bugzilla.redhat.com/show_bug.cgi?id=2345524"
    ],
    "summaries": [
      "python-astropy fails to build with Python 3.14: test_info_preserved_pickle_copy_init[arrayswap]: AssertionError: assert dtype('>i4') == dtype('int32')"
    ]
  },
  "python-astropy-healpix": {
    "urls": [],
    "summaries": []
  },
  "python-astropy-iers-data": {
    "urls": [
      "https://bugzilla.redhat.com/show_bug.cgi?id=2349443"
    ],
    "summaries": [
      "python-astropy-iers-data fails to build with Python 3.14: 4 tests fail with KeyError: 'ra_in' and 'lon_in'"
    ]
  },
  "python-astroquery": {
    "urls": [],
    "summaries": []
  },
  "python-async-upnp-client": {
    "urls": [],
    "summaries": []
  },
  "python-asyncssh": {
    "urls": [
      "https://bugzilla.redhat.com/show_bug.cgi?id=2325445"
    ],
    "summaries": [
      "python-asyncssh fails to build with Python 3.14: multiple test failures (failures=25, errors=697)"
    ]
  },
  "python-atomicwrites": {
    "urls": [
      "https://bugzilla.redhat.com/show_bug.cgi?id=2341128"
    ],
    "summaries": [
      "python-atomicwrites: FTBFS in Fedora rawhide/f42"
    ]
  },
  "python-autocommand": {
    "urls": [
      "https://bugzilla.redhat.com/show_bug.cgi?id=2327972"
    ],
    "summaries": [
      "python-autocommand fails to build with Python 3.14: RuntimeError: There is no current event loop in thread 'MainThread'."
    ]
  },
  "python-avocado": {
    "urls": [
      "https://bugzilla.redhat.com/show_bug.cgi?id=2341130",
      "https://bugzilla.redhat.com/show_bug.cgi?id=2325218"
    ],
    "summaries": [
      "python-avocado: FTBFS in Fedora rawhide/f42",
      "python-avocado fails to build with Python 3.14: Error running method \"pre_tests\" of plugin \"fetchasset\": module 'ast' has no attribute 'Str' + Avocado crashed: TypeError: cannot pickle '_thread.RLock' object"
    ]
  },
  "python-aw-core": {
    "urls": [],
    "summaries": []
  },
  "python-awesomeversion": {
    "urls": [
      "https://bugzilla.redhat.com/show_bug.cgi?id=2366476"
    ],
    "summaries": [
      "python-awesomeversion fails to build in Fedora Rawhide: rm: cannot remove '/builddir/build/BUILD/python-awesomeversion-22.9.0-build/BUILDROOT//usr/lib/python3.14/site-packages/LICENCE.md': No such file or directory"
    ]
  },
  "python-aws-sam-translator": {
    "urls": [
      "https://bugzilla.redhat.com/show_bug.cgi?id=2353126"
    ],
    "summaries": [
      "python-aws-sam-translator fails to build with Python 3.14: 77 test failures, 4 error"
    ]
  },
  "python-aws-xray-sdk": {
    "urls": [],
    "summaries": []
  },
  "python-axolotl": {
    "urls": [
      "https://bugzilla.redhat.com/show_bug.cgi?id=2366200"
    ],
    "summaries": [
      "python-axolotl fails to build with Python 3.14: protobuf: TypeError: Metaclasses with custom tp_new are not supported."
    ]
  },
  "python-azure-multiapi-storage": {
    "urls": [],
    "summaries": []
  },
  "python-azure-servicebus": {
    "urls": [],
    "summaries": []
  },
  "python-b4": {
    "urls": [],
    "summaries": []
  },
  "python-beancount": {
    "urls": [
      "https://bugzilla.redhat.com/show_bug.cgi?id=2359530"
    ],
    "summaries": [
      "python-beancount fails to build with Python 3.14: TestReferenceCounting and TestLexer fail with AssertionError"
    ]
  },
  "python-beartype": {
    "urls": [
      "https://bugzilla.redhat.com/show_bug.cgi?id=2341131",
      "https://bugzilla.redhat.com/show_bug.cgi?id=2322721"
    ],
    "summaries": [
      "python-beartype: FTBFS in Fedora rawhide/f42",
      "python-beartype fails to build with Python 3.14: ImportError: cannot import name 'ByteString' from 'typing'"
    ]
  },
  "python-beautifulsoup4": {
    "urls": [],
    "summaries": []
  },
  "python-behave": {
    "urls": [
      "https://bugzilla.redhat.com/show_bug.cgi?id=2339094"
    ],
    "summaries": [
      "python-behave fails to build with Python 3.14: RuntimeError: There is no current event loop in thread 'MainThread'."
    ]
  },
  "python-billiard": {
    "urls": [
      "https://bugzilla.redhat.com/show_bug.cgi?id=2323167"
    ],
    "summaries": [
      "python-billiard fails to build with Python 3.14: AttributeError: module 'subprocess' has no attribute '_USE_VFORK'"
    ]
  },
  "python-binary-memcached": {
    "urls": [],
    "summaries": []
  },
  "python-bioframe": {
    "urls": [],
    "summaries": []
  },
  "python-blinker": {
    "urls": [
      "https://bugzilla.redhat.com/show_bug.cgi?id=2325193"
    ],
    "summaries": [
      "python-blinker fails to build with Python 3.14: pluggy.PluggyTeardownRaisedWarning: A plugin raised an exception during an old-style hookwrapper teardown."
    ]
  },
  "python-blosc2": {
    "urls": [],
    "summaries": []
  },
  "python-boto3": {
    "urls": [],
    "summaries": []
  },
  "python-botocore": {
    "urls": [
      "https://bugzilla.redhat.com/show_bug.cgi?id=2367782"
    ],
    "summaries": [
      "python-botocore fails to build with Python 3.14: test_lru_cache_weakref: AssertionError: assert getrefcount(cls1) == 2"
    ]
  },
  "python-boutdata": {
    "urls": [
      "https://bugzilla.redhat.com/show_bug.cgi?id=2352553"
    ],
    "summaries": [
      "python-boutdata fails to build with Python 3.14: NotImplementedError: Dataset is not picklable"
    ]
  },
  "python-bsmschema": {
    "urls": [],
    "summaries": []
  },
  "python-capturer": {
    "urls": [
      "https://bugzilla.redhat.com/show_bug.cgi?id=2328004"
    ],
    "summaries": [
      "python-capturer fails to build with Python 3.14: OSError: [Errno 29] Illegal seek"
    ]
  },
  "python-carbon": {
    "urls": [
      "https://bugzilla.redhat.com/show_bug.cgi?id=2368591"
    ],
    "summaries": [
      "python-carbon fails to build with Python 3.14: protobuf: TypeError: Metaclasses with custom tp_new are not supported."
    ]
  },
  "python-catkin_tools": {
    "urls": [
      "https://bugzilla.redhat.com/show_bug.cgi?id=2341134",
      "https://bugzilla.redhat.com/show_bug.cgi?id=2329848"
    ],
    "summaries": [
      "python-catkin_tools: FTBFS in Fedora rawhide/f42",
      "python-catkin_tools fails to build with sphinx 8.x:  ERROR: Invalid value `None` in intersphinx_mapping['http://docs.python.org/']."
    ]
  },
  "python-cattrs": {
    "urls": [
      "https://bugzilla.redhat.com/show_bug.cgi?id=2343916"
    ],
    "summaries": [
      "python-cattrs fails to build with Python 3.14: TypeError: <class 'tests.strategies.test_include_subclasses.GrandChild'> has no usable non-default attributes"
    ]
  },
  "python-cerberus": {
    "urls": [
      "https://bugzilla.redhat.com/show_bug.cgi?id=2366466"
    ],
    "summaries": [
      "python-cerberus fails to build in Fedora Rawhide:  File not found: /builddir/build/BUILD/python-cerberus-1.3.4-build/BUILDROOT/usr/lib/python3.14/site-packages/Cerberus-1.3.4.dist-info"
    ]
  },
  "python-chalice": {
    "urls": [
      "https://bugzilla.redhat.com/show_bug.cgi?id=2342568"
    ],
    "summaries": [
      "python-chalice fails to build with Python 3.14: AttributeError: module 'ast' has no attribute 'Str'"
    ]
  },
  "python-chaospy": {
    "urls": [],
    "summaries": []
  },
  "python-cliff": {
    "urls": [],
    "summaries": []
  },
  "python-cmd2": {
    "urls": [
      "https://bugzilla.redhat.com/show_bug.cgi?id=2356178"
    ],
    "summaries": [
      "python-cmd2 fails to build with Python 3.14:  ValueError: action 'store_true' is not valid for positional arguments"
    ]
  },
  "python-colcon-meson": {
    "urls": [],
    "summaries": []
  },
  "python-colcon-parallel-executor": {
    "urls": [
      "https://bugzilla.redhat.com/show_bug.cgi?id=2325186"
    ],
    "summaries": [
      "python-colcon-parallel-executor fails to build with Python 3.14: test_parallel: AssertionError: DeprecationWarning: 'asyncio.iscoroutinefunction' is deprecated and slated for removal in Python 3.16; use inspect.iscoroutinefunction() instead"
    ]
  },
  "python-colorful": {
    "urls": [
      "https://bugzilla.redhat.com/show_bug.cgi?id=2325168"
    ],
    "summaries": [
      "python-colorful fails to build with Python 3.14: ast.Constant.s has been removed from Python 3.14"
    ]
  },
  "python-confuse": {
    "urls": [
      "https://bugzilla.redhat.com/show_bug.cgi?id=2327966"
    ],
    "summaries": [
      "python-confuse fails to build with Python 3.14: AttributeError: module 'pkgutil' has no attribute 'get_loader'"
    ]
  },
  "python-contextualbandits": {
    "urls": [],
    "summaries": []
  },
  "python-crcmod": {
    "urls": [
      "https://bugzilla.redhat.com/show_bug.cgi?id=2329852"
    ],
    "summaries": [
      "python-crcmod fails to build with sphinx 8.x: ERROR: Invalid value `None` in intersphinx_mapping['/usr/share/doc/python3-docs/html/']."
    ]
  },
  "python-crick": {
    "urls": [
      "https://bugzilla.redhat.com/show_bug.cgi?id=2367454"
    ],
    "summaries": [
      "python-crick fails to build with Python 3.14: crick/tests/test_space_saving.py::test_merge_algorithm[s111-s211] Fatal Python error: Segmentation fault"
    ]
  },
  "python-cro": {
    "urls": [],
    "summaries": []
  },
  "python-cryptography": {
    "urls": [],
    "summaries": []
  },
  "python-cs": {
    "urls": [],
    "summaries": []
  },
  "python-daikin": {
    "urls": [],
    "summaries": []
  },
  "python-damo": {
    "urls": [],
    "summaries": []
  },
  "python-dataclassy": {
    "urls": [
      "https://bugzilla.redhat.com/show_bug.cgi?id=2325200"
    ],
    "summaries": [
      "python-dataclassy fails to build with Python 3.14: TypeError: Beta() takes no arguments"
    ]
  },
  "python-dateparser": {
    "urls": [
      "https://bugzilla.redhat.com/show_bug.cgi?id=2367245"
    ],
    "summaries": [
      "python-dateparser fails to build with Python 3.14: 11 test failures"
    ]
  },
  "python-deconz": {
    "urls": [],
    "summaries": []
  },
  "python-deepdiff": {
    "urls": [],
    "summaries": []
  },
  "python-defcon": {
    "urls": [],
    "summaries": []
  },
  "python-diff-cover": {
    "urls": [
      "https://bugzilla.redhat.com/show_bug.cgi?id=2350299"
    ],
    "summaries": [
      "Heads-up: python-diff-cover fails to build with python-pygments 2.19.1 on Fedora 43"
    ]
  },
  "python-dill": {
    "urls": [
      "https://bugzilla.redhat.com/show_bug.cgi?id=2323157"
    ],
    "summaries": [
      "python-dill fails to build with Python 3.14: TypeError: _Pickler._batch_setitems() missing 1 required positional argument: 'obj'"
    ]
  },
  "python-dipy": {
    "urls": [],
    "summaries": []
  },
  "python-dirty-equals": {
    "urls": [],
    "summaries": []
  },
  "python-django-configurations": {
    "urls": [
      "https://bugzilla.redhat.com/show_bug.cgi?id=2366494"
    ],
    "summaries": [
      "python-django-configurations fails to build with Python 3.14: ValueTests.test_cache_url_value: AssertionError:"
    ]
  },
  "python-django-contrib-comments": {
    "urls": [
      "https://bugzilla.redhat.com/show_bug.cgi?id=2366520"
    ],
    "summaries": [
      "python-django-contrib-comments fails to build with Python 3.14: ImportError: Module \"django.contrib.auth.hashers\" does not define a \"UnsaltedMD5PasswordHasher\" attribute/class"
    ]
  },
  "python-django-extensions": {
    "urls": [],
    "summaries": []
  },
  "python-django-filter": {
    "urls": [
      "https://bugzilla.redhat.com/show_bug.cgi?id=2336944"
    ],
    "summaries": [
      "python-django-filter fails to build with Python 3.14: AttributeError: module 'pkgutil' has no attribute 'find_loader'"
    ]
  },
  "python-django-mailman3": {
    "urls": [],
    "summaries": []
  },
  "python-domdf-python-tools": {
    "urls": [
      "https://bugzilla.redhat.com/show_bug.cgi?id=2345519"
    ],
    "summaries": [
      "python-domdf-python-tools fails to build with Python 3.14: tests/test_words.py::test_alpha_sort - AssertionError: Regex pattern did not match."
    ]
  },
  "python-doubleratchet": {
    "urls": [],
    "summaries": []
  },
  "python-drgn": {
    "urls": [],
    "summaries": []
  },
  "python-duecredit": {
    "urls": [],
    "summaries": []
  },
  "python-dunamai": {
    "urls": [],
    "summaries": []
  },
  "python-efel": {
    "urls": [],
    "summaries": []
  },
  "python-elephant": {
    "urls": [],
    "summaries": []
  },
  "python-email-validator": {
    "urls": [],
    "summaries": []
  },
  "python-engineio": {
    "urls": [],
    "summaries": []
  },
  "python-enturclient": {
    "urls": [],
    "summaries": []
  },
  "python-envisage": {
    "urls": [],
    "summaries": []
  },
  "python-ephyviewer": {
    "urls": [],
    "summaries": []
  },
  "python-epson-projector": {
    "urls": [],
    "summaries": []
  },
  "python-et_xmlfile": {
    "urls": [
      "https://bugzilla.redhat.com/show_bug.cgi?id=2359509"
    ],
    "summaries": [
      "python-et_xmlfile fails to build with Python 3.14: ElementTreeTest.test_simpleops: AssertionError: 'Element.remove(x): element not found' != 'list.remove(x): x not in list'"
    ]
  },
  "python-eth-stdlib": {
    "urls": [
      "https://bugzilla.redhat.com/show_bug.cgi?id=2368527"
    ],
    "summaries": [
      "python-eth-stdlib fails to build in Copr: error: Bad file: /builddir/build/SOURCES/python-eth-stdlib-0004-Fix-for-modern-poetry.patch: No such file or directory"
    ]
  },
  "python-exdir": {
    "urls": [
      "https://bugzilla.redhat.com/show_bug.cgi?id=2367253"
    ],
    "summaries": [
      "python-exdir fails to build with Python 3.14: TypeError: 'module' object is not iterable | TypeError: 'Plugin' object is not iterable"
    ]
  },
  "python-executing": {
    "urls": [
      "https://bugzilla.redhat.com/show_bug.cgi?id=2349436"
    ],
    "summaries": [
      "python-executing fails to build with Python 3.14: 52 test fail during the build"
    ]
  },
  "python-factory-boy": {
    "urls": [],
    "summaries": []
  },
  "python-fastavro": {
    "urls": [],
    "summaries": []
  },
  "python-fiona": {
    "urls": [],
    "summaries": []
  },
  "python-flake8-comprehensions": {
    "urls": [
      "https://bugzilla.redhat.com/show_bug.cgi?id=2351385"
    ],
    "summaries": [
      "python-flake8-comprehensions fails to build with Python 3.14: Unnecessary reversed call around sorted() in 10 tests"
    ]
  },
  "python-flask": {
    "urls": [
      "https://bugzilla.redhat.com/show_bug.cgi?id=2327965"
    ],
    "summaries": [
      "python-flask fails to build with Python 3.14: AttributeError: module 'pkgutil' has no attribute 'get_loader'"
    ]
  },
  "python-flask-caching": {
    "urls": [
      "https://bugzilla.redhat.com/show_bug.cgi?id=2341153",
      "https://bugzilla.redhat.com/show_bug.cgi?id=2329857"
    ],
    "summaries": [
      "python-flask-caching: FTBFS in Fedora rawhide/f42",
      "python-flask-caching fails to build with sphinx 8.x: ERROR: Invalid value `None` in intersphinx_mapping['https://docs.python.org/3/']."
    ]
  },
  "python-flask-session": {
    "urls": [
      "https://bugzilla.redhat.com/show_bug.cgi?id=2354108"
    ],
    "summaries": [
      "python-flask-session FTBFS due to missing tox configuration"
    ]
  },
  "python-fluidity-sm": {
    "urls": [],
    "summaries": []
  },
  "python-formulaic": {
    "urls": [],
    "summaries": []
  },
  "python-fs": {
    "urls": [
      "https://bugzilla.redhat.com/show_bug.cgi?id=2336951"
    ],
    "summaries": [
      "python-fs fails to build with Python 3.14: AssertionError: 'osfs://///tmp/tmppauy69swfstestosfs/foo' != 'osfs:///tmp/tmppauy69swfstestosfs/foo'"
    ]
  },
  "python-fsleyes-widgets": {
    "urls": [
      "https://bugzilla.redhat.com/show_bug.cgi?id=2336911"
    ],
    "summaries": [
      "python-fsleyes-widgets fails to build with Python 3.14: AssertionError: assert 'file:/home/b...htmlfile.html' == 'file:///home...htmlfile.html'"
    ]
  },
  "python-fsspec": {
    "urls": [],
    "summaries": []
  },
  "python-geoip2": {
    "urls": [],
    "summaries": []
  },
  "python-geopmpy": {
    "urls": [],
    "summaries": []
  },
  "python-geopy": {
    "urls": [],
    "summaries": []
  },
  "python-giacpy": {
    "urls": [
      "https://bugzilla.redhat.com/show_bug.cgi?id=2366459",
      "https://bugzilla.redhat.com/show_bug.cgi?id=2341608"
    ],
    "summaries": [
      "python-giacpy fails to build with Python 3.14: RuntimeError: Unable to multiply two graphic objects Error: Bad Argument Value",
      "python-giacpy: FTBFS in Fedora rawhide/f42"
    ]
  },
  "python-gios": {
    "urls": [],
    "summaries": []
  },
  "python-googleapis-common-protos": {
    "urls": [
      "https://bugzilla.redhat.com/show_bug.cgi?id=2365822"
    ],
    "summaries": [
      "python-googleapis-common-protos fails to build with Python 3.14: protobuf: TypeError: Metaclasses with custom tp_new are not supported."
    ]
  },
  "python-gphoto2": {
    "urls": [
      "https://bugzilla.redhat.com/show_bug.cgi?id=2366465",
      "https://bugzilla.redhat.com/show_bug.cgi?id=2341158"
    ],
    "summaries": [
      "python-gphoto2 fails to build with Python 3.14: ModuleNotFoundError: No module named 'distutils.command.upload'",
      "python-gphoto2: FTBFS in Fedora rawhide/f42"
    ]
  },
  "python-gql": {
    "urls": [],
    "summaries": []
  },
  "python-greenlet": {
    "urls": [],
    "summaries": []
  },
  "python-h5io": {
    "urls": [],
    "summaries": []
  },
  "python-h5netcdf": {
    "urls": [
      "https://bugzilla.redhat.com/show_bug.cgi?id=2325222"
    ],
    "summaries": [
      "python-h5netcdf fails to build with Python 3.14: test_no_circular_references: AssertionError"
    ]
  },
  "python-hamcrest": {
    "urls": [
      "https://bugzilla.redhat.com/show_bug.cgi?id=2346504"
    ],
    "summaries": [
      "python-hamcrest fails to build with Python 3.14: RuntimeError: There is no current event loop in thread 'MainThread'."
    ]
  },
  "python-hass-data-detective": {
    "urls": [],
    "summaries": []
  },
  "python-hdfs": {
    "urls": [],
    "summaries": []
  },
  "python-healpy": {
    "urls": [],
    "summaries": []
  },
  "python-hl7": {
    "urls": [
      "https://bugzilla.redhat.com/show_bug.cgi?id=2341161",
      "https://bugzilla.redhat.com/show_bug.cgi?id=2329855"
    ],
    "summaries": [
      "python-hl7: FTBFS in Fedora rawhide/f42",
      "python-hl7 fails to build with sphinx 8.x: ERROR: Invalid value `None` in intersphinx_mapping['http://docs.python.org/']."
    ]
  },
  "python-howdoi": {
    "urls": [
      "https://bugzilla.redhat.com/show_bug.cgi?id=2342558"
    ],
    "summaries": [
      "python-howdoi fails to build with Python 3.14: AssertionError: 'ERROR: Unable to reach google. Do you need to use a proxy? + json.decoder.JSONDecodeError"
    ]
  },
  "python-igraph": {
    "urls": [],
    "summaries": []
  },
  "python-imbalanced-learn": {
    "urls": [],
    "summaries": []
  },
  "python-influxdb-client": {
    "urls": [],
    "summaries": []
  },
  "python-iniparse": {
    "urls": [
      "https://bugzilla.redhat.com/show_bug.cgi?id=2323164"
    ],
    "summaries": [
      "python-iniparse fails to build with Python 3.14: _pickle.PicklingError: Can't pickle local object <function TestIni.test_queue.<locals>.getxy at 0x7f86659a7740>"
    ]
  },
  "python-inject": {
    "urls": [
      "https://bugzilla.redhat.com/show_bug.cgi?id=2327978"
    ],
    "summaries": [
      "python-inject fails to build with Python 3.14: RuntimeError: There is no current event loop in thread 'MainThread'."
    ]
  },
  "python-injector": {
    "urls": [
      "https://bugzilla.redhat.com/show_bug.cgi?id=2341165",
      "https://bugzilla.redhat.com/show_bug.cgi?id=2329880"
    ],
    "summaries": [
      "python-injector: FTBFS in Fedora rawhide/f42",
      "python-injector fails to build with sphinx 8.x: ERROR: Invalid value `None` in intersphinx_mapping['http://docs.python.org/']."
    ]
  },
  "python-invoke": {
    "urls": [
      "https://bugzilla.redhat.com/show_bug.cgi?id=2365652"
    ],
    "summaries": [
      "python-invoke fails to build with Python 3.14: SystemError: buffer overflow in 16 tests"
    ]
  },
  "python-ipfshttpclient": {
    "urls": [
      "https://bugzilla.redhat.com/show_bug.cgi?id=2368589"
    ],
    "summaries": [
      "python-ipfshttpclient fails to build with Python 3.14: AssertionError: assert ['(?![.])(?s:literal)\\\\z'] == ['(?![.])(?s:literal)\\\\Z']"
    ]
  },
  "python-ipyparallel": {
    "urls": [
      "https://bugzilla.redhat.com/show_bug.cgi?id=2359525"
    ],
    "summaries": [
      "python-ipyparallel fails to build with Python 3.14: TestAsyncResult.test_display_output_error: SyntaxWarning: 'return' in a 'finally' block treated as error"
    ]
  },
  "python-irc": {
    "urls": [
      "https://bugzilla.redhat.com/show_bug.cgi?id=2327991"
    ],
    "summaries": [
      "python-irc fails to build with Python 3.14: RuntimeError: There is no current event loop in thread 'MainThread'."
    ]
  },
  "python-janus": {
    "urls": [],
    "summaries": []
  },
  "python-jedi": {
    "urls": [],
    "summaries": []
  },
  "python-joblib": {
    "urls": [
      "https://bugzilla.redhat.com/show_bug.cgi?id=2339519"
    ],
    "summaries": [
      "python-joblib fails to build with Python 3.14: TypeError: Hasher._batch_setitems() takes 2 positional arguments but 3 were given"
    ]
  },
  "python-josepy": {
    "urls": [
      "https://bugzilla.redhat.com/show_bug.cgi?id=2359514"
    ],
    "summaries": [
      "python-josepy fails to build with Python 3.14: ValueError: Field `alg` in JSONObject `Header` has no type annotation."
    ]
  },
  "python-jsonpickle": {
    "urls": [],
    "summaries": []
  },
  "python-jupyter-events": {
    "urls": [],
    "summaries": []
  },
  "python-jupyter-kernel-test": {
    "urls": [],
    "summaries": []
  },
  "python-jupyter-server": {
    "urls": [],
    "summaries": []
  },
  "python-jupytext": {
    "urls": [],
    "summaries": []
  },
  "python-lazr-uri": {
    "urls": [],
    "summaries": []
  },
  "python-libNeuroML": {
    "urls": [],
    "summaries": []
  },
  "python-libcst": {
    "urls": [
      "https://bugzilla.redhat.com/show_bug.cgi?id=2356182"
    ],
    "summaries": [
      "python-libcst fails to build with Python 3.14: Exception: Logic error, unexpected top level type! when importing libcst.codegen.gen_matcher_classes"
    ]
  },
  "python-loguru": {
    "urls": [
      "https://bugzilla.redhat.com/show_bug.cgi?id=2356181"
    ],
    "summaries": [
      "python-loguru fails to build with Python 3.14: test_exception_modern[type_hints-minimum_python_version0]: m<class 'typing.Union'>"
    ]
  },
  "python-lz4": {
    "urls": [
      "https://bugzilla.redhat.com/show_bug.cgi?id=2365823"
    ],
    "summaries": [
      "python-lz4 fails to build with Python 3.14: ImportError: cannot import name '_compression' from partially initialized module 'lz4.frame' (most likely due to a circular import)"
    ]
  },
  "python-makefun": {
    "urls": [
      "https://bugzilla.redhat.com/show_bug.cgi?id=2328706"
    ],
    "summaries": [
      "python-makefun fails to build with Python 3.14: RuntimeError: There is no current event loop in thread 'MainThread'."
    ]
  },
  "python-markups": {
    "urls": [
      "https://bugzilla.redhat.com/show_bug.cgi?id=2366489"
    ],
    "summaries": [
      "python-markups fails to build with Python 3.14: AssertionError in test_get_pygments_stylesheet"
    ]
  },
  "python-matplotlib": {
    "urls": [
      "https://bugzilla.redhat.com/show_bug.cgi?id=2328713"
    ],
    "summaries": [
      "python-matplotlib fails to build with Python 3.14: RecursionError: maximum recursion depth exceeded"
    ]
  },
  "python-matrix-nio": {
    "urls": [],
    "summaries": []
  },
  "python-mccabe": {
    "urls": [
      "https://bugzilla.redhat.com/show_bug.cgi?id=2328016"
    ],
    "summaries": [
      "python-mccabe fails to build with Python 3.14: test_idempotent_any_syntatically_valid_python fails"
    ]
  },
  "python-mechanize": {
    "urls": [
      "https://bugzilla.redhat.com/show_bug.cgi?id=2368592"
    ],
    "summaries": [
      "python-mechanize fails to build with Python 3.14: test.test_cookies.CookieTests.test_missing_name: AssertionError"
    ]
  },
  "python-metakernel": {
    "urls": [
      "https://bugzilla.redhat.com/show_bug.cgi?id=2357903"
    ],
    "summaries": [
      "python-metakernel fails to build with Python 3.14: AssertionError in test_parallel_magic"
    ]
  },
  "python-missingno": {
    "urls": [],
    "summaries": []
  },
  "python-mizani": {
    "urls": [],
    "summaries": []
  },
  "python-mkdocs-d2-plugin": {
    "urls": [],
    "summaries": []
  },
  "python-mplcursors": {
    "urls": [
      "https://bugzilla.redhat.com/show_bug.cgi?id=2367456"
    ],
    "summaries": [
      "python-mplcursors: FTBFS in Fedora Rawhide"
    ]
  },
  "python-msal": {
    "urls": [
      "https://bugzilla.redhat.com/show_bug.cgi?id=2323170"
    ],
    "summaries": [
      "python-msal fails to build with Python 3.14: test_no_two_concurrent_receivers_can_listen_on_same_port: AssertionError: OSError not raised"
    ]
  },
  "python-msgspec": {
    "urls": [
      "https://bugzilla.redhat.com/show_bug.cgi?id=2365636"
    ],
    "summaries": [
      "python-msgspec fails to build with Python 3.14: TypeError: Extra positional arguments provided"
    ]
  },
  "python-msrest": {
    "urls": [],
    "summaries": []
  },
  "python-music21": {
    "urls": [
      "https://bugzilla.redhat.com/show_bug.cgi?id=2354114"
    ],
    "summaries": [
      "python-music21 FTBFS due to missing tox configuration"
    ]
  },
  "python-nbclient": {
    "urls": [],
    "summaries": []
  },
  "python-nbconvert": {
    "urls": [],
    "summaries": []
  },
  "python-nbdime": {
    "urls": [],
    "summaries": []
  },
  "python-neatdend": {
    "urls": [
      "https://bugzilla.redhat.com/show_bug.cgi?id=2341170"
    ],
    "summaries": [
      "python-neatdend: FTBFS in Fedora rawhide/f42"
    ]
  },
  "python-netpyne": {
    "urls": [],
    "summaries": []
  },
  "python-network-runner": {
    "urls": [
      "https://bugzilla.redhat.com/show_bug.cgi?id=2341172"
    ],
    "summaries": [
      "python-network-runner: FTBFS in Fedora rawhide/f42"
    ]
  },
  "python-niaaml": {
    "urls": [],
    "summaries": []
  },
  "python-niaarmts": {
    "urls": [],
    "summaries": []
  },
  "python-niaclass": {
    "urls": [],
    "summaries": []
  },
  "python-niapy": {
    "urls": [],
    "summaries": []
  },
  "python-nikola": {
    "urls": [
      "https://bugzilla.redhat.com/show_bug.cgi?id=2341174"
    ],
    "summaries": [
      "python-nikola: FTBFS in Fedora rawhide/f42"
    ]
  },
  "python-notebook": {
    "urls": [],
    "summaries": []
  },
  "python-notify2": {
    "urls": [
      "https://bugzilla.redhat.com/show_bug.cgi?id=2341175",
      "https://bugzilla.redhat.com/show_bug.cgi?id=2329864"
    ],
    "summaries": [
      "python-notify2: FTBFS in Fedora rawhide/f42",
      "python-notify2 fails to build with sphinx 8.x: ERROR: Invalid value `None` in intersphinx_mapping['http://docs.python.org/']."
    ]
  },
  "python-numexpr": {
    "urls": [
      "https://bugzilla.redhat.com/show_bug.cgi?id=2359520"
    ],
    "summaries": [
      "python-numexpr fails to build with Python 3.14: 8 errors: ValueError: operands could not be broadcast together with shapes (1000000,) (0,)  2 failures: AssertionError: sys.getrefcount(a) == 2"
    ]
  },
  "python-odata-query": {
    "urls": [],
    "summaries": []
  },
  "python-ollama": {
    "urls": [],
    "summaries": []
  },
  "python-opensearch-py": {
    "urls": [],
    "summaries": []
  },
  "python-opfunu": {
    "urls": [],
    "summaries": []
  },
  "python-orjson": {
    "urls": [],
    "summaries": []
  },
  "python-osc-lib": {
    "urls": [
      "https://bugzilla.redhat.com/show_bug.cgi?id=2351387"
    ],
    "summaries": [
      "python-osc-lib fails to build with Python 3.14: testtools.matchers._impl.MismatchError in 4 tests"
    ]
  },
  "python-oslo-config": {
    "urls": [],
    "summaries": []
  },
  "python-oslo-log": {
    "urls": [],
    "summaries": []
  },
  "python-packvers": {
    "urls": [
      "https://bugzilla.redhat.com/show_bug.cgi?id=2341178",
      "https://bugzilla.redhat.com/show_bug.cgi?id=2329888"
    ],
    "summaries": [
      "python-packvers: FTBFS in Fedora rawhide/f42",
      "python-packvers fails to build with sphinx 8.x: ERROR: Invalid value `None` in intersphinx_mapping['https://docs.python.org/']."
    ]
  },
  "python-paginate": {
    "urls": [
      "https://bugzilla.redhat.com/show_bug.cgi?id=2354116"
    ],
    "summaries": [
      "python-paginate FTBFS due to missing tox configuration"
    ]
  },
  "python-pamela": {
    "urls": [
      "https://bugzilla.redhat.com/show_bug.cgi?id=2366474"
    ],
    "summaries": [
      "python-pamela fails to build with Python 3.14: pamela.PAMError: [PAM Error 26] Critical error - immediate abort"
    ]
  },
  "python-pandas": {
    "urls": [
      "https://bugzilla.redhat.com/show_bug.cgi?id=2341179"
    ],
    "summaries": [
      "python-pandas: FTBFS in Fedora rawhide/f42"
    ]
  },
  "python-pandas-datareader": {
    "urls": [],
    "summaries": []
  },
  "python-paperwork-backend": {
    "urls": [],
    "summaries": []
  },
  "python-pecan": {
    "urls": [],
    "summaries": []
  },
  "python-peewee": {
    "urls": [],
    "summaries": []
  },
  "python-pendulum": {
    "urls": [
      "https://bugzilla.redhat.com/show_bug.cgi?id=2367458"
    ],
    "summaries": [
      "python-pendulum fails to build with Python 3.14: tests/datetime/test_from_format.py ...........................Fatal Python error: Segmentation fault"
    ]
  },
  "python-photutils": {
    "urls": [],
    "summaries": []
  },
  "python-pika": {
    "urls": [
      "https://bugzilla.redhat.com/show_bug.cgi?id=2351384"
    ],
    "summaries": [
      "python-pika fails to build with Python 3.14: RuntimeError: There is no current event loop in thread 'MainThread'."
    ]
  },
  "python-pikepdf": {
    "urls": [
      "https://bugzilla.redhat.com/show_bug.cgi?id=2359815"
    ],
    "summaries": [
      "python-pikepdf fails to build with Python 3.14: Test failures related to refcounting"
    ]
  },
  "python-pip": {
    "urls": [
      "https://bugzilla.redhat.com/show_bug.cgi?id=2335909"
    ],
    "summaries": [
      "python-pip fails to build with Python 3.14: AssertionError: assert 'file:/tmp/file' == 'file:///tmp/file'"
    ]
  },
  "python-pkg-depgraph": {
    "urls": [],
    "summaries": []
  },
  "python-pkginfo2": {
    "urls": [
      "https://bugzilla.redhat.com/show_bug.cgi?id=2366490"
    ],
    "summaries": [
      "python-pkginfo2: FTBFS in Fedora Rawhide: AssertionError: None != '30.0.0'"
    ]
  },
  "python-poi-tracker": {
    "urls": [],
    "summaries": []
  },
  "python-praw": {
    "urls": [
      "https://bugzilla.redhat.com/show_bug.cgi?id=2342562"
    ],
    "summaries": [
      "python-praw fails to build with Python 3.14: RuntimeError: There is no current event loop in thread 'MainThread'."
    ]
  },
  "python-priority": {
    "urls": [
      "https://bugzilla.redhat.com/show_bug.cgi?id=2341182",
      "https://bugzilla.redhat.com/show_bug.cgi?id=2329881"
    ],
    "summaries": [
      "python-priority: FTBFS in Fedora rawhide/f42",
      "python-priority fails to build with sphinx 8.x: ERROR: Invalid value `None` in intersphinx_mapping['http://docs.python.org/']."
    ]
  },
  "python-proton-core": {
    "urls": [],
    "summaries": []
  },
  "python-proton-vpn-network-manager": {
    "urls": [],
    "summaries": []
  },
  "python-psycopg3": {
    "urls": [
      "https://bugzilla.redhat.com/show_bug.cgi?id=2339461"
    ],
    "summaries": [
      "python-psycopg3 fails to build with Python 3.14: DeprecationWarning: 'asyncio.set_event_loop' is deprecated and slated for removal in Python 3.16"
    ]
  },
  "python-pudb": {
    "urls": [
      "https://bugzilla.redhat.com/show_bug.cgi?id=2365643"
    ],
    "summaries": [
      "python-pudb fails to build with Python 3.14: ImportError: cannot import name 'format_exception' from 'pudb.lowlevel'"
    ]
  },
  "python-pure-protobuf": {
    "urls": [
      "https://bugzilla.redhat.com/show_bug.cgi?id=2322710"
    ],
    "summaries": [
      "python-pure-protobuf fails to build with Python 3.14: ImportError: cannot import name 'ByteString' from 'typing'"
    ]
  },
  "python-pybbi": {
    "urls": [],
    "summaries": []
  },
  "python-pycec": {
    "urls": [
      "https://bugzilla.redhat.com/show_bug.cgi?id=2327973"
    ],
    "summaries": [
      "python-pycec fails to build with Python 3.14: RuntimeError: There is no current event loop in thread 'MainThread'."
    ]
  },
  "python-pydantic": {
    "urls": [],
    "summaries": []
  },
  "python-pydantic-core": {
    "urls": [
      "https://bugzilla.redhat.com/show_bug.cgi?id=2325425"
    ],
    "summaries": [
      "python-pydantic-core fails to build with Python 3.14: AssertionError: Regex pattern did not match. + AttributeError: module 'typing' has no attribute 'ByteString'"
    ]
  },
  "python-pydantic-settings": {
    "urls": [],
    "summaries": []
  },
  "python-pydepsdev": {
    "urls": [],
    "summaries": []
  },
  "python-pydocstyle": {
    "urls": [
      "https://bugzilla.redhat.com/show_bug.cgi?id=2366488"
    ],
    "summaries": [
      "python-pydocstyle fails to build with Python 3.14: AssertionError in test_overload_nested_function_valid"
    ]
  },
  "python-pyemd": {
    "urls": [
      "https://bugzilla.redhat.com/show_bug.cgi?id=2319698"
    ],
    "summaries": [
      "python-pyemd fails to build with setuptools 74+"
    ]
  },
  "python-pyforgejo": {
    "urls": [],
    "summaries": []
  },
  "python-pygmtools": {
    "urls": [],
    "summaries": []
  },
  "python-pyiqvia": {
    "urls": [],
    "summaries": []
  },
  "python-pymdown-extensions": {
    "urls": [
      "https://bugzilla.redhat.com/show_bug.cgi?id=2350300",
      "https://bugzilla.redhat.com/show_bug.cgi?id=2336948"
    ],
    "summaries": [
      "Heads-up: python-pymdown-extensions fails to build with python-pygments 2.19.1 on Fedora 43",
      "python-pymdown-extensions fails to build with Python 3.14: TestAbsolute.test_relative_path and TestAbsoluteFileScheme.test_relative_path AssertionErrors"
    ]
  },
  "python-pymeeus": {
    "urls": [
      "https://bugzilla.redhat.com/show_bug.cgi?id=2341186",
      "https://bugzilla.redhat.com/show_bug.cgi?id=2329890"
    ],
    "summaries": [
      "python-pymeeus: FTBFS in Fedora rawhide/f42",
      "python-pymeeus fails to build with sphinx 8.x: ERROR: Invalid value `None` in intersphinx_mapping['https://docs.python.org/']."
    ]
  },
  "python-pymongo": {
    "urls": [
      "https://bugzilla.redhat.com/show_bug.cgi?id=2356166",
      "https://bugzilla.redhat.com/show_bug.cgi?id=2341188"
    ],
    "summaries": [
      "python-pymongo fails to build with Python 3.14: DeprecationWarning: 'asyncio.iscoroutinefunction' and 'asyncio.get_event_loop_policy' is deprecated and slated for removal in Python 3.16",
      "python-pymongo: FTBFS in Fedora rawhide/f42"
    ]
  },
  "python-pynn": {
    "urls": [],
    "summaries": []
  },
  "python-pyongc": {
    "urls": [],
    "summaries": []
  },
  "python-pyopencl": {
    "urls": [
      "https://bugzilla.redhat.com/show_bug.cgi?id=2341190"
    ],
    "summaries": [
      "python-pyopencl: FTBFS in Fedora rawhide/f42"
    ]
  },
  "python-pyopengl": {
    "urls": [
      "https://bugzilla.redhat.com/show_bug.cgi?id=2341191"
    ],
    "summaries": [
      "python-pyopengl: FTBFS in Fedora rawhide/f42"
    ]
  },
  "python-pyopengltk": {
    "urls": [],
    "summaries": []
  },
  "python-pypcapkit": {
    "urls": [],
    "summaries": []
  },
  "python-pypet": {
    "urls": [
      "https://bugzilla.redhat.com/show_bug.cgi?id=2341192"
    ],
    "summaries": [
      "python-pypet: FTBFS in Fedora rawhide/f42"
    ]
  },
  "python-pyphi": {
    "urls": [
      "https://bugzilla.redhat.com/show_bug.cgi?id=2341193"
    ],
    "summaries": [
      "python-pyphi: FTBFS in Fedora rawhide/f42"
    ]
  },
  "python-pyproject-api": {
    "urls": [],
    "summaries": []
  },
  "python-pyqtgraph": {
    "urls": [],
    "summaries": []
  },
  "python-pyregion": {
    "urls": [],
    "summaries": []
  },
  "python-pyriemann": {
    "urls": [],
    "summaries": []
  },
  "python-pysaml2": {
    "urls": [
      "https://bugzilla.redhat.com/show_bug.cgi?id=2341199"
    ],
    "summaries": [
      "python-pysaml2: FTBFS in Fedora rawhide/f42"
    ]
  },
  "python-pyside6": {
    "urls": [
      "https://bugzilla.redhat.com/show_bug.cgi?id=2325444"
    ],
    "summaries": [
      "python-pyside6 fails to build with Python 3.14: TypeError: Formatter.formatannotation() got an unexpected keyword argument 'quote_annotation_strings'"
    ]
  },
  "python-pytest-lsp": {
    "urls": [
      "https://bugzilla.redhat.com/show_bug.cgi?id=2349451"
    ],
    "summaries": [
      "python-pytest-lsp fails to build with Python 3.14: warnings counts differ, resulting in AssertionError in 3 tests"
    ]
  },
  "python-pytest-testinfra": {
    "urls": [
      "https://bugzilla.redhat.com/show_bug.cgi?id=2361631"
    ],
    "summaries": [
      "python-pytest-testinfra FTBFS in rawhide"
    ]
  },
  "python-pytest-twisted": {
    "urls": [
      "https://bugzilla.redhat.com/show_bug.cgi?id=2368594"
    ],
    "summaries": [
      "python-pytest-twisted fails to build with Python 3.14: RuntimeError: There is no current event loop in thread 'MainThread'."
    ]
  },
  "python-python-ulid": {
    "urls": [],
    "summaries": []
  },
  "python-pyupgrade": {
    "urls": [
      "https://bugzilla.redhat.com/show_bug.cgi?id=2322713"
    ],
    "summaries": [
      "python-pyupgrade fails to build with Python 3.14: AttributeError: module 'ast' has no attribute 'Str'"
    ]
  },
  "python-rasterio": {
    "urls": [],
    "summaries": []
  },
  "python-rdflib": {
    "urls": [
      "https://bugzilla.redhat.com/show_bug.cgi?id=2343978",
      "https://bugzilla.redhat.com/show_bug.cgi?id=2336891"
    ],
    "summaries": [
      "python-rdflib fails to build with Python 3.14: AttributeError: term 'value' not in namespace 'http://www.w3.org/1999/02/22-rdf-syntax-ns#'",
      "python-rdflib fails to build with Python 3.14: \"TypeError: '<' not supported between instances of 'Literal' and 'Literal'\""
    ]
  },
  "python-readability-lxml": {
    "urls": [
      "https://bugzilla.redhat.com/show_bug.cgi?id=2323185"
    ],
    "summaries": [
      "python-readability-lxml fails to build with Python 3.14: _pickle.PicklingError: Can't pickle <function TestArticleOnly.test_many_repeated_spaces at 0x7ff0ea064460>: it's not the same object as tests.test_article_only.TestArticleOnly.test_many_repeated_spa"
    ]
  },
  "python-recordclass": {
    "urls": [
      "https://bugzilla.redhat.com/show_bug.cgi?id=2327968"
    ],
    "summaries": [
      "python-recordclass fails to build with Python 3.14: 25 failures, 65 errors in the test suite"
    ]
  },
  "python-remoto": {
    "urls": [
      "https://bugzilla.redhat.com/show_bug.cgi?id=2366491",
      "https://bugzilla.redhat.com/show_bug.cgi?id=2341205"
    ],
    "summaries": [
      "python-remoto fails to build with Python 3.14: AttributeError: 'TestRemoteError' object has no attribute 'traceback'",
      "python-remoto: FTBFS in Fedora rawhide/f42"
    ]
  },
  "python-rope": {
    "urls": [
      "https://bugzilla.redhat.com/show_bug.cgi?id=2351391"
    ],
    "summaries": [
      "python-rope fails to build with Python 3.14: ImportError while loading conftest '/builddir/build/BUILD/python-rope-1.13.0-build/rope-1.13.0/ropetest/conftest.py'.: AssertionError: assert sys.version_info < (3, 8)"
    ]
  },
  "python-rq": {
    "urls": [
      "https://bugzilla.redhat.com/show_bug.cgi?id=2342234"
    ],
    "summaries": [
      "python-rq fails to build with Python 3.14: test_worker.py::HerokuWorkerShutdownTestCase::test_handle_shutdown_request shuts down the whole build"
    ]
  },
  "python-rstcheck": {
    "urls": [
      "https://bugzilla.redhat.com/show_bug.cgi?id=2322705"
    ],
    "summaries": [
      "python-rstcheck fails to build with Python 3.14: AttributeError: 'Constant' object has no attribute 's'"
    ]
  },
  "python-scikit-build": {
    "urls": [],
    "summaries": []
  },
  "python-scikit-image": {
    "urls": [
      "https://bugzilla.redhat.com/show_bug.cgi?id=2368531"
    ],
    "summaries": [
      "python-scikit-image fails to build with Python 3.14: AssertionError: Regex pattern did not match. Regex: \"'old' is not in list\" Input: 'list.index(x): x not in list'"
    ]
  },
  "python-simframe": {
    "urls": [
      "https://bugzilla.redhat.com/show_bug.cgi?id=2352552"
    ],
    "summaries": [
      "python-simframe fails to build with Python 3.14: TypeError: cannot pickle 'itertools.cycle' object"
    ]
  },
  "python-smart_open": {
    "urls": [],
    "summaries": []
  },
  "python-steam": {
    "urls": [
      "https://bugzilla.redhat.com/show_bug.cgi?id=2341218"
    ],
    "summaries": [
      "python-steam: FTBFS in Fedora rawhide/f42"
    ]
  },
  "python-streamlink": {
    "urls": [
      "https://bugzilla.redhat.com/show_bug.cgi?id=2353127"
    ],
    "summaries": [
      "python-streamlink fails to build with Python 3.14: test_deprecated: AssetionError: Left contains one more item: <warnings.WarningMessage object at 0x7fd80afa3410>"
    ]
  },
  "python-toolz": {
    "urls": [
      "https://bugzilla.redhat.com/show_bug.cgi?id=2323168"
    ],
    "summaries": [
      "python-toolz fails to build with Python 3.14: AssertionError: is_none: assert should_curry(getattr(operator, k)) == isinstance(v, toolz.curry), k"
    ]
  },
  "python-torch": {
    "urls": [],
    "summaries": []
  },
  "python-typing-inspect": {
    "urls": [
      "https://bugzilla.redhat.com/show_bug.cgi?id=2325455"
    ],
    "summaries": [
      "python-typing-inspect fails to build with Python 3.14: AssertionError: {} != {'x': <class 'int'>, 'y': <class 'int'>}"
    ]
  },
  "python-ufoLib2": {
    "urls": [],
    "summaries": []
  },
  "python-uvloop": {
    "urls": [
      "https://bugzilla.redhat.com/show_bug.cgi?id=2341233",
      "https://bugzilla.redhat.com/show_bug.cgi?id=2326210"
    ],
    "summaries": [
      "python-uvloop: FTBFS in Fedora rawhide/f42",
      "python-uvloop fails to build with Python 3.14: AttributeError: module 'asyncio' has no attribute 'AbstractChildWatcher'"
    ]
  },
  "python-wordcloud": {
    "urls": [
      "https://bugzilla.redhat.com/show_bug.cgi?id=2335908"
    ],
    "summaries": [
      "python-wordcloud fails to build with Python 3.14: test_cli_as_executable: AssertionError: assert expected_output in out if ret_code == 0 else err"
    ]
  },
  "python-yappi": {
    "urls": [
      "https://bugzilla.redhat.com/show_bug.cgi?id=2323160"
    ],
    "summaries": [
      "python-yappi fails to build with Python 3.14: error: invalid use of incomplete typedef \u2018PyGenObject\u2019 {aka \u2018struct _PyGenObject\u2019}"
    ]
  },
  "python-zarr": {
    "urls": [],
    "summaries": []
  },
  "python3-exiv2": {
    "urls": [
      "https://bugzilla.redhat.com/show_bug.cgi?id=2354137"
    ],
    "summaries": [
      "python3-exiv2 FTBFS due to missing tox configuration"
    ]
  },
  "qtile": {
    "urls": [
      "https://bugzilla.redhat.com/show_bug.cgi?id=2328711"
    ],
    "summaries": [
      "qtile fails to build with Python 3.14: _pickle.PicklingError: Can't pickle local object <function TestManager.start.<locals>.run_qtile at 0x7f9c5918fed0>"
    ]
  },
  "rebase-helper": {
    "urls": [
      "https://bugzilla.redhat.com/show_bug.cgi?id=2352551"
    ],
    "summaries": [
      "rebase-helper fails to build with Python 3.14: AssertionError in TestCLI.test_cli_unit and TestConfig.test_merge"
    ]
  },
  "swift-lang": {
    "urls": [
      "https://bugzilla.redhat.com/show_bug.cgi?id=2341403"
    ],
    "summaries": [
      "swift-lang: FTBFS in Fedora rawhide/f42"
    ]
  },
  "tree-sitter-java": {
    "urls": [],
    "summaries": []
  },
  "visidata": {
    "urls": [
      "https://bugzilla.redhat.com/show_bug.cgi?id=2325446"
    ],
    "summaries": [
      "visidata fails to build with Python 3.14: TestVisidataPath.test_withName: AssertionError: assert 'foo' == 'foo.'"
    ]
  },
  "xpra": {
    "urls": [
      "https://bugzilla.redhat.com/show_bug.cgi?id=2350289"
    ],
    "summaries": [
      "xpra fails to build from source with Python 3.14: RuntimeError: An attempt has been made to start a new process before the current process has finished its bootstrapping phase."
    ]
  }
}