{
  "Mayavi": {
    "urls": [
      "https://bugzilla.redhat.com/show_bug.cgi?id=2351390"
    ],
    "summaries": [
      "Mayavi fails to build with Python 3.14: TestMayaviGarbageCollection.test_mlab_scene_model_with_gui: IndexError: list index out of range"
    ]
  },
  "NiaAML-GUI": {
    "urls": [],
    "summaries": []
  },
  "ansible": {
    "urls": [],
    "summaries": []
  },
  "ansible-core": {
    "urls": [
      "https://bugzilla.redhat.com/show_bug.cgi?id=2366307"
    ],
    "summaries": [
      "ansible-core fails to build with Python 3.14: This version of ansible-test cannot be executed with Python version 3.14.0"
    ]
  },
  "arbor": {
    "urls": [],
    "summaries": []
  },
  "asv": {
    "urls": [
      "https://bugzilla.redhat.com/show_bug.cgi?id=2367256",
      "https://bugzilla.redhat.com/show_bug.cgi?id=2339908"
    ],
    "summaries": [
      "asv fails to build with Python 3.14: AttributeError: 'Constant' object has no attribute 's'",
      "asv: FTBFS in Fedora rawhide/f42"
    ]
  },
  "avogadro2-libs": {
    "urls": [],
    "summaries": []
  },
  "awscli2": {
    "urls": [
      "https://bugzilla.redhat.com/show_bug.cgi?id=2367786"
    ],
    "summaries": [
      "awscli2 fails to build with Python 3.14: various test failures"
    ]
  },
  "bandit": {
    "urls": [
      "https://bugzilla.redhat.com/show_bug.cgi?id=2351393"
    ],
    "summaries": [
      "bandit fails to build with Python 3.14: TypeError: Error: Str is not a valid node type in AST"
    ]
  },
  "bids-schema": {
    "urls": [],
    "summaries": []
  },
  "binwalk": {
    "urls": [
      "https://bugzilla.redhat.com/show_bug.cgi?id=2336914"
    ],
    "summaries": [
      "binwalk fails to build with Python 3.14: TypeError: unsupported operand type(s) for +=: 'NoneType' and 'int'"
    ]
  },
  "borgbackup": {
    "urls": [
      "https://bugzilla.redhat.com/show_bug.cgi?id=2326916"
    ],
    "summaries": [
      "borgbackup fails to build with Python 3.14: OSError: AF_UNIX path too long when compiling"
    ]
  },
  "calibre": {
    "urls": [],
    "summaries": []
  },
  "capstone": {
    "urls": [
      "https://bugzilla.redhat.com/show_bug.cgi?id=2345714"
    ],
    "summaries": [
      "capstone fails to build with Python 3.14: from capstone import *: ImportError: ERROR: fail to load the dynamic library"
    ]
  },
  "centpkg": {
    "urls": [],
    "summaries": []
  },
  "ceph": {
    "urls": [],
    "summaries": []
  },
  "chirp": {
    "urls": [
      "https://bugzilla.redhat.com/show_bug.cgi?id=2361634"
    ],
    "summaries": [
      "chirp FTBFS in rawhide"
    ]
  },
  "cjdns": {
    "urls": [
      "https://bugzilla.redhat.com/show_bug.cgi?id=2339969"
    ],
    "summaries": [
      "cjdns: FTBFS in Fedora rawhide/f42"
    ]
  },
  "conda": {
    "urls": [
      "https://bugzilla.redhat.com/show_bug.cgi?id=2356170"
    ],
    "summaries": [
      "conda fails to build with Python 3.14: tests/test_shell.py: TypeError: 'str' object cannot be interpreted as an integer"
    ]
  },
  "conda-build": {
    "urls": [
      "https://bugzilla.redhat.com/show_bug.cgi?id=2356162"
    ],
    "summaries": [
      "conda-build fails to build with Python 3.14: TypeError: _WorkItem.__init__() takes 3 positional arguments but 5 were given"
    ]
  },
  "copr-backend": {
    "urls": [
      "https://bugzilla.redhat.com/show_bug.cgi?id=2351386"
    ],
    "summaries": [
      "copr-backend fails to build with Python 3.14: TestActionWorkerManager.test_add_task_for_running_worker: TypeError: cannot pickle 'itertools.count' object"
    ]
  },
  "copr-dist-git": {
    "urls": [],
    "summaries": []
  },
  "cozy": {
    "urls": [],
    "summaries": []
  },
  "criu": {
    "urls": [
      "https://bugzilla.redhat.com/show_bug.cgi?id=2365821"
    ],
    "summaries": [
      "criu fails to build with Python 3.14: protobuf - TypeError: Metaclasses with custom tp_new are not supported."
    ]
  },
  "diceware": {
    "urls": [
      "https://bugzilla.redhat.com/show_bug.cgi?id=2340075",
      "https://bugzilla.redhat.com/show_bug.cgi?id=2329832"
    ],
    "summaries": [
      "diceware: FTBFS in Fedora rawhide/f42",
      "diceware fails to build with sphinx 8.x: ERROR: Invalid value `None` in intersphinx_mapping['http://docs.python.org/']."
    ]
  },
  "did": {
    "urls": [
      "https://bugzilla.redhat.com/show_bug.cgi?id=2328006"
    ],
    "summaries": [
      "did fails to build with Python 3.14: AttributeError: module 'urllib.request' has no attribute 'FancyURLopener'"
    ]
  },
  "dlib": {
    "urls": [
      "https://bugzilla.redhat.com/show_bug.cgi?id=2366197"
    ],
    "summaries": [
      "dlib fails to build with Python 3.14: AssertionError in tests checking refcounting"
    ]
  },
  "espresso": {
    "urls": [
      "https://bugzilla.redhat.com/show_bug.cgi?id=2340139"
    ],
    "summaries": [
      "espresso: FTBFS in Fedora rawhide/f42"
    ]
  },
  "fedrq": {
    "urls": [],
    "summaries": []
  },
  "getmail": {
    "urls": [],
    "summaries": []
  },
  "git-filter-repo": {
    "urls": [
      "https://bugzilla.redhat.com/show_bug.cgi?id=2365637"
    ],
    "summaries": [
      "git-filter-repo fails to build with Python 3.14: == t9394-filter-repo-sanity-checks-and-bigger-repo-setup.sh == --replace-text all options not ok"
    ]
  },
  "gnofract4d": {
    "urls": [
      "https://bugzilla.redhat.com/show_bug.cgi?id=2339539"
    ],
    "summaries": [
      "gnofract4d fails to build with Python 3.14: AssertionError: 'ct_sin6 = (0.841471,-0)' != 'ct_sin6 = (0.841471,0)'"
    ]
  },
  "httpie": {
    "urls": [
      "https://bugzilla.redhat.com/show_bug.cgi?id=2350335"
    ],
    "summaries": [
      "httpie fails to build with Python 3.14: test_lazy_choices_help: AssertionError: Expected 'getter' to not have been called. Called 1 times."
    ]
  },
  "ikiwiki": {
    "urls": [
      "https://bugzilla.redhat.com/show_bug.cgi?id=2366456",
      "https://bugzilla.redhat.com/show_bug.cgi?id=2340642"
    ],
    "summaries": [
      "ikiwiki fails to build in Rawhide: error: Installed (but unpackaged) file(s) found:  /usr/sbin/ikiwiki-mass-rebuild",
      "ikiwiki: FTBFS in Fedora rawhide/f42"
    ]
  },
  "ipython": {
    "urls": [
      "https://bugzilla.redhat.com/show_bug.cgi?id=2356174"
    ],
    "summaries": [
      "ipython fails to build with Python 3.14: AssertionErrors, pexpect.exceptions.TIMEOUTs and more in 12 tests"
    ]
  },
  "kitty": {
    "urls": [],
    "summaries": []
  },
  "kmymoney": {
    "urls": [],
    "summaries": []
  },
  "kvirc": {
    "urls": [],
    "summaries": []
  },
  "lensfun": {
    "urls": [
      "https://bugzilla.redhat.com/show_bug.cgi?id=2368735"
    ],
    "summaries": [
      "lensfun: FTBFS in Fedora Rawhide (probably with doxygen 1.14)"
    ]
  },
  "libarrow": {
    "urls": [],
    "summaries": []
  },
  "libpeas": {
    "urls": [
      "https://bugzilla.redhat.com/show_bug.cgi?id=2366247"
    ],
    "summaries": [
      "libpeas fails to build with Python 3.14: test-extension-py  TIMEOUT"
    ]
  },
  "libunity": {
    "urls": [
      "https://bugzilla.redhat.com/show_bug.cgi?id=2368739"
    ],
    "summaries": [
      "libunity: FTBFS in Fedora Rawhide (probably since gettext 0.25)"
    ]
  },
  "libxc": {
    "urls": [],
    "summaries": []
  },
  "linode-cli": {
    "urls": [
      "https://bugzilla.redhat.com/show_bug.cgi?id=2368974",
      "https://bugzilla.redhat.com/show_bug.cgi?id=2340775"
    ],
    "summaries": [
      "linode-cli fails to build with Python 3.14: The current dist-git state is unbuildable",
      "linode-cli: FTBFS in Fedora rawhide/f42"
    ]
  },
  "mlpack": {
    "urls": [],
    "summaries": []
  },
  "monkeytype": {
    "urls": [
      "https://bugzilla.redhat.com/show_bug.cgi?id=2356179"
    ],
    "summaries": [
      "monkeytype fails to build with Python 3.14: typing.Union changed with Python 3.14.0a6"
    ]
  },
  "mopidy": {
    "urls": [
      "https://bugzilla.redhat.com/show_bug.cgi?id=2367738"
    ],
    "summaries": [
      "mopidy fails to build with Python 3.14:  RuntimeError: unable to get value"
    ]
  },
  "mopidy-mpd": {
    "urls": [],
    "summaries": []
  },
  "mrchem": {
    "urls": [
      "https://bugzilla.redhat.com/show_bug.cgi?id=2359498"
    ],
    "summaries": [
      "mrchem fails to build with Python 3.14: /builddir/build/BUILD/mrchem-1.1.4-build/mrchem-1.1.4/python/mrchem/input_parser/plumbing/pyparsing/core.py:5332: SyntaxWarning: 'return' in a 'finally' block"
    ]
  },
  "myst-nb": {
    "urls": [],
    "summaries": []
  },
  "nextpnr": {
    "urls": [],
    "summaries": []
  },
  "ocrmypdf": {
    "urls": [
      "https://bugzilla.redhat.com/show_bug.cgi?id=2357508"
    ],
    "summaries": [
      "ocrmypdf fails to build with Python 3.14: multiprocessing.Process now starts with forkserver method instead of fork, causing pickling error"
    ]
  },
  "onnx": {
    "urls": [
      "https://bugzilla.redhat.com/show_bug.cgi?id=2366510"
    ],
    "summaries": [
      "onnx fails to build with Python 3.14: protobuf: TypeError: Metaclasses with custom tp_new are not supported."
    ]
  },
  "openapi-python-client": {
    "urls": [],
    "summaries": []
  },
  "opencv": {
    "urls": [
      "https://bugzilla.redhat.com/show_bug.cgi?id=2368529"
    ],
    "summaries": [
      "opencv fails to build with Python 3.14: a failure in the %build phase"
    ]
  },
  "openvino": {
    "urls": [],
    "summaries": []
  },
  "paperwork": {
    "urls": [],
    "summaries": []
  },
  "paraview": {
    "urls": [],
    "summaries": []
  },
  "patool": {
    "urls": [
      "https://bugzilla.redhat.com/show_bug.cgi?id=2366470"
    ],
    "summaries": [
      "patool fails to build with Python 3.14: Codec Load Error: /usr/bin/7z.so : errno=25 : Inappropriate ioctl for device"
    ]
  },
  "pcs": {
    "urls": [],
    "summaries": []
  },
  "petsc": {
    "urls": [
      "https://bugzilla.redhat.com/show_bug.cgi?id=2359524"
    ],
    "summaries": [
      "petsc fails to build with Python 3.14: AssertionError: 2 != 3 self.assertEqual(getrefcount(ctx), 3)"
    ]
  },
  "poezio": {
    "urls": [
      "https://bugzilla.redhat.com/show_bug.cgi?id=2341088",
      "https://bugzilla.redhat.com/show_bug.cgi?id=2329835"
    ],
    "summaries": [
      "poezio: FTBFS in Fedora rawhide/f42",
      "poezio fails to build with sphinx 8.x:  ERROR: Invalid value `None` in intersphinx_mapping['http://docs.python.org/']."
    ]
  },
  "prewikka-updatedb": {
    "urls": [],
    "summaries": []
  },
  "pybind11": {
    "urls": [
      "https://bugzilla.redhat.com/show_bug.cgi?id=2336889"
    ],
    "summaries": [
      "pybind11 fails to build with Python 3.14: AttributeError: 'pybind11_tests.pickling.PickleableWithDict' object has no attribute 'dynamic' + AssertionError"
    ]
  },
  "pychess": {
    "urls": [
      "https://bugzilla.redhat.com/show_bug.cgi?id=2328708"
    ],
    "summaries": [
      "pychess fails to build with Python 3.14: RuntimeError: There is no current event loop in thread 'MainThread'."
    ]
  },
  "pychromecast": {
    "urls": [
      "https://bugzilla.redhat.com/show_bug.cgi?id=2366486"
    ],
    "summaries": [
      "pychromecast fails to build with Python 3.14: protobuf: TypeError: Metaclasses with custom tp_new are not supported."
    ]
  },
  "pyflakes": {
    "urls": [
      "https://bugzilla.redhat.com/show_bug.cgi?id=2359503"
    ],
    "summaries": [
      "pyflakes fails to build with Python 3.14: SyntaxError: future feature print_statement is not defined"
    ]
  },
  "pylibacl": {
    "urls": [
      "https://bugzilla.redhat.com/show_bug.cgi?id=2359502"
    ],
    "summaries": [
      "pylibacl fails to build with Python 3.14: tests/test_acls.py::TestModification: Failed: Wrong reference count, expected 2-1024 and got 1"
    ]
  },
  "pylint": {
    "urls": [
      "https://bugzilla.redhat.com/show_bug.cgi?id=2368703"
    ],
    "summaries": [
      "pylint fails to build with Python 3.14: AssertionError tests/test_functional.py::test_functional"
    ]
  },
  "pyproj": {
    "urls": [],
    "summaries": []
  },
  "pyserial-asyncio": {
    "urls": [
      "https://bugzilla.redhat.com/show_bug.cgi?id=2327980"
    ],
    "summaries": [
      "pyserial-asyncio fails to build with Python 3.14: RuntimeError: There is no current event loop in thread 'MainThread'."
    ]
  },
  "pysubnettree": {
    "urls": [
      "https://bugzilla.redhat.com/show_bug.cgi?id=2366464",
      "https://bugzilla.redhat.com/show_bug.cgi?id=2341123"
    ],
    "summaries": [
      "pysubnettree fails to build with Python 3.14/Fedora Rawhide: error: too many arguments to function \u2018func\u2019; expected 0, have 1",
      "pysubnettree: FTBFS in Fedora rawhide/f42"
    ]
  },
  "python-Mastodon": {
    "urls": [
      "https://bugzilla.redhat.com/show_bug.cgi?id=2369422"
    ],
    "summaries": [
      "python-Mastodon fails to build with Python 3.14: ValueError: Unknown type <something> | None"
    ]
  },
  "python-SALib": {
    "urls": [],
    "summaries": []
  },
  "python-TestSlide": {
    "urls": [
      "https://bugzilla.redhat.com/show_bug.cgi?id=2350306",
      "https://bugzilla.redhat.com/show_bug.cgi?id=2343971"
    ],
    "summaries": [
      "Heads-up: python-TestSlide fails to build with python-pygments 2.19.1 on Fedora 43",
      "python-TestSlide fails to build with Python 3.14: ERROR collecting tests/mock_callable_testslide.py: RuntimeError: dictionary changed size during iteration"
    ]
  },
  "python-aioesphomeapi": {
    "urls": [
      "https://bugzilla.redhat.com/show_bug.cgi?id=2366202"
    ],
    "summaries": [
      "python-aioesphomeapi fails to build with Python 3.14: protobuf: TypeError: Metaclasses with custom tp_new are not supported"
    ]
  },
  "python-aiokafka": {
    "urls": [
      "https://bugzilla.redhat.com/show_bug.cgi?id=2346517"
    ],
    "summaries": [
      "python-aiokafka fails to build with Python 3.14: DeprecationWarning: 'asyncio.get_event_loop_policy' is deprecated and slated for removal in Python 3.16"
    ]
  },
  "python-aiosmtpd": {
    "urls": [
      "https://bugzilla.redhat.com/show_bug.cgi?id=2322718"
    ],
    "summaries": [
      "python-aiosmtpd fails to build with Python 3.14: ImportError: cannot import name 'ByteString' from 'typing'"
    ]
  },
  "python-ansible-runner": {
    "urls": [],
    "summaries": []
  },
  "python-astdoc": {
    "urls": [
      "https://bugzilla.redhat.com/show_bug.cgi?id=2349452"
    ],
    "summaries": [
      "python-astdoc fails to build with Python 3.14: 3 doctests fail, e.g.: Expected: <ast.Name object at 0x...> Got: Name(id='int', ctx=Load())"
    ]
  },
  "python-astroML": {
    "urls": [],
    "summaries": []
  },
  "python-astroplan": {
    "urls": [],
    "summaries": []
  },
  "python-astropy": {
    "urls": [
      "https://bugzilla.redhat.com/show_bug.cgi?id=2345524"
    ],
    "summaries": [
      "python-astropy fails to build with Python 3.14: test_info_preserved_pickle_copy_init[arrayswap]: AssertionError: assert dtype('>i4') == dtype('int32')"
    ]
  },
  "python-astropy-healpix": {
    "urls": [],
    "summaries": []
  },
  "python-astropy-iers-data": {
    "urls": [
      "https://bugzilla.redhat.com/show_bug.cgi?id=2349443"
    ],
    "summaries": [
      "python-astropy-iers-data fails to build with Python 3.14: 4 tests fail with KeyError: 'ra_in' and 'lon_in'"
    ]
  },
  "python-astroquery": {
    "urls": [],
    "summaries": []
  },
  "python-atomicwrites": {
    "urls": [
      "https://bugzilla.redhat.com/show_bug.cgi?id=2341128",
      "https://bugzilla.redhat.com/show_bug.cgi?id=2329842"
    ],
    "summaries": [
      "python-atomicwrites: FTBFS in Fedora rawhide/f42",
      "python-atomicwrites fails to build with sphinx 8.x: ERROR: Invalid value `None` in intersphinx_mapping['http://docs.python.org/']."
    ]
  },
  "python-avocado": {
    "urls": [
      "https://bugzilla.redhat.com/show_bug.cgi?id=2341130",
      "https://bugzilla.redhat.com/show_bug.cgi?id=2325218"
    ],
    "summaries": [
      "python-avocado: FTBFS in Fedora rawhide/f42",
      "python-avocado fails to build with Python 3.14: Error running method \"pre_tests\" of plugin \"fetchasset\": module 'ast' has no attribute 'Str' + Avocado crashed: TypeError: cannot pickle '_thread.RLock' object"
    ]
  },
  "python-aw-core": {
    "urls": [],
    "summaries": []
  },
  "python-awesomeversion": {
    "urls": [
      "https://bugzilla.redhat.com/show_bug.cgi?id=2366476"
    ],
    "summaries": [
      "python-awesomeversion fails to build in Fedora Rawhide: rm: cannot remove '/builddir/build/BUILD/python-awesomeversion-22.9.0-build/BUILDROOT//usr/lib/python3.14/site-packages/LICENCE.md': No such file or directory"
    ]
  },
  "python-aws-sam-translator": {
    "urls": [
      "https://bugzilla.redhat.com/show_bug.cgi?id=2353126"
    ],
    "summaries": [
      "python-aws-sam-translator fails to build with Python 3.14: 77 test failures, 4 error"
    ]
  },
  "python-axolotl": {
    "urls": [
      "https://bugzilla.redhat.com/show_bug.cgi?id=2366200"
    ],
    "summaries": [
      "python-axolotl fails to build with Python 3.14: protobuf: TypeError: Metaclasses with custom tp_new are not supported."
    ]
  },
  "python-b4": {
    "urls": [],
    "summaries": []
  },
  "python-beancount": {
    "urls": [
      "https://bugzilla.redhat.com/show_bug.cgi?id=2359530"
    ],
    "summaries": [
      "python-beancount fails to build with Python 3.14: TestReferenceCounting and TestLexer fail with AssertionError"
    ]
  },
  "python-beartype": {
    "urls": [
      "https://bugzilla.redhat.com/show_bug.cgi?id=2341131",
      "https://bugzilla.redhat.com/show_bug.cgi?id=2322721"
    ],
    "summaries": [
      "python-beartype: FTBFS in Fedora rawhide/f42",
      "python-beartype fails to build with Python 3.14: ImportError: cannot import name 'ByteString' from 'typing'"
    ]
  },
  "python-behave": {
    "urls": [
      "https://bugzilla.redhat.com/show_bug.cgi?id=2339094"
    ],
    "summaries": [
      "python-behave fails to build with Python 3.14: RuntimeError: There is no current event loop in thread 'MainThread'."
    ]
  },
  "python-billiard": {
    "urls": [
      "https://bugzilla.redhat.com/show_bug.cgi?id=2323167"
    ],
    "summaries": [
      "python-billiard fails to build with Python 3.14: AttributeError: module 'subprocess' has no attribute '_USE_VFORK'"
    ]
  },
  "python-bioframe": {
    "urls": [],
    "summaries": []
  },
  "python-blinker": {
    "urls": [
      "https://bugzilla.redhat.com/show_bug.cgi?id=2325193"
    ],
    "summaries": [
      "python-blinker fails to build with Python 3.14: pluggy.PluggyTeardownRaisedWarning: A plugin raised an exception during an old-style hookwrapper teardown."
    ]
  },
  "python-blosc2": {
    "urls": [],
    "summaries": []
  },
  "python-boto3": {
    "urls": [],
    "summaries": []
  },
  "python-boutdata": {
    "urls": [
      "https://bugzilla.redhat.com/show_bug.cgi?id=2352553"
    ],
    "summaries": [
      "python-boutdata fails to build with Python 3.14: NotImplementedError: Dataset is not picklable"
    ]
  },
  "python-bsmschema": {
    "urls": [],
    "summaries": []
  },
  "python-capturer": {
    "urls": [
      "https://bugzilla.redhat.com/show_bug.cgi?id=2328004"
    ],
    "summaries": [
      "python-capturer fails to build with Python 3.14: OSError: [Errno 29] Illegal seek"
    ]
  },
  "python-carbon": {
    "urls": [
      "https://bugzilla.redhat.com/show_bug.cgi?id=2368591"
    ],
    "summaries": [
      "python-carbon fails to build with Python 3.14: protobuf: TypeError: Metaclasses with custom tp_new are not supported."
    ]
  },
  "python-catkin_tools": {
    "urls": [
      "https://bugzilla.redhat.com/show_bug.cgi?id=2341134",
      "https://bugzilla.redhat.com/show_bug.cgi?id=2329848"
    ],
    "summaries": [
      "python-catkin_tools: FTBFS in Fedora rawhide/f42",
      "python-catkin_tools fails to build with sphinx 8.x:  ERROR: Invalid value `None` in intersphinx_mapping['http://docs.python.org/']."
    ]
  },
  "python-cattrs": {
    "urls": [
      "https://bugzilla.redhat.com/show_bug.cgi?id=2343916"
    ],
    "summaries": [
      "python-cattrs fails to build with Python 3.14: TypeError: <class 'tests.strategies.test_include_subclasses.GrandChild'> has no usable non-default attributes"
    ]
  },
  "python-cerberus": {
    "urls": [
      "https://bugzilla.redhat.com/show_bug.cgi?id=2366466"
    ],
    "summaries": [
      "python-cerberus fails to build in Fedora Rawhide:  File not found: /builddir/build/BUILD/python-cerberus-1.3.4-build/BUILDROOT/usr/lib/python3.14/site-packages/Cerberus-1.3.4.dist-info"
    ]
  },
  "python-chalice": {
    "urls": [
      "https://bugzilla.redhat.com/show_bug.cgi?id=2342568"
    ],
    "summaries": [
      "python-chalice fails to build with Python 3.14: AttributeError: module 'ast' has no attribute 'Str'"
    ]
  },
  "python-chaospy": {
    "urls": [],
    "summaries": []
  },
  "python-cliff": {
    "urls": [],
    "summaries": []
  },
  "python-colcon-meson": {
    "urls": [
      "https://bugzilla.redhat.com/show_bug.cgi?id=2368744"
    ],
    "summaries": [
      "python-colcon-meson fails to build with Python 3.14: test_capital_case: TypeError: InterpreterBase.__init__() missing 2 required positional arguments: 'subproject_dir' and 'env'"
    ]
  },
  "python-colcon-parallel-executor": {
    "urls": [
      "https://bugzilla.redhat.com/show_bug.cgi?id=2325186"
    ],
    "summaries": [
      "python-colcon-parallel-executor fails to build with Python 3.14: test_parallel: AssertionError: DeprecationWarning: 'asyncio.iscoroutinefunction' is deprecated and slated for removal in Python 3.16; use inspect.iscoroutinefunction() instead"
    ]
  },
  "python-colorful": {
    "urls": [
      "https://bugzilla.redhat.com/show_bug.cgi?id=2325168"
    ],
    "summaries": [
      "python-colorful fails to build with Python 3.14: ast.Constant.s has been removed from Python 3.14"
    ]
  },
  "python-confuse": {
    "urls": [
      "https://bugzilla.redhat.com/show_bug.cgi?id=2327966"
    ],
    "summaries": [
      "python-confuse fails to build with Python 3.14: AttributeError: module 'pkgutil' has no attribute 'get_loader'"
    ]
  },
  "python-contextualbandits": {
    "urls": [],
    "summaries": []
  },
  "python-crcmod": {
    "urls": [
      "https://bugzilla.redhat.com/show_bug.cgi?id=2329852"
    ],
    "summaries": [
      "python-crcmod fails to build with sphinx 8.x: ERROR: Invalid value `None` in intersphinx_mapping['/usr/share/doc/python3-docs/html/']."
    ]
  },
  "python-crick": {
    "urls": [
      "https://bugzilla.redhat.com/show_bug.cgi?id=2367454"
    ],
    "summaries": [
      "python-crick fails to build with Python 3.14: crick/tests/test_space_saving.py::test_merge_algorithm[s111-s211] Fatal Python error: Segmentation fault"
    ]
  },
  "python-cro": {
    "urls": [],
    "summaries": []
  },
  "python-dataclassy": {
    "urls": [
      "https://bugzilla.redhat.com/show_bug.cgi?id=2325200"
    ],
    "summaries": [
      "python-dataclassy fails to build with Python 3.14: TypeError: Beta() takes no arguments"
    ]
  },
  "python-defcon": {
    "urls": [],
    "summaries": []
  },
  "python-diff-cover": {
    "urls": [
      "https://bugzilla.redhat.com/show_bug.cgi?id=2350299"
    ],
    "summaries": [
      "Heads-up: python-diff-cover fails to build with python-pygments 2.19.1 on Fedora 43"
    ]
  },
  "python-dipy": {
    "urls": [],
    "summaries": []
  },
  "python-dirty-equals": {
    "urls": [],
    "summaries": []
  },
  "python-django-configurations": {
    "urls": [
      "https://bugzilla.redhat.com/show_bug.cgi?id=2366494"
    ],
    "summaries": [
      "python-django-configurations fails to build with Python 3.14: ValueTests.test_cache_url_value: AssertionError:"
    ]
  },
  "python-django-contrib-comments": {
    "urls": [
      "https://bugzilla.redhat.com/show_bug.cgi?id=2366520"
    ],
    "summaries": [
      "python-django-contrib-comments fails to build with Python 3.14: ImportError: Module \"django.contrib.auth.hashers\" does not define a \"UnsaltedMD5PasswordHasher\" attribute/class"
    ]
  },
  "python-django-extensions": {
    "urls": [],
    "summaries": []
  },
  "python-django-filter": {
    "urls": [
      "https://bugzilla.redhat.com/show_bug.cgi?id=2336944"
    ],
    "summaries": [
      "python-django-filter fails to build with Python 3.14: AttributeError: module 'pkgutil' has no attribute 'find_loader'"
    ]
  },
  "python-django-mailman3": {
    "urls": [],
    "summaries": []
  },
  "python-domdf-python-tools": {
    "urls": [
      "https://bugzilla.redhat.com/show_bug.cgi?id=2345519"
    ],
    "summaries": [
      "python-domdf-python-tools fails to build with Python 3.14: tests/test_words.py::test_alpha_sort - AssertionError: Regex pattern did not match."
    ]
  },
  "python-doubleratchet": {
    "urls": [],
    "summaries": []
  },
  "python-duecredit": {
    "urls": [],
    "summaries": []
  },
  "python-dunamai": {
    "urls": [],
    "summaries": []
  },
  "python-efel": {
    "urls": [],
    "summaries": []
  },
  "python-elephant": {
    "urls": [],
    "summaries": []
  },
  "python-envisage": {
    "urls": [
      "https://bugzilla.redhat.com/show_bug.cgi?id=2369420"
    ],
    "summaries": [
      "python-envisage: FTBFS in Fedora Rawhide: ModuleNotFoundError: No module named 'configobj'"
    ]
  },
  "python-ephyviewer": {
    "urls": [],
    "summaries": []
  },
  "python-et_xmlfile": {
    "urls": [
      "https://bugzilla.redhat.com/show_bug.cgi?id=2359509"
    ],
    "summaries": [
      "python-et_xmlfile fails to build with Python 3.14: ElementTreeTest.test_simpleops: AssertionError: 'Element.remove(x): element not found' != 'list.remove(x): x not in list'"
    ]
  },
  "python-eth-stdlib": {
    "urls": [
      "https://bugzilla.redhat.com/show_bug.cgi?id=2368527"
    ],
    "summaries": [
      "python-eth-stdlib fails to build in Copr: error: Bad file: /builddir/build/SOURCES/python-eth-stdlib-0004-Fix-for-modern-poetry.patch: No such file or directory"
    ]
  },
  "python-exdir": {
    "urls": [
      "https://bugzilla.redhat.com/show_bug.cgi?id=2367253"
    ],
    "summaries": [
      "python-exdir fails to build with Python 3.14: TypeError: 'module' object is not iterable | TypeError: 'Plugin' object is not iterable"
    ]
  },
  "python-executing": {
    "urls": [
      "https://bugzilla.redhat.com/show_bug.cgi?id=2349436"
    ],
    "summaries": [
      "python-executing fails to build with Python 3.14: 52 test fail during the build"
    ]
  },
  "python-factory-boy": {
    "urls": [],
    "summaries": []
  },
  "python-fastavro": {
    "urls": [],
    "summaries": []
  },
  "python-flake8-comprehensions": {
    "urls": [
      "https://bugzilla.redhat.com/show_bug.cgi?id=2351385"
    ],
    "summaries": [
      "python-flake8-comprehensions fails to build with Python 3.14: Unnecessary reversed call around sorted() in 10 tests"
    ]
  },
  "python-flask-session": {
    "urls": [
      "https://bugzilla.redhat.com/show_bug.cgi?id=2354108"
    ],
    "summaries": [
      "python-flask-session FTBFS due to missing tox configuration"
    ]
  },
  "python-formulaic": {
    "urls": [],
    "summaries": []
  },
  "python-fs": {
    "urls": [
      "https://bugzilla.redhat.com/show_bug.cgi?id=2336951"
    ],
    "summaries": [
      "python-fs fails to build with Python 3.14: AssertionError: 'osfs://///tmp/tmppauy69swfstestosfs/foo' != 'osfs:///tmp/tmppauy69swfstestosfs/foo'"
    ]
  },
  "python-fsleyes-widgets": {
    "urls": [
      "https://bugzilla.redhat.com/show_bug.cgi?id=2336911"
    ],
    "summaries": [
      "python-fsleyes-widgets fails to build with Python 3.14: AssertionError: assert 'file:/home/b...htmlfile.html' == 'file:///home...htmlfile.html'"
    ]
  },
  "python-fsspec": {
    "urls": [],
    "summaries": []
  },
  "python-geopmpy": {
    "urls": [],
    "summaries": []
  },
  "python-googleapis-common-protos": {
    "urls": [
      "https://bugzilla.redhat.com/show_bug.cgi?id=2365822"
    ],
    "summaries": [
      "python-googleapis-common-protos fails to build with Python 3.14: protobuf: TypeError: Metaclasses with custom tp_new are not supported."
    ]
  },
  "python-gphoto2": {
    "urls": [
      "https://bugzilla.redhat.com/show_bug.cgi?id=2366465",
      "https://bugzilla.redhat.com/show_bug.cgi?id=2341158"
    ],
    "summaries": [
      "python-gphoto2 fails to build with Python 3.14: ModuleNotFoundError: No module named 'distutils.command.upload'",
      "python-gphoto2: FTBFS in Fedora rawhide/f42"
    ]
  },
  "python-gstreamer1": {
    "urls": [],
    "summaries": []
  },
  "python-h5io": {
    "urls": [],
    "summaries": []
  },
  "python-h5netcdf": {
    "urls": [
      "https://bugzilla.redhat.com/show_bug.cgi?id=2325222"
    ],
    "summaries": [
      "python-h5netcdf fails to build with Python 3.14: test_no_circular_references: AssertionError"
    ]
  },
  "python-healpy": {
    "urls": [],
    "summaries": []
  },
  "python-hl7": {
    "urls": [
      "https://bugzilla.redhat.com/show_bug.cgi?id=2341161",
      "https://bugzilla.redhat.com/show_bug.cgi?id=2329855"
    ],
    "summaries": [
      "python-hl7: FTBFS in Fedora rawhide/f42",
      "python-hl7 fails to build with sphinx 8.x: ERROR: Invalid value `None` in intersphinx_mapping['http://docs.python.org/']."
    ]
  },
  "python-howdoi": {
    "urls": [
      "https://bugzilla.redhat.com/show_bug.cgi?id=2342558"
    ],
    "summaries": [
      "python-howdoi fails to build with Python 3.14: AssertionError: 'ERROR: Unable to reach google. Do you need to use a proxy? + json.decoder.JSONDecodeError"
    ]
  },
  "python-httpx": {
    "urls": [],
    "summaries": []
  },
  "python-igraph": {
    "urls": [],
    "summaries": []
  },
  "python-imbalanced-learn": {
    "urls": [],
    "summaries": []
  },
  "python-influxdb-client": {
    "urls": [],
    "summaries": []
  },
  "python-inject": {
    "urls": [
      "https://bugzilla.redhat.com/show_bug.cgi?id=2327978"
    ],
    "summaries": [
      "python-inject fails to build with Python 3.14: RuntimeError: There is no current event loop in thread 'MainThread'."
    ]
  },
  "python-injector": {
    "urls": [
      "https://bugzilla.redhat.com/show_bug.cgi?id=2341165",
      "https://bugzilla.redhat.com/show_bug.cgi?id=2329880"
    ],
    "summaries": [
      "python-injector: FTBFS in Fedora rawhide/f42",
      "python-injector fails to build with sphinx 8.x: ERROR: Invalid value `None` in intersphinx_mapping['http://docs.python.org/']."
    ]
  },
  "python-invoke": {
    "urls": [
      "https://bugzilla.redhat.com/show_bug.cgi?id=2365652"
    ],
    "summaries": [
      "python-invoke fails to build with Python 3.14: SystemError: buffer overflow in 16 tests"
    ]
  },
  "python-ipfshttpclient": {
    "urls": [
      "https://bugzilla.redhat.com/show_bug.cgi?id=2368589"
    ],
    "summaries": [
      "python-ipfshttpclient fails to build with Python 3.14: AssertionError: assert ['(?![.])(?s:literal)\\\\z'] == ['(?![.])(?s:literal)\\\\Z']"
    ]
  },
  "python-ipyparallel": {
    "urls": [
      "https://bugzilla.redhat.com/show_bug.cgi?id=2359525"
    ],
    "summaries": [
      "python-ipyparallel fails to build with Python 3.14: TestAsyncResult.test_display_output_error: SyntaxWarning: 'return' in a 'finally' block treated as error"
    ]
  },
  "python-irc": {
    "urls": [
      "https://bugzilla.redhat.com/show_bug.cgi?id=2327991"
    ],
    "summaries": [
      "python-irc fails to build with Python 3.14: RuntimeError: There is no current event loop in thread 'MainThread'."
    ]
  },
  "python-janus": {
    "urls": [],
    "summaries": []
  },
  "python-jedi": {
    "urls": [
      "https://bugzilla.redhat.com/show_bug.cgi?id=2368972"
    ],
    "summaries": [
      "python-jedi fails to build with Python 3.14: test_string_annotation: AssertionError: assert [] == ['int', 'str'] etc."
    ]
  },
  "python-joblib": {
    "urls": [
      "https://bugzilla.redhat.com/show_bug.cgi?id=2369159"
    ],
    "summaries": [
      "python-joblib fails to build with Python 3.13.3+: AssertionError: assert b\"resource_tracker\" not in err, err.decode()"
    ]
  },
  "python-josepy": {
    "urls": [
      "https://bugzilla.redhat.com/show_bug.cgi?id=2359514"
    ],
    "summaries": [
      "python-josepy fails to build with Python 3.14: ValueError: Field `alg` in JSONObject `Header` has no type annotation."
    ]
  },
  "python-jsonpickle": {
    "urls": [],
    "summaries": []
  },
  "python-jupyter-kernel-test": {
    "urls": [],
    "summaries": []
  },
  "python-jupyter-server": {
    "urls": [],
    "summaries": []
  },
  "python-jupytext": {
    "urls": [],
    "summaries": []
  },
  "python-libNeuroML": {
    "urls": [],
    "summaries": []
  },
  "python-loguru": {
    "urls": [
      "https://bugzilla.redhat.com/show_bug.cgi?id=2356181"
    ],
    "summaries": [
      "python-loguru fails to build with Python 3.14: test_exception_modern[type_hints-minimum_python_version0]: m<class 'typing.Union'>"
    ]
  },
  "python-makefun": {
    "urls": [
      "https://bugzilla.redhat.com/show_bug.cgi?id=2328706"
    ],
    "summaries": [
      "python-makefun fails to build with Python 3.14: RuntimeError: There is no current event loop in thread 'MainThread'."
    ]
  },
  "python-markups": {
    "urls": [
      "https://bugzilla.redhat.com/show_bug.cgi?id=2366489"
    ],
    "summaries": [
      "python-markups fails to build with Python 3.14: AssertionError in test_get_pygments_stylesheet"
    ]
  },
  "python-matrix-nio": {
    "urls": [],
    "summaries": []
  },
  "python-mechanize": {
    "urls": [
      "https://bugzilla.redhat.com/show_bug.cgi?id=2368592"
    ],
    "summaries": [
      "python-mechanize fails to build with Python 3.14: test.test_cookies.CookieTests.test_missing_name: AssertionError"
    ]
  },
  "python-metakernel": {
    "urls": [
      "https://bugzilla.redhat.com/show_bug.cgi?id=2357903"
    ],
    "summaries": [
      "python-metakernel fails to build with Python 3.14: AssertionError in test_parallel_magic"
    ]
  },
  "python-missingno": {
    "urls": [],
    "summaries": []
  },
  "python-mizani": {
    "urls": [],
    "summaries": []
  },
  "python-mkdocs-d2-plugin": {
    "urls": [],
    "summaries": []
  },
  "python-mplcursors": {
    "urls": [],
    "summaries": []
  },
  "python-msal": {
    "urls": [
      "https://bugzilla.redhat.com/show_bug.cgi?id=2323170"
    ],
    "summaries": [
      "python-msal fails to build with Python 3.14: test_no_two_concurrent_receivers_can_listen_on_same_port: AssertionError: OSError not raised"
    ]
  },
  "python-nbclient": {
    "urls": [],
    "summaries": []
  },
  "python-nbconvert": {
    "urls": [],
    "summaries": []
  },
  "python-neatdend": {
    "urls": [
      "https://bugzilla.redhat.com/show_bug.cgi?id=2341170"
    ],
    "summaries": [
      "python-neatdend: FTBFS in Fedora rawhide/f42"
    ]
  },
  "python-netpyne": {
    "urls": [],
    "summaries": []
  },
  "python-network-runner": {
    "urls": [
      "https://bugzilla.redhat.com/show_bug.cgi?id=2341172"
    ],
    "summaries": [
      "python-network-runner: FTBFS in Fedora rawhide/f42"
    ]
  },
  "python-niaaml": {
    "urls": [],
    "summaries": []
  },
  "python-niaarmts": {
    "urls": [
      "https://bugzilla.redhat.com/show_bug.cgi?id=2369421"
    ],
    "summaries": [
      "python-niaarmts fails to build with Python 3.14: ERROR: Package 'niaarmts' requires a different Python: 3.14.0 not in '<3.14,>=3.11'"
    ]
  },
  "python-niaclass": {
    "urls": [],
    "summaries": []
  },
  "python-nikola": {
    "urls": [
      "https://bugzilla.redhat.com/show_bug.cgi?id=2341174"
    ],
    "summaries": [
      "python-nikola: FTBFS in Fedora rawhide/f42"
    ]
  },
  "python-odata-query": {
    "urls": [],
    "summaries": []
  },
  "python-ollama": {
    "urls": [],
    "summaries": []
  },
  "python-opfunu": {
    "urls": [],
    "summaries": []
  },
  "python-osc-lib": {
    "urls": [
      "https://bugzilla.redhat.com/show_bug.cgi?id=2351387"
    ],
    "summaries": [
      "python-osc-lib fails to build with Python 3.14: testtools.matchers._impl.MismatchError in 4 tests"
    ]
  },
  "python-oslo-config": {
    "urls": [],
    "summaries": []
  },
  "python-oslo-log": {
    "urls": [
      "https://bugzilla.redhat.com/show_bug.cgi?id=2368746"
    ],
    "summaries": [
      "python-oslo-log fails to build with Python 3.14: 2 test failures (MismatchErrors)"
    ]
  },
  "python-packvers": {
    "urls": [
      "https://bugzilla.redhat.com/show_bug.cgi?id=2341178",
      "https://bugzilla.redhat.com/show_bug.cgi?id=2329888"
    ],
    "summaries": [
      "python-packvers: FTBFS in Fedora rawhide/f42",
      "python-packvers fails to build with sphinx 8.x: ERROR: Invalid value `None` in intersphinx_mapping['https://docs.python.org/']."
    ]
  },
  "python-paginate": {
    "urls": [
      "https://bugzilla.redhat.com/show_bug.cgi?id=2354116"
    ],
    "summaries": [
      "python-paginate FTBFS due to missing tox configuration"
    ]
  },
  "python-pamela": {
    "urls": [
      "https://bugzilla.redhat.com/show_bug.cgi?id=2366474"
    ],
    "summaries": [
      "python-pamela fails to build with Python 3.14: pamela.PAMError: [PAM Error 26] Critical error - immediate abort"
    ]
  },
  "python-pandas-datareader": {
    "urls": [],
    "summaries": []
  },
  "python-paperwork-backend": {
    "urls": [],
    "summaries": []
  },
  "python-peewee": {
    "urls": [],
    "summaries": []
  },
  "python-photutils": {
    "urls": [],
    "summaries": []
  },
  "python-pika": {
    "urls": [
      "https://bugzilla.redhat.com/show_bug.cgi?id=2351384"
    ],
    "summaries": [
      "python-pika fails to build with Python 3.14: RuntimeError: There is no current event loop in thread 'MainThread'."
    ]
  },
  "python-pip": {
    "urls": [
      "https://bugzilla.redhat.com/show_bug.cgi?id=2335909"
    ],
    "summaries": [
      "python-pip fails to build with Python 3.14: AssertionError: assert 'file:/tmp/file' == 'file:///tmp/file'"
    ]
  },
  "python-pkg-depgraph": {
    "urls": [],
    "summaries": []
  },
  "python-pkginfo2": {
    "urls": [
      "https://bugzilla.redhat.com/show_bug.cgi?id=2366490"
    ],
    "summaries": [
      "python-pkginfo2: FTBFS in Fedora Rawhide: AssertionError: None != '30.0.0'"
    ]
  },
  "python-poi-tracker": {
    "urls": [],
    "summaries": []
  },
  "python-praw": {
    "urls": [
      "https://bugzilla.redhat.com/show_bug.cgi?id=2342562"
    ],
    "summaries": [
      "python-praw fails to build with Python 3.14: RuntimeError: There is no current event loop in thread 'MainThread'."
    ]
  },
  "python-priority": {
    "urls": [
      "https://bugzilla.redhat.com/show_bug.cgi?id=2341182",
      "https://bugzilla.redhat.com/show_bug.cgi?id=2329881"
    ],
    "summaries": [
      "python-priority: FTBFS in Fedora rawhide/f42",
      "python-priority fails to build with sphinx 8.x: ERROR: Invalid value `None` in intersphinx_mapping['http://docs.python.org/']."
    ]
  },
  "python-pudb": {
    "urls": [
      "https://bugzilla.redhat.com/show_bug.cgi?id=2365643"
    ],
    "summaries": [
      "python-pudb fails to build with Python 3.14: ImportError: cannot import name 'format_exception' from 'pudb.lowlevel'"
    ]
  },
  "python-pure-protobuf": {
    "urls": [
      "https://bugzilla.redhat.com/show_bug.cgi?id=2322710"
    ],
    "summaries": [
      "python-pure-protobuf fails to build with Python 3.14: ImportError: cannot import name 'ByteString' from 'typing'"
    ]
  },
  "python-pycec": {
    "urls": [
      "https://bugzilla.redhat.com/show_bug.cgi?id=2327973"
    ],
    "summaries": [
      "python-pycec fails to build with Python 3.14: RuntimeError: There is no current event loop in thread 'MainThread'."
    ]
  },
  "python-pydantic": {
    "urls": [],
    "summaries": []
  },
  "python-pydantic-core": {
    "urls": [
      "https://bugzilla.redhat.com/show_bug.cgi?id=2325425"
    ],
    "summaries": [
      "python-pydantic-core fails to build with Python 3.14: AssertionError: Regex pattern did not match. + AttributeError: module 'typing' has no attribute 'ByteString'"
    ]
  },
  "python-pydantic-settings": {
    "urls": [],
    "summaries": []
  },
  "python-pydocstyle": {
    "urls": [
      "https://bugzilla.redhat.com/show_bug.cgi?id=2366488"
    ],
    "summaries": [
      "python-pydocstyle fails to build with Python 3.14: AssertionError in test_overload_nested_function_valid"
    ]
  },
  "python-pyemd": {
    "urls": [
      "https://bugzilla.redhat.com/show_bug.cgi?id=2319698"
    ],
    "summaries": [
      "python-pyemd fails to build with setuptools 74+"
    ]
  },
  "python-pyforgejo": {
    "urls": [],
    "summaries": []
  },
  "python-pymdown-extensions": {
    "urls": [
      "https://bugzilla.redhat.com/show_bug.cgi?id=2350300",
      "https://bugzilla.redhat.com/show_bug.cgi?id=2336948"
    ],
    "summaries": [
      "Heads-up: python-pymdown-extensions fails to build with python-pygments 2.19.1 on Fedora 43",
      "python-pymdown-extensions fails to build with Python 3.14: TestAbsolute.test_relative_path and TestAbsoluteFileScheme.test_relative_path AssertionErrors"
    ]
  },
  "python-pymeeus": {
    "urls": [
      "https://bugzilla.redhat.com/show_bug.cgi?id=2341186",
      "https://bugzilla.redhat.com/show_bug.cgi?id=2329890"
    ],
    "summaries": [
      "python-pymeeus: FTBFS in Fedora rawhide/f42",
      "python-pymeeus fails to build with sphinx 8.x: ERROR: Invalid value `None` in intersphinx_mapping['https://docs.python.org/']."
    ]
  },
  "python-pymongo": {
    "urls": [
      "https://bugzilla.redhat.com/show_bug.cgi?id=2356166",
      "https://bugzilla.redhat.com/show_bug.cgi?id=2341188"
    ],
    "summaries": [
      "python-pymongo fails to build with Python 3.14: DeprecationWarning: 'asyncio.iscoroutinefunction' and 'asyncio.get_event_loop_policy' is deprecated and slated for removal in Python 3.16",
      "python-pymongo: FTBFS in Fedora rawhide/f42"
    ]
  },
  "python-pynn": {
    "urls": [],
    "summaries": []
  },
  "python-pyopencl": {
    "urls": [
      "https://bugzilla.redhat.com/show_bug.cgi?id=2341190"
    ],
    "summaries": [
      "python-pyopencl: FTBFS in Fedora rawhide/f42"
    ]
  },
  "python-pyopengl": {
    "urls": [
      "https://bugzilla.redhat.com/show_bug.cgi?id=2341191"
    ],
    "summaries": [
      "python-pyopengl: FTBFS in Fedora rawhide/f42"
    ]
  },
  "python-pyopengltk": {
    "urls": [],
    "summaries": []
  },
  "python-pyphi": {
    "urls": [
      "https://bugzilla.redhat.com/show_bug.cgi?id=2341193"
    ],
    "summaries": [
      "python-pyphi: FTBFS in Fedora rawhide/f42"
    ]
  },
  "python-pyqtgraph": {
    "urls": [],
    "summaries": []
  },
  "python-pyregion": {
    "urls": [],
    "summaries": []
  },
  "python-pyriemann": {
    "urls": [],
    "summaries": []
  },
  "python-pysaml2": {
    "urls": [
      "https://bugzilla.redhat.com/show_bug.cgi?id=2341199"
    ],
    "summaries": [
      "python-pysaml2: FTBFS in Fedora rawhide/f42"
    ]
  },
  "python-pytesseract": {
    "urls": [
      "https://bugzilla.redhat.com/show_bug.cgi?id=2341201"
    ],
    "summaries": [
      "python-pytesseract: FTBFS in Fedora rawhide/f42"
    ]
  },
  "python-pytest-aiohttp": {
    "urls": [
      "https://bugzilla.redhat.com/show_bug.cgi?id=2339466"
    ],
    "summaries": [
      "python-pytest-aiohttp fails to build with Python 3.14: DeprecationWarning: 'asyncio.get_event_loop_policy' is deprecated and slated for removal in Python 3.16"
    ]
  },
  "python-pytest-asyncio": {
    "urls": [
      "https://bugzilla.redhat.com/show_bug.cgi?id=2342564"
    ],
    "summaries": [
      "python-pytest-asyncio fails to build with Python 3.14: DeprecationWarning: 'asyncio.get_event_loop_policy' is deprecated and slated for removal in Python 3.16"
    ]
  },
  "python-pytest-lsp": {
    "urls": [
      "https://bugzilla.redhat.com/show_bug.cgi?id=2349451"
    ],
    "summaries": [
      "python-pytest-lsp fails to build with Python 3.14: warnings counts differ, resulting in AssertionError in 3 tests"
    ]
  },
  "python-pytest-testinfra": {
    "urls": [
      "https://bugzilla.redhat.com/show_bug.cgi?id=2361631"
    ],
    "summaries": [
      "python-pytest-testinfra FTBFS in rawhide"
    ]
  },
  "python-pytest-twisted": {
    "urls": [
      "https://bugzilla.redhat.com/show_bug.cgi?id=2368594"
    ],
    "summaries": [
      "python-pytest-twisted fails to build with Python 3.14: RuntimeError: There is no current event loop in thread 'MainThread'."
    ]
  },
  "python-python-ulid": {
    "urls": [],
    "summaries": []
  },
  "python-pyupgrade": {
    "urls": [
      "https://bugzilla.redhat.com/show_bug.cgi?id=2322713"
    ],
    "summaries": [
      "python-pyupgrade fails to build with Python 3.14: AttributeError: module 'ast' has no attribute 'Str'"
    ]
  },
  "python-pyvlx": {
    "urls": [
      "https://bugzilla.redhat.com/show_bug.cgi?id=2327983"
    ],
    "summaries": [
      "python-pyvlx fails to build with Python 3.14: RuntimeError: There is no current event loop in thread 'MainThread'."
    ]
  },
  "python-pyvo": {
    "urls": [],
    "summaries": []
  },
  "python-qudida": {
    "urls": [],
    "summaries": []
  },
  "python-rasterio": {
    "urls": [
      "https://bugzilla.redhat.com/show_bug.cgi?id=2369423"
    ],
    "summaries": [
      "python-rasterio fails to build with Python 3.14: Multiprocessing switched the default context method from fork to forkserver"
    ]
  },
  "python-rdflib": {
    "urls": [
      "https://bugzilla.redhat.com/show_bug.cgi?id=2343978",
      "https://bugzilla.redhat.com/show_bug.cgi?id=2336891"
    ],
    "summaries": [
      "python-rdflib fails to build with Python 3.14: AttributeError: term 'value' not in namespace 'http://www.w3.org/1999/02/22-rdf-syntax-ns#'",
      "python-rdflib fails to build with Python 3.14: \"TypeError: '<' not supported between instances of 'Literal' and 'Literal'\""
    ]
  },
  "python-reactivex": {
    "urls": [
      "https://bugzilla.redhat.com/show_bug.cgi?id=2327987"
    ],
    "summaries": [
      "python-reactivex fails to build with Python 3.14: RuntimeError: There is no current event loop in thread 'MainThread'."
    ]
  },
  "python-readability-lxml": {
    "urls": [
      "https://bugzilla.redhat.com/show_bug.cgi?id=2323185"
    ],
    "summaries": [
      "python-readability-lxml fails to build with Python 3.14: _pickle.PicklingError: Can't pickle <function TestArticleOnly.test_many_repeated_spaces at 0x7ff0ea064460>: it's not the same object as tests.test_article_only.TestArticleOnly.test_many_repeated_spa"
    ]
  },
  "python-recordclass": {
    "urls": [
      "https://bugzilla.redhat.com/show_bug.cgi?id=2327968"
    ],
    "summaries": [
      "python-recordclass fails to build with Python 3.14: 25 failures, 65 errors in the test suite"
    ]
  },
  "python-remoto": {
    "urls": [
      "https://bugzilla.redhat.com/show_bug.cgi?id=2366491",
      "https://bugzilla.redhat.com/show_bug.cgi?id=2341205"
    ],
    "summaries": [
      "python-remoto fails to build with Python 3.14: AttributeError: 'TestRemoteError' object has no attribute 'traceback'",
      "python-remoto: FTBFS in Fedora rawhide/f42"
    ]
  },
  "python-rope": {
    "urls": [
      "https://bugzilla.redhat.com/show_bug.cgi?id=2351391"
    ],
    "summaries": [
      "python-rope fails to build with Python 3.14: ImportError while loading conftest '/builddir/build/BUILD/python-rope-1.13.0-build/rope-1.13.0/ropetest/conftest.py'.: AssertionError: assert sys.version_info < (3, 8)"
    ]
  },
  "python-rosdep": {
    "urls": [
      "https://bugzilla.redhat.com/show_bug.cgi?id=2341207",
      "https://bugzilla.redhat.com/show_bug.cgi?id=2329891"
    ],
    "summaries": [
      "python-rosdep: FTBFS in Fedora rawhide/f42",
      "python-rosdep fails to build with sphinx 8.x: ERROR: Invalid value `None` in intersphinx_mapping['http://docs.python.org/']."
    ]
  },
  "python-rq": {
    "urls": [
      "https://bugzilla.redhat.com/show_bug.cgi?id=2342234"
    ],
    "summaries": [
      "python-rq fails to build with Python 3.14: test_worker.py::HerokuWorkerShutdownTestCase::test_handle_shutdown_request shuts down the whole build"
    ]
  },
  "python-rstcheck": {
    "urls": [
      "https://bugzilla.redhat.com/show_bug.cgi?id=2322705"
    ],
    "summaries": [
      "python-rstcheck fails to build with Python 3.14: AttributeError: 'Constant' object has no attribute 's'"
    ]
  },
  "python-rstcheck-core": {
    "urls": [],
    "summaries": []
  },
  "python-rx": {
    "urls": [
      "https://bugzilla.redhat.com/show_bug.cgi?id=2327979"
    ],
    "summaries": [
      "python-rx fails to build with Python 3.14: RuntimeError: There is no current event loop in thread 'MainThread'."
    ]
  },
  "python-scikit-build": {
    "urls": [],
    "summaries": []
  },
  "python-scikit-image": {
    "urls": [
      "https://bugzilla.redhat.com/show_bug.cgi?id=2368531"
    ],
    "summaries": [
      "python-scikit-image fails to build with Python 3.14: AssertionError: Regex pattern did not match. Regex: \"'old' is not in list\" Input: 'list.index(x): x not in list'"
    ]
  },
  "python-scikit-uplift": {
    "urls": [],
    "summaries": []
  },
  "python-sciunit": {
    "urls": [],
    "summaries": []
  },
  "python-seaborn": {
    "urls": [],
    "summaries": []
  },
  "python-simframe": {
    "urls": [
      "https://bugzilla.redhat.com/show_bug.cgi?id=2352552"
    ],
    "summaries": [
      "python-simframe fails to build with Python 3.14: TypeError: cannot pickle 'itertools.cycle' object"
    ]
  },
  "python-sklearn-genetic": {
    "urls": [],
    "summaries": []
  },
  "python-sklearn-genetic-opt": {
    "urls": [],
    "summaries": []
  },
  "python-sklearn-nature-inspired-algorithms": {
    "urls": [],
    "summaries": []
  },
  "python-smart_open": {
    "urls": [],
    "summaries": []
  },
  "python-sphinx": {
    "urls": [
      "https://bugzilla.redhat.com/show_bug.cgi?id=2368973"
    ],
    "summaries": [
      "python-sphinx fails to build with Python 3.14: test_autodoc_special_members'   .. py:attribute:: Class.__annotations_cache__' != '   .. py:attribute:: Class.__annotations__'"
    ]
  },
  "python-sphinxygen": {
    "urls": [
      "https://bugzilla.redhat.com/show_bug.cgi?id=2368738"
    ],
    "summaries": [
      "python-sphinxygen: FTBFS in Fedora Rawhide (probably with doxygen 1.14)"
    ]
  },
  "python-sqlalchemy1.4": {
    "urls": [
      "https://bugzilla.redhat.com/show_bug.cgi?id=2327976"
    ],
    "summaries": [
      "python-sqlalchemy1.4 fails to build with Python 3.14: RuntimeError: There is no current event loop in thread 'MainThread'."
    ]
  },
  "python-stdlibs": {
    "urls": [
      "https://bugzilla.redhat.com/show_bug.cgi?id=2359504"
    ],
    "summaries": [
      "python-stdlibs fails to build with Python 3.14: AssertionError: Items in the second set but not the first: '_hmac' '_ast_unparse' '_types'"
    ]
  },
  "python-steam": {
    "urls": [
      "https://bugzilla.redhat.com/show_bug.cgi?id=2341218"
    ],
    "summaries": [
      "python-steam: FTBFS in Fedora rawhide/f42"
    ]
  },
  "python-streamlink": {
    "urls": [
      "https://bugzilla.redhat.com/show_bug.cgi?id=2353127"
    ],
    "summaries": [
      "python-streamlink fails to build with Python 3.14: test_deprecated: AssetionError: Left contains one more item: <warnings.WarningMessage object at 0x7fd80afa3410>"
    ]
  },
  "python-succulent": {
    "urls": [],
    "summaries": []
  },
  "python-tables": {
    "urls": [],
    "summaries": []
  },
  "python-tablib": {
    "urls": [],
    "summaries": []
  },
  "python-telnetlib3": {
    "urls": [
      "https://bugzilla.redhat.com/show_bug.cgi?id=2354126"
    ],
    "summaries": [
      "python-telnetlib3 FTBFS due to missing tox configuration"
    ]
  },
  "python-tenacity": {
    "urls": [
      "https://bugzilla.redhat.com/show_bug.cgi?id=2327977"
    ],
    "summaries": [
      "python-tenacity fails to build with Python 3.14: RuntimeError: There is no current event loop in thread 'MainThread'."
    ]
  },
  "python-textual": {
    "urls": [
      "https://bugzilla.redhat.com/show_bug.cgi?id=2367457",
      "https://bugzilla.redhat.com/show_bug.cgi?id=2341224"
    ],
    "summaries": [
      "python-textual fails to build with Python 3.14: RuntimeError: There is no current event loop in thread 'MainThread'.",
      "python-textual: FTBFS in Fedora rawhide/f42"
    ]
  },
  "python-toolz": {
    "urls": [
      "https://bugzilla.redhat.com/show_bug.cgi?id=2323168"
    ],
    "summaries": [
      "python-toolz fails to build with Python 3.14: AssertionError: is_none: assert should_curry(getattr(operator, k)) == isinstance(v, toolz.curry), k"
    ]
  },
  "python-torch": {
    "urls": [],
    "summaries": []
  },
  "python-towncrier": {
    "urls": [
      "https://bugzilla.redhat.com/show_bug.cgi?id=2354131"
    ],
    "summaries": [
      "python-towncrier FTBFS due to missing tox configuration"
    ]
  },
  "python-trio": {
    "urls": [
      "https://bugzilla.redhat.com/show_bug.cgi?id=2345516"
    ],
    "summaries": [
      "python-trio fails to build with Python 3.14: test_ki_protection_doesnt_leave_cyclic_garbage: Left contains one more item: <coroutine object test_ki_protection_doesnt_leave_cyclic_garbage at 0x7fbaa2f162c0>"
    ]
  },
  "python-trx-python": {
    "urls": [],
    "summaries": []
  },
  "python-txaio": {
    "urls": [
      "https://bugzilla.redhat.com/show_bug.cgi?id=2327981"
    ],
    "summaries": [
      "python-txaio fails to build with Python 3.14: RuntimeError: There is no current event loop in thread 'MainThread'."
    ]
  },
  "python-typeguard": {
    "urls": [
      "https://bugzilla.redhat.com/show_bug.cgi?id=2366201"
    ],
    "summaries": [
      "python-typeguard fails to build with Python 3.14: AssertionError: assert 'str | int' == 'Union[str, int]' and more"
    ]
  },
  "python-typing-inspect": {
    "urls": [
      "https://bugzilla.redhat.com/show_bug.cgi?id=2325455"
    ],
    "summaries": [
      "python-typing-inspect fails to build with Python 3.14: AssertionError: {} != {'x': <class 'int'>, 'y': <class 'int'>}"
    ]
  },
  "python-ufoLib2": {
    "urls": [],
    "summaries": []
  },
  "python-usort": {
    "urls": [],
    "summaries": []
  },
  "python-uvloop": {
    "urls": [
      "https://bugzilla.redhat.com/show_bug.cgi?id=2341233",
      "https://bugzilla.redhat.com/show_bug.cgi?id=2326210"
    ],
    "summaries": [
      "python-uvloop: FTBFS in Fedora rawhide/f42",
      "python-uvloop fails to build with Python 3.14: AttributeError: module 'asyncio' has no attribute 'AbstractChildWatcher'"
    ]
  },
  "python-valkey": {
    "urls": [
      "https://bugzilla.redhat.com/show_bug.cgi?id=2349444"
    ],
    "summaries": [
      "python-valkey fails to build with Python 3.14: _pickle.PicklingError: Can't pickle local object <function TestMultiprocessing.test_close_connection_in_child.<locals>.target at 0x7f5aa68cddd0>"
    ]
  },
  "python-vascpy": {
    "urls": [],
    "summaries": []
  },
  "python-versioningit": {
    "urls": [],
    "summaries": []
  },
  "python-watchfiles": {
    "urls": [
      "https://bugzilla.redhat.com/show_bug.cgi?id=2339462"
    ],
    "summaries": [
      "python-watchfiles fails to build with Python 3.14: DeprecationWarning: 'asyncio.set_event_loop' is deprecated and slated for removal in Python 3.16"
    ]
  },
  "python-webob": {
    "urls": [
      "https://bugzilla.redhat.com/show_bug.cgi?id=2365645"
    ],
    "summaries": [
      "python-webob fails to build with Python 3.14: test_interrupted_request: AssertionError: False disconnect alert"
    ]
  },
  "python-wordcloud": {
    "urls": [
      "https://bugzilla.redhat.com/show_bug.cgi?id=2335908"
    ],
    "summaries": [
      "python-wordcloud fails to build with Python 3.14: test_cli_as_executable: AssertionError: assert expected_output in out if ret_code == 0 else err"
    ]
  },
  "python-yappi": {
    "urls": [
      "https://bugzilla.redhat.com/show_bug.cgi?id=2323160"
    ],
    "summaries": [
      "python-yappi fails to build with Python 3.14: error: invalid use of incomplete typedef \u2018PyGenObject\u2019 {aka \u2018struct _PyGenObject\u2019}"
    ]
  },
  "python-zope-exceptions": {
    "urls": [
      "https://bugzilla.redhat.com/show_bug.cgi?id=2341240",
      "https://bugzilla.redhat.com/show_bug.cgi?id=2329901"
    ],
    "summaries": [
      "python-zope-exceptions: FTBFS in Fedora rawhide/f42",
      "python-zope-exceptions fails to build with sphinx 8.x:  ERROR: Invalid value `None` in intersphinx_mapping['http://docs.python.org/']."
    ]
  },
  "python-zstarfile": {
    "urls": [],
    "summaries": []
  },
  "python3-exiv2": {
    "urls": [
      "https://bugzilla.redhat.com/show_bug.cgi?id=2354137"
    ],
    "summaries": [
      "python3-exiv2 FTBFS due to missing tox configuration"
    ]
  },
  "qtile": {
    "urls": [
      "https://bugzilla.redhat.com/show_bug.cgi?id=2328711"
    ],
    "summaries": [
      "qtile fails to build with Python 3.14: _pickle.PicklingError: Can't pickle local object <function TestManager.start.<locals>.run_qtile at 0x7f9c5918fed0>"
    ]
  },
  "rebase-helper": {
    "urls": [
      "https://bugzilla.redhat.com/show_bug.cgi?id=2352551"
    ],
    "summaries": [
      "rebase-helper fails to build with Python 3.14: AssertionError in TestCLI.test_cli_unit and TestConfig.test_merge"
    ]
  },
  "root": {
    "urls": [
      "https://bugzilla.redhat.com/show_bug.cgi?id=2366454"
    ],
    "summaries": [
      "root fails to build with Python 3.14: AssertionErrors in test_refcount"
    ]
  },
  "rpkg-util": {
    "urls": [],
    "summaries": []
  },
  "rpm-head-signing": {
    "urls": [
      "https://bugzilla.redhat.com/show_bug.cgi?id=2366308"
    ],
    "summaries": [
      "rpm-head-signing: FTBFS in Fedora Rawhide with RPM 6"
    ]
  },
  "rss2email": {
    "urls": [
      "https://bugzilla.redhat.com/show_bug.cgi?id=2368743"
    ],
    "summaries": [
      "rss2email fails to build with Python 3.14: ERROR: test_email_data/tails/1.config..."
    ]
  },
  "ruff": {
    "urls": [],
    "summaries": []
  },
  "sherlock-project": {
    "urls": [],
    "summaries": []
  },
  "signon-glib": {
    "urls": [
      "https://bugzilla.redhat.com/show_bug.cgi?id=2341348"
    ],
    "summaries": [
      "signon-glib: FTBFS in Fedora rawhide/f42"
    ]
  },
  "strongswan": {
    "urls": [
      "https://bugzilla.redhat.com/show_bug.cgi?id=2368971",
      "https://bugzilla.redhat.com/show_bug.cgi?id=2332864"
    ],
    "summaries": [
      "strongswan: FTBFS in Fedora Rawhide: error: possibly undefined macro: AC_LIB_PREFIX",
      "strongswan-5.9.14-5.fc42 FTBFS: strongswan-5.9.14/missing: line 81: aclocal-1.16: command not found"
    ]
  },
  "subversion": {
    "urls": [
      "https://bugzilla.redhat.com/show_bug.cgi?id=2359500"
    ],
    "summaries": [
      "subversion fails to build with Python 3.14: AssertionError: 3 != 4 : Memory leak!  Expected a ref count of 4 for svn_merge_range_t object, but got 3 instead (path: b'/trunk', index: 0)"
    ]
  },
  "sugar": {
    "urls": [
      "https://bugzilla.redhat.com/show_bug.cgi?id=2368968"
    ],
    "summaries": [
      "sugar: FTBFS in Fedora Rawhide"
    ]
  },
  "sugar-toolkit-gtk3": {
    "urls": [],
    "summaries": []
  },
  "swift-lang": {
    "urls": [
      "https://bugzilla.redhat.com/show_bug.cgi?id=2341403"
    ],
    "summaries": [
      "swift-lang: FTBFS in Fedora rawhide/f42"
    ]
  },
  "sympy": {
    "urls": [],
    "summaries": []
  },
  "tree-sitter-java": {
    "urls": [],
    "summaries": []
  },
  "ufw": {
    "urls": [
      "https://bugzilla.redhat.com/show_bug.cgi?id=2366458",
      "https://bugzilla.redhat.com/show_bug.cgi?id=2341477"
    ],
    "summaries": [
      "ufw fails to build in Fedora Rawhide: File not found: /builddir/build/BUILD/ufw-0.35-build/BUILDROOT/usr/bin/ufw",
      "ufw: FTBFS in Fedora rawhide/f42"
    ]
  },
  "uwsgi": {
    "urls": [
      "https://bugzilla.redhat.com/show_bug.cgi?id=2366193",
      "https://bugzilla.redhat.com/show_bug.cgi?id=2341497"
    ],
    "summaries": [
      "uwsgi fails to build with Python 3.14: plugins/python/python_plugin.c:1620:80: error: \u2018PyThreadState\u2019 {aka \u2018struct _ts\u2019} has no member named \u2018c_recursion_remaining\u2019; did you mean \u2018py_recursion_remaining\u2019?",
      "uwsgi: FTBFS in Fedora rawhide/f42"
    ]
  },
  "variety": {
    "urls": [],
    "summaries": []
  },
  "vdr-epg-daemon": {
    "urls": [],
    "summaries": []
  },
  "vdr-epg2vdr": {
    "urls": [],
    "summaries": []
  },
  "visidata": {
    "urls": [
      "https://bugzilla.redhat.com/show_bug.cgi?id=2325446"
    ],
    "summaries": [
      "visidata fails to build with Python 3.14: TestVisidataPath.test_withName: AssertionError: assert 'foo' == 'foo.'"
    ]
  },
  "weasyprint": {
    "urls": [],
    "summaries": []
  },
  "xpra": {
    "urls": [
      "https://bugzilla.redhat.com/show_bug.cgi?id=2350289"
    ],
    "summaries": [
      "xpra fails to build from source with Python 3.14: RuntimeError: An attempt has been made to start a new process before the current process has finished its bootstrapping phase."
    ]
  },
  "yt-dlp": {
    "urls": [
      "https://bugzilla.redhat.com/show_bug.cgi?id=2345522"
    ],
    "summaries": [
      "yt-dlp fails to build with Python 3.14: TestTraversal.test_traversal_morsel: AssertionError: `...` should yield all values: Left contains one more item: 'item_value'"
    ]
  },
  "zeek": {
    "urls": [
      "https://bugzilla.redhat.com/show_bug.cgi?id=2366467",
      "https://bugzilla.redhat.com/show_bug.cgi?id=2341601"
    ],
    "summaries": [
      "zeek fails to build in Fedora Rawhide: Could not find prerequisite package 'BIND'",
      "zeek: FTBFS in Fedora rawhide/f42"
    ]
  }
}