{
  "PyMca": {
    "urls": [],
    "summaries": []
  },
  "ara": {
    "urls": [
      "https://bugzilla.redhat.com/show_bug.cgi?id=2331346"
    ],
    "summaries": [
      "ara fails to build with Python 3.14: AttributeError: module 'pkgutil' has no attribute 'find_loader'"
    ]
  },
  "awscli2": {
    "urls": [
      "https://bugzilla.redhat.com/show_bug.cgi?id=2336910"
    ],
    "summaries": [
      "awscli2 fails to build with Python 3.14: ValueError('badly formed help string'),  KeyError: 'PATH'"
    ]
  },
  "binwalk": {
    "urls": [
      "https://bugzilla.redhat.com/show_bug.cgi?id=2336914"
    ],
    "summaries": [
      "binwalk fails to build with Python 3.14: TypeError: unsupported operand type(s) for +=: 'NoneType' and 'int'"
    ]
  },
  "borgbackup": {
    "urls": [
      "https://bugzilla.redhat.com/show_bug.cgi?id=2326916"
    ],
    "summaries": [
      "borgbackup fails to build with Python 3.14: OSError: AF_UNIX path too long when compiling"
    ]
  },
  "botan2": {
    "urls": [
      "https://bugzilla.redhat.com/show_bug.cgi?id=2339942"
    ],
    "summaries": [
      "botan2: FTBFS in Fedora rawhide/f42"
    ]
  },
  "capstone": {
    "urls": [],
    "summaries": []
  },
  "ceph": {
    "urls": [
      "https://bugzilla.redhat.com/show_bug.cgi?id=2336913"
    ],
    "summaries": [
      "ceph fails to build with Python 3.14: AttributeError: module 'pkgutil' has no attribute 'find_loader'"
    ]
  },
  "chirp": {
    "urls": [],
    "summaries": []
  },
  "cjdns": {
    "urls": [
      "https://bugzilla.redhat.com/show_bug.cgi?id=2339969"
    ],
    "summaries": [
      "cjdns: FTBFS in Fedora rawhide/f42"
    ]
  },
  "cockpit": {
    "urls": [],
    "summaries": []
  },
  "collectd": {
    "urls": [],
    "summaries": []
  },
  "condor": {
    "urls": [
      "https://bugzilla.redhat.com/show_bug.cgi?id=2339993"
    ],
    "summaries": [
      "condor: FTBFS in Fedora rawhide/f42"
    ]
  },
  "criu": {
    "urls": [
      "https://bugzilla.redhat.com/show_bug.cgi?id=2340011"
    ],
    "summaries": [
      "criu: FTBFS in Fedora rawhide/f42"
    ]
  },
  "dee": {
    "urls": [
      "https://bugzilla.redhat.com/show_bug.cgi?id=2340038"
    ],
    "summaries": [
      "dee: FTBFS in Fedora rawhide/f42"
    ]
  },
  "diceware": {
    "urls": [
      "https://bugzilla.redhat.com/show_bug.cgi?id=2340075"
    ],
    "summaries": [
      "diceware: FTBFS in Fedora rawhide/f42"
    ]
  },
  "did": {
    "urls": [
      "https://bugzilla.redhat.com/show_bug.cgi?id=2328006"
    ],
    "summaries": [
      "did fails to build with Python 3.14: AttributeError: module 'urllib.request' has no attribute 'FancyURLopener'"
    ]
  },
  "dlib": {
    "urls": [
      "https://bugzilla.redhat.com/show_bug.cgi?id=2340079",
      "https://bugzilla.redhat.com/show_bug.cgi?id=2328014"
    ],
    "summaries": [
      "dlib: FTBFS in Fedora rawhide/f42",
      "dlib fails to build with Python 3.14: AttributeError: module 'pkgutil' has no attribute 'find_loader'"
    ]
  },
  "dnsconfd": {
    "urls": [
      "https://bugzilla.redhat.com/show_bug.cgi?id=2340084"
    ],
    "summaries": [
      "dnsconfd: FTBFS in Fedora rawhide/f42"
    ]
  },
  "espresso": {
    "urls": [
      "https://bugzilla.redhat.com/show_bug.cgi?id=2340139"
    ],
    "summaries": [
      "espresso: FTBFS in Fedora rawhide/f42"
    ]
  },
  "gdl": {
    "urls": [
      "https://bugzilla.redhat.com/show_bug.cgi?id=2345533"
    ],
    "summaries": [
      "gdl fails to build with Python 3.14: test_tic_toc.pro failed"
    ]
  },
  "gnofract4d": {
    "urls": [
      "https://bugzilla.redhat.com/show_bug.cgi?id=2339539"
    ],
    "summaries": [
      "gnofract4d fails to build with Python 3.14: AssertionError: 'ct_sin6 = (0.841471,-0)' != 'ct_sin6 = (0.841471,0)'"
    ]
  },
  "gpgme": {
    "urls": [],
    "summaries": []
  },
  "h5py": {
    "urls": [
      "https://bugzilla.redhat.com/show_bug.cgi?id=2345536",
      "https://bugzilla.redhat.com/show_bug.cgi?id=2339470"
    ],
    "summaries": [
      "h5py fails to import with Python 3.14: ValueError: chr() arg not in range(0x110000)",
      "h5py fails to build with Python 3.14: ResourceWarning: TestFileObj.test_TemporaryFile: Implicitly cleaning up <_TemporaryFileWrapper file=<_io.BufferedRandom name='/tmp/tmp8pqafmzv'>>"
    ]
  },
  "httpie": {
    "urls": [
      "https://bugzilla.redhat.com/show_bug.cgi?id=2340619"
    ],
    "summaries": [
      "httpie: FTBFS in Fedora rawhide/f42"
    ]
  },
  "ikiwiki": {
    "urls": [
      "https://bugzilla.redhat.com/show_bug.cgi?id=2340642"
    ],
    "summaries": [
      "ikiwiki: FTBFS in Fedora rawhide/f42"
    ]
  },
  "insight": {
    "urls": [],
    "summaries": []
  },
  "kicad": {
    "urls": [],
    "summaries": []
  },
  "kmymoney": {
    "urls": [],
    "summaries": []
  },
  "koji": {
    "urls": [
      "https://bugzilla.redhat.com/show_bug.cgi?id=2340700"
    ],
    "summaries": [
      "koji: FTBFS in Fedora rawhide/f42"
    ]
  },
  "lammps": {
    "urls": [
      "https://bugzilla.redhat.com/show_bug.cgi?id=2340706"
    ],
    "summaries": [
      "lammps: FTBFS in Fedora rawhide/f42"
    ]
  },
  "lasso": {
    "urls": [
      "https://bugzilla.redhat.com/show_bug.cgi?id=2340708"
    ],
    "summaries": [
      "lasso: FTBFS in Fedora rawhide/f42"
    ]
  },
  "lazygal": {
    "urls": [],
    "summaries": []
  },
  "libarcus": {
    "urls": [
      "https://bugzilla.redhat.com/show_bug.cgi?id=2340716"
    ],
    "summaries": [
      "libarcus: FTBFS in Fedora rawhide/f42"
    ]
  },
  "libnvme": {
    "urls": [
      "https://bugzilla.redhat.com/show_bug.cgi?id=2325194"
    ],
    "summaries": [
      "libnvme fails to build with Python 3.14: /usr/include/python3.14/pyport.h:629:35: error: missing ')' after \"__has_attribute\""
    ]
  },
  "libsolv": {
    "urls": [
      "https://bugzilla.redhat.com/show_bug.cgi?id=2340762"
    ],
    "summaries": [
      "libsolv: FTBFS in Fedora rawhide/f42: bool redefinitions with GCC 15 in bindings/solv.i (via Swig-generated solv_perl.c)"
    ]
  },
  "libsonata": {
    "urls": [],
    "summaries": []
  },
  "llvm": {
    "urls": [
      "https://bugzilla.redhat.com/show_bug.cgi?id=2336915"
    ],
    "summaries": [
      "llvm fails to build with Python 3.14: tools/opt-viewer/suppress.test: AttributeError: type object 'Passed' has no attribute 'demangler_lock'"
    ]
  },
  "mathgl": {
    "urls": [
      "https://bugzilla.redhat.com/show_bug.cgi?id=2340819"
    ],
    "summaries": [
      "mathgl: FTBFS in Fedora rawhide/f42"
    ]
  },
  "morphio": {
    "urls": [],
    "summaries": []
  },
  "needrestart": {
    "urls": [
      "https://bugzilla.redhat.com/show_bug.cgi?id=2340913"
    ],
    "summaries": [
      "needrestart: FTBFS in Fedora rawhide/f42"
    ]
  },
  "neuron": {
    "urls": [
      "https://bugzilla.redhat.com/show_bug.cgi?id=2340926"
    ],
    "summaries": [
      "neuron: FTBFS in Fedora rawhide/f42"
    ]
  },
  "nox": {
    "urls": [],
    "summaries": []
  },
  "nwchem": {
    "urls": [
      "https://bugzilla.redhat.com/show_bug.cgi?id=2340948"
    ],
    "summaries": [
      "nwchem: FTBFS in Fedora rawhide/f42"
    ]
  },
  "obs-studio": {
    "urls": [
      "https://bugzilla.redhat.com/show_bug.cgi?id=2340952"
    ],
    "summaries": [
      "obs-studio: FTBFS in Fedora rawhide/f42"
    ]
  },
  "onnx": {
    "urls": [],
    "summaries": []
  },
  "pcs": {
    "urls": [],
    "summaries": []
  },
  "poetry": {
    "urls": [],
    "summaries": []
  },
  "poezio": {
    "urls": [
      "https://bugzilla.redhat.com/show_bug.cgi?id=2341088"
    ],
    "summaries": [
      "poezio: FTBFS in Fedora rawhide/f42"
    ]
  },
  "postgresql16": {
    "urls": [
      "https://bugzilla.redhat.com/show_bug.cgi?id=2332981"
    ],
    "summaries": [
      "postgresql16-16.3-7.fc42 FTBFS: tests fail with tzdata-2024b"
    ]
  },
  "postgresql17": {
    "urls": [
      "https://bugzilla.redhat.com/show_bug.cgi?id=2332978",
      "https://bugzilla.redhat.com/show_bug.cgi?id=2327967"
    ],
    "summaries": [
      "postgresql17-17.0-1.fc42 FTBFS: RPM build errors: line 227: second Description",
      "postgresql17 fails to build with Python 3.14: jsonb_jsonpath fails: - \"12:34:56-07:00\" != + \"12:34:56-08:00\""
    ]
  },
  "powerline": {
    "urls": [
      "https://bugzilla.redhat.com/show_bug.cgi?id=2336943"
    ],
    "summaries": [
      "powerline fails to build with Python 3.14: ValueError: argument groups cannot be nested"
    ]
  },
  "protobuf": {
    "urls": [
      "https://bugzilla.redhat.com/show_bug.cgi?id=2343969",
      "https://bugzilla.redhat.com/show_bug.cgi?id=2341106"
    ],
    "summaries": [
      "protobuf doesn't work with Python 3.14: test_error_reason: TypeError: Metaclasses with custom tp_new are not supported.",
      "protobuf: FTBFS in Fedora rawhide/f42, missing a dependency on mvn(com.google.truth:truth)"
    ]
  },
  "pychess": {
    "urls": [
      "https://bugzilla.redhat.com/show_bug.cgi?id=2328708"
    ],
    "summaries": [
      "pychess fails to build with Python 3.14: RuntimeError: There is no current event loop in thread 'MainThread'."
    ]
  },
  "pychromecast": {
    "urls": [],
    "summaries": []
  },
  "pygsl": {
    "urls": [
      "https://bugzilla.redhat.com/show_bug.cgi?id=2341119"
    ],
    "summaries": [
      "pygsl: FTBFS in Fedora rawhide/f42"
    ]
  },
  "pykka": {
    "urls": [
      "https://bugzilla.redhat.com/show_bug.cgi?id=2345521"
    ],
    "summaries": [
      "pykka fails to build with Python 3.14: RuntimeError: There is no current event loop in thread 'MainThread'."
    ]
  },
  "pyserial-asyncio": {
    "urls": [
      "https://bugzilla.redhat.com/show_bug.cgi?id=2327980"
    ],
    "summaries": [
      "pyserial-asyncio fails to build with Python 3.14: RuntimeError: There is no current event loop in thread 'MainThread'."
    ]
  },
  "pysubnettree": {
    "urls": [
      "https://bugzilla.redhat.com/show_bug.cgi?id=2341123"
    ],
    "summaries": [
      "pysubnettree: FTBFS in Fedora rawhide/f42"
    ]
  },
  "python-TestSlide": {
    "urls": [
      "https://bugzilla.redhat.com/show_bug.cgi?id=2343971"
    ],
    "summaries": [
      "python-TestSlide fails to build with Python 3.14: ERROR collecting tests/mock_callable_testslide.py: RuntimeError: dictionary changed size during iteration"
    ]
  },
  "python-aioesphomeapi": {
    "urls": [],
    "summaries": []
  },
  "python-aioflo": {
    "urls": [
      "https://bugzilla.redhat.com/show_bug.cgi?id=2341124"
    ],
    "summaries": [
      "python-aioflo: FTBFS in Fedora rawhide/f42"
    ]
  },
  "python-aiokafka": {
    "urls": [],
    "summaries": []
  },
  "python-aiosmtpd": {
    "urls": [
      "https://bugzilla.redhat.com/show_bug.cgi?id=2322718"
    ],
    "summaries": [
      "python-aiosmtpd fails to build with Python 3.14: ImportError: cannot import name 'ByteString' from 'typing'"
    ]
  },
  "python-anyio": {
    "urls": [
      "https://bugzilla.redhat.com/show_bug.cgi?id=2328710"
    ],
    "summaries": [
      "python-anyio fails to build with Python 3.14: AttributeError: '_UnixDefaultEventLoopPolicy' object has no attribute 'get_child_watcher' && TypeError: PurePath.relative_to() takes 2 positional arguments but 3 were given"
    ]
  },
  "python-apsw": {
    "urls": [],
    "summaries": []
  },
  "python-asgiref": {
    "urls": [
      "https://bugzilla.redhat.com/show_bug.cgi?id=2345528"
    ],
    "summaries": [
      "python-asgiref fails to build with Python 3.14: DeprecationWarning: 'asyncio.set_event_loop' is deprecated and slated for removal in Python 3.16"
    ]
  },
  "python-astroid": {
    "urls": [
      "https://bugzilla.redhat.com/show_bug.cgi?id=2323166"
    ],
    "summaries": [
      "python-astroid fails to build with Python 3.14: astroid.exceptions.InferenceError: StopIteration raised without any error information."
    ]
  },
  "python-astropy": {
    "urls": [
      "https://bugzilla.redhat.com/show_bug.cgi?id=2345524"
    ],
    "summaries": [
      "python-astropy fails to build with Python 3.14: test_info_preserved_pickle_copy_init[arrayswap]: AssertionError: assert dtype('>i4') == dtype('int32')"
    ]
  },
  "python-astropy-iers-data": {
    "urls": [],
    "summaries": []
  },
  "python-astroscrappy": {
    "urls": [],
    "summaries": []
  },
  "python-asyncssh": {
    "urls": [
      "https://bugzilla.redhat.com/show_bug.cgi?id=2325445"
    ],
    "summaries": [
      "python-asyncssh fails to build with Python 3.14: multiple test failures (failures=25, errors=697)"
    ]
  },
  "python-atomicwrites": {
    "urls": [
      "https://bugzilla.redhat.com/show_bug.cgi?id=2341128"
    ],
    "summaries": [
      "python-atomicwrites: FTBFS in Fedora rawhide/f42"
    ]
  },
  "python-autocommand": {
    "urls": [
      "https://bugzilla.redhat.com/show_bug.cgi?id=2327972"
    ],
    "summaries": [
      "python-autocommand fails to build with Python 3.14: RuntimeError: There is no current event loop in thread 'MainThread'."
    ]
  },
  "python-avocado": {
    "urls": [
      "https://bugzilla.redhat.com/show_bug.cgi?id=2341130",
      "https://bugzilla.redhat.com/show_bug.cgi?id=2325218"
    ],
    "summaries": [
      "python-avocado: FTBFS in Fedora rawhide/f42",
      "python-avocado fails to build with Python 3.14: Error running method \"pre_tests\" of plugin \"fetchasset\": module 'ast' has no attribute 'Str' + Avocado crashed: TypeError: cannot pickle '_thread.RLock' object"
    ]
  },
  "python-aw-qt": {
    "urls": [],
    "summaries": []
  },
  "python-awscrt": {
    "urls": [
      "https://bugzilla.redhat.com/show_bug.cgi?id=2322714"
    ],
    "summaries": [
      "python-awscrt fails to build with Python 3.14: ImportError: cannot import name 'ByteString' from 'collections.abc'"
    ]
  },
  "python-backrefs": {
    "urls": [
      "https://bugzilla.redhat.com/show_bug.cgi?id=2325184"
    ],
    "summaries": [
      "python-backrefs fails to build with Python 3.14: Failed to acquire all needed Unicode files!"
    ]
  },
  "python-beartype": {
    "urls": [
      "https://bugzilla.redhat.com/show_bug.cgi?id=2341131",
      "https://bugzilla.redhat.com/show_bug.cgi?id=2322721"
    ],
    "summaries": [
      "python-beartype: FTBFS in Fedora rawhide/f42",
      "python-beartype fails to build with Python 3.14: ImportError: cannot import name 'ByteString' from 'typing'"
    ]
  },
  "python-behave": {
    "urls": [
      "https://bugzilla.redhat.com/show_bug.cgi?id=2339094"
    ],
    "summaries": [
      "python-behave fails to build with Python 3.14: RuntimeError: There is no current event loop in thread 'MainThread'."
    ]
  },
  "python-billiard": {
    "urls": [
      "https://bugzilla.redhat.com/show_bug.cgi?id=2323167"
    ],
    "summaries": [
      "python-billiard fails to build with Python 3.14: AttributeError: module 'subprocess' has no attribute '_USE_VFORK'"
    ]
  },
  "python-bioread": {
    "urls": [
      "https://bugzilla.redhat.com/show_bug.cgi?id=2345530"
    ],
    "summaries": [
      "python-bioread fails to build with Python 3.14: help2man: can't get `--help' info from /builddir/build/BUILD/python-bioread-3.0.1-build/BUILDROOT/usr/bin/acq2hdf5"
    ]
  },
  "python-blinker": {
    "urls": [
      "https://bugzilla.redhat.com/show_bug.cgi?id=2325193"
    ],
    "summaries": [
      "python-blinker fails to build with Python 3.14: pluggy.PluggyTeardownRaisedWarning: A plugin raised an exception during an old-style hookwrapper teardown."
    ]
  },
  "python-boto3": {
    "urls": [],
    "summaries": []
  },
  "python-breathe": {
    "urls": [
      "https://bugzilla.redhat.com/show_bug.cgi?id=2341133"
    ],
    "summaries": [
      "python-breathe: FTBFS in Fedora rawhide/f42"
    ]
  },
  "python-capturer": {
    "urls": [
      "https://bugzilla.redhat.com/show_bug.cgi?id=2328004"
    ],
    "summaries": [
      "python-capturer fails to build with Python 3.14: OSError: [Errno 29] Illegal seek"
    ]
  },
  "python-catkin_tools": {
    "urls": [
      "https://bugzilla.redhat.com/show_bug.cgi?id=2341134"
    ],
    "summaries": [
      "python-catkin_tools: FTBFS in Fedora rawhide/f42"
    ]
  },
  "python-cattrs": {
    "urls": [
      "https://bugzilla.redhat.com/show_bug.cgi?id=2343916"
    ],
    "summaries": [
      "python-cattrs fails to build with Python 3.14: TypeError: <class 'tests.strategies.test_include_subclasses.GrandChild'> has no usable non-default attributes"
    ]
  },
  "python-chalice": {
    "urls": [
      "https://bugzilla.redhat.com/show_bug.cgi?id=2342568"
    ],
    "summaries": [
      "python-chalice fails to build with Python 3.14: AttributeError: module 'ast' has no attribute 'Str'"
    ]
  },
  "python-colcon-cmake": {
    "urls": [
      "https://bugzilla.redhat.com/show_bug.cgi?id=2339465"
    ],
    "summaries": [
      "python-colcon-cmake fails to build with Python 3.14: DeprecationWarning: 'asyncio.set_event_loop' is deprecated and slated for removal in Python 3.16"
    ]
  },
  "python-colcon-core": {
    "urls": [
      "https://bugzilla.redhat.com/show_bug.cgi?id=2339464"
    ],
    "summaries": [
      "python-colcon-core fails to build with Python 3.14: DeprecationWarning: 'asyncio.set_event_loop' is deprecated and slated for removal in Python 3.16"
    ]
  },
  "python-colcon-parallel-executor": {
    "urls": [
      "https://bugzilla.redhat.com/show_bug.cgi?id=2325186"
    ],
    "summaries": [
      "python-colcon-parallel-executor fails to build with Python 3.14: test_parallel: AssertionError: DeprecationWarning: 'asyncio.iscoroutinefunction' is deprecated and slated for removal in Python 3.16; use inspect.iscoroutinefunction() instead"
    ]
  },
  "python-colorful": {
    "urls": [
      "https://bugzilla.redhat.com/show_bug.cgi?id=2325168"
    ],
    "summaries": [
      "python-colorful fails to build with Python 3.14: ast.Constant.s has been removed from Python 3.14"
    ]
  },
  "python-commoncode": {
    "urls": [
      "https://bugzilla.redhat.com/show_bug.cgi?id=2325197"
    ],
    "summaries": [
      "python-commoncode fails to build with Python 3.14: tarfile.SpecialFileError: '6-FIFOTYPE' is a special file"
    ]
  },
  "python-confuse": {
    "urls": [
      "https://bugzilla.redhat.com/show_bug.cgi?id=2327966"
    ],
    "summaries": [
      "python-confuse fails to build with Python 3.14: AttributeError: module 'pkgutil' has no attribute 'get_loader'"
    ]
  },
  "python-crcmod": {
    "urls": [],
    "summaries": []
  },
  "python-crick": {
    "urls": [],
    "summaries": []
  },
  "python-dataclassy": {
    "urls": [
      "https://bugzilla.redhat.com/show_bug.cgi?id=2325200"
    ],
    "summaries": [
      "python-dataclassy fails to build with Python 3.14: TypeError: Beta() takes no arguments"
    ]
  },
  "python-dateparser": {
    "urls": [
      "https://bugzilla.redhat.com/show_bug.cgi?id=2336931"
    ],
    "summaries": [
      "python-dateparser: FTBFS in Fedora Rawhide: AssertionError in TestTranslateSearch.test_relative_base_setting_2_en"
    ]
  },
  "python-dbus-next": {
    "urls": [
      "https://bugzilla.redhat.com/show_bug.cgi?id=2345525"
    ],
    "summaries": [
      "python-dbus-next fails to build with Python 3.14: test_sending_file_descriptor_low_level: At index 0 diff: 'The name :1.46 was not provided by any .service files' != 'got it'"
    ]
  },
  "python-defcon": {
    "urls": [],
    "summaries": []
  },
  "python-dill": {
    "urls": [
      "https://bugzilla.redhat.com/show_bug.cgi?id=2323157"
    ],
    "summaries": [
      "python-dill fails to build with Python 3.14: TypeError: _Pickler._batch_setitems() missing 1 required positional argument: 'obj'"
    ]
  },
  "python-dipy": {
    "urls": [],
    "summaries": []
  },
  "python-django-filter": {
    "urls": [
      "https://bugzilla.redhat.com/show_bug.cgi?id=2336944"
    ],
    "summaries": [
      "python-django-filter fails to build with Python 3.14: AttributeError: module 'pkgutil' has no attribute 'find_loader'"
    ]
  },
  "python-domdf-python-tools": {
    "urls": [
      "https://bugzilla.redhat.com/show_bug.cgi?id=2345519"
    ],
    "summaries": [
      "python-domdf-python-tools fails to build with Python 3.14: tests/test_words.py::test_alpha_sort - AssertionError: Regex pattern did not match."
    ]
  },
  "python-ducc0": {
    "urls": [
      "https://bugzilla.redhat.com/show_bug.cgi?id=2341145"
    ],
    "summaries": [
      "python-ducc0: FTBFS in Fedora rawhide/f42"
    ]
  },
  "python-emcee": {
    "urls": [],
    "summaries": []
  },
  "python-epub": {
    "urls": [
      "https://bugzilla.redhat.com/show_bug.cgi?id=2319654"
    ],
    "summaries": [
      "python-epub fails to build with setuptools 74+"
    ]
  },
  "python-etcd": {
    "urls": [
      "https://bugzilla.redhat.com/show_bug.cgi?id=2323184"
    ],
    "summaries": [
      "python-etcd fails to build with Python 3.14: _pickle.PicklingError: Can't pickle local object <function TestWatch.test_watch_indexed_generator.<locals>.watch_value at 0x7f0d39f71dd0>"
    ]
  },
  "python-events": {
    "urls": [
      "https://bugzilla.redhat.com/show_bug.cgi?id=2319655"
    ],
    "summaries": [
      "python-events fails to build with setuptools 74+"
    ]
  },
  "python-exdir": {
    "urls": [],
    "summaries": []
  },
  "python-executing": {
    "urls": [],
    "summaries": []
  },
  "python-flask": {
    "urls": [
      "https://bugzilla.redhat.com/show_bug.cgi?id=2327965"
    ],
    "summaries": [
      "python-flask fails to build with Python 3.14: AttributeError: module 'pkgutil' has no attribute 'get_loader'"
    ]
  },
  "python-flask-caching": {
    "urls": [
      "https://bugzilla.redhat.com/show_bug.cgi?id=2341153"
    ],
    "summaries": [
      "python-flask-caching: FTBFS in Fedora rawhide/f42"
    ]
  },
  "python-fs": {
    "urls": [
      "https://bugzilla.redhat.com/show_bug.cgi?id=2336951"
    ],
    "summaries": [
      "python-fs fails to build with Python 3.14: AssertionError: 'osfs://///tmp/tmppauy69swfstestosfs/foo' != 'osfs:///tmp/tmppauy69swfstestosfs/foo'"
    ]
  },
  "python-fsleyes-widgets": {
    "urls": [
      "https://bugzilla.redhat.com/show_bug.cgi?id=2336911"
    ],
    "summaries": [
      "python-fsleyes-widgets fails to build with Python 3.14: AssertionError: assert 'file:/home/b...htmlfile.html' == 'file:///home...htmlfile.html'"
    ]
  },
  "python-giacpy": {
    "urls": [
      "https://bugzilla.redhat.com/show_bug.cgi?id=2341608"
    ],
    "summaries": [
      "python-giacpy: FTBFS in Fedora rawhide/f42"
    ]
  },
  "python-git-revise": {
    "urls": [
      "https://bugzilla.redhat.com/show_bug.cgi?id=2341157"
    ],
    "summaries": [
      "python-git-revise: FTBFS in Fedora rawhide/f42"
    ]
  },
  "python-gitlab": {
    "urls": [
      "https://bugzilla.redhat.com/show_bug.cgi?id=2342565"
    ],
    "summaries": [
      "python-gitlab fails to build with Python 3.14: AttributeError: 'Variable' object has no attribute '__annotations__'. Did you mean: '__annotate__'? and more"
    ]
  },
  "python-glyphsLib": {
    "urls": [],
    "summaries": []
  },
  "python-googleapis-common-protos": {
    "urls": [],
    "summaries": []
  },
  "python-gphoto2": {
    "urls": [
      "https://bugzilla.redhat.com/show_bug.cgi?id=2341158"
    ],
    "summaries": [
      "python-gphoto2: FTBFS in Fedora rawhide/f42"
    ]
  },
  "python-graph-tool": {
    "urls": [],
    "summaries": []
  },
  "python-h5netcdf": {
    "urls": [
      "https://bugzilla.redhat.com/show_bug.cgi?id=2325222"
    ],
    "summaries": [
      "python-h5netcdf fails to build with Python 3.14: test_no_circular_references: AssertionError"
    ]
  },
  "python-hamcrest": {
    "urls": [
      "https://bugzilla.redhat.com/show_bug.cgi?id=2341160"
    ],
    "summaries": [
      "python-hamcrest: FTBFS in Fedora rawhide/f42"
    ]
  },
  "python-hdf5storage": {
    "urls": [],
    "summaries": []
  },
  "python-hexbytes": {
    "urls": [],
    "summaries": []
  },
  "python-hl7": {
    "urls": [
      "https://bugzilla.redhat.com/show_bug.cgi?id=2341161"
    ],
    "summaries": [
      "python-hl7: FTBFS in Fedora rawhide/f42"
    ]
  },
  "python-howdoi": {
    "urls": [
      "https://bugzilla.redhat.com/show_bug.cgi?id=2342558"
    ],
    "summaries": [
      "python-howdoi fails to build with Python 3.14: AssertionError: 'ERROR: Unable to reach google. Do you need to use a proxy? + json.decoder.JSONDecodeError"
    ]
  },
  "python-httpretty": {
    "urls": [
      "https://bugzilla.redhat.com/show_bug.cgi?id=2343976"
    ],
    "summaries": [
      "python-httpretty fails to build with Python 3.14: AttributeError: 'SSLContext' object has no attribute 'close' & 'sendall'"
    ]
  },
  "python-icalendar": {
    "urls": [
      "https://bugzilla.redhat.com/show_bug.cgi?id=2336946"
    ],
    "summaries": [
      "python-icalendar: FTBFS in Fedora Rawhide: AssertionError: assert 'WET' in ('Europe/Lisbon', 'Portugal')  where ('Europe/Lisbon', 'Portugal') = tzids_from_tzinfo(tzfile('/usr/share/zoneinfo/WET'))"
    ]
  },
  "python-img2pdf": {
    "urls": [
      "https://bugzilla.redhat.com/show_bug.cgi?id=2328707"
    ],
    "summaries": [
      "python-img2pdf fails to build in rawhide: 48 AssertionErrors"
    ]
  },
  "python-iniparse": {
    "urls": [
      "https://bugzilla.redhat.com/show_bug.cgi?id=2323164"
    ],
    "summaries": [
      "python-iniparse fails to build with Python 3.14: _pickle.PicklingError: Can't pickle local object <function TestIni.test_queue.<locals>.getxy at 0x7f86659a7740>"
    ]
  },
  "python-inject": {
    "urls": [
      "https://bugzilla.redhat.com/show_bug.cgi?id=2327978"
    ],
    "summaries": [
      "python-inject fails to build with Python 3.14: RuntimeError: There is no current event loop in thread 'MainThread'."
    ]
  },
  "python-injector": {
    "urls": [
      "https://bugzilla.redhat.com/show_bug.cgi?id=2341165"
    ],
    "summaries": [
      "python-injector: FTBFS in Fedora rawhide/f42"
    ]
  },
  "python-irc": {
    "urls": [
      "https://bugzilla.redhat.com/show_bug.cgi?id=2327991"
    ],
    "summaries": [
      "python-irc fails to build with Python 3.14: RuntimeError: There is no current event loop in thread 'MainThread'."
    ]
  },
  "python-janus": {
    "urls": [],
    "summaries": []
  },
  "python-jeepney": {
    "urls": [
      "https://bugzilla.redhat.com/show_bug.cgi?id=2327982"
    ],
    "summaries": [
      "python-jeepney fails to build with Python 3.14: RuntimeError: There is no current event loop in thread 'MainThread'."
    ]
  },
  "python-jiter": {
    "urls": [],
    "summaries": []
  },
  "python-joblib": {
    "urls": [
      "https://bugzilla.redhat.com/show_bug.cgi?id=2339519"
    ],
    "summaries": [
      "python-joblib fails to build with Python 3.14: TypeError: Hasher._batch_setitems() takes 2 positional arguments but 3 were given"
    ]
  },
  "python-josepy": {
    "urls": [
      "https://bugzilla.redhat.com/show_bug.cgi?id=2342557",
      "https://bugzilla.redhat.com/show_bug.cgi?id=2323171"
    ],
    "summaries": [
      "python-josepy fails to build with Python 3.14: 7 tests fail with ValueError: Field `alg` in JSONObject `Header` has no type annotation.",
      "python-josepy fails to build with Python 3.14: 6x ValueError: Field `alg` in JSONObject `Header` has no type annotation."
    ]
  },
  "python-jupyter-events": {
    "urls": [],
    "summaries": []
  },
  "python-klusta": {
    "urls": [
      "https://bugzilla.redhat.com/show_bug.cgi?id=2345531"
    ],
    "summaries": [
      "python-klusta fails to build with Python 3.14: help2man: can't get `--help' info from /builddir/build/BUILD/python-klusta-3.0.16-build/BUILDROOT/usr/bin/klusta"
    ]
  },
  "python-makefun": {
    "urls": [
      "https://bugzilla.redhat.com/show_bug.cgi?id=2328706"
    ],
    "summaries": [
      "python-makefun fails to build with Python 3.14: RuntimeError: There is no current event loop in thread 'MainThread'."
    ]
  },
  "python-matplotlib": {
    "urls": [
      "https://bugzilla.redhat.com/show_bug.cgi?id=2328713"
    ],
    "summaries": [
      "python-matplotlib fails to build with Python 3.14: RecursionError: maximum recursion depth exceeded"
    ]
  },
  "python-mccabe": {
    "urls": [
      "https://bugzilla.redhat.com/show_bug.cgi?id=2328016"
    ],
    "summaries": [
      "python-mccabe fails to build with Python 3.14: AttributeError: module 'typing' has no attribute 'ByteString'"
    ]
  },
  "python-meshio": {
    "urls": [
      "https://bugzilla.redhat.com/show_bug.cgi?id=2333493"
    ],
    "summaries": [
      "python-meshio: FTBFS in Fedora Rawhide"
    ]
  },
  "python-metakernel": {
    "urls": [],
    "summaries": []
  },
  "python-mkapi": {
    "urls": [
      "https://bugzilla.redhat.com/show_bug.cgi?id=2342559"
    ],
    "summaries": [
      "python-mkapi fails to build with Python 3.14: Expected: [None, <ast.Constant object at 0x...>, <ast.Constant object at 0x...>] Got: [None, Constant(value=2, kind=None), Constant(value=3, kind=None)]"
    ]
  },
  "python-msal": {
    "urls": [
      "https://bugzilla.redhat.com/show_bug.cgi?id=2323170"
    ],
    "summaries": [
      "python-msal fails to build with Python 3.14: test_no_two_concurrent_receivers_can_listen_on_same_port: AssertionError: OSError not raised"
    ]
  },
  "python-neurotune": {
    "urls": [
      "https://bugzilla.redhat.com/show_bug.cgi?id=2341173"
    ],
    "summaries": [
      "python-neurotune: FTBFS in Fedora rawhide/f42"
    ]
  },
  "python-nine": {
    "urls": [
      "https://bugzilla.redhat.com/show_bug.cgi?id=2343977"
    ],
    "summaries": [
      "python-nine fails to build with Python 3.14: AttributeError: module 'urllib.request' has no attribute 'URLopener'"
    ]
  },
  "python-nixio": {
    "urls": [],
    "summaries": []
  },
  "python-nose": {
    "urls": [
      "https://bugzilla.redhat.com/show_bug.cgi?id=2323163"
    ],
    "summaries": [
      "python-nose fails to build with Python 3.14: multiple AssertionErrors related to timeouts in test outputs"
    ]
  },
  "python-notify2": {
    "urls": [
      "https://bugzilla.redhat.com/show_bug.cgi?id=2341175"
    ],
    "summaries": [
      "python-notify2: FTBFS in Fedora rawhide/f42"
    ]
  },
  "python-opytimark": {
    "urls": [],
    "summaries": []
  },
  "python-orjson": {
    "urls": [],
    "summaries": []
  },
  "python-packvers": {
    "urls": [
      "https://bugzilla.redhat.com/show_bug.cgi?id=2341178"
    ],
    "summaries": [
      "python-packvers: FTBFS in Fedora rawhide/f42"
    ]
  },
  "python-pandas": {
    "urls": [
      "https://bugzilla.redhat.com/show_bug.cgi?id=2341179"
    ],
    "summaries": [
      "python-pandas: FTBFS in Fedora rawhide/f42"
    ]
  },
  "python-pexpect": {
    "urls": [
      "https://bugzilla.redhat.com/show_bug.cgi?id=2341180"
    ],
    "summaries": [
      "python-pexpect: FTBFS in Fedora rawhide/f42"
    ]
  },
  "python-pip": {
    "urls": [
      "https://bugzilla.redhat.com/show_bug.cgi?id=2335909"
    ],
    "summaries": [
      "python-pip fails to build with Python 3.14: AssertionError: assert 'file:/tmp/file' == 'file:///tmp/file'"
    ]
  },
  "python-praw": {
    "urls": [
      "https://bugzilla.redhat.com/show_bug.cgi?id=2342562"
    ],
    "summaries": [
      "python-praw fails to build with Python 3.14: RuntimeError: There is no current event loop in thread 'MainThread'."
    ]
  },
  "python-priority": {
    "urls": [
      "https://bugzilla.redhat.com/show_bug.cgi?id=2341182"
    ],
    "summaries": [
      "python-priority: FTBFS in Fedora rawhide/f42"
    ]
  },
  "python-pure-protobuf": {
    "urls": [
      "https://bugzilla.redhat.com/show_bug.cgi?id=2322710"
    ],
    "summaries": [
      "python-pure-protobuf fails to build with Python 3.14: ImportError: cannot import name 'ByteString' from 'typing'"
    ]
  },
  "python-pyahocorasick": {
    "urls": [
      "https://bugzilla.redhat.com/show_bug.cgi?id=2341183"
    ],
    "summaries": [
      "python-pyahocorasick: FTBFS in Fedora rawhide/f42"
    ]
  },
  "python-pycec": {
    "urls": [
      "https://bugzilla.redhat.com/show_bug.cgi?id=2327973"
    ],
    "summaries": [
      "python-pycec fails to build with Python 3.14: RuntimeError: There is no current event loop in thread 'MainThread'."
    ]
  },
  "python-pydantic-core": {
    "urls": [
      "https://bugzilla.redhat.com/show_bug.cgi?id=2325425"
    ],
    "summaries": [
      "python-pydantic-core fails to build with Python 3.14: AssertionError: Regex pattern did not match. + AttributeError: module 'typing' has no attribute 'ByteString'"
    ]
  },
  "python-pyemd": {
    "urls": [
      "https://bugzilla.redhat.com/show_bug.cgi?id=2319698"
    ],
    "summaries": [
      "python-pyemd fails to build with setuptools 74+"
    ]
  },
  "python-pyface": {
    "urls": [],
    "summaries": []
  },
  "python-pymapvbvd": {
    "urls": [],
    "summaries": []
  },
  "python-pymatreader": {
    "urls": [],
    "summaries": []
  },
  "python-pymdown-extensions": {
    "urls": [
      "https://bugzilla.redhat.com/show_bug.cgi?id=2336948"
    ],
    "summaries": [
      "python-pymdown-extensions fails to build with Python 3.14: TestAbsolute.test_relative_path and TestAbsoluteFileScheme.test_relative_path AssertionErrors"
    ]
  },
  "python-pymeeus": {
    "urls": [
      "https://bugzilla.redhat.com/show_bug.cgi?id=2341186"
    ],
    "summaries": [
      "python-pymeeus: FTBFS in Fedora rawhide/f42"
    ]
  },
  "python-pymilter": {
    "urls": [
      "https://bugzilla.redhat.com/show_bug.cgi?id=2341187"
    ],
    "summaries": [
      "python-pymilter: FTBFS in Fedora rawhide/f42"
    ]
  },
  "python-pymssql": {
    "urls": [],
    "summaries": []
  },
  "python-pyopencl": {
    "urls": [
      "https://bugzilla.redhat.com/show_bug.cgi?id=2341190"
    ],
    "summaries": [
      "python-pyopencl: FTBFS in Fedora rawhide/f42"
    ]
  },
  "python-pyopengl": {
    "urls": [
      "https://bugzilla.redhat.com/show_bug.cgi?id=2341191"
    ],
    "summaries": [
      "python-pyopengl: FTBFS in Fedora rawhide/f42"
    ]
  },
  "python-pyqt6": {
    "urls": [
      "https://bugzilla.redhat.com/show_bug.cgi?id=2345504"
    ],
    "summaries": [
      "python-pyqt6 fails to build with Python 3.14: error: \u2018PySequence_Fast\u2019 was not declared in this scope; did you mean \u2018PySequence_List\u2019?"
    ]
  },
  "python-pyqt6-charts": {
    "urls": [],
    "summaries": []
  },
  "python-pyqt6-webengine": {
    "urls": [],
    "summaries": []
  },
  "python-pyqtgraph": {
    "urls": [],
    "summaries": []
  },
  "python-pysdl2": {
    "urls": [
      "https://bugzilla.redhat.com/show_bug.cgi?id=2339020"
    ],
    "summaries": [
      "python-pysdl2: FTBFS in Fedora Rawhide"
    ]
  },
  "python-pyside6": {
    "urls": [
      "https://bugzilla.redhat.com/show_bug.cgi?id=2325444"
    ],
    "summaries": [
      "python-pyside6 fails to build with Python 3.14: TypeError: Formatter.formatannotation() got an unexpected keyword argument 'quote_annotation_strings'"
    ]
  },
  "python-pytesseract": {
    "urls": [
      "https://bugzilla.redhat.com/show_bug.cgi?id=2341201"
    ],
    "summaries": [
      "python-pytesseract: FTBFS in Fedora rawhide/f42"
    ]
  },
  "python-pytest-aiohttp": {
    "urls": [
      "https://bugzilla.redhat.com/show_bug.cgi?id=2339466"
    ],
    "summaries": [
      "python-pytest-aiohttp fails to build with Python 3.14: DeprecationWarning: 'asyncio.get_event_loop_policy' is deprecated and slated for removal in Python 3.16"
    ]
  },
  "python-pytest-lsp": {
    "urls": [],
    "summaries": []
  },
  "python-pyupgrade": {
    "urls": [
      "https://bugzilla.redhat.com/show_bug.cgi?id=2322713"
    ],
    "summaries": [
      "python-pyupgrade fails to build with Python 3.14: AttributeError: module 'ast' has no attribute 'Str'"
    ]
  },
  "python-pyvlx": {
    "urls": [
      "https://bugzilla.redhat.com/show_bug.cgi?id=2327983"
    ],
    "summaries": [
      "python-pyvlx fails to build with Python 3.14: RuntimeError: There is no current event loop in thread 'MainThread'."
    ]
  },
  "python-qcustomplot-pyqt": {
    "urls": [],
    "summaries": []
  },
  "python-qt5": {
    "urls": [
      "https://bugzilla.redhat.com/show_bug.cgi?id=2345529"
    ],
    "summaries": [
      "python-qt5 fails to build with Python 3.14: error: \u2018PySequence_Fast\u2019 was not declared in this scope; did you mean \u2018PySequence_List\u2019"
    ]
  },
  "python-rdflib": {
    "urls": [
      "https://bugzilla.redhat.com/show_bug.cgi?id=2343978",
      "https://bugzilla.redhat.com/show_bug.cgi?id=2336891"
    ],
    "summaries": [
      "python-rdflib fails to build with Python 3.14: AttributeError: term 'value' not in namespace 'http://www.w3.org/1999/02/22-rdf-syntax-ns#'",
      "python-rdflib fails to build with Python 3.14: \"TypeError: '<' not supported between instances of 'Literal' and 'Literal'\""
    ]
  },
  "python-reactivex": {
    "urls": [
      "https://bugzilla.redhat.com/show_bug.cgi?id=2327987"
    ],
    "summaries": [
      "python-reactivex fails to build with Python 3.14: RuntimeError: There is no current event loop in thread 'MainThread'."
    ]
  },
  "python-readability-lxml": {
    "urls": [
      "https://bugzilla.redhat.com/show_bug.cgi?id=2323185"
    ],
    "summaries": [
      "python-readability-lxml fails to build with Python 3.14: _pickle.PicklingError: Can't pickle <function TestArticleOnly.test_many_repeated_spaces at 0x7ff0ea064460>: it's not the same object as tests.test_article_only.TestArticleOnly.test_many_repeated_spa"
    ]
  },
  "python-recordclass": {
    "urls": [
      "https://bugzilla.redhat.com/show_bug.cgi?id=2327968"
    ],
    "summaries": [
      "python-recordclass fails to build with Python 3.14: 25 failures, 65 errors in the test suite"
    ]
  },
  "python-redis": {
    "urls": [
      "https://bugzilla.redhat.com/show_bug.cgi?id=2345526",
      "https://bugzilla.redhat.com/show_bug.cgi?id=2326927"
    ],
    "summaries": [
      "python-redis fails to build with Python 3.14: _pickle.PicklingError: Can't pickle local object <function TestMultiprocessing.test_close_connection_in_child.<locals>.target at 0x7f10027f31c0>",
      "python-redis fails to build with Python 3.14: _pickle.PicklingError: Can't pickle local object <function TestMultiprocessing.test_redis_client.<locals>.target at 0x7fd5f829efb0>"
    ]
  },
  "python-remoto": {
    "urls": [
      "https://bugzilla.redhat.com/show_bug.cgi?id=2341205"
    ],
    "summaries": [
      "python-remoto: FTBFS in Fedora rawhide/f42"
    ]
  },
  "python-respx": {
    "urls": [],
    "summaries": []
  },
  "python-rich": {
    "urls": [
      "https://bugzilla.redhat.com/show_bug.cgi?id=2339510"
    ],
    "summaries": [
      "python-rich fails to build with Python 3.14: 5 test fail"
    ]
  },
  "python-rosdep": {
    "urls": [
      "https://bugzilla.redhat.com/show_bug.cgi?id=2341207"
    ],
    "summaries": [
      "python-rosdep: FTBFS in Fedora rawhide/f42"
    ]
  },
  "python-rq": {
    "urls": [
      "https://bugzilla.redhat.com/show_bug.cgi?id=2342234"
    ],
    "summaries": [
      "python-rq fails to build with Python 3.14: test_worker.py::HerokuWorkerShutdownTestCase::test_handle_shutdown_request shuts down the whole build"
    ]
  },
  "python-rstcheck": {
    "urls": [
      "https://bugzilla.redhat.com/show_bug.cgi?id=2322705"
    ],
    "summaries": [
      "python-rstcheck fails to build with Python 3.14: AttributeError: 'Constant' object has no attribute 's'"
    ]
  },
  "python-rx": {
    "urls": [
      "https://bugzilla.redhat.com/show_bug.cgi?id=2327979"
    ],
    "summaries": [
      "python-rx fails to build with Python 3.14: RuntimeError: There is no current event loop in thread 'MainThread'."
    ]
  },
  "python-s3transfer": {
    "urls": [
      "https://bugzilla.redhat.com/show_bug.cgi?id=2326933"
    ],
    "summaries": [
      "python-s3transfer fails to build with Python 3.14: _pickle.PicklingError: Can't pickle local object <class 'tests.unit.test_compat.TestBaseManager.create_pid_manager.<locals>.PIDManager'>"
    ]
  },
  "python-serpy": {
    "urls": [
      "https://bugzilla.redhat.com/show_bug.cgi?id=2319716"
    ],
    "summaries": [
      "python-serpy fails to build with setuptools 74+"
    ]
  },
  "python-setproctitle": {
    "urls": [
      "https://bugzilla.redhat.com/show_bug.cgi?id=2341212"
    ],
    "summaries": [
      "python-setproctitle: FTBFS in Fedora rawhide/f42"
    ]
  },
  "python-social-auth-core": {
    "urls": [
      "https://bugzilla.redhat.com/show_bug.cgi?id=2341215",
      "https://bugzilla.redhat.com/show_bug.cgi?id=2328010"
    ],
    "summaries": [
      "python-social-auth-core: FTBFS in Fedora rawhide/f42",
      "python-social-auth-core fails to build with Python 3.14: 'SSLContext' object has no attribute 'close'"
    ]
  },
  "python-sqlalchemy1.4": {
    "urls": [
      "https://bugzilla.redhat.com/show_bug.cgi?id=2327976"
    ],
    "summaries": [
      "python-sqlalchemy1.4 fails to build with Python 3.14: RuntimeError: There is no current event loop in thread 'MainThread'."
    ]
  },
  "python-stack-data": {
    "urls": [
      "https://bugzilla.redhat.com/show_bug.cgi?id=2345532"
    ],
    "summaries": [
      "python-stack-data fails to build with Python 3.14: test_example: IndexError: list index out of range"
    ]
  },
  "python-starlette": {
    "urls": [],
    "summaries": []
  },
  "python-stdlibs": {
    "urls": [
      "https://bugzilla.redhat.com/show_bug.cgi?id=2336938"
    ],
    "summaries": [
      "python-stdlibs fails to build with Python 3.14: test_all_my_modules_are_there: AssertionError: Items in the second set but not the first: '_apple_support'"
    ]
  },
  "python-steam": {
    "urls": [
      "https://bugzilla.redhat.com/show_bug.cgi?id=2341218"
    ],
    "summaries": [
      "python-steam: FTBFS in Fedora rawhide/f42"
    ]
  },
  "python-stochastic": {
    "urls": [
      "https://bugzilla.redhat.com/show_bug.cgi?id=2341219"
    ],
    "summaries": [
      "python-stochastic: FTBFS in Fedora rawhide/f42"
    ]
  },
  "python-svg2tikz": {
    "urls": [
      "https://bugzilla.redhat.com/show_bug.cgi?id=2341220"
    ],
    "summaries": [
      "python-svg2tikz: FTBFS in Fedora rawhide/f42"
    ]
  },
  "python-tenacity": {
    "urls": [
      "https://bugzilla.redhat.com/show_bug.cgi?id=2327977"
    ],
    "summaries": [
      "python-tenacity fails to build with Python 3.14: RuntimeError: There is no current event loop in thread 'MainThread'."
    ]
  },
  "python-terminado": {
    "urls": [
      "https://bugzilla.redhat.com/show_bug.cgi?id=2345527"
    ],
    "summaries": [
      "python-terminado fails to build with Python 3.14: DeprecationWarning: 'asyncio.DefaultEventLoopPolicy' is deprecated and slated for removal in Python 3.16"
    ]
  },
  "python-textual": {
    "urls": [
      "https://bugzilla.redhat.com/show_bug.cgi?id=2341224"
    ],
    "summaries": [
      "python-textual: FTBFS in Fedora rawhide/f42"
    ]
  },
  "python-toolz": {
    "urls": [
      "https://bugzilla.redhat.com/show_bug.cgi?id=2323168"
    ],
    "summaries": [
      "python-toolz fails to build with Python 3.14: AssertionError: is_none: assert should_curry(getattr(operator, k)) == isinstance(v, toolz.curry), k"
    ]
  },
  "python-tornado": {
    "urls": [
      "https://bugzilla.redhat.com/show_bug.cgi?id=2327969"
    ],
    "summaries": [
      "python-tornado fails to build with Python 3.14: RuntimeError: There is no current event loop in thread 'MainThread'."
    ]
  },
  "python-traitsui": {
    "urls": [],
    "summaries": []
  },
  "python-tree-format": {
    "urls": [
      "https://bugzilla.redhat.com/show_bug.cgi?id=2319731"
    ],
    "summaries": [
      "python-tree-format fails to build with setuptools 74+"
    ]
  },
  "python-trio": {
    "urls": [
      "https://bugzilla.redhat.com/show_bug.cgi?id=2345516"
    ],
    "summaries": [
      "python-trio fails to build with Python 3.14: test_ki_protection_doesnt_leave_cyclic_garbage: Left contains one more item: <coroutine object test_ki_protection_doesnt_leave_cyclic_garbage at 0x7fbaa2f162c0>"
    ]
  },
  "python-twisted": {
    "urls": [
      "https://bugzilla.redhat.com/show_bug.cgi?id=2342754"
    ],
    "summaries": [
      "python-twisted fails to build with Python 3.14: RuntimeError: There is no current event loop in thread 'MainThread'. + more"
    ]
  },
  "python-txaio": {
    "urls": [
      "https://bugzilla.redhat.com/show_bug.cgi?id=2327981"
    ],
    "summaries": [
      "python-txaio fails to build with Python 3.14: RuntimeError: There is no current event loop in thread 'MainThread'."
    ]
  },
  "python-typeguard": {
    "urls": [],
    "summaries": []
  },
  "python-typing-extensions": {
    "urls": [
      "https://bugzilla.redhat.com/show_bug.cgi?id=2336937"
    ],
    "summaries": [
      "python-typing-extensions fails to build with Python 3.14: test_drop_in_for_typing: AssertionError: self.assertGreaterEqual(te_all, t_all - exceptions)"
    ]
  },
  "python-typing-inspect": {
    "urls": [
      "https://bugzilla.redhat.com/show_bug.cgi?id=2325455"
    ],
    "summaries": [
      "python-typing-inspect fails to build with Python 3.14: AssertionError: {} != {'x': <class 'int'>, 'y': <class 'int'>}"
    ]
  },
  "python-ufoLib2": {
    "urls": [],
    "summaries": []
  },
  "python-urwid": {
    "urls": [
      "https://bugzilla.redhat.com/show_bug.cgi?id=2327984"
    ],
    "summaries": [
      "python-urwid fails to build with Python 3.14: RuntimeError: There is no current event loop in thread 'MainThread'."
    ]
  },
  "python-uvloop": {
    "urls": [
      "https://bugzilla.redhat.com/show_bug.cgi?id=2341233",
      "https://bugzilla.redhat.com/show_bug.cgi?id=2326210"
    ],
    "summaries": [
      "python-uvloop: FTBFS in Fedora rawhide/f42",
      "python-uvloop fails to build with Python 3.14: AttributeError: module 'asyncio' has no attribute 'AbstractChildWatcher'"
    ]
  },
  "python-valkey": {
    "urls": [
      "https://bugzilla.redhat.com/show_bug.cgi?id=2326934"
    ],
    "summaries": [
      "python-valkey fails to build with Python 3.14: _pickle.PicklingError: Can't pickle local object <function TestMultiprocessing.test_close_connection_in_child.<locals>.target at 0x7f7d711b5dd0>"
    ]
  },
  "python-watchfiles": {
    "urls": [
      "https://bugzilla.redhat.com/show_bug.cgi?id=2339462"
    ],
    "summaries": [
      "python-watchfiles fails to build with Python 3.14: DeprecationWarning: 'asyncio.set_event_loop' is deprecated and slated for removal in Python 3.16"
    ]
  },
  "python-webscrapbook": {
    "urls": [
      "https://bugzilla.redhat.com/show_bug.cgi?id=2341237",
      "https://bugzilla.redhat.com/show_bug.cgi?id=2326915"
    ],
    "summaries": [
      "python-webscrapbook: FTBFS in Fedora rawhide/f42",
      "python-webscrapbook fails to build with Python 3.14: 60x AssertionError in the test suite"
    ]
  },
  "python-wordcloud": {
    "urls": [
      "https://bugzilla.redhat.com/show_bug.cgi?id=2335908"
    ],
    "summaries": [
      "python-wordcloud fails to build with Python 3.14: test_cli_as_executable: AssertionError: assert expected_output in out if ret_code == 0 else err"
    ]
  },
  "python-xnat": {
    "urls": [],
    "summaries": []
  },
  "python-xunitparser": {
    "urls": [
      "https://bugzilla.redhat.com/show_bug.cgi?id=2319738"
    ],
    "summaries": [
      "python-xunitparser fails to build with setuptools 74+"
    ]
  },
  "python-yappi": {
    "urls": [
      "https://bugzilla.redhat.com/show_bug.cgi?id=2323160"
    ],
    "summaries": [
      "python-yappi fails to build with Python 3.14: error: invalid use of incomplete typedef \u2018PyGenObject\u2019 {aka \u2018struct _PyGenObject\u2019}"
    ]
  },
  "python-zope-deprecation": {
    "urls": [],
    "summaries": []
  },
  "python-zope-exceptions": {
    "urls": [
      "https://bugzilla.redhat.com/show_bug.cgi?id=2341240"
    ],
    "summaries": [
      "python-zope-exceptions: FTBFS in Fedora rawhide/f42"
    ]
  },
  "python-zope-i18nmessageid": {
    "urls": [
      "https://bugzilla.redhat.com/show_bug.cgi?id=2341241"
    ],
    "summaries": [
      "python-zope-i18nmessageid: FTBFS in Fedora rawhide/f42"
    ]
  },
  "python-zope-testing": {
    "urls": [
      "https://bugzilla.redhat.com/show_bug.cgi?id=2341242"
    ],
    "summaries": [
      "python-zope-testing: FTBFS in Fedora rawhide/f42"
    ]
  },
  "python-zope-testrunner": {
    "urls": [
      "https://bugzilla.redhat.com/show_bug.cgi?id=2335907"
    ],
    "summaries": [
      "python-zope-testrunner fails to build with Python 3.14: difference in the asserted content in testrunner-edge-cases.rst"
    ]
  },
  "python-zstandard": {
    "urls": [
      "https://bugzilla.redhat.com/show_bug.cgi?id=2326925"
    ],
    "summaries": [
      "python-zstandard fails to build with Python 3.14: ImportError: cannot import name 'ByteString' from 'typing'"
    ]
  },
  "pythran": {
    "urls": [
      "https://bugzilla.redhat.com/show_bug.cgi?id=2341244"
    ],
    "summaries": [
      "pythran: FTBFS in Fedora rawhide/f42"
    ]
  },
  "qscintilla": {
    "urls": [],
    "summaries": []
  },
  "qtile": {
    "urls": [
      "https://bugzilla.redhat.com/show_bug.cgi?id=2328711"
    ],
    "summaries": [
      "qtile fails to build with Python 3.14: _pickle.PicklingError: Can't pickle local object <function TestManager.start.<locals>.run_qtile at 0x7f9c5918fed0>"
    ]
  },
  "recoll": {
    "urls": [
      "https://bugzilla.redhat.com/show_bug.cgi?id=2341273"
    ],
    "summaries": [
      "recoll: FTBFS in Fedora rawhide/f42"
    ]
  },
  "remmina": {
    "urls": [
      "https://bugzilla.redhat.com/show_bug.cgi?id=2341277"
    ],
    "summaries": [
      "remmina: FTBFS in Fedora rawhide/f42"
    ]
  },
  "renderdoc": {
    "urls": [
      "https://bugzilla.redhat.com/show_bug.cgi?id=2341279"
    ],
    "summaries": [
      "renderdoc: FTBFS in Fedora rawhide/f42"
    ]
  },
  "retext": {
    "urls": [],
    "summaries": []
  },
  "rrdtool": {
    "urls": [],
    "summaries": []
  },
  "satyr": {
    "urls": [
      "https://bugzilla.redhat.com/show_bug.cgi?id=2325452"
    ],
    "summaries": [
      "satyr fails to build with Python 3.14: _pickle.PicklingError: Can't pickle local object <function TestDistances.test_distances_part_parallel.<locals>.do_test.<locals>.compute_part at 0x7f7f845f2560>"
    ]
  },
  "signon-glib": {
    "urls": [
      "https://bugzilla.redhat.com/show_bug.cgi?id=2341348"
    ],
    "summaries": [
      "signon-glib: FTBFS in Fedora rawhide/f42"
    ]
  },
  "strongswan": {
    "urls": [
      "https://bugzilla.redhat.com/show_bug.cgi?id=2332864"
    ],
    "summaries": [
      "strongswan-5.9.14-5.fc42 FTBFS: strongswan-5.9.14/missing: line 81: aclocal-1.16: command not found"
    ]
  },
  "sudo": {
    "urls": [
      "https://bugzilla.redhat.com/show_bug.cgi?id=2341397"
    ],
    "summaries": [
      "sudo: FTBFS in Fedora rawhide/f42"
    ]
  },
  "syslog-ng": {
    "urls": [],
    "summaries": []
  },
  "tcl-snack": {
    "urls": [
      "https://bugzilla.redhat.com/show_bug.cgi?id=2341418"
    ],
    "summaries": [
      "tcl-snack: FTBFS in Fedora rawhide/f42"
    ]
  },
  "thrift": {
    "urls": [
      "https://bugzilla.redhat.com/show_bug.cgi?id=2341433"
    ],
    "summaries": [
      "thrift: FTBFS in Fedora rawhide/f42"
    ]
  },
  "tiled": {
    "urls": [],
    "summaries": []
  },
  "tortoisehg": {
    "urls": [],
    "summaries": []
  },
  "ufw": {
    "urls": [
      "https://bugzilla.redhat.com/show_bug.cgi?id=2341477"
    ],
    "summaries": [
      "ufw: FTBFS in Fedora rawhide/f42"
    ]
  },
  "uhd": {
    "urls": [
      "https://bugzilla.redhat.com/show_bug.cgi?id=2341478"
    ],
    "summaries": [
      "uhd: FTBFS in Fedora rawhide/f42"
    ]
  },
  "vdr-epg-daemon": {
    "urls": [],
    "summaries": []
  },
  "veusz": {
    "urls": [],
    "summaries": []
  },
  "visidata": {
    "urls": [
      "https://bugzilla.redhat.com/show_bug.cgi?id=2325446"
    ],
    "summaries": [
      "visidata fails to build with Python 3.14: TestVisidataPath.test_withName: AssertionError: assert 'foo' == 'foo.'"
    ]
  },
  "vorta": {
    "urls": [],
    "summaries": []
  },
  "weasyprint": {
    "urls": [],
    "summaries": []
  },
  "xapian-bindings": {
    "urls": [],
    "summaries": []
  },
  "xonsh": {
    "urls": [
      "https://bugzilla.redhat.com/show_bug.cgi?id=2336895"
    ],
    "summaries": [
      "xonsh fails to build with Python 3.14: ValueError: action 'store_true' is not valid for positional arguments"
    ]
  },
  "xpra": {
    "urls": [],
    "summaries": []
  },
  "yt-dlp": {
    "urls": [
      "https://bugzilla.redhat.com/show_bug.cgi?id=2345522"
    ],
    "summaries": [
      "yt-dlp fails to build with Python 3.14: TestTraversal.test_traversal_morsel: AssertionError: `...` should yield all values: Left contains one more item: 'item_value'"
    ]
  },
  "zeek": {
    "urls": [
      "https://bugzilla.redhat.com/show_bug.cgi?id=2341601"
    ],
    "summaries": [
      "zeek: FTBFS in Fedora rawhide/f42"
    ]
  }
}