{
  "Mayavi": {
    "urls": [
      "https://bugzilla.redhat.com/show_bug.cgi?id=2351390"
    ],
    "summaries": [
      "Mayavi fails to build with Python 3.14: TestMayaviGarbageCollection.test_mlab_scene_model_with_gui: IndexError: list index out of range"
    ]
  },
  "NiaAML-GUI": {
    "urls": [],
    "summaries": []
  },
  "PyGreSQL": {
    "urls": [],
    "summaries": []
  },
  "PyMca": {
    "urls": [],
    "summaries": []
  },
  "PyX": {
    "urls": [],
    "summaries": []
  },
  "alot": {
    "urls": [],
    "summaries": []
  },
  "ansible": {
    "urls": [],
    "summaries": []
  },
  "ansible-builder": {
    "urls": [],
    "summaries": []
  },
  "ansible-core": {
    "urls": [],
    "summaries": []
  },
  "arbor": {
    "urls": [],
    "summaries": []
  },
  "asv": {
    "urls": [
      "https://bugzilla.redhat.com/show_bug.cgi?id=2339908"
    ],
    "summaries": [
      "asv: FTBFS in Fedora rawhide/f42"
    ]
  },
  "avogadro2-libs": {
    "urls": [],
    "summaries": []
  },
  "awscli2": {
    "urls": [],
    "summaries": []
  },
  "babel": {
    "urls": [],
    "summaries": []
  },
  "bandit": {
    "urls": [
      "https://bugzilla.redhat.com/show_bug.cgi?id=2351393"
    ],
    "summaries": [
      "bandit fails to build with Python 3.14: TypeError: Error: Str is not a valid node type in AST"
    ]
  },
  "beaker": {
    "urls": [],
    "summaries": []
  },
  "beets": {
    "urls": [],
    "summaries": []
  },
  "bids-schema": {
    "urls": [],
    "summaries": []
  },
  "binwalk": {
    "urls": [
      "https://bugzilla.redhat.com/show_bug.cgi?id=2336914"
    ],
    "summaries": [
      "binwalk fails to build with Python 3.14: TypeError: unsupported operand type(s) for +=: 'NoneType' and 'int'"
    ]
  },
  "bluechi": {
    "urls": [],
    "summaries": []
  },
  "boom-boot": {
    "urls": [],
    "summaries": []
  },
  "borgbackup": {
    "urls": [
      "https://bugzilla.redhat.com/show_bug.cgi?id=2326916"
    ],
    "summaries": [
      "borgbackup fails to build with Python 3.14: OSError: AF_UNIX path too long when compiling"
    ]
  },
  "borgmatic": {
    "urls": [],
    "summaries": []
  },
  "botan": {
    "urls": [],
    "summaries": []
  },
  "botan2": {
    "urls": [],
    "summaries": []
  },
  "breezy": {
    "urls": [],
    "summaries": []
  },
  "calibre": {
    "urls": [],
    "summaries": []
  },
  "cantor": {
    "urls": [],
    "summaries": []
  },
  "capstone": {
    "urls": [
      "https://bugzilla.redhat.com/show_bug.cgi?id=2345714"
    ],
    "summaries": [
      "capstone fails to build with Python 3.14: from capstone import *: ImportError: ERROR: fail to load the dynamic library"
    ]
  },
  "ceph": {
    "urls": [
      "https://bugzilla.redhat.com/show_bug.cgi?id=2336913"
    ],
    "summaries": [
      "ceph fails to build with Python 3.14: AttributeError: module 'pkgutil' has no attribute 'find_loader'"
    ]
  },
  "cffconvert": {
    "urls": [],
    "summaries": []
  },
  "chirp": {
    "urls": [
      "https://bugzilla.redhat.com/show_bug.cgi?id=2361634"
    ],
    "summaries": [
      "chirp FTBFS in rawhide"
    ]
  },
  "cjdns": {
    "urls": [
      "https://bugzilla.redhat.com/show_bug.cgi?id=2339969"
    ],
    "summaries": [
      "cjdns: FTBFS in Fedora rawhide/f42"
    ]
  },
  "claws-mail": {
    "urls": [],
    "summaries": []
  },
  "cloud-init": {
    "urls": [],
    "summaries": []
  },
  "cmake": {
    "urls": [],
    "summaries": []
  },
  "colin": {
    "urls": [],
    "summaries": []
  },
  "conda": {
    "urls": [
      "https://bugzilla.redhat.com/show_bug.cgi?id=2356170"
    ],
    "summaries": [
      "conda fails to build with Python 3.14: tests/test_shell.py: TypeError: 'str' object cannot be interpreted as an integer"
    ]
  },
  "conda-build": {
    "urls": [
      "https://bugzilla.redhat.com/show_bug.cgi?id=2356162"
    ],
    "summaries": [
      "conda-build fails to build with Python 3.14: TypeError: _WorkItem.__init__() takes 3 positional arguments but 5 were given"
    ]
  },
  "conu": {
    "urls": [],
    "summaries": []
  },
  "copr-backend": {
    "urls": [
      "https://bugzilla.redhat.com/show_bug.cgi?id=2351386"
    ],
    "summaries": [
      "copr-backend fails to build with Python 3.14: TestActionWorkerManager.test_add_task_for_running_worker: TypeError: cannot pickle 'itertools.count' object"
    ]
  },
  "cozy": {
    "urls": [],
    "summaries": []
  },
  "credslayer": {
    "urls": [],
    "summaries": []
  },
  "criu": {
    "urls": [
      "https://bugzilla.redhat.com/show_bug.cgi?id=2365821"
    ],
    "summaries": [
      "criu fails to build with Python 3.14: protobuf - TypeError: Metaclasses with custom tp_new are not supported."
    ]
  },
  "cvc5": {
    "urls": [],
    "summaries": []
  },
  "dftd4": {
    "urls": [],
    "summaries": []
  },
  "diceware": {
    "urls": [
      "https://bugzilla.redhat.com/show_bug.cgi?id=2340075"
    ],
    "summaries": [
      "diceware: FTBFS in Fedora rawhide/f42"
    ]
  },
  "did": {
    "urls": [
      "https://bugzilla.redhat.com/show_bug.cgi?id=2328006"
    ],
    "summaries": [
      "did fails to build with Python 3.14: AttributeError: module 'urllib.request' has no attribute 'FancyURLopener'"
    ]
  },
  "dionaea": {
    "urls": [
      "https://bugzilla.redhat.com/show_bug.cgi?id=2340077"
    ],
    "summaries": [
      "dionaea: FTBFS in Fedora rawhide/f42"
    ]
  },
  "dlib": {
    "urls": [],
    "summaries": []
  },
  "dogtag-pki": {
    "urls": [],
    "summaries": []
  },
  "dt-schema": {
    "urls": [],
    "summaries": []
  },
  "dxf2gcode": {
    "urls": [],
    "summaries": []
  },
  "electron-cash": {
    "urls": [],
    "summaries": []
  },
  "emacs-jedi": {
    "urls": [],
    "summaries": []
  },
  "enki": {
    "urls": [],
    "summaries": []
  },
  "ephemeral-port-reserve": {
    "urls": [],
    "summaries": []
  },
  "espresso": {
    "urls": [
      "https://bugzilla.redhat.com/show_bug.cgi?id=2340139"
    ],
    "summaries": [
      "espresso: FTBFS in Fedora rawhide/f42"
    ]
  },
  "fedfind": {
    "urls": [],
    "summaries": []
  },
  "fedrq": {
    "urls": [],
    "summaries": []
  },
  "flent": {
    "urls": [],
    "summaries": []
  },
  "fmf": {
    "urls": [],
    "summaries": []
  },
  "fontforge": {
    "urls": [],
    "summaries": []
  },
  "fonttools": {
    "urls": [],
    "summaries": []
  },
  "gcovr": {
    "urls": [],
    "summaries": []
  },
  "gedit": {
    "urls": [],
    "summaries": []
  },
  "geopmd": {
    "urls": [],
    "summaries": []
  },
  "gfal2-python": {
    "urls": [],
    "summaries": []
  },
  "git-cola": {
    "urls": [],
    "summaries": []
  },
  "git-filter-repo": {
    "urls": [
      "https://bugzilla.redhat.com/show_bug.cgi?id=2365637"
    ],
    "summaries": [
      "git-filter-repo fails to build with Python 3.14: == t9394-filter-repo-sanity-checks-and-bigger-repo-setup.sh == --replace-text all options not ok"
    ]
  },
  "gmsh": {
    "urls": [],
    "summaries": []
  },
  "gnofract4d": {
    "urls": [
      "https://bugzilla.redhat.com/show_bug.cgi?id=2339539"
    ],
    "summaries": [
      "gnofract4d fails to build with Python 3.14: AssertionError: 'ct_sin6 = (0.841471,-0)' != 'ct_sin6 = (0.841471,0)'"
    ]
  },
  "gns3-server": {
    "urls": [],
    "summaries": []
  },
  "gom": {
    "urls": [],
    "summaries": []
  },
  "gpaw": {
    "urls": [],
    "summaries": []
  },
  "gplugin": {
    "urls": [],
    "summaries": []
  },
  "h5py": {
    "urls": [
      "https://bugzilla.redhat.com/show_bug.cgi?id=2365887",
      "https://bugzilla.redhat.com/show_bug.cgi?id=2339470"
    ],
    "summaries": [
      "h5py fails to build with Python 3.14: TestFileObj.test_TemporaryFile: ResourceWarning: Implicitly cleaning up <_TemporaryFileWrapper file=<_io.BufferedRandom name='/tmp/tmp86bropaf'>>",
      "h5py fails to build with Python 3.14: ResourceWarning: TestFileObj.test_TemporaryFile: Implicitly cleaning up <_TemporaryFileWrapper file=<_io.BufferedRandom name='/tmp/tmp8pqafmzv'>>"
    ]
  },
  "hokuyoaist": {
    "urls": [],
    "summaries": []
  },
  "home-assistant-cli": {
    "urls": [],
    "summaries": []
  },
  "httpie": {
    "urls": [
      "https://bugzilla.redhat.com/show_bug.cgi?id=2350335"
    ],
    "summaries": [
      "httpie fails to build with Python 3.14: test_lazy_choices_help: AssertionError: Expected 'getter' to not have been called. Called 1 times."
    ]
  },
  "ibus-cangjie": {
    "urls": [],
    "summaries": []
  },
  "ikiwiki": {
    "urls": [
      "https://bugzilla.redhat.com/show_bug.cgi?id=2340642"
    ],
    "summaries": [
      "ikiwiki: FTBFS in Fedora rawhide/f42"
    ]
  },
  "insight": {
    "urls": [],
    "summaries": []
  },
  "intelhex": {
    "urls": [],
    "summaries": []
  },
  "ipa-hcc": {
    "urls": [],
    "summaries": []
  },
  "ipython": {
    "urls": [
      "https://bugzilla.redhat.com/show_bug.cgi?id=2356174"
    ],
    "summaries": [
      "ipython fails to build with Python 3.14: AssertionErrors, pexpect.exceptions.TIMEOUTs and more in 12 tests"
    ]
  },
  "javapackages-tools": {
    "urls": [],
    "summaries": []
  },
  "jrnl": {
    "urls": [],
    "summaries": []
  },
  "jupyterlab": {
    "urls": [],
    "summaries": []
  },
  "kea": {
    "urls": [],
    "summaries": []
  },
  "kernel": {
    "urls": [
      "https://bugzilla.redhat.com/show_bug.cgi?id=2363674",
      "https://bugzilla.redhat.com/show_bug.cgi?id=2340285"
    ],
    "summaries": [
      "Dependency between termios.h and struct termio causes userspace to FTBFS on ppc64le",
      "kernel: FTBFS in Fedora rawhide/f42"
    ]
  },
  "khal": {
    "urls": [],
    "summaries": []
  },
  "kitty": {
    "urls": [],
    "summaries": []
  },
  "kmymoney": {
    "urls": [],
    "summaries": []
  },
  "krita": {
    "urls": [],
    "summaries": []
  },
  "kvirc": {
    "urls": [],
    "summaries": []
  },
  "lammps": {
    "urls": [],
    "summaries": []
  },
  "lasso": {
    "urls": [
      "https://bugzilla.redhat.com/show_bug.cgi?id=2365819"
    ],
    "summaries": [
      "lasso fails to build with Python 3.14: FAIL: binding_tests.py"
    ]
  },
  "lector": {
    "urls": [],
    "summaries": []
  },
  "libcamera": {
    "urls": [],
    "summaries": []
  },
  "libcomps": {
    "urls": [],
    "summaries": []
  },
  "libffado": {
    "urls": [],
    "summaries": []
  },
  "libgit2-glib": {
    "urls": [],
    "summaries": []
  },
  "libiio": {
    "urls": [],
    "summaries": []
  },
  "libnvme": {
    "urls": [],
    "summaries": []
  },
  "libpeas": {
    "urls": [],
    "summaries": []
  },
  "libpeas1": {
    "urls": [],
    "summaries": []
  },
  "librealsense": {
    "urls": [],
    "summaries": []
  },
  "libreoffice": {
    "urls": [],
    "summaries": []
  },
  "libsonata": {
    "urls": [],
    "summaries": []
  },
  "libsvm": {
    "urls": [],
    "summaries": []
  },
  "libvirt-test-API": {
    "urls": [],
    "summaries": []
  },
  "linkchecker": {
    "urls": [],
    "summaries": []
  },
  "liquidctl": {
    "urls": [],
    "summaries": []
  },
  "lutris": {
    "urls": [],
    "summaries": []
  },
  "mercurial": {
    "urls": [
      "https://bugzilla.redhat.com/show_bug.cgi?id=2365820"
    ],
    "summaries": [
      "mercurial fails to build with Python 3.14: AttributeError: partially initialized module 'threading' from '/usr/lib64/python3.14/threading.py' has no attribute 'RLock' (most likely due to a circular import)"
    ]
  },
  "meson": {
    "urls": [],
    "summaries": []
  },
  "micropipenv": {
    "urls": [],
    "summaries": []
  },
  "mkdocs": {
    "urls": [],
    "summaries": []
  },
  "mkdocs-bootstrap": {
    "urls": [],
    "summaries": []
  },
  "mkdocs-bootswatch": {
    "urls": [],
    "summaries": []
  },
  "mkdocs-material": {
    "urls": [],
    "summaries": []
  },
  "mock": {
    "urls": [],
    "summaries": []
  },
  "mod_wsgi": {
    "urls": [],
    "summaries": []
  },
  "mogui": {
    "urls": [],
    "summaries": []
  },
  "monkeytype": {
    "urls": [
      "https://bugzilla.redhat.com/show_bug.cgi?id=2356179"
    ],
    "summaries": [
      "monkeytype fails to build with Python 3.14: typing.Union changed with Python 3.14.0a6"
    ]
  },
  "moose": {
    "urls": [],
    "summaries": []
  },
  "mopidy": {
    "urls": [],
    "summaries": []
  },
  "mopidy-mpd": {
    "urls": [],
    "summaries": []
  },
  "morphio": {
    "urls": [],
    "summaries": []
  },
  "mrchem": {
    "urls": [
      "https://bugzilla.redhat.com/show_bug.cgi?id=2359498"
    ],
    "summaries": [
      "mrchem fails to build with Python 3.14: /builddir/build/BUILD/mrchem-1.1.4-build/mrchem-1.1.4/python/mrchem/input_parser/plumbing/pyparsing/core.py:5332: SyntaxWarning: 'return' in a 'finally' block"
    ]
  },
  "myst-nb": {
    "urls": [],
    "summaries": []
  },
  "nagios-plugins-systemd": {
    "urls": [],
    "summaries": []
  },
  "netcdf4-python": {
    "urls": [],
    "summaries": []
  },
  "nextpnr": {
    "urls": [],
    "summaries": []
  },
  "nfs-ganesha": {
    "urls": [],
    "summaries": []
  },
  "nordugrid-arc-nagios-plugins": {
    "urls": [],
    "summaries": []
  },
  "nox": {
    "urls": [],
    "summaries": []
  },
  "nwchem": {
    "urls": [],
    "summaries": []
  },
  "ocrmypdf": {
    "urls": [
      "https://bugzilla.redhat.com/show_bug.cgi?id=2357508"
    ],
    "summaries": [
      "ocrmypdf fails to build with Python 3.14: multiprocessing.Process now starts with forkserver method instead of fork, causing pickling error"
    ]
  },
  "offlineimap": {
    "urls": [],
    "summaries": []
  },
  "onnx": {
    "urls": [],
    "summaries": []
  },
  "onnxruntime": {
    "urls": [],
    "summaries": []
  },
  "opae": {
    "urls": [],
    "summaries": []
  },
  "openapi-python-client": {
    "urls": [],
    "summaries": []
  },
  "opencv": {
    "urls": [],
    "summaries": []
  },
  "openmeeg": {
    "urls": [
      "https://bugzilla.redhat.com/show_bug.cgi?id=2365873"
    ],
    "summaries": [
      "openmeeg fails to build with Python 3.14: openmeeg/tests/test_python.py: ValueError: operands could not be broadcast together with shapes (20124196,) (0,)"
    ]
  },
  "openmpi": {
    "urls": [],
    "summaries": []
  },
  "openscap-report": {
    "urls": [],
    "summaries": []
  },
  "openshot": {
    "urls": [],
    "summaries": []
  },
  "openvino": {
    "urls": [],
    "summaries": []
  },
  "openvswitch": {
    "urls": [
      "https://bugzilla.redhat.com/show_bug.cgi?id=2340983",
      "https://bugzilla.redhat.com/show_bug.cgi?id=2328018"
    ],
    "summaries": [
      "openvswitch: FTBFS in Fedora rawhide/f42",
      "openvswitch fails to build with Python 3.14: 3 tests failure"
    ]
  },
  "oz": {
    "urls": [],
    "summaries": []
  },
  "paperwork": {
    "urls": [],
    "summaries": []
  },
  "paraview": {
    "urls": [],
    "summaries": []
  },
  "patool": {
    "urls": [],
    "summaries": []
  },
  "pcp": {
    "urls": [],
    "summaries": []
  },
  "pcs": {
    "urls": [],
    "summaries": []
  },
  "pdf-stapler": {
    "urls": [],
    "summaries": []
  },
  "petsc": {
    "urls": [
      "https://bugzilla.redhat.com/show_bug.cgi?id=2359524"
    ],
    "summaries": [
      "petsc fails to build with Python 3.14: AssertionError: 2 != 3 self.assertEqual(getrefcount(ctx), 3)"
    ]
  },
  "piper": {
    "urls": [],
    "summaries": []
  },
  "poetry": {
    "urls": [
      "https://bugzilla.redhat.com/show_bug.cgi?id=2351383"
    ],
    "summaries": [
      "poetry fails to build with Python 3.14: AssertionError in test_isolated_env_install_discards_requirements_not_needed_by_env and test_python_get_preferred_default"
    ]
  },
  "poezio": {
    "urls": [
      "https://bugzilla.redhat.com/show_bug.cgi?id=2341088"
    ],
    "summaries": [
      "poezio: FTBFS in Fedora rawhide/f42"
    ]
  },
  "postfix-mta-sts-resolver": {
    "urls": [],
    "summaries": []
  },
  "powerline": {
    "urls": [
      "https://bugzilla.redhat.com/show_bug.cgi?id=2336943"
    ],
    "summaries": [
      "powerline fails to build with Python 3.14: ValueError: argument groups cannot be nested"
    ]
  },
  "pre-commit": {
    "urls": [],
    "summaries": []
  },
  "profanity": {
    "urls": [],
    "summaries": []
  },
  "protobuf": {
    "urls": [
      "https://bugzilla.redhat.com/show_bug.cgi?id=2356165",
      "https://bugzilla.redhat.com/show_bug.cgi?id=2343969"
    ],
    "summaries": [
      "protobuf with Python 3.14: TypeError: Metaclasses with custom tp_new are not supported.",
      "protobuf doesn't work with Python 3.14: test_error_reason: TypeError: Metaclasses with custom tp_new are not supported."
    ]
  },
  "pungi": {
    "urls": [],
    "summaries": []
  },
  "pyOpenSSL": {
    "urls": [],
    "summaries": []
  },
  "pybind11": {
    "urls": [
      "https://bugzilla.redhat.com/show_bug.cgi?id=2336889"
    ],
    "summaries": [
      "pybind11 fails to build with Python 3.14: AttributeError: 'pybind11_tests.pickling.PickleableWithDict' object has no attribute 'dynamic' + AssertionError"
    ]
  },
  "pychess": {
    "urls": [
      "https://bugzilla.redhat.com/show_bug.cgi?id=2328708"
    ],
    "summaries": [
      "pychess fails to build with Python 3.14: RuntimeError: There is no current event loop in thread 'MainThread'."
    ]
  },
  "pychromecast": {
    "urls": [],
    "summaries": []
  },
  "pydot": {
    "urls": [],
    "summaries": []
  },
  "pyflakes": {
    "urls": [
      "https://bugzilla.redhat.com/show_bug.cgi?id=2359503"
    ],
    "summaries": [
      "pyflakes fails to build with Python 3.14: SyntaxError: future feature print_statement is not defined"
    ]
  },
  "pygobject3": {
    "urls": [
      "https://bugzilla.redhat.com/show_bug.cgi?id=2359811"
    ],
    "summaries": [
      "pygobject3 fails to build with Python 3.14: Failed TestPythonReferenceCounting and TestRefCountsIntrospected and TestRefCountsNonIntrospected"
    ]
  },
  "pygsl": {
    "urls": [],
    "summaries": []
  },
  "pyinstrument": {
    "urls": [],
    "summaries": []
  },
  "pykakasi": {
    "urls": [],
    "summaries": []
  },
  "pykka": {
    "urls": [],
    "summaries": []
  },
  "pylibacl": {
    "urls": [
      "https://bugzilla.redhat.com/show_bug.cgi?id=2359502"
    ],
    "summaries": [
      "pylibacl fails to build with Python 3.14: tests/test_acls.py::TestModification: Failed: Wrong reference count, expected 2-1024 and got 1"
    ]
  },
  "pylint": {
    "urls": [],
    "summaries": []
  },
  "pyp2spec": {
    "urls": [],
    "summaries": []
  },
  "pyparsing": {
    "urls": [],
    "summaries": []
  },
  "pyserial-asyncio": {
    "urls": [
      "https://bugzilla.redhat.com/show_bug.cgi?id=2327980"
    ],
    "summaries": [
      "pyserial-asyncio fails to build with Python 3.14: RuntimeError: There is no current event loop in thread 'MainThread'."
    ]
  },
  "pysubnettree": {
    "urls": [
      "https://bugzilla.redhat.com/show_bug.cgi?id=2341123"
    ],
    "summaries": [
      "pysubnettree: FTBFS in Fedora rawhide/f42"
    ]
  },
  "pytest": {
    "urls": [
      "https://bugzilla.redhat.com/show_bug.cgi?id=2353140"
    ],
    "summaries": [
      "pytest fails to build with Python 3.14: mismatch of expected and actual strings in test output"
    ]
  },
  "python-AppTools": {
    "urls": [],
    "summaries": []
  },
  "python-Automat": {
    "urls": [],
    "summaries": []
  },
  "python-Bottleneck": {
    "urls": [],
    "summaries": []
  },
  "python-Levenshtein": {
    "urls": [],
    "summaries": []
  },
  "python-OWSLib": {
    "urls": [],
    "summaries": []
  },
  "python-PyAVM": {
    "urls": [],
    "summaries": []
  },
  "python-PyMuPDF": {
    "urls": [],
    "summaries": []
  },
  "python-SALib": {
    "urls": [],
    "summaries": []
  },
  "python-SecretStorage": {
    "urls": [],
    "summaries": []
  },
  "python-TestSlide": {
    "urls": [
      "https://bugzilla.redhat.com/show_bug.cgi?id=2350306",
      "https://bugzilla.redhat.com/show_bug.cgi?id=2343971"
    ],
    "summaries": [
      "Heads-up: python-TestSlide fails to build with python-pygments 2.19.1 on Fedora 43",
      "python-TestSlide fails to build with Python 3.14: ERROR collecting tests/mock_callable_testslide.py: RuntimeError: dictionary changed size during iteration"
    ]
  },
  "python-abimap": {
    "urls": [],
    "summaries": []
  },
  "python-accept-types": {
    "urls": [],
    "summaries": []
  },
  "python-accuweather": {
    "urls": [],
    "summaries": []
  },
  "python-adafruit-platformdetect": {
    "urls": [],
    "summaries": []
  },
  "python-adafruit-pureio": {
    "urls": [],
    "summaries": []
  },
  "python-adjustText": {
    "urls": [],
    "summaries": []
  },
  "python-advisory-parser": {
    "urls": [],
    "summaries": []
  },
  "python-agate": {
    "urls": [],
    "summaries": []
  },
  "python-agate-dbf": {
    "urls": [],
    "summaries": []
  },
  "python-agate-excel": {
    "urls": [],
    "summaries": []
  },
  "python-agate-sql": {
    "urls": [],
    "summaries": []
  },
  "python-aioesphomeapi": {
    "urls": [],
    "summaries": []
  },
  "python-aiohttp": {
    "urls": [],
    "summaries": []
  },
  "python-aiohttp-cors": {
    "urls": [],
    "summaries": []
  },
  "python-aiohttp-oauthlib": {
    "urls": [],
    "summaries": []
  },
  "python-aiohttp-retry": {
    "urls": [],
    "summaries": []
  },
  "python-aiohttp-sse-client": {
    "urls": [],
    "summaries": []
  },
  "python-aiokafka": {
    "urls": [
      "https://bugzilla.redhat.com/show_bug.cgi?id=2346517"
    ],
    "summaries": [
      "python-aiokafka fails to build with Python 3.14: DeprecationWarning: 'asyncio.get_event_loop_policy' is deprecated and slated for removal in Python 3.16"
    ]
  },
  "python-aioresponses": {
    "urls": [],
    "summaries": []
  },
  "python-aioruckus": {
    "urls": [],
    "summaries": []
  },
  "python-aiosmtpd": {
    "urls": [
      "https://bugzilla.redhat.com/show_bug.cgi?id=2322718"
    ],
    "summaries": [
      "python-aiosmtpd fails to build with Python 3.14: ImportError: cannot import name 'ByteString' from 'typing'"
    ]
  },
  "python-aiounittest": {
    "urls": [
      "https://bugzilla.redhat.com/show_bug.cgi?id=2356177"
    ],
    "summaries": [
      "python-aiounittest fails to build with Python 3.14: RuntimeError: There is no current event loop in thread 'MainThread'."
    ]
  },
  "python-ajpy": {
    "urls": [],
    "summaries": []
  },
  "python-alembic": {
    "urls": [],
    "summaries": []
  },
  "python-androguard": {
    "urls": [],
    "summaries": []
  },
  "python-animatplot": {
    "urls": [],
    "summaries": []
  },
  "python-annarchy": {
    "urls": [],
    "summaries": []
  },
  "python-ansi2html": {
    "urls": [],
    "summaries": []
  },
  "python-ansible-compat": {
    "urls": [],
    "summaries": []
  },
  "python-ansible-pylibssh": {
    "urls": [],
    "summaries": []
  },
  "python-ansible-runner": {
    "urls": [],
    "summaries": []
  },
  "python-ansicolor": {
    "urls": [],
    "summaries": []
  },
  "python-anyconfig": {
    "urls": [],
    "summaries": []
  },
  "python-anyio": {
    "urls": [],
    "summaries": []
  },
  "python-apipkg": {
    "urls": [],
    "summaries": []
  },
  "python-apkinspector": {
    "urls": [],
    "summaries": []
  },
  "python-apsw": {
    "urls": [],
    "summaries": []
  },
  "python-archspec": {
    "urls": [],
    "summaries": []
  },
  "python-aresponses": {
    "urls": [],
    "summaries": []
  },
  "python-array-api-strict": {
    "urls": [
      "https://bugzilla.redhat.com/show_bug.cgi?id=2365875"
    ],
    "summaries": [
      "python-array-api-strict fails to build with Python 3.14: test_iter: Failed: DID NOT RAISE <class 'TypeError'>"
    ]
  },
  "python-arrow": {
    "urls": [],
    "summaries": []
  },
  "python-ase": {
    "urls": [],
    "summaries": []
  },
  "python-asn1": {
    "urls": [],
    "summaries": []
  },
  "python-astdoc": {
    "urls": [
      "https://bugzilla.redhat.com/show_bug.cgi?id=2349452"
    ],
    "summaries": [
      "python-astdoc fails to build with Python 3.14: 3 doctests fail, e.g.: Expected: <ast.Name object at 0x...> Got: Name(id='int', ctx=Load())"
    ]
  },
  "python-asteval": {
    "urls": [],
    "summaries": []
  },
  "python-astral": {
    "urls": [],
    "summaries": []
  },
  "python-astroML": {
    "urls": [],
    "summaries": []
  },
  "python-astroid": {
    "urls": [
      "https://bugzilla.redhat.com/show_bug.cgi?id=2323166"
    ],
    "summaries": [
      "python-astroid fails to build with Python 3.14: astroid.exceptions.InferenceError: StopIteration raised without any error information."
    ]
  },
  "python-astroplan": {
    "urls": [],
    "summaries": []
  },
  "python-astropy": {
    "urls": [
      "https://bugzilla.redhat.com/show_bug.cgi?id=2345524"
    ],
    "summaries": [
      "python-astropy fails to build with Python 3.14: test_info_preserved_pickle_copy_init[arrayswap]: AssertionError: assert dtype('>i4') == dtype('int32')"
    ]
  },
  "python-astropy-healpix": {
    "urls": [],
    "summaries": []
  },
  "python-astropy-iers-data": {
    "urls": [
      "https://bugzilla.redhat.com/show_bug.cgi?id=2349443"
    ],
    "summaries": [
      "python-astropy-iers-data fails to build with Python 3.14: 4 tests fail with KeyError: 'ra_in' and 'lon_in'"
    ]
  },
  "python-astroquery": {
    "urls": [],
    "summaries": []
  },
  "python-astroscrappy": {
    "urls": [],
    "summaries": []
  },
  "python-asyncssh": {
    "urls": [
      "https://bugzilla.redhat.com/show_bug.cgi?id=2325445"
    ],
    "summaries": [
      "python-asyncssh fails to build with Python 3.14: multiple test failures (failures=25, errors=697)"
    ]
  },
  "python-atlassian-python-api": {
    "urls": [],
    "summaries": []
  },
  "python-atomicwrites": {
    "urls": [
      "https://bugzilla.redhat.com/show_bug.cgi?id=2341128"
    ],
    "summaries": [
      "python-atomicwrites: FTBFS in Fedora rawhide/f42"
    ]
  },
  "python-audioread": {
    "urls": [],
    "summaries": []
  },
  "python-authlib": {
    "urls": [],
    "summaries": []
  },
  "python-autocommand": {
    "urls": [
      "https://bugzilla.redhat.com/show_bug.cgi?id=2327972"
    ],
    "summaries": [
      "python-autocommand fails to build with Python 3.14: RuntimeError: There is no current event loop in thread 'MainThread'."
    ]
  },
  "python-autograd": {
    "urls": [],
    "summaries": []
  },
  "python-automaton": {
    "urls": [],
    "summaries": []
  },
  "python-autopage": {
    "urls": [],
    "summaries": []
  },
  "python-avocado": {
    "urls": [
      "https://bugzilla.redhat.com/show_bug.cgi?id=2341130",
      "https://bugzilla.redhat.com/show_bug.cgi?id=2325218"
    ],
    "summaries": [
      "python-avocado: FTBFS in Fedora rawhide/f42",
      "python-avocado fails to build with Python 3.14: Error running method \"pre_tests\" of plugin \"fetchasset\": module 'ast' has no attribute 'Str' + Avocado crashed: TypeError: cannot pickle '_thread.RLock' object"
    ]
  },
  "python-aw-core": {
    "urls": [],
    "summaries": []
  },
  "python-aw-qt": {
    "urls": [],
    "summaries": []
  },
  "python-awesomeversion": {
    "urls": [],
    "summaries": []
  },
  "python-aws-sam-translator": {
    "urls": [
      "https://bugzilla.redhat.com/show_bug.cgi?id=2353126"
    ],
    "summaries": [
      "python-aws-sam-translator fails to build with Python 3.14: 77 test failures, 4 error"
    ]
  },
  "python-aws-xray-sdk": {
    "urls": [],
    "summaries": []
  },
  "python-axolotl": {
    "urls": [],
    "summaries": []
  },
  "python-azure-core": {
    "urls": [],
    "summaries": []
  },
  "python-azure-loganalytics": {
    "urls": [],
    "summaries": []
  },
  "python-azure-mgmt-advisor": {
    "urls": [],
    "summaries": []
  },
  "python-azure-mgmt-billing": {
    "urls": [],
    "summaries": []
  },
  "python-azure-mgmt-botservice": {
    "urls": [],
    "summaries": []
  },
  "python-azure-mgmt-consumption": {
    "urls": [],
    "summaries": []
  },
  "python-azure-mgmt-core": {
    "urls": [],
    "summaries": []
  },
  "python-azure-mgmt-databoxedge": {
    "urls": [],
    "summaries": []
  },
  "python-azure-mgmt-datamigration": {
    "urls": [],
    "summaries": []
  },
  "python-azure-mgmt-devtestlabs": {
    "urls": [],
    "summaries": []
  },
  "python-azure-mgmt-dns": {
    "urls": [],
    "summaries": []
  },
  "python-azure-mgmt-managedservices": {
    "urls": [],
    "summaries": []
  },
  "python-azure-mgmt-maps": {
    "urls": [],
    "summaries": []
  },
  "python-azure-mgmt-marketplaceordering": {
    "urls": [],
    "summaries": []
  },
  "python-azure-multiapi-storage": {
    "urls": [],
    "summaries": []
  },
  "python-azure-servicebus": {
    "urls": [],
    "summaries": []
  },
  "python-azure-storage-blob": {
    "urls": [],
    "summaries": []
  },
  "python-b4": {
    "urls": [],
    "summaries": []
  },
  "python-backrefs": {
    "urls": [],
    "summaries": []
  },
  "python-bashate": {
    "urls": [],
    "summaries": []
  },
  "python-bcrypt": {
    "urls": [],
    "summaries": []
  },
  "python-beaker": {
    "urls": [],
    "summaries": []
  },
  "python-beancount": {
    "urls": [
      "https://bugzilla.redhat.com/show_bug.cgi?id=2359530"
    ],
    "summaries": [
      "python-beancount fails to build with Python 3.14: TestReferenceCounting and TestLexer fail with AssertionError"
    ]
  },
  "python-beartype": {
    "urls": [
      "https://bugzilla.redhat.com/show_bug.cgi?id=2341131",
      "https://bugzilla.redhat.com/show_bug.cgi?id=2322721"
    ],
    "summaries": [
      "python-beartype: FTBFS in Fedora rawhide/f42",
      "python-beartype fails to build with Python 3.14: ImportError: cannot import name 'ByteString' from 'typing'"
    ]
  },
  "python-beautifulsoup4": {
    "urls": [],
    "summaries": []
  },
  "python-behave": {
    "urls": [
      "https://bugzilla.redhat.com/show_bug.cgi?id=2339094"
    ],
    "summaries": [
      "python-behave fails to build with Python 3.14: RuntimeError: There is no current event loop in thread 'MainThread'."
    ]
  },
  "python-bibtexparser": {
    "urls": [],
    "summaries": []
  },
  "python-bids-validator": {
    "urls": [],
    "summaries": []
  },
  "python-billiard": {
    "urls": [
      "https://bugzilla.redhat.com/show_bug.cgi?id=2323167"
    ],
    "summaries": [
      "python-billiard fails to build with Python 3.14: AttributeError: module 'subprocess' has no attribute '_USE_VFORK'"
    ]
  },
  "python-binary-manager": {
    "urls": [],
    "summaries": []
  },
  "python-binaryornot": {
    "urls": [],
    "summaries": []
  },
  "python-bioframe": {
    "urls": [],
    "summaries": []
  },
  "python-bioread": {
    "urls": [],
    "summaries": []
  },
  "python-blinker": {
    "urls": [
      "https://bugzilla.redhat.com/show_bug.cgi?id=2325193"
    ],
    "summaries": [
      "python-blinker fails to build with Python 3.14: pluggy.PluggyTeardownRaisedWarning: A plugin raised an exception during an old-style hookwrapper teardown."
    ]
  },
  "python-blosc2": {
    "urls": [],
    "summaries": []
  },
  "python-boolean.py": {
    "urls": [],
    "summaries": []
  },
  "python-boto3": {
    "urls": [],
    "summaries": []
  },
  "python-botocore": {
    "urls": [],
    "summaries": []
  },
  "python-boutdata": {
    "urls": [
      "https://bugzilla.redhat.com/show_bug.cgi?id=2352553"
    ],
    "summaries": [
      "python-boutdata fails to build with Python 3.14: NotImplementedError: Dataset is not picklable"
    ]
  },
  "python-bravado": {
    "urls": [],
    "summaries": []
  },
  "python-bravado-core": {
    "urls": [],
    "summaries": []
  },
  "python-breathe": {
    "urls": [
      "https://bugzilla.redhat.com/show_bug.cgi?id=2341133"
    ],
    "summaries": [
      "python-breathe: FTBFS in Fedora rawhide/f42"
    ]
  },
  "python-brian2": {
    "urls": [],
    "summaries": []
  },
  "python-bsmschema": {
    "urls": [],
    "summaries": []
  },
  "python-btrfs": {
    "urls": [],
    "summaries": []
  },
  "python-bugzilla": {
    "urls": [],
    "summaries": []
  },
  "python-cached_property": {
    "urls": [],
    "summaries": []
  },
  "python-cairocffi": {
    "urls": [],
    "summaries": []
  },
  "python-canonicaljson": {
    "urls": [],
    "summaries": []
  },
  "python-capturer": {
    "urls": [
      "https://bugzilla.redhat.com/show_bug.cgi?id=2328004"
    ],
    "summaries": [
      "python-capturer fails to build with Python 3.14: OSError: [Errno 29] Illegal seek"
    ]
  },
  "python-carbon": {
    "urls": [],
    "summaries": []
  },
  "python-catkin_lint": {
    "urls": [],
    "summaries": []
  },
  "python-catkin_pkg": {
    "urls": [],
    "summaries": []
  },
  "python-catkin_tools": {
    "urls": [
      "https://bugzilla.redhat.com/show_bug.cgi?id=2341134"
    ],
    "summaries": [
      "python-catkin_tools: FTBFS in Fedora rawhide/f42"
    ]
  },
  "python-cattrs": {
    "urls": [
      "https://bugzilla.redhat.com/show_bug.cgi?id=2343916"
    ],
    "summaries": [
      "python-cattrs fails to build with Python 3.14: TypeError: <class 'tests.strategies.test_include_subclasses.GrandChild'> has no usable non-default attributes"
    ]
  },
  "python-cbor2": {
    "urls": [],
    "summaries": []
  },
  "python-cclib": {
    "urls": [],
    "summaries": []
  },
  "python-cerberus": {
    "urls": [],
    "summaries": []
  },
  "python-cffi": {
    "urls": [],
    "summaries": []
  },
  "python-chalice": {
    "urls": [
      "https://bugzilla.redhat.com/show_bug.cgi?id=2342568"
    ],
    "summaries": [
      "python-chalice fails to build with Python 3.14: AttributeError: module 'ast' has no attribute 'Str'"
    ]
  },
  "python-chameleon": {
    "urls": [],
    "summaries": []
  },
  "python-chaospy": {
    "urls": [],
    "summaries": []
  },
  "python-cheetah": {
    "urls": [],
    "summaries": []
  },
  "python-cinderclient": {
    "urls": [],
    "summaries": []
  },
  "python-citeproc-py": {
    "urls": [],
    "summaries": []
  },
  "python-cleo": {
    "urls": [],
    "summaries": []
  },
  "python-cliff": {
    "urls": [],
    "summaries": []
  },
  "python-cliff-tablib": {
    "urls": [],
    "summaries": []
  },
  "python-cloudpickle": {
    "urls": [],
    "summaries": []
  },
  "python-cloup": {
    "urls": [],
    "summaries": []
  },
  "python-cmd2": {
    "urls": [
      "https://bugzilla.redhat.com/show_bug.cgi?id=2356178"
    ],
    "summaries": [
      "python-cmd2 fails to build with Python 3.14:  ValueError: action 'store_true' is not valid for positional arguments"
    ]
  },
  "python-coincurve": {
    "urls": [],
    "summaries": []
  },
  "python-colander": {
    "urls": [],
    "summaries": []
  },
  "python-colcon-parallel-executor": {
    "urls": [
      "https://bugzilla.redhat.com/show_bug.cgi?id=2325186"
    ],
    "summaries": [
      "python-colcon-parallel-executor fails to build with Python 3.14: test_parallel: AssertionError: DeprecationWarning: 'asyncio.iscoroutinefunction' is deprecated and slated for removal in Python 3.16; use inspect.iscoroutinefunction() instead"
    ]
  },
  "python-colcon-ros": {
    "urls": [],
    "summaries": []
  },
  "python-collectd_cvmfs": {
    "urls": [],
    "summaries": []
  },
  "python-colorful": {
    "urls": [
      "https://bugzilla.redhat.com/show_bug.cgi?id=2325168"
    ],
    "summaries": [
      "python-colorful fails to build with Python 3.14: ast.Constant.s has been removed from Python 3.14"
    ]
  },
  "python-colormath2": {
    "urls": [],
    "summaries": []
  },
  "python-compal": {
    "urls": [],
    "summaries": []
  },
  "python-compreffor": {
    "urls": [],
    "summaries": []
  },
  "python-conda-index": {
    "urls": [],
    "summaries": []
  },
  "python-confuse": {
    "urls": [
      "https://bugzilla.redhat.com/show_bug.cgi?id=2327966"
    ],
    "summaries": [
      "python-confuse fails to build with Python 3.14: AttributeError: module 'pkgutil' has no attribute 'get_loader'"
    ]
  },
  "python-constantly": {
    "urls": [
      "https://bugzilla.redhat.com/show_bug.cgi?id=2341138"
    ],
    "summaries": [
      "python-constantly: FTBFS in Fedora rawhide/f42"
    ]
  },
  "python-contextualbandits": {
    "urls": [],
    "summaries": []
  },
  "python-copr": {
    "urls": [],
    "summaries": []
  },
  "python-cotyledon": {
    "urls": [],
    "summaries": []
  },
  "python-coveralls": {
    "urls": [],
    "summaries": []
  },
  "python-cppy": {
    "urls": [],
    "summaries": []
  },
  "python-cramjam": {
    "urls": [],
    "summaries": []
  },
  "python-crcmod": {
    "urls": [],
    "summaries": []
  },
  "python-crick": {
    "urls": [],
    "summaries": []
  },
  "python-cro": {
    "urls": [],
    "summaries": []
  },
  "python-crochet": {
    "urls": [],
    "summaries": []
  },
  "python-croniter": {
    "urls": [],
    "summaries": []
  },
  "python-crossword": {
    "urls": [],
    "summaries": []
  },
  "python-cs": {
    "urls": [],
    "summaries": []
  },
  "python-cssselect": {
    "urls": [],
    "summaries": []
  },
  "python-csvkit": {
    "urls": [],
    "summaries": []
  },
  "python-cvelib": {
    "urls": [],
    "summaries": []
  },
  "python-cvxopt": {
    "urls": [
      "https://bugzilla.redhat.com/show_bug.cgi?id=2365907"
    ],
    "summaries": [
      "python-cvxopt fails to build with Python 3.14: tests/test_dsdp.py::TestDSDP::test_options Fatal Python error: Segmentation fault"
    ]
  },
  "python-cyipopt": {
    "urls": [],
    "summaries": []
  },
  "python-daikin": {
    "urls": [],
    "summaries": []
  },
  "python-daiquiri": {
    "urls": [],
    "summaries": []
  },
  "python-dataclassy": {
    "urls": [
      "https://bugzilla.redhat.com/show_bug.cgi?id=2325200"
    ],
    "summaries": [
      "python-dataclassy fails to build with Python 3.14: TypeError: Beta() takes no arguments"
    ]
  },
  "python-datalad": {
    "urls": [],
    "summaries": []
  },
  "python-dateparser": {
    "urls": [],
    "summaries": []
  },
  "python-dateutil": {
    "urls": [],
    "summaries": []
  },
  "python-datrie": {
    "urls": [],
    "summaries": []
  },
  "python-dbfread": {
    "urls": [],
    "summaries": []
  },
  "python-deap": {
    "urls": [],
    "summaries": []
  },
  "python-debtcollector": {
    "urls": [],
    "summaries": []
  },
  "python-deepdiff": {
    "urls": [],
    "summaries": []
  },
  "python-defcon": {
    "urls": [],
    "summaries": []
  },
  "python-defusedxml": {
    "urls": [],
    "summaries": []
  },
  "python-detect-secrets": {
    "urls": [],
    "summaries": []
  },
  "python-dict-sorted": {
    "urls": [],
    "summaries": []
  },
  "python-dictdiffer": {
    "urls": [],
    "summaries": []
  },
  "python-diff-cover": {
    "urls": [
      "https://bugzilla.redhat.com/show_bug.cgi?id=2350299"
    ],
    "summaries": [
      "Heads-up: python-diff-cover fails to build with python-pygments 2.19.1 on Fedora 43"
    ]
  },
  "python-diff-match-patch": {
    "urls": [
      "https://bugzilla.redhat.com/show_bug.cgi?id=2354097"
    ],
    "summaries": [
      "python-diff-match-patch FTBFS due to missing tox configuration"
    ]
  },
  "python-dill": {
    "urls": [
      "https://bugzilla.redhat.com/show_bug.cgi?id=2323157"
    ],
    "summaries": [
      "python-dill fails to build with Python 3.14: TypeError: _Pickler._batch_setitems() missing 1 required positional argument: 'obj'"
    ]
  },
  "python-dipy": {
    "urls": [],
    "summaries": []
  },
  "python-dirhash": {
    "urls": [],
    "summaries": []
  },
  "python-dirty-equals": {
    "urls": [],
    "summaries": []
  },
  "python-diskcache": {
    "urls": [],
    "summaries": []
  },
  "python-distroinfo": {
    "urls": [],
    "summaries": []
  },
  "python-django-allauth": {
    "urls": [],
    "summaries": []
  },
  "python-django-angular": {
    "urls": [],
    "summaries": []
  },
  "python-django-appconf": {
    "urls": [],
    "summaries": []
  },
  "python-django-authority": {
    "urls": [],
    "summaries": []
  },
  "python-django-configurations": {
    "urls": [],
    "summaries": []
  },
  "python-django-contrib-comments": {
    "urls": [],
    "summaries": []
  },
  "python-django-debreach": {
    "urls": [
      "https://bugzilla.redhat.com/show_bug.cgi?id=2328003"
    ],
    "summaries": [
      "python-django-debreach fails to build with Python 3.14: AttributeError: 'super' object has no attribute 'dicts' and no __dict__ for setting new attributes"
    ]
  },
  "python-django-extensions": {
    "urls": [],
    "summaries": []
  },
  "python-django-filter": {
    "urls": [
      "https://bugzilla.redhat.com/show_bug.cgi?id=2336944"
    ],
    "summaries": [
      "python-django-filter fails to build with Python 3.14: AttributeError: module 'pkgutil' has no attribute 'find_loader'"
    ]
  },
  "python-django-formtools": {
    "urls": [],
    "summaries": []
  },
  "python-django-haystack": {
    "urls": [],
    "summaries": []
  },
  "python-django-mailman3": {
    "urls": [],
    "summaries": []
  },
  "python-django-picklefield": {
    "urls": [],
    "summaries": []
  },
  "python-django-tastypie": {
    "urls": [],
    "summaries": []
  },
  "python-django4.2": {
    "urls": [],
    "summaries": []
  },
  "python-djangoql": {
    "urls": [],
    "summaries": []
  },
  "python-dns-lexicon": {
    "urls": [],
    "summaries": []
  },
  "python-dnspython": {
    "urls": [],
    "summaries": []
  },
  "python-dogpile-cache": {
    "urls": [],
    "summaries": []
  },
  "python-doit": {
    "urls": [],
    "summaries": []
  },
  "python-domdf-python-tools": {
    "urls": [
      "https://bugzilla.redhat.com/show_bug.cgi?id=2345519"
    ],
    "summaries": [
      "python-domdf-python-tools fails to build with Python 3.14: tests/test_words.py::test_alpha_sort - AssertionError: Regex pattern did not match."
    ]
  },
  "python-dotenv": {
    "urls": [],
    "summaries": []
  },
  "python-doubleratchet": {
    "urls": [],
    "summaries": []
  },
  "python-drgn": {
    "urls": [],
    "summaries": []
  },
  "python-duecredit": {
    "urls": [],
    "summaries": []
  },
  "python-dulwich": {
    "urls": [],
    "summaries": []
  },
  "python-dunamai": {
    "urls": [],
    "summaries": []
  },
  "python-ebooklib": {
    "urls": [],
    "summaries": []
  },
  "python-eccodes": {
    "urls": [],
    "summaries": []
  },
  "python-efel": {
    "urls": [],
    "summaries": []
  },
  "python-elementpath": {
    "urls": [],
    "summaries": []
  },
  "python-elephant": {
    "urls": [],
    "summaries": []
  },
  "python-emcee": {
    "urls": [],
    "summaries": []
  },
  "python-engineio": {
    "urls": [],
    "summaries": []
  },
  "python-entrypoints": {
    "urls": [],
    "summaries": []
  },
  "python-environs": {
    "urls": [],
    "summaries": []
  },
  "python-envisage": {
    "urls": [],
    "summaries": []
  },
  "python-enzyme": {
    "urls": [],
    "summaries": []
  },
  "python-ephem": {
    "urls": [],
    "summaries": []
  },
  "python-ephyviewer": {
    "urls": [],
    "summaries": []
  },
  "python-et_xmlfile": {
    "urls": [
      "https://bugzilla.redhat.com/show_bug.cgi?id=2359509"
    ],
    "summaries": [
      "python-et_xmlfile fails to build with Python 3.14: ElementTreeTest.test_simpleops: AssertionError: 'Element.remove(x): element not found' != 'list.remove(x): x not in list'"
    ]
  },
  "python-etcd": {
    "urls": [
      "https://bugzilla.redhat.com/show_bug.cgi?id=2323184"
    ],
    "summaries": [
      "python-etcd fails to build with Python 3.14: _pickle.PicklingError: Can't pickle local object <function TestWatch.test_watch_indexed_generator.<locals>.watch_value at 0x7f0d39f71dd0>"
    ]
  },
  "python-eth-stdlib": {
    "urls": [],
    "summaries": []
  },
  "python-exabgp": {
    "urls": [],
    "summaries": []
  },
  "python-exdir": {
    "urls": [],
    "summaries": []
  },
  "python-execnet": {
    "urls": [],
    "summaries": []
  },
  "python-executing": {
    "urls": [
      "https://bugzilla.redhat.com/show_bug.cgi?id=2349436"
    ],
    "summaries": [
      "python-executing fails to build with Python 3.14: 52 test fail during the build"
    ]
  },
  "python-exrex": {
    "urls": [],
    "summaries": []
  },
  "python-extension-helpers": {
    "urls": [],
    "summaries": []
  },
  "python-factory-boy": {
    "urls": [],
    "summaries": []
  },
  "python-faker": {
    "urls": [],
    "summaries": []
  },
  "python-falcon": {
    "urls": [],
    "summaries": []
  },
  "python-fasjson-client": {
    "urls": [],
    "summaries": []
  },
  "python-fastavro": {
    "urls": [],
    "summaries": []
  },
  "python-fastrlock": {
    "urls": [],
    "summaries": []
  },
  "python-feedgen": {
    "urls": [],
    "summaries": []
  },
  "python-feedparser": {
    "urls": [],
    "summaries": []
  },
  "python-fields": {
    "urls": [],
    "summaries": []
  },
  "python-filelock": {
    "urls": [],
    "summaries": []
  },
  "python-fingerprints": {
    "urls": [],
    "summaries": []
  },
  "python-fixit": {
    "urls": [],
    "summaries": []
  },
  "python-fixtures": {
    "urls": [],
    "summaries": []
  },
  "python-flake8-comprehensions": {
    "urls": [
      "https://bugzilla.redhat.com/show_bug.cgi?id=2351385"
    ],
    "summaries": [
      "python-flake8-comprehensions fails to build with Python 3.14: Unnecessary reversed call around sorted() in 10 tests"
    ]
  },
  "python-flask": {
    "urls": [
      "https://bugzilla.redhat.com/show_bug.cgi?id=2327965"
    ],
    "summaries": [
      "python-flask fails to build with Python 3.14: AttributeError: module 'pkgutil' has no attribute 'get_loader'"
    ]
  },
  "python-flask-babel": {
    "urls": [],
    "summaries": []
  },
  "python-flask-caching": {
    "urls": [
      "https://bugzilla.redhat.com/show_bug.cgi?id=2341153"
    ],
    "summaries": [
      "python-flask-caching: FTBFS in Fedora rawhide/f42"
    ]
  },
  "python-flask-cors": {
    "urls": [],
    "summaries": []
  },
  "python-flask-httpauth": {
    "urls": [],
    "summaries": []
  },
  "python-flask-login": {
    "urls": [],
    "summaries": []
  },
  "python-flask-migrate": {
    "urls": [],
    "summaries": []
  },
  "python-flask-oidc": {
    "urls": [],
    "summaries": []
  },
  "python-flask-paranoid": {
    "urls": [],
    "summaries": []
  },
  "python-flask-principal": {
    "urls": [],
    "summaries": []
  },
  "python-flask-session": {
    "urls": [
      "https://bugzilla.redhat.com/show_bug.cgi?id=2354108"
    ],
    "summaries": [
      "python-flask-session FTBFS due to missing tox configuration"
    ]
  },
  "python-flask-sqlalchemy": {
    "urls": [],
    "summaries": []
  },
  "python-flask-whooshee": {
    "urls": [],
    "summaries": []
  },
  "python-flexmock": {
    "urls": [],
    "summaries": []
  },
  "python-flufl-bounce": {
    "urls": [],
    "summaries": []
  },
  "python-fontMath": {
    "urls": [],
    "summaries": []
  },
  "python-formulaic": {
    "urls": [],
    "summaries": []
  },
  "python-freecell_solver": {
    "urls": [],
    "summaries": []
  },
  "python-freetype": {
    "urls": [],
    "summaries": []
  },
  "python-freezegun": {
    "urls": [],
    "summaries": []
  },
  "python-frozenlist": {
    "urls": [],
    "summaries": []
  },
  "python-fs": {
    "urls": [
      "https://bugzilla.redhat.com/show_bug.cgi?id=2336951"
    ],
    "summaries": [
      "python-fs fails to build with Python 3.14: AssertionError: 'osfs://///tmp/tmppauy69swfstestosfs/foo' != 'osfs:///tmp/tmppauy69swfstestosfs/foo'"
    ]
  },
  "python-fsleyes-widgets": {
    "urls": [],
    "summaries": []
  },
  "python-fsspec": {
    "urls": [],
    "summaries": []
  },
  "python-funcsigs": {
    "urls": [],
    "summaries": []
  },
  "python-furo": {
    "urls": [],
    "summaries": []
  },
  "python-futurist": {
    "urls": [],
    "summaries": []
  },
  "python-gbulb": {
    "urls": [
      "https://bugzilla.redhat.com/show_bug.cgi?id=2341155"
    ],
    "summaries": [
      "python-gbulb: FTBFS in Fedora rawhide/f42"
    ]
  },
  "python-gemfileparser2": {
    "urls": [],
    "summaries": []
  },
  "python-geoip2": {
    "urls": [],
    "summaries": []
  },
  "python-geojson": {
    "urls": [],
    "summaries": []
  },
  "python-geopmpy": {
    "urls": [],
    "summaries": []
  },
  "python-geopy": {
    "urls": [],
    "summaries": []
  },
  "python-giacpy": {
    "urls": [
      "https://bugzilla.redhat.com/show_bug.cgi?id=2341608"
    ],
    "summaries": [
      "python-giacpy: FTBFS in Fedora rawhide/f42"
    ]
  },
  "python-gilt": {
    "urls": [],
    "summaries": []
  },
  "python-gios": {
    "urls": [],
    "summaries": []
  },
  "python-git-url-parse": {
    "urls": [],
    "summaries": []
  },
  "python-gitlab": {
    "urls": [],
    "summaries": []
  },
  "python-glanceclient": {
    "urls": [],
    "summaries": []
  },
  "python-gmpy2": {
    "urls": [],
    "summaries": []
  },
  "python-gnocchiclient": {
    "urls": [],
    "summaries": []
  },
  "python-gnupg": {
    "urls": [],
    "summaries": []
  },
  "python-googleapis-common-protos": {
    "urls": [
      "https://bugzilla.redhat.com/show_bug.cgi?id=2365822"
    ],
    "summaries": [
      "python-googleapis-common-protos fails to build with Python 3.14: protobuf: TypeError: Metaclasses with custom tp_new are not supported."
    ]
  },
  "python-gphoto2": {
    "urls": [
      "https://bugzilla.redhat.com/show_bug.cgi?id=2341158"
    ],
    "summaries": [
      "python-gphoto2: FTBFS in Fedora rawhide/f42"
    ]
  },
  "python-gql": {
    "urls": [],
    "summaries": []
  },
  "python-gradunwarp": {
    "urls": [],
    "summaries": []
  },
  "python-graphviz": {
    "urls": [],
    "summaries": []
  },
  "python-greenlet": {
    "urls": [],
    "summaries": []
  },
  "python-grip": {
    "urls": [],
    "summaries": []
  },
  "python-gunicorn": {
    "urls": [],
    "summaries": []
  },
  "python-h2": {
    "urls": [],
    "summaries": []
  },
  "python-h5io": {
    "urls": [],
    "summaries": []
  },
  "python-hacking": {
    "urls": [],
    "summaries": []
  },
  "python-hamcrest": {
    "urls": [
      "https://bugzilla.redhat.com/show_bug.cgi?id=2346504"
    ],
    "summaries": [
      "python-hamcrest fails to build with Python 3.14: RuntimeError: There is no current event loop in thread 'MainThread'."
    ]
  },
  "python-haversion": {
    "urls": [],
    "summaries": []
  },
  "python-hdf5storage": {
    "urls": [],
    "summaries": []
  },
  "python-healpy": {
    "urls": [],
    "summaries": []
  },
  "python-hl7": {
    "urls": [
      "https://bugzilla.redhat.com/show_bug.cgi?id=2341161"
    ],
    "summaries": [
      "python-hl7: FTBFS in Fedora rawhide/f42"
    ]
  },
  "python-howdoi": {
    "urls": [
      "https://bugzilla.redhat.com/show_bug.cgi?id=2342558"
    ],
    "summaries": [
      "python-howdoi fails to build with Python 3.14: AssertionError: 'ERROR: Unable to reach google. Do you need to use a proxy? + json.decoder.JSONDecodeError"
    ]
  },
  "python-hpack": {
    "urls": [],
    "summaries": []
  },
  "python-hpilo": {
    "urls": [],
    "summaries": []
  },
  "python-html-text": {
    "urls": [],
    "summaries": []
  },
  "python-html5-parser": {
    "urls": [],
    "summaries": []
  },
  "python-html5lib": {
    "urls": [],
    "summaries": []
  },
  "python-httmock": {
    "urls": [],
    "summaries": []
  },
  "python-http-server-mock": {
    "urls": [],
    "summaries": []
  },
  "python-httpbin": {
    "urls": [],
    "summaries": []
  },
  "python-httpcore": {
    "urls": [],
    "summaries": []
  },
  "python-humanfriendly": {
    "urls": [],
    "summaries": []
  },
  "python-humanize": {
    "urls": [],
    "summaries": []
  },
  "python-hupper": {
    "urls": [],
    "summaries": []
  },
  "python-hyperframe": {
    "urls": [],
    "summaries": []
  },
  "python-hyperkitty": {
    "urls": [],
    "summaries": []
  },
  "python-hyperlink": {
    "urls": [],
    "summaries": []
  },
  "python-igraph": {
    "urls": [],
    "summaries": []
  },
  "python-imagehash": {
    "urls": [],
    "summaries": []
  },
  "python-imbalanced-learn": {
    "urls": [],
    "summaries": []
  },
  "python-img2pdf": {
    "urls": [],
    "summaries": []
  },
  "python-inflect": {
    "urls": [],
    "summaries": []
  },
  "python-influxdb-client": {
    "urls": [],
    "summaries": []
  },
  "python-iniparse": {
    "urls": [
      "https://bugzilla.redhat.com/show_bug.cgi?id=2323164"
    ],
    "summaries": [
      "python-iniparse fails to build with Python 3.14: _pickle.PicklingError: Can't pickle local object <function TestIni.test_queue.<locals>.getxy at 0x7f86659a7740>"
    ]
  },
  "python-inject": {
    "urls": [
      "https://bugzilla.redhat.com/show_bug.cgi?id=2327978"
    ],
    "summaries": [
      "python-inject fails to build with Python 3.14: RuntimeError: There is no current event loop in thread 'MainThread'."
    ]
  },
  "python-injector": {
    "urls": [
      "https://bugzilla.redhat.com/show_bug.cgi?id=2341165"
    ],
    "summaries": [
      "python-injector: FTBFS in Fedora rawhide/f42"
    ]
  },
  "python-inkex": {
    "urls": [],
    "summaries": []
  },
  "python-intbitset": {
    "urls": [],
    "summaries": []
  },
  "python-interrogate": {
    "urls": [],
    "summaries": []
  },
  "python-invoke": {
    "urls": [
      "https://bugzilla.redhat.com/show_bug.cgi?id=2365652"
    ],
    "summaries": [
      "python-invoke fails to build with Python 3.14: SystemError: buffer overflow in 16 tests"
    ]
  },
  "python-ipfshttpclient": {
    "urls": [],
    "summaries": []
  },
  "python-ipuz": {
    "urls": [],
    "summaries": []
  },
  "python-ipyparallel": {
    "urls": [
      "https://bugzilla.redhat.com/show_bug.cgi?id=2359525"
    ],
    "summaries": [
      "python-ipyparallel fails to build with Python 3.14: TestAsyncResult.test_display_output_error: SyntaxWarning: 'return' in a 'finally' block treated as error"
    ]
  },
  "python-ipywidgets": {
    "urls": [],
    "summaries": []
  },
  "python-irc": {
    "urls": [
      "https://bugzilla.redhat.com/show_bug.cgi?id=2327991"
    ],
    "summaries": [
      "python-irc fails to build with Python 3.14: RuntimeError: There is no current event loop in thread 'MainThread'."
    ]
  },
  "python-iso3166": {
    "urls": [],
    "summaries": []
  },
  "python-janus": {
    "urls": [],
    "summaries": []
  },
  "python-jedi": {
    "urls": [],
    "summaries": []
  },
  "python-jeepney": {
    "urls": [],
    "summaries": []
  },
  "python-jenkins": {
    "urls": [],
    "summaries": []
  },
  "python-jinja2": {
    "urls": [],
    "summaries": []
  },
  "python-jiter": {
    "urls": [],
    "summaries": []
  },
  "python-jnius": {
    "urls": [],
    "summaries": []
  },
  "python-joblib": {
    "urls": [
      "https://bugzilla.redhat.com/show_bug.cgi?id=2339519"
    ],
    "summaries": [
      "python-joblib fails to build with Python 3.14: TypeError: Hasher._batch_setitems() takes 2 positional arguments but 3 were given"
    ]
  },
  "python-josepy": {
    "urls": [
      "https://bugzilla.redhat.com/show_bug.cgi?id=2359514"
    ],
    "summaries": [
      "python-josepy fails to build with Python 3.14: ValueError: Field `alg` in JSONObject `Header` has no type annotation."
    ]
  },
  "python-jsonpath-rw-ext": {
    "urls": [],
    "summaries": []
  },
  "python-jsonpickle": {
    "urls": [],
    "summaries": []
  },
  "python-jsonschema": {
    "urls": [],
    "summaries": []
  },
  "python-jsonschema-path": {
    "urls": [],
    "summaries": []
  },
  "python-jsonschema-specifications": {
    "urls": [],
    "summaries": []
  },
  "python-jsonstreams": {
    "urls": [],
    "summaries": []
  },
  "python-junit_xml": {
    "urls": [],
    "summaries": []
  },
  "python-jupyter-cache": {
    "urls": [],
    "summaries": []
  },
  "python-jupyter-client": {
    "urls": [],
    "summaries": []
  },
  "python-jupyter-events": {
    "urls": [],
    "summaries": []
  },
  "python-jupyter-kernel-test": {
    "urls": [],
    "summaries": []
  },
  "python-jupyter-lsp": {
    "urls": [],
    "summaries": []
  },
  "python-jupyter-server": {
    "urls": [],
    "summaries": []
  },
  "python-jupyterlab-server": {
    "urls": [],
    "summaries": []
  },
  "python-jupytext": {
    "urls": [],
    "summaries": []
  },
  "python-kafka": {
    "urls": [],
    "summaries": []
  },
  "python-kazoo": {
    "urls": [],
    "summaries": []
  },
  "python-keystoneauth1": {
    "urls": [],
    "summaries": []
  },
  "python-keystoneclient": {
    "urls": [],
    "summaries": []
  },
  "python-klein": {
    "urls": [],
    "summaries": []
  },
  "python-klusta": {
    "urls": [],
    "summaries": []
  },
  "python-latexcodec": {
    "urls": [],
    "summaries": []
  },
  "python-lazr-config": {
    "urls": [],
    "summaries": []
  },
  "python-lazr-delegates": {
    "urls": [],
    "summaries": []
  },
  "python-lazy-loader": {
    "urls": [],
    "summaries": []
  },
  "python-lazy-object-proxy": {
    "urls": [],
    "summaries": []
  },
  "python-lazyarray": {
    "urls": [],
    "summaries": []
  },
  "python-leather": {
    "urls": [],
    "summaries": []
  },
  "python-lfpy": {
    "urls": [
      "https://bugzilla.redhat.com/show_bug.cgi?id=2341168"
    ],
    "summaries": [
      "python-lfpy: FTBFS in Fedora rawhide/f42"
    ]
  },
  "python-lfpykit": {
    "urls": [],
    "summaries": []
  },
  "python-libNeuroML": {
    "urls": [],
    "summaries": []
  },
  "python-libcst": {
    "urls": [
      "https://bugzilla.redhat.com/show_bug.cgi?id=2356182"
    ],
    "summaries": [
      "python-libcst fails to build with Python 3.14: Exception: Logic error, unexpected top level type! when importing libcst.codegen.gen_matcher_classes"
    ]
  },
  "python-libdiscid": {
    "urls": [],
    "summaries": []
  },
  "python-libnacl": {
    "urls": [],
    "summaries": []
  },
  "python-license-expression": {
    "urls": [],
    "summaries": []
  },
  "python-listparser": {
    "urls": [],
    "summaries": []
  },
  "python-llama-cpp-python": {
    "urls": [],
    "summaries": []
  },
  "python-localzone": {
    "urls": [],
    "summaries": []
  },
  "python-lockfile": {
    "urls": [],
    "summaries": []
  },
  "python-logbook": {
    "urls": [],
    "summaries": []
  },
  "python-loguru": {
    "urls": [
      "https://bugzilla.redhat.com/show_bug.cgi?id=2356181"
    ],
    "summaries": [
      "python-loguru fails to build with Python 3.14: test_exception_modern[type_hints-minimum_python_version0]: m<class 'typing.Union'>"
    ]
  },
  "python-lqrt": {
    "urls": [],
    "summaries": []
  },
  "python-lunr": {
    "urls": [],
    "summaries": []
  },
  "python-lupa": {
    "urls": [],
    "summaries": []
  },
  "python-lxml-html-clean": {
    "urls": [],
    "summaries": []
  },
  "python-lz4": {
    "urls": [
      "https://bugzilla.redhat.com/show_bug.cgi?id=2365823"
    ],
    "summaries": [
      "python-lz4 fails to build with Python 3.14: ImportError: cannot import name '_compression' from partially initialized module 'lz4.frame' (most likely due to a circular import)"
    ]
  },
  "python-makefun": {
    "urls": [
      "https://bugzilla.redhat.com/show_bug.cgi?id=2328706"
    ],
    "summaries": [
      "python-makefun fails to build with Python 3.14: RuntimeError: There is no current event loop in thread 'MainThread'."
    ]
  },
  "python-mako": {
    "urls": [],
    "summaries": []
  },
  "python-manuel": {
    "urls": [],
    "summaries": []
  },
  "python-markdown-callouts": {
    "urls": [],
    "summaries": []
  },
  "python-markups": {
    "urls": [],
    "summaries": []
  },
  "python-marshmallow": {
    "urls": [],
    "summaries": []
  },
  "python-matplotlib": {
    "urls": [
      "https://bugzilla.redhat.com/show_bug.cgi?id=2328713"
    ],
    "summaries": [
      "python-matplotlib fails to build with Python 3.14: RecursionError: maximum recursion depth exceeded"
    ]
  },
  "python-matplotlib-inline": {
    "urls": [],
    "summaries": []
  },
  "python-matrix-common": {
    "urls": [],
    "summaries": []
  },
  "python-matrix-nio": {
    "urls": [],
    "summaries": []
  },
  "python-mccabe": {
    "urls": [
      "https://bugzilla.redhat.com/show_bug.cgi?id=2328016"
    ],
    "summaries": [
      "python-mccabe fails to build with Python 3.14: AttributeError: module 'typing' has no attribute 'ByteString'"
    ]
  },
  "python-mdit-py-plugins": {
    "urls": [],
    "summaries": []
  },
  "python-mechanicalsoup": {
    "urls": [],
    "summaries": []
  },
  "python-mechanize": {
    "urls": [],
    "summaries": []
  },
  "python-mediafile": {
    "urls": [],
    "summaries": []
  },
  "python-memray": {
    "urls": [],
    "summaries": []
  },
  "python-mercantile": {
    "urls": [],
    "summaries": []
  },
  "python-merge3": {
    "urls": [],
    "summaries": []
  },
  "python-mergedeep": {
    "urls": [],
    "summaries": []
  },
  "python-meshio": {
    "urls": [],
    "summaries": []
  },
  "python-metakernel": {
    "urls": [
      "https://bugzilla.redhat.com/show_bug.cgi?id=2357903"
    ],
    "summaries": [
      "python-metakernel fails to build with Python 3.14: AssertionError in test_parallel_magic"
    ]
  },
  "python-mf2py": {
    "urls": [],
    "summaries": []
  },
  "python-micawber": {
    "urls": [],
    "summaries": []
  },
  "python-mido": {
    "urls": [],
    "summaries": []
  },
  "python-missingno": {
    "urls": [],
    "summaries": []
  },
  "python-mistune": {
    "urls": [],
    "summaries": []
  },
  "python-mizani": {
    "urls": [],
    "summaries": []
  },
  "python-mkdocs-d2-plugin": {
    "urls": [],
    "summaries": []
  },
  "python-mkdocs-git-revision-date-localized-plugin": {
    "urls": [],
    "summaries": []
  },
  "python-mkdocs-material-extensions": {
    "urls": [],
    "summaries": []
  },
  "python-mkdocs-rss-plugin": {
    "urls": [],
    "summaries": []
  },
  "python-mkdocs-static-i18n": {
    "urls": [],
    "summaries": []
  },
  "python-mnemonic": {
    "urls": [],
    "summaries": []
  },
  "python-mongoengine": {
    "urls": [],
    "summaries": []
  },
  "python-more-executors": {
    "urls": [],
    "summaries": []
  },
  "python-more-itertools": {
    "urls": [],
    "summaries": []
  },
  "python-mpd2": {
    "urls": [],
    "summaries": []
  },
  "python-mplcairo": {
    "urls": [],
    "summaries": []
  },
  "python-mplcursors": {
    "urls": [],
    "summaries": []
  },
  "python-mpmath": {
    "urls": [],
    "summaries": []
  },
  "python-mrcrowbar": {
    "urls": [],
    "summaries": []
  },
  "python-msal": {
    "urls": [
      "https://bugzilla.redhat.com/show_bug.cgi?id=2323170"
    ],
    "summaries": [
      "python-msal fails to build with Python 3.14: test_no_two_concurrent_receivers_can_listen_on_same_port: AssertionError: OSError not raised"
    ]
  },
  "python-msgspec": {
    "urls": [
      "https://bugzilla.redhat.com/show_bug.cgi?id=2365636"
    ],
    "summaries": [
      "python-msgspec fails to build with Python 3.14: TypeError: Extra positional arguments provided"
    ]
  },
  "python-msrest": {
    "urls": [],
    "summaries": []
  },
  "python-multiprocess": {
    "urls": [],
    "summaries": []
  },
  "python-music21": {
    "urls": [
      "https://bugzilla.redhat.com/show_bug.cgi?id=2354114"
    ],
    "summaries": [
      "python-music21 FTBFS due to missing tox configuration"
    ]
  },
  "python-mutagen": {
    "urls": [],
    "summaries": []
  },
  "python-mwclient": {
    "urls": [],
    "summaries": []
  },
  "python-mysqlclient": {
    "urls": [],
    "summaries": []
  },
  "python-myst-parser": {
    "urls": [],
    "summaries": []
  },
  "python-nbclassic": {
    "urls": [],
    "summaries": []
  },
  "python-nbclient": {
    "urls": [],
    "summaries": []
  },
  "python-nbconvert": {
    "urls": [],
    "summaries": []
  },
  "python-nbdime": {
    "urls": [],
    "summaries": []
  },
  "python-nbformat": {
    "urls": [],
    "summaries": []
  },
  "python-nbsphinx": {
    "urls": [],
    "summaries": []
  },
  "python-ncclient": {
    "urls": [],
    "summaries": []
  },
  "python-ndindex": {
    "urls": [],
    "summaries": []
  },
  "python-neatdend": {
    "urls": [
      "https://bugzilla.redhat.com/show_bug.cgi?id=2341170"
    ],
    "summaries": [
      "python-neatdend: FTBFS in Fedora rawhide/f42"
    ]
  },
  "python-neo": {
    "urls": [],
    "summaries": []
  },
  "python-neovim": {
    "urls": [
      "https://bugzilla.redhat.com/show_bug.cgi?id=2336888"
    ],
    "summaries": [
      "python-neovim fails to build with Python 3.14: ImportError: cannot import name 'ThreadedChildWatcher' from 'asyncio.unix_events' (/usr/lib64/python3.14/asyncio/unix_events.py)"
    ]
  },
  "python-netaddr": {
    "urls": [],
    "summaries": []
  },
  "python-netpyne": {
    "urls": [],
    "summaries": []
  },
  "python-network-runner": {
    "urls": [
      "https://bugzilla.redhat.com/show_bug.cgi?id=2341172"
    ],
    "summaries": [
      "python-network-runner: FTBFS in Fedora rawhide/f42"
    ]
  },
  "python-neurodsp": {
    "urls": [],
    "summaries": []
  },
  "python-neurotune": {
    "urls": [
      "https://bugzilla.redhat.com/show_bug.cgi?id=2341173"
    ],
    "summaries": [
      "python-neurotune: FTBFS in Fedora rawhide/f42"
    ]
  },
  "python-niaaml": {
    "urls": [],
    "summaries": []
  },
  "python-niaarmts": {
    "urls": [],
    "summaries": []
  },
  "python-niaclass": {
    "urls": [],
    "summaries": []
  },
  "python-nibabel": {
    "urls": [],
    "summaries": []
  },
  "python-nikola": {
    "urls": [
      "https://bugzilla.redhat.com/show_bug.cgi?id=2341174"
    ],
    "summaries": [
      "python-nikola: FTBFS in Fedora rawhide/f42"
    ]
  },
  "python-nipy": {
    "urls": [],
    "summaries": []
  },
  "python-nitime": {
    "urls": [],
    "summaries": []
  },
  "python-nixio": {
    "urls": [],
    "summaries": []
  },
  "python-nmrglue": {
    "urls": [],
    "summaries": []
  },
  "python-noiseprotocol": {
    "urls": [],
    "summaries": []
  },
  "python-normality": {
    "urls": [],
    "summaries": []
  },
  "python-nose2": {
    "urls": [],
    "summaries": []
  },
  "python-notebook": {
    "urls": [],
    "summaries": []
  },
  "python-notebook-shim": {
    "urls": [],
    "summaries": []
  },
  "python-notify2": {
    "urls": [
      "https://bugzilla.redhat.com/show_bug.cgi?id=2341175"
    ],
    "summaries": [
      "python-notify2: FTBFS in Fedora rawhide/f42"
    ]
  },
  "python-numcodecs": {
    "urls": [],
    "summaries": []
  },
  "python-numexpr": {
    "urls": [
      "https://bugzilla.redhat.com/show_bug.cgi?id=2359520"
    ],
    "summaries": [
      "python-numexpr fails to build with Python 3.14: 8 errors: ValueError: operands could not be broadcast together with shapes (1000000,) (0,)  2 failures: AssertionError: sys.getrefcount(a) == 2"
    ]
  },
  "python-numpoly": {
    "urls": [],
    "summaries": []
  },
  "python-numpy-stl": {
    "urls": [],
    "summaries": []
  },
  "python-numpydoc": {
    "urls": [],
    "summaries": []
  },
  "python-odata-query": {
    "urls": [],
    "summaries": []
  },
  "python-ofxparse": {
    "urls": [],
    "summaries": []
  },
  "python-olefile": {
    "urls": [],
    "summaries": []
  },
  "python-oletools": {
    "urls": [],
    "summaries": []
  },
  "python-ollama": {
    "urls": [],
    "summaries": []
  },
  "python-openapi-schema-validator": {
    "urls": [],
    "summaries": []
  },
  "python-openapi-spec-validator": {
    "urls": [],
    "summaries": []
  },
  "python-openqa_client": {
    "urls": [],
    "summaries": []
  },
  "python-opensearch-py": {
    "urls": [],
    "summaries": []
  },
  "python-openshift": {
    "urls": [],
    "summaries": []
  },
  "python-openslide": {
    "urls": [],
    "summaries": []
  },
  "python-openstackdocstheme": {
    "urls": [],
    "summaries": []
  },
  "python-openstacksdk": {
    "urls": [],
    "summaries": []
  },
  "python-openstep-plist": {
    "urls": [],
    "summaries": []
  },
  "python-opfunu": {
    "urls": [],
    "summaries": []
  },
  "python-opnsense": {
    "urls": [],
    "summaries": []
  },
  "python-orjson": {
    "urls": [],
    "summaries": []
  },
  "python-os-client-config": {
    "urls": [],
    "summaries": []
  },
  "python-os-service-types": {
    "urls": [],
    "summaries": []
  },
  "python-os-testr": {
    "urls": [],
    "summaries": []
  },
  "python-osc-lib": {
    "urls": [
      "https://bugzilla.redhat.com/show_bug.cgi?id=2351387"
    ],
    "summaries": [
      "python-osc-lib fails to build with Python 3.14: testtools.matchers._impl.MismatchError in 4 tests"
    ]
  },
  "python-oslo-concurrency": {
    "urls": [],
    "summaries": []
  },
  "python-oslo-config": {
    "urls": [],
    "summaries": []
  },
  "python-oslo-context": {
    "urls": [],
    "summaries": []
  },
  "python-oslo-i18n": {
    "urls": [],
    "summaries": []
  },
  "python-oslo-log": {
    "urls": [],
    "summaries": []
  },
  "python-oslo-metrics": {
    "urls": [],
    "summaries": []
  },
  "python-oslo-serialization": {
    "urls": [],
    "summaries": []
  },
  "python-oslo-utils": {
    "urls": [],
    "summaries": []
  },
  "python-oslotest": {
    "urls": [],
    "summaries": []
  },
  "python-osrf-pycommon": {
    "urls": [],
    "summaries": []
  },
  "python-overpy": {
    "urls": [],
    "summaries": []
  },
  "python-packvers": {
    "urls": [
      "https://bugzilla.redhat.com/show_bug.cgi?id=2341178"
    ],
    "summaries": [
      "python-packvers: FTBFS in Fedora rawhide/f42"
    ]
  },
  "python-paginate": {
    "urls": [
      "https://bugzilla.redhat.com/show_bug.cgi?id=2354116"
    ],
    "summaries": [
      "python-paginate FTBFS due to missing tox configuration"
    ]
  },
  "python-pamela": {
    "urls": [],
    "summaries": []
  },
  "python-pandas": {
    "urls": [
      "https://bugzilla.redhat.com/show_bug.cgi?id=2341179"
    ],
    "summaries": [
      "python-pandas: FTBFS in Fedora rawhide/f42"
    ]
  },
  "python-paperwork-backend": {
    "urls": [],
    "summaries": []
  },
  "python-paramiko": {
    "urls": [],
    "summaries": []
  },
  "python-pari-jupyter": {
    "urls": [],
    "summaries": []
  },
  "python-parse_type": {
    "urls": [],
    "summaries": []
  },
  "python-parsel": {
    "urls": [],
    "summaries": []
  },
  "python-parsimonious": {
    "urls": [],
    "summaries": []
  },
  "python-parsley": {
    "urls": [],
    "summaries": []
  },
  "python-parso": {
    "urls": [],
    "summaries": []
  },
  "python-pass-import": {
    "urls": [],
    "summaries": []
  },
  "python-paste-script": {
    "urls": [],
    "summaries": []
  },
  "python-pathos": {
    "urls": [],
    "summaries": []
  },
  "python-pathtools": {
    "urls": [],
    "summaries": []
  },
  "python-patsy": {
    "urls": [],
    "summaries": []
  },
  "python-pbr": {
    "urls": [],
    "summaries": []
  },
  "python-peewee": {
    "urls": [],
    "summaries": []
  },
  "python-pelican": {
    "urls": [],
    "summaries": []
  },
  "python-pendulum": {
    "urls": [],
    "summaries": []
  },
  "python-periodictable": {
    "urls": [],
    "summaries": []
  },
  "python-photutils": {
    "urls": [],
    "summaries": []
  },
  "python-pika": {
    "urls": [
      "https://bugzilla.redhat.com/show_bug.cgi?id=2351384"
    ],
    "summaries": [
      "python-pika fails to build with Python 3.14: RuntimeError: There is no current event loop in thread 'MainThread'."
    ]
  },
  "python-pikepdf": {
    "urls": [
      "https://bugzilla.redhat.com/show_bug.cgi?id=2359815"
    ],
    "summaries": [
      "python-pikepdf fails to build with Python 3.14: Test failures related to refcounting"
    ]
  },
  "python-pip": {
    "urls": [
      "https://bugzilla.redhat.com/show_bug.cgi?id=2335909"
    ],
    "summaries": [
      "python-pip fails to build with Python 3.14: AssertionError: assert 'file:/tmp/file' == 'file:///tmp/file'"
    ]
  },
  "python-pip-requirements-parser": {
    "urls": [],
    "summaries": []
  },
  "python-pipdeptree": {
    "urls": [
      "https://bugzilla.redhat.com/show_bug.cgi?id=2365874"
    ],
    "summaries": [
      "python-pipdeptree fails to build with Python 3.14: TypeError: _Formatter.__init__() got an unexpected keyword argument 'prefix_chars'"
    ]
  },
  "python-pkg-depgraph": {
    "urls": [],
    "summaries": []
  },
  "python-pkginfo": {
    "urls": [],
    "summaries": []
  },
  "python-pkginfo2": {
    "urls": [],
    "summaries": []
  },
  "python-plaster": {
    "urls": [],
    "summaries": []
  },
  "python-plaster-pastedeploy": {
    "urls": [],
    "summaries": []
  },
  "python-poi-tracker": {
    "urls": [],
    "summaries": []
  },
  "python-pox": {
    "urls": [],
    "summaries": []
  },
  "python-praw": {
    "urls": [
      "https://bugzilla.redhat.com/show_bug.cgi?id=2342562"
    ],
    "summaries": [
      "python-praw fails to build with Python 3.14: RuntimeError: There is no current event loop in thread 'MainThread'."
    ]
  },
  "python-priority": {
    "urls": [
      "https://bugzilla.redhat.com/show_bug.cgi?id=2341182"
    ],
    "summaries": [
      "python-priority: FTBFS in Fedora rawhide/f42"
    ]
  },
  "python-proton-core": {
    "urls": [],
    "summaries": []
  },
  "python-psycopg2": {
    "urls": [],
    "summaries": []
  },
  "python-pudb": {
    "urls": [
      "https://bugzilla.redhat.com/show_bug.cgi?id=2365643"
    ],
    "summaries": [
      "python-pudb fails to build with Python 3.14: ImportError: cannot import name 'format_exception' from 'pudb.lowlevel'"
    ]
  },
  "python-pure-eval": {
    "urls": [],
    "summaries": []
  },
  "python-pure-protobuf": {
    "urls": [
      "https://bugzilla.redhat.com/show_bug.cgi?id=2322710"
    ],
    "summaries": [
      "python-pure-protobuf fails to build with Python 3.14: ImportError: cannot import name 'ByteString' from 'typing'"
    ]
  },
  "python-puzpy": {
    "urls": [],
    "summaries": []
  },
  "python-pvc": {
    "urls": [],
    "summaries": []
  },
  "python-py3nvml": {
    "urls": [],
    "summaries": []
  },
  "python-pyahocorasick": {
    "urls": [],
    "summaries": []
  },
  "python-pyairvisual": {
    "urls": [],
    "summaries": []
  },
  "python-pyarlo": {
    "urls": [],
    "summaries": []
  },
  "python-pyasn1": {
    "urls": [],
    "summaries": []
  },
  "python-pybtex": {
    "urls": [],
    "summaries": []
  },
  "python-pybtex-docutils": {
    "urls": [],
    "summaries": []
  },
  "python-pycares": {
    "urls": [],
    "summaries": []
  },
  "python-pycec": {
    "urls": [
      "https://bugzilla.redhat.com/show_bug.cgi?id=2327973"
    ],
    "summaries": [
      "python-pycec fails to build with Python 3.14: RuntimeError: There is no current event loop in thread 'MainThread'."
    ]
  },
  "python-pydantic": {
    "urls": [],
    "summaries": []
  },
  "python-pydantic-core": {
    "urls": [
      "https://bugzilla.redhat.com/show_bug.cgi?id=2325425"
    ],
    "summaries": [
      "python-pydantic-core fails to build with Python 3.14: AssertionError: Regex pattern did not match. + AttributeError: module 'typing' has no attribute 'ByteString'"
    ]
  },
  "python-pydantic-settings": {
    "urls": [],
    "summaries": []
  },
  "python-pydata-sphinx-theme": {
    "urls": [],
    "summaries": []
  },
  "python-pydepsdev": {
    "urls": [],
    "summaries": []
  },
  "python-pydocstyle": {
    "urls": [],
    "summaries": []
  },
  "python-pydoctor": {
    "urls": [],
    "summaries": []
  },
  "python-pyelectro": {
    "urls": [],
    "summaries": []
  },
  "python-pyemd": {
    "urls": [
      "https://bugzilla.redhat.com/show_bug.cgi?id=2319698"
    ],
    "summaries": [
      "python-pyemd fails to build with setuptools 74+"
    ]
  },
  "python-pyerfa": {
    "urls": [],
    "summaries": []
  },
  "python-pyforgejo": {
    "urls": [],
    "summaries": []
  },
  "python-pyfzf": {
    "urls": [],
    "summaries": []
  },
  "python-pyghmi": {
    "urls": [],
    "summaries": []
  },
  "python-pygit2": {
    "urls": [],
    "summaries": []
  },
  "python-pygmars": {
    "urls": [],
    "summaries": []
  },
  "python-pygments": {
    "urls": [],
    "summaries": []
  },
  "python-pygments-git": {
    "urls": [],
    "summaries": []
  },
  "python-pygmtools": {
    "urls": [],
    "summaries": []
  },
  "python-pygraphviz": {
    "urls": [],
    "summaries": []
  },
  "python-pykcs11": {
    "urls": [],
    "summaries": []
  },
  "python-pykeepass": {
    "urls": [],
    "summaries": []
  },
  "python-pymacaroons-pynacl": {
    "urls": [],
    "summaries": []
  },
  "python-pymapvbvd": {
    "urls": [],
    "summaries": []
  },
  "python-pymatreader": {
    "urls": [],
    "summaries": []
  },
  "python-pymaven-patch": {
    "urls": [],
    "summaries": []
  },
  "python-pymdown-extensions": {
    "urls": [
      "https://bugzilla.redhat.com/show_bug.cgi?id=2350300",
      "https://bugzilla.redhat.com/show_bug.cgi?id=2336948"
    ],
    "summaries": [
      "Heads-up: python-pymdown-extensions fails to build with python-pygments 2.19.1 on Fedora 43",
      "python-pymdown-extensions fails to build with Python 3.14: TestAbsolute.test_relative_path and TestAbsoluteFileScheme.test_relative_path AssertionErrors"
    ]
  },
  "python-pymediawiki": {
    "urls": [],
    "summaries": []
  },
  "python-pymeeus": {
    "urls": [
      "https://bugzilla.redhat.com/show_bug.cgi?id=2341186"
    ],
    "summaries": [
      "python-pymeeus: FTBFS in Fedora rawhide/f42"
    ]
  },
  "python-pymemcache": {
    "urls": [],
    "summaries": []
  },
  "python-pymochad": {
    "urls": [],
    "summaries": []
  },
  "python-pymongo": {
    "urls": [
      "https://bugzilla.redhat.com/show_bug.cgi?id=2356166",
      "https://bugzilla.redhat.com/show_bug.cgi?id=2341188"
    ],
    "summaries": [
      "python-pymongo fails to build with Python 3.14: DeprecationWarning: 'asyncio.iscoroutinefunction' and 'asyncio.get_event_loop_policy' is deprecated and slated for removal in Python 3.16",
      "python-pymongo: FTBFS in Fedora rawhide/f42"
    ]
  },
  "python-pymssql": {
    "urls": [],
    "summaries": []
  },
  "python-pynetdicom": {
    "urls": [],
    "summaries": []
  },
  "python-pynn": {
    "urls": [],
    "summaries": []
  },
  "python-pyocr": {
    "urls": [],
    "summaries": []
  },
  "python-pyopencl": {
    "urls": [
      "https://bugzilla.redhat.com/show_bug.cgi?id=2341190"
    ],
    "summaries": [
      "python-pyopencl: FTBFS in Fedora rawhide/f42"
    ]
  },
  "python-pyopengl": {
    "urls": [
      "https://bugzilla.redhat.com/show_bug.cgi?id=2341191"
    ],
    "summaries": [
      "python-pyopengl: FTBFS in Fedora rawhide/f42"
    ]
  },
  "python-pyopengltk": {
    "urls": [],
    "summaries": []
  },
  "python-pypdf": {
    "urls": [],
    "summaries": []
  },
  "python-pyperclip": {
    "urls": [],
    "summaries": []
  },
  "python-pypet": {
    "urls": [
      "https://bugzilla.redhat.com/show_bug.cgi?id=2341192"
    ],
    "summaries": [
      "python-pypet: FTBFS in Fedora rawhide/f42"
    ]
  },
  "python-pyphi": {
    "urls": [
      "https://bugzilla.redhat.com/show_bug.cgi?id=2341193"
    ],
    "summaries": [
      "python-pyphi: FTBFS in Fedora rawhide/f42"
    ]
  },
  "python-pyproject-api": {
    "urls": [],
    "summaries": []
  },
  "python-pyqtgraph": {
    "urls": [],
    "summaries": []
  },
  "python-pyquery": {
    "urls": [],
    "summaries": []
  },
  "python-pyramid": {
    "urls": [],
    "summaries": []
  },
  "python-pyramid-mako": {
    "urls": [],
    "summaries": []
  },
  "python-pyramid-tm": {
    "urls": [],
    "summaries": []
  },
  "python-pyregion": {
    "urls": [],
    "summaries": []
  },
  "python-pyriemann": {
    "urls": [],
    "summaries": []
  },
  "python-pyroaring": {
    "urls": [],
    "summaries": []
  },
  "python-pysam": {
    "urls": [],
    "summaries": []
  },
  "python-pysaml2": {
    "urls": [
      "https://bugzilla.redhat.com/show_bug.cgi?id=2341199"
    ],
    "summaries": [
      "python-pysaml2: FTBFS in Fedora rawhide/f42"
    ]
  },
  "python-pysb": {
    "urls": [],
    "summaries": []
  },
  "python-pyscaffold": {
    "urls": [],
    "summaries": []
  },
  "python-pyside6": {
    "urls": [
      "https://bugzilla.redhat.com/show_bug.cgi?id=2325444"
    ],
    "summaries": [
      "python-pyside6 fails to build with Python 3.14: TypeError: Formatter.formatannotation() got an unexpected keyword argument 'quote_annotation_strings'"
    ]
  },
  "python-pyspike": {
    "urls": [],
    "summaries": []
  },
  "python-pysqueezebox": {
    "urls": [],
    "summaries": []
  },
  "python-pysrt": {
    "urls": [],
    "summaries": []
  },
  "python-pystemd": {
    "urls": [],
    "summaries": []
  },
  "python-pystray": {
    "urls": [],
    "summaries": []
  },
  "python-pyte": {
    "urls": [],
    "summaries": []
  },
  "python-pytesseract": {
    "urls": [
      "https://bugzilla.redhat.com/show_bug.cgi?id=2341201"
    ],
    "summaries": [
      "python-pytesseract: FTBFS in Fedora rawhide/f42"
    ]
  },
  "python-pytest-aiohttp": {
    "urls": [
      "https://bugzilla.redhat.com/show_bug.cgi?id=2339466"
    ],
    "summaries": [
      "python-pytest-aiohttp fails to build with Python 3.14: DeprecationWarning: 'asyncio.get_event_loop_policy' is deprecated and slated for removal in Python 3.16"
    ]
  },
  "python-pytest-asyncio": {
    "urls": [
      "https://bugzilla.redhat.com/show_bug.cgi?id=2342564"
    ],
    "summaries": [
      "python-pytest-asyncio fails to build with Python 3.14: DeprecationWarning: 'asyncio.get_event_loop_policy' is deprecated and slated for removal in Python 3.16"
    ]
  },
  "python-pytest-bdd": {
    "urls": [],
    "summaries": []
  },
  "python-pytest-cid": {
    "urls": [],
    "summaries": []
  },
  "python-pytest-console-scripts": {
    "urls": [],
    "summaries": []
  },
  "python-pytest-datadir": {
    "urls": [],
    "summaries": []
  },
  "python-pytest-django": {
    "urls": [],
    "summaries": []
  },
  "python-pytest-httpbin": {
    "urls": [],
    "summaries": []
  },
  "python-pytest-httpserver": {
    "urls": [],
    "summaries": []
  },
  "python-pytest-jupyter": {
    "urls": [],
    "summaries": []
  },
  "python-pytest-localserver": {
    "urls": [],
    "summaries": []
  },
  "python-pytest-lsp": {
    "urls": [
      "https://bugzilla.redhat.com/show_bug.cgi?id=2349451"
    ],
    "summaries": [
      "python-pytest-lsp fails to build with Python 3.14: warnings counts differ, resulting in AssertionError in 3 tests"
    ]
  },
  "python-pytest-ordering": {
    "urls": [],
    "summaries": []
  },
  "python-pytest-regressions": {
    "urls": [],
    "summaries": []
  },
  "python-pytest-sourceorder": {
    "urls": [],
    "summaries": []
  },
  "python-pytest-testinfra": {
    "urls": [
      "https://bugzilla.redhat.com/show_bug.cgi?id=2361631"
    ],
    "summaries": [
      "python-pytest-testinfra FTBFS in rawhide"
    ]
  },
  "python-pytest-timeout": {
    "urls": [],
    "summaries": []
  },
  "python-pytest-tldr": {
    "urls": [],
    "summaries": []
  },
  "python-pytest-xdist": {
    "urls": [],
    "summaries": []
  },
  "python-python-ulid": {
    "urls": [],
    "summaries": []
  },
  "python-pyuca": {
    "urls": [],
    "summaries": []
  },
  "python-pyunormalize": {
    "urls": [],
    "summaries": []
  },
  "python-pyupgrade": {
    "urls": [
      "https://bugzilla.redhat.com/show_bug.cgi?id=2322713"
    ],
    "summaries": [
      "python-pyupgrade fails to build with Python 3.14: AttributeError: module 'ast' has no attribute 'Str'"
    ]
  },
  "python-pyvirtualdisplay": {
    "urls": [],
    "summaries": []
  },
  "python-pyvirtualize": {
    "urls": [],
    "summaries": []
  },
  "python-pyvlx": {
    "urls": [
      "https://bugzilla.redhat.com/show_bug.cgi?id=2327983"
    ],
    "summaries": [
      "python-pyvlx fails to build with Python 3.14: RuntimeError: There is no current event loop in thread 'MainThread'."
    ]
  },
  "python-pyvmomi": {
    "urls": [],
    "summaries": []
  },
  "python-pyvo": {
    "urls": [],
    "summaries": []
  },
  "python-pywt": {
    "urls": [],
    "summaries": []
  },
  "python-qdarkstyle": {
    "urls": [],
    "summaries": []
  },
  "python-qpageview": {
    "urls": [],
    "summaries": []
  },
  "python-qtconsole": {
    "urls": [],
    "summaries": []
  },
  "python-qudida": {
    "urls": [],
    "summaries": []
  },
  "python-qutepart": {
    "urls": [],
    "summaries": []
  },
  "python-random2": {
    "urls": [],
    "summaries": []
  },
  "python-rapidfuzz": {
    "urls": [],
    "summaries": []
  },
  "python-rasterio": {
    "urls": [],
    "summaries": []
  },
  "python-rdflib": {
    "urls": [
      "https://bugzilla.redhat.com/show_bug.cgi?id=2343978",
      "https://bugzilla.redhat.com/show_bug.cgi?id=2336891"
    ],
    "summaries": [
      "python-rdflib fails to build with Python 3.14: AttributeError: term 'value' not in namespace 'http://www.w3.org/1999/02/22-rdf-syntax-ns#'",
      "python-rdflib fails to build with Python 3.14: \"TypeError: '<' not supported between instances of 'Literal' and 'Literal'\""
    ]
  },
  "python-re-assert": {
    "urls": [],
    "summaries": []
  },
  "python-reactivex": {
    "urls": [
      "https://bugzilla.redhat.com/show_bug.cgi?id=2327987"
    ],
    "summaries": [
      "python-reactivex fails to build with Python 3.14: RuntimeError: There is no current event loop in thread 'MainThread'."
    ]
  },
  "python-readability-lxml": {
    "urls": [
      "https://bugzilla.redhat.com/show_bug.cgi?id=2323185"
    ],
    "summaries": [
      "python-readability-lxml fails to build with Python 3.14: _pickle.PicklingError: Can't pickle <function TestArticleOnly.test_many_repeated_spaces at 0x7ff0ea064460>: it's not the same object as tests.test_article_only.TestArticleOnly.test_many_repeated_spa"
    ]
  },
  "python-readme-renderer": {
    "urls": [],
    "summaries": []
  },
  "python-recordclass": {
    "urls": [
      "https://bugzilla.redhat.com/show_bug.cgi?id=2327968"
    ],
    "summaries": [
      "python-recordclass fails to build with Python 3.14: 25 failures, 65 errors in the test suite"
    ]
  },
  "python-redis": {
    "urls": [
      "https://bugzilla.redhat.com/show_bug.cgi?id=2345526"
    ],
    "summaries": [
      "python-redis fails to build with Python 3.14: _pickle.PicklingError: Can't pickle local object <function TestMultiprocessing.test_close_connection_in_child.<locals>.target at 0x7f10027f31c0>"
    ]
  },
  "python-referencing": {
    "urls": [],
    "summaries": []
  },
  "python-reflink": {
    "urls": [],
    "summaries": []
  },
  "python-relatorio": {
    "urls": [],
    "summaries": []
  },
  "python-remoto": {
    "urls": [
      "https://bugzilla.redhat.com/show_bug.cgi?id=2341205"
    ],
    "summaries": [
      "python-remoto: FTBFS in Fedora rawhide/f42"
    ]
  },
  "python-renderspec": {
    "urls": [],
    "summaries": []
  },
  "python-reno": {
    "urls": [],
    "summaries": []
  },
  "python-repomd": {
    "urls": [],
    "summaries": []
  },
  "python-requests": {
    "urls": [],
    "summaries": []
  },
  "python-retry": {
    "urls": [],
    "summaries": []
  },
  "python-rich": {
    "urls": [
      "https://bugzilla.redhat.com/show_bug.cgi?id=2350303",
      "https://bugzilla.redhat.com/show_bug.cgi?id=2339510"
    ],
    "summaries": [
      "Heads-up: python-rich fails to build with python-pygments 2.19.1 on Fedora 43",
      "python-rich fails to build with Python 3.14: 5 test fail"
    ]
  },
  "python-rjsmin": {
    "urls": [],
    "summaries": []
  },
  "python-robot-detection": {
    "urls": [],
    "summaries": []
  },
  "python-robotframework": {
    "urls": [],
    "summaries": []
  },
  "python-roman": {
    "urls": [],
    "summaries": []
  },
  "python-rope": {
    "urls": [
      "https://bugzilla.redhat.com/show_bug.cgi?id=2351391"
    ],
    "summaries": [
      "python-rope fails to build with Python 3.14: ImportError while loading conftest '/builddir/build/BUILD/python-rope-1.13.0-build/rope-1.13.0/ropetest/conftest.py'.: AssertionError: assert sys.version_info < (3, 8)"
    ]
  },
  "python-rosdep": {
    "urls": [
      "https://bugzilla.redhat.com/show_bug.cgi?id=2341207"
    ],
    "summaries": [
      "python-rosdep: FTBFS in Fedora rawhide/f42"
    ]
  },
  "python-rosdistro": {
    "urls": [],
    "summaries": []
  },
  "python-rospkg": {
    "urls": [],
    "summaries": []
  },
  "python-routes": {
    "urls": [],
    "summaries": []
  },
  "python-rpds-py": {
    "urls": [],
    "summaries": []
  },
  "python-rq": {
    "urls": [
      "https://bugzilla.redhat.com/show_bug.cgi?id=2342234"
    ],
    "summaries": [
      "python-rq fails to build with Python 3.14: test_worker.py::HerokuWorkerShutdownTestCase::test_handle_shutdown_request shuts down the whole build"
    ]
  },
  "python-rsd-lib": {
    "urls": [],
    "summaries": []
  },
  "python-rsdclient": {
    "urls": [],
    "summaries": []
  },
  "python-rstcheck": {
    "urls": [
      "https://bugzilla.redhat.com/show_bug.cgi?id=2322705"
    ],
    "summaries": [
      "python-rstcheck fails to build with Python 3.14: AttributeError: 'Constant' object has no attribute 's'"
    ]
  },
  "python-rstcheck-core": {
    "urls": [],
    "summaries": []
  },
  "python-rx": {
    "urls": [
      "https://bugzilla.redhat.com/show_bug.cgi?id=2327979"
    ],
    "summaries": [
      "python-rx fails to build with Python 3.14: RuntimeError: There is no current event loop in thread 'MainThread'."
    ]
  },
  "python-s3transfer": {
    "urls": [
      "https://bugzilla.redhat.com/show_bug.cgi?id=2326933"
    ],
    "summaries": [
      "python-s3transfer fails to build with Python 3.14: _pickle.PicklingError: Can't pickle local object <class 'tests.unit.test_compat.TestBaseManager.create_pid_manager.<locals>.PIDManager'>"
    ]
  },
  "python-sane": {
    "urls": [],
    "summaries": []
  },
  "python-saneyaml": {
    "urls": [],
    "summaries": []
  },
  "python-scikit-build": {
    "urls": [],
    "summaries": []
  },
  "python-scikit-build-core": {
    "urls": [],
    "summaries": []
  },
  "python-scikit-learn": {
    "urls": [
      "https://bugzilla.redhat.com/show_bug.cgi?id=2353125"
    ],
    "summaries": [
      "python-scikit-learn fails to build with Python 3.14: AssertionError in test_warn_if_metric_bool_data_no_bool and test_open_openml_url_retry_on_network_error"
    ]
  },
  "python-scikit-uplift": {
    "urls": [],
    "summaries": []
  },
  "python-scipy-doctest": {
    "urls": [],
    "summaries": []
  },
  "python-sciunit": {
    "urls": [],
    "summaries": []
  },
  "python-seaborn": {
    "urls": [],
    "summaries": []
  },
  "python-sep": {
    "urls": [],
    "summaries": []
  },
  "python-service-identity": {
    "urls": [],
    "summaries": []
  },
  "python-setproctitle": {
    "urls": [],
    "summaries": []
  },
  "python-sexpdata": {
    "urls": [],
    "summaries": []
  },
  "python-shodan": {
    "urls": [],
    "summaries": []
  },
  "python-simframe": {
    "urls": [
      "https://bugzilla.redhat.com/show_bug.cgi?id=2352552"
    ],
    "summaries": [
      "python-simframe fails to build with Python 3.14: TypeError: cannot pickle 'itertools.cycle' object"
    ]
  },
  "python-simple-salesforce": {
    "urls": [],
    "summaries": []
  },
  "python-simplejson": {
    "urls": [],
    "summaries": []
  },
  "python-sklearn-genetic": {
    "urls": [],
    "summaries": []
  },
  "python-sklearn-genetic-opt": {
    "urls": [],
    "summaries": []
  },
  "python-slackclient": {
    "urls": [],
    "summaries": []
  },
  "python-slixmpp": {
    "urls": [],
    "summaries": []
  },
  "python-smart_open": {
    "urls": [],
    "summaries": []
  },
  "python-smartypants": {
    "urls": [],
    "summaries": []
  },
  "python-snuggs": {
    "urls": [],
    "summaries": []
  },
  "python-social-auth-core": {
    "urls": [
      "https://bugzilla.redhat.com/show_bug.cgi?id=2341215",
      "https://bugzilla.redhat.com/show_bug.cgi?id=2328010"
    ],
    "summaries": [
      "python-social-auth-core: FTBFS in Fedora rawhide/f42",
      "python-social-auth-core fails to build with Python 3.14: 'SSLContext' object has no attribute 'close'"
    ]
  },
  "python-socks": {
    "urls": [],
    "summaries": []
  },
  "python-sortedcontainers": {
    "urls": [],
    "summaries": []
  },
  "python-soupsieve": {
    "urls": [],
    "summaries": []
  },
  "python-sphinx": {
    "urls": [],
    "summaries": []
  },
  "python-sphinx-argparse": {
    "urls": [],
    "summaries": []
  },
  "python-sphinx-argparse-cli": {
    "urls": [],
    "summaries": []
  },
  "python-sphinx-autoapi": {
    "urls": [
      "https://bugzilla.redhat.com/show_bug.cgi?id=2341216"
    ],
    "summaries": [
      "python-sphinx-autoapi: FTBFS in Fedora rawhide/f42"
    ]
  },
  "python-sphinx-basic-ng": {
    "urls": [],
    "summaries": []
  },
  "python-sphinx-design": {
    "urls": [],
    "summaries": []
  },
  "python-sphinx-gallery": {
    "urls": [],
    "summaries": []
  },
  "python-sphinx-hoverxref": {
    "urls": [],
    "summaries": []
  },
  "python-sphinx-jsonschema": {
    "urls": [],
    "summaries": []
  },
  "python-sphinx-lint": {
    "urls": [],
    "summaries": []
  },
  "python-sphinx-math-dollar": {
    "urls": [],
    "summaries": []
  },
  "python-sphinx-notfound-page": {
    "urls": [],
    "summaries": []
  },
  "python-sphinx-pytest": {
    "urls": [],
    "summaries": []
  },
  "python-sphinx-removed-in": {
    "urls": [],
    "summaries": []
  },
  "python-sphinx-reredirects": {
    "urls": [],
    "summaries": []
  },
  "python-sphinx-sitemap": {
    "urls": [],
    "summaries": []
  },
  "python-sphinx-tabs": {
    "urls": [],
    "summaries": []
  },
  "python-sphinx_rtd_theme": {
    "urls": [],
    "summaries": []
  },
  "python-sphinxcontrib-apidoc": {
    "urls": [],
    "summaries": []
  },
  "python-sphinxcontrib-autoprogram": {
    "urls": [],
    "summaries": []
  },
  "python-sphinxcontrib-bibtex": {
    "urls": [],
    "summaries": []
  },
  "python-sphinxcontrib-devhelp": {
    "urls": [],
    "summaries": []
  },
  "python-sphinxcontrib-htmlhelp": {
    "urls": [],
    "summaries": []
  },
  "python-sphinxcontrib-jquery": {
    "urls": [],
    "summaries": []
  },
  "python-sphinxcontrib-programoutput": {
    "urls": [],
    "summaries": []
  },
  "python-sphinxcontrib-qthelp": {
    "urls": [],
    "summaries": []
  },
  "python-sphinxcontrib-serializinghtml": {
    "urls": [],
    "summaries": []
  },
  "python-sphinxcontrib-trio": {
    "urls": [],
    "summaries": []
  },
  "python-sphinxcontrib-websupport": {
    "urls": [],
    "summaries": []
  },
  "python-sphinxtesters": {
    "urls": [],
    "summaries": []
  },
  "python-sphinxygen": {
    "urls": [],
    "summaries": []
  },
  "python-spotipy": {
    "urls": [],
    "summaries": []
  },
  "python-sqlalchemy": {
    "urls": [
      "https://bugzilla.redhat.com/show_bug.cgi?id=2350336"
    ],
    "summaries": [
      "python-sqlalchemy fails to build with Python 3.14: _pickle.PicklingError: Can't pickle local object <function profile_memory.<locals>.decorate.<locals>.profile at 0x7f0f43d5d170> + typing + more"
    ]
  },
  "python-sqlalchemy1.4": {
    "urls": [
      "https://bugzilla.redhat.com/show_bug.cgi?id=2327976"
    ],
    "summaries": [
      "python-sqlalchemy1.4 fails to build with Python 3.14: RuntimeError: There is no current event loop in thread 'MainThread'."
    ]
  },
  "python-sqlalchemy_schemadisplay": {
    "urls": [],
    "summaries": []
  },
  "python-ssdeep": {
    "urls": [],
    "summaries": []
  },
  "python-ssh-python": {
    "urls": [
      "https://bugzilla.redhat.com/show_bug.cgi?id=2350333"
    ],
    "summaries": [
      "python-ssh-python fails to build with Python 3.14: SessionTest.test_set_timeout: ssh.exceptions.SSHError: (-1, b'Invalid argument in ssh_options_set')"
    ]
  },
  "python-stack-data": {
    "urls": [
      "https://bugzilla.redhat.com/show_bug.cgi?id=2350304",
      "https://bugzilla.redhat.com/show_bug.cgi?id=2345532"
    ],
    "summaries": [
      "Heads-up: python-stack-data fails to build with python-pygments 2.19.1 on Fedora 43",
      "python-stack-data fails to build with Python 3.14: test_example: IndexError: list index out of range"
    ]
  },
  "python-starlette": {
    "urls": [],
    "summaries": []
  },
  "python-stdlibs": {
    "urls": [
      "https://bugzilla.redhat.com/show_bug.cgi?id=2359504"
    ],
    "summaries": [
      "python-stdlibs fails to build with Python 3.14: AssertionError: Items in the second set but not the first: '_hmac' '_ast_unparse' '_types'"
    ]
  },
  "python-stdnum": {
    "urls": [],
    "summaries": []
  },
  "python-steam": {
    "urls": [
      "https://bugzilla.redhat.com/show_bug.cgi?id=2341218"
    ],
    "summaries": [
      "python-steam: FTBFS in Fedora rawhide/f42"
    ]
  },
  "python-stem": {
    "urls": [],
    "summaries": []
  },
  "python-stestr": {
    "urls": [],
    "summaries": []
  },
  "python-stevedore": {
    "urls": [],
    "summaries": []
  },
  "python-streamlink": {
    "urls": [
      "https://bugzilla.redhat.com/show_bug.cgi?id=2353127"
    ],
    "summaries": [
      "python-streamlink fails to build with Python 3.14: test_deprecated: AssetionError: Left contains one more item: <warnings.WarningMessage object at 0x7fd80afa3410>"
    ]
  },
  "python-string_utils": {
    "urls": [],
    "summaries": []
  },
  "python-succulent": {
    "urls": [],
    "summaries": []
  },
  "python-surt": {
    "urls": [],
    "summaries": []
  },
  "python-sushy": {
    "urls": [],
    "summaries": []
  },
  "python-svg2tikz": {
    "urls": [],
    "summaries": []
  },
  "python-swagger-spec-validator": {
    "urls": [],
    "summaries": []
  },
  "python-swiftclient": {
    "urls": [],
    "summaries": []
  },
  "python-systemd": {
    "urls": [],
    "summaries": []
  },
  "python-tables": {
    "urls": [],
    "summaries": []
  },
  "python-tabulate": {
    "urls": [],
    "summaries": []
  },
  "python-tcx2gpx": {
    "urls": [],
    "summaries": []
  },
  "python-tcxparser": {
    "urls": [],
    "summaries": []
  },
  "python-telnetlib3": {
    "urls": [
      "https://bugzilla.redhat.com/show_bug.cgi?id=2354126"
    ],
    "summaries": [
      "python-telnetlib3 FTBFS due to missing tox configuration"
    ]
  },
  "python-tenacity": {
    "urls": [
      "https://bugzilla.redhat.com/show_bug.cgi?id=2327977"
    ],
    "summaries": [
      "python-tenacity fails to build with Python 3.14: RuntimeError: There is no current event loop in thread 'MainThread'."
    ]
  },
  "python-terminaltables": {
    "urls": [],
    "summaries": []
  },
  "python-teslajsonpy": {
    "urls": [],
    "summaries": []
  },
  "python-testpath": {
    "urls": [],
    "summaries": []
  },
  "python-testtools": {
    "urls": [],
    "summaries": []
  },
  "python-texext": {
    "urls": [],
    "summaries": []
  },
  "python-textdistance": {
    "urls": [],
    "summaries": []
  },
  "python-textile": {
    "urls": [],
    "summaries": []
  },
  "python-textual": {
    "urls": [
      "https://bugzilla.redhat.com/show_bug.cgi?id=2341224"
    ],
    "summaries": [
      "python-textual: FTBFS in Fedora rawhide/f42"
    ]
  },
  "python-threadpoolctl": {
    "urls": [],
    "summaries": []
  },
  "python-tiktoken": {
    "urls": [],
    "summaries": []
  },
  "python-timeout-decorator": {
    "urls": [
      "https://bugzilla.redhat.com/show_bug.cgi?id=2354129"
    ],
    "summaries": [
      "python-timeout-decorator FTBFS due to missing tox configuration"
    ]
  },
  "python-tkrzw": {
    "urls": [],
    "summaries": []
  },
  "python-tld": {
    "urls": [],
    "summaries": []
  },
  "python-token-bucket": {
    "urls": [],
    "summaries": []
  },
  "python-toml": {
    "urls": [],
    "summaries": []
  },
  "python-toolz": {
    "urls": [
      "https://bugzilla.redhat.com/show_bug.cgi?id=2323168"
    ],
    "summaries": [
      "python-toolz fails to build with Python 3.14: AssertionError: is_none: assert should_curry(getattr(operator, k)) == isinstance(v, toolz.curry), k"
    ]
  },
  "python-torch": {
    "urls": [],
    "summaries": []
  },
  "python-tornado": {
    "urls": [
      "https://bugzilla.redhat.com/show_bug.cgi?id=2327969"
    ],
    "summaries": [
      "python-tornado fails to build with Python 3.14: RuntimeError: There is no current event loop in thread 'MainThread'."
    ]
  },
  "python-tosca-parser": {
    "urls": [],
    "summaries": []
  },
  "python-towncrier": {
    "urls": [
      "https://bugzilla.redhat.com/show_bug.cgi?id=2354131"
    ],
    "summaries": [
      "python-towncrier FTBFS due to missing tox configuration"
    ]
  },
  "python-tox": {
    "urls": [],
    "summaries": []
  },
  "python-tox-current-env": {
    "urls": [],
    "summaries": []
  },
  "python-tox-uv": {
    "urls": [],
    "summaries": []
  },
  "python-trailrunner": {
    "urls": [],
    "summaries": []
  },
  "python-traitsui": {
    "urls": [],
    "summaries": []
  },
  "python-transforms3d": {
    "urls": [],
    "summaries": []
  },
  "python-translationstring": {
    "urls": [],
    "summaries": []
  },
  "python-treq": {
    "urls": [],
    "summaries": []
  },
  "python-trio": {
    "urls": [
      "https://bugzilla.redhat.com/show_bug.cgi?id=2345516"
    ],
    "summaries": [
      "python-trio fails to build with Python 3.14: test_ki_protection_doesnt_leave_cyclic_garbage: Left contains one more item: <coroutine object test_ki_protection_doesnt_leave_cyclic_garbage at 0x7fbaa2f162c0>"
    ]
  },
  "python-trio-websocket": {
    "urls": [],
    "summaries": []
  },
  "python-trustme": {
    "urls": [],
    "summaries": []
  },
  "python-trx-python": {
    "urls": [],
    "summaries": []
  },
  "python-tvb-gdist": {
    "urls": [],
    "summaries": []
  },
  "python-twilio": {
    "urls": [
      "https://bugzilla.redhat.com/show_bug.cgi?id=2341229"
    ],
    "summaries": [
      "python-twilio: FTBFS in Fedora rawhide/f42"
    ]
  },
  "python-twisted": {
    "urls": [
      "https://bugzilla.redhat.com/show_bug.cgi?id=2342754"
    ],
    "summaries": [
      "python-twisted fails to build with Python 3.14: RuntimeError: There is no current event loop in thread 'MainThread'. + more"
    ]
  },
  "python-txaio": {
    "urls": [
      "https://bugzilla.redhat.com/show_bug.cgi?id=2327981"
    ],
    "summaries": [
      "python-txaio fails to build with Python 3.14: RuntimeError: There is no current event loop in thread 'MainThread'."
    ]
  },
  "python-typeguard": {
    "urls": [],
    "summaries": []
  },
  "python-typing-extensions": {
    "urls": [
      "https://bugzilla.redhat.com/show_bug.cgi?id=2336937"
    ],
    "summaries": [
      "python-typing-extensions fails to build with Python 3.14: test_drop_in_for_typing: AssertionError: self.assertGreaterEqual(te_all, t_all - exceptions)"
    ]
  },
  "python-typing-inspect": {
    "urls": [
      "https://bugzilla.redhat.com/show_bug.cgi?id=2325455"
    ],
    "summaries": [
      "python-typing-inspect fails to build with Python 3.14: AssertionError: {} != {'x': <class 'int'>, 'y': <class 'int'>}"
    ]
  },
  "python-typing-inspection": {
    "urls": [
      "https://bugzilla.redhat.com/show_bug.cgi?id=2362887"
    ],
    "summaries": [
      "python-typing-inspection fails to build with Python 3.14: AssertionError: test_is_union_does_not_match_uniontype"
    ]
  },
  "python-u-msgpack-python": {
    "urls": [],
    "summaries": []
  },
  "python-ufoLib2": {
    "urls": [],
    "summaries": []
  },
  "python-uharfbuzz": {
    "urls": [],
    "summaries": []
  },
  "python-uranium": {
    "urls": [],
    "summaries": []
  },
  "python-usort": {
    "urls": [],
    "summaries": []
  },
  "python-uswid": {
    "urls": [],
    "summaries": []
  },
  "python-uvloop": {
    "urls": [
      "https://bugzilla.redhat.com/show_bug.cgi?id=2341233",
      "https://bugzilla.redhat.com/show_bug.cgi?id=2326210"
    ],
    "summaries": [
      "python-uvloop: FTBFS in Fedora rawhide/f42",
      "python-uvloop fails to build with Python 3.14: AttributeError: module 'asyncio' has no attribute 'AbstractChildWatcher'"
    ]
  },
  "python-validator-collection": {
    "urls": [],
    "summaries": []
  },
  "python-valkey": {
    "urls": [
      "https://bugzilla.redhat.com/show_bug.cgi?id=2349444"
    ],
    "summaries": [
      "python-valkey fails to build with Python 3.14: _pickle.PicklingError: Can't pickle local object <function TestMultiprocessing.test_close_connection_in_child.<locals>.target at 0x7f5aa68cddd0>"
    ]
  },
  "python-vascpy": {
    "urls": [],
    "summaries": []
  },
  "python-vcrpy": {
    "urls": [
      "https://bugzilla.redhat.com/show_bug.cgi?id=2342566"
    ],
    "summaries": [
      "python-vcrpy fails to build with Python 3.14: DeprecationWarning: 'asyncio.iscoroutinefunction' is deprecated and slated for removal in Python 3.16"
    ]
  },
  "python-versioningit": {
    "urls": [],
    "summaries": []
  },
  "python-virtualenv-clone": {
    "urls": [],
    "summaries": []
  },
  "python-w3lib": {
    "urls": [],
    "summaries": []
  },
  "python-warlock": {
    "urls": [
      "https://bugzilla.redhat.com/show_bug.cgi?id=2354135"
    ],
    "summaries": [
      "python-warlock FTBFS due to missing tox configuration"
    ]
  },
  "python-watchdog": {
    "urls": [],
    "summaries": []
  },
  "python-watchfiles": {
    "urls": [
      "https://bugzilla.redhat.com/show_bug.cgi?id=2339462"
    ],
    "summaries": [
      "python-watchfiles fails to build with Python 3.14: DeprecationWarning: 'asyncio.set_event_loop' is deprecated and slated for removal in Python 3.16"
    ]
  },
  "python-wcag-contrast-ratio": {
    "urls": [],
    "summaries": []
  },
  "python-wcwidth": {
    "urls": [],
    "summaries": []
  },
  "python-webob": {
    "urls": [
      "https://bugzilla.redhat.com/show_bug.cgi?id=2365645"
    ],
    "summaries": [
      "python-webob fails to build with Python 3.14: test_interrupted_request: AssertionError: False disconnect alert"
    ]
  },
  "python-webscrapbook": {
    "urls": [
      "https://bugzilla.redhat.com/show_bug.cgi?id=2326915"
    ],
    "summaries": [
      "python-webscrapbook fails to build with Python 3.14: 60x AssertionError in the test suite"
    ]
  },
  "python-webtest": {
    "urls": [],
    "summaries": []
  },
  "python-whoosh": {
    "urls": [],
    "summaries": []
  },
  "python-wikitcms": {
    "urls": [],
    "summaries": []
  },
  "python-wled": {
    "urls": [],
    "summaries": []
  },
  "python-wordcloud": {
    "urls": [
      "https://bugzilla.redhat.com/show_bug.cgi?id=2335908"
    ],
    "summaries": [
      "python-wordcloud fails to build with Python 3.14: test_cli_as_executable: AssertionError: assert expected_output in out if ret_code == 0 else err"
    ]
  },
  "python-wsgidav": {
    "urls": [],
    "summaries": []
  },
  "python-xmlschema": {
    "urls": [],
    "summaries": []
  },
  "python-xrst": {
    "urls": [],
    "summaries": []
  },
  "python-xvfbwrapper": {
    "urls": [],
    "summaries": []
  },
  "python-yapf": {
    "urls": [],
    "summaries": []
  },
  "python-yappi": {
    "urls": [
      "https://bugzilla.redhat.com/show_bug.cgi?id=2323160"
    ],
    "summaries": [
      "python-yappi fails to build with Python 3.14: error: invalid use of incomplete typedef \u2018PyGenObject\u2019 {aka \u2018struct _PyGenObject\u2019}"
    ]
  },
  "python-yaql": {
    "urls": [],
    "summaries": []
  },
  "python-zarr": {
    "urls": [],
    "summaries": []
  },
  "python-zc-lockfile": {
    "urls": [],
    "summaries": []
  },
  "python-zeep": {
    "urls": [],
    "summaries": []
  },
  "python-zict": {
    "urls": [
      "https://bugzilla.redhat.com/show_bug.cgi?id=2328012"
    ],
    "summaries": [
      "python-zict fails to build with Python 3.14: test_stress_different_keys_threadsafe Timeout"
    ]
  },
  "python-zoidberg": {
    "urls": [],
    "summaries": []
  },
  "python-zombie-imp": {
    "urls": [],
    "summaries": []
  },
  "python-zope-configuration": {
    "urls": [],
    "summaries": []
  },
  "python-zope-deprecation": {
    "urls": [],
    "summaries": []
  },
  "python-zope-event": {
    "urls": [],
    "summaries": []
  },
  "python-zope-exceptions": {
    "urls": [
      "https://bugzilla.redhat.com/show_bug.cgi?id=2341240"
    ],
    "summaries": [
      "python-zope-exceptions: FTBFS in Fedora rawhide/f42"
    ]
  },
  "python-zope-i18nmessageid": {
    "urls": [],
    "summaries": []
  },
  "python-zope-schema": {
    "urls": [],
    "summaries": []
  },
  "python-zope-testrunner": {
    "urls": [
      "https://bugzilla.redhat.com/show_bug.cgi?id=2335907"
    ],
    "summaries": [
      "python-zope-testrunner fails to build with Python 3.14: difference in the asserted content in testrunner-edge-cases.rst"
    ]
  },
  "python-zstarfile": {
    "urls": [],
    "summaries": []
  },
  "python3-exiv2": {
    "urls": [
      "https://bugzilla.redhat.com/show_bug.cgi?id=2354137"
    ],
    "summaries": [
      "python3-exiv2 FTBFS due to missing tox configuration"
    ]
  },
  "python3-saml": {
    "urls": [],
    "summaries": []
  },
  "pywbem": {
    "urls": [],
    "summaries": []
  },
  "qgis": {
    "urls": [],
    "summaries": []
  },
  "qpid-proton": {
    "urls": [
      "https://bugzilla.redhat.com/show_bug.cgi?id=2327999"
    ],
    "summaries": [
      "qpid-proton fails to build with Python 3.14: error: File not found: /builddir/build/BUILD/qpid-proton-0.38.0-build/BUILDROOT/usr/share/proton/docs/api-py"
    ]
  },
  "qtile": {
    "urls": [
      "https://bugzilla.redhat.com/show_bug.cgi?id=2328711"
    ],
    "summaries": [
      "qtile fails to build with Python 3.14: _pickle.PicklingError: Can't pickle local object <function TestManager.start.<locals>.run_qtile at 0x7f9c5918fed0>"
    ]
  },
  "rebase-helper": {
    "urls": [
      "https://bugzilla.redhat.com/show_bug.cgi?id=2352551"
    ],
    "summaries": [
      "rebase-helper fails to build with Python 3.14: AssertionError in TestCLI.test_cli_unit and TestConfig.test_merge"
    ]
  },
  "relval": {
    "urls": [],
    "summaries": []
  },
  "resalloc": {
    "urls": [],
    "summaries": []
  },
  "resultsdb_conventions": {
    "urls": [],
    "summaries": []
  },
  "root": {
    "urls": [],
    "summaries": []
  },
  "rpkg-util": {
    "urls": [],
    "summaries": []
  },
  "rpm-head-signing": {
    "urls": [],
    "summaries": []
  },
  "rpmconf": {
    "urls": [],
    "summaries": []
  },
  "rust2rpm": {
    "urls": [],
    "summaries": []
  },
  "salt-lint": {
    "urls": [],
    "summaries": []
  },
  "satyr": {
    "urls": [
      "https://bugzilla.redhat.com/show_bug.cgi?id=2325452"
    ],
    "summaries": [
      "satyr fails to build with Python 3.14: _pickle.PicklingError: Can't pickle local object <function TestDistances.test_distances_part_parallel.<locals>.do_test.<locals>.compute_part at 0x7f7f845f2560>"
    ]
  },
  "scapy": {
    "urls": [],
    "summaries": []
  },
  "scidavis": {
    "urls": [],
    "summaries": []
  },
  "scipy": {
    "urls": [
      "https://bugzilla.redhat.com/show_bug.cgi?id=2341927"
    ],
    "summaries": [
      "scipy fails to build with Python 3.14: TestSystematic::test_bessely, TestSystematic::test_bessely_int and TestSystematic::test_wrightomega fail"
    ]
  },
  "sherlock-project": {
    "urls": [],
    "summaries": []
  },
  "shybrid": {
    "urls": [],
    "summaries": []
  },
  "signon-glib": {
    "urls": [
      "https://bugzilla.redhat.com/show_bug.cgi?id=2341348"
    ],
    "summaries": [
      "signon-glib: FTBFS in Fedora rawhide/f42"
    ]
  },
  "snapm": {
    "urls": [],
    "summaries": []
  },
  "spglib": {
    "urls": [],
    "summaries": []
  },
  "ssh-audit": {
    "urls": [],
    "summaries": []
  },
  "subversion": {
    "urls": [
      "https://bugzilla.redhat.com/show_bug.cgi?id=2359500"
    ],
    "summaries": [
      "subversion fails to build with Python 3.14: AssertionError: 3 != 4 : Memory leak!  Expected a ref count of 4 for svn_merge_range_t object, but got 3 instead (path: b'/trunk', index: 0)"
    ]
  },
  "swift-lang": {
    "urls": [
      "https://bugzilla.redhat.com/show_bug.cgi?id=2341403"
    ],
    "summaries": [
      "swift-lang: FTBFS in Fedora rawhide/f42"
    ]
  },
  "sympy": {
    "urls": [],
    "summaries": []
  },
  "tbb": {
    "urls": [],
    "summaries": []
  },
  "thefuck": {
    "urls": [],
    "summaries": []
  },
  "trash-cli": {
    "urls": [],
    "summaries": []
  },
  "tree-sitter-java": {
    "urls": [],
    "summaries": []
  },
  "ufw": {
    "urls": [
      "https://bugzilla.redhat.com/show_bug.cgi?id=2341477"
    ],
    "summaries": [
      "ufw: FTBFS in Fedora rawhide/f42"
    ]
  },
  "uwsgi": {
    "urls": [
      "https://bugzilla.redhat.com/show_bug.cgi?id=2341497"
    ],
    "summaries": [
      "uwsgi: FTBFS in Fedora rawhide/f42"
    ]
  },
  "variety": {
    "urls": [],
    "summaries": []
  },
  "veusz": {
    "urls": [],
    "summaries": []
  },
  "visidata": {
    "urls": [
      "https://bugzilla.redhat.com/show_bug.cgi?id=2325446"
    ],
    "summaries": [
      "visidata fails to build with Python 3.14: TestVisidataPath.test_withName: AssertionError: assert 'foo' == 'foo.'"
    ]
  },
  "weasyprint": {
    "urls": [],
    "summaries": []
  },
  "xpra": {
    "urls": [
      "https://bugzilla.redhat.com/show_bug.cgi?id=2350289"
    ],
    "summaries": [
      "xpra fails to build from source with Python 3.14: RuntimeError: An attempt has been made to start a new process before the current process has finished its bootstrapping phase."
    ]
  },
  "yt-dlp": {
    "urls": [
      "https://bugzilla.redhat.com/show_bug.cgi?id=2345522"
    ],
    "summaries": [
      "yt-dlp fails to build with Python 3.14: TestTraversal.test_traversal_morsel: AssertionError: `...` should yield all values: Left contains one more item: 'item_value'"
    ]
  },
  "zeek": {
    "urls": [
      "https://bugzilla.redhat.com/show_bug.cgi?id=2341601"
    ],
    "summaries": [
      "zeek: FTBFS in Fedora rawhide/f42"
    ]
  }
}